Workbook

Sheet Summary
A1: Teman Journey - 2027 plan: profitable with both founders paid
A2: Goal for 2027: a business that is profitable on its own and pays both founders. Investors come later, after scale. All money in Rp million.
A3: Active scenario: | B3: =CHOOSE(Inputs!$C$6,"1. Base plan","2. No new B2B deal Jan-Jun 2027","3. BI cuts volume","4. Worst case (2 + 3)") -> 1. Base plan
A4: Active price plan: | B4: =CHOOSE(Inputs!$C$85,"1. Current prices","2. New rate card") -> 2. New rate card
A5: Question | B5: Answer | C5: Unit | D5: What it means
A6: A. Is 2027 profitable?
A7: Revenue FY 2027 | B7: =PnL!$D$12 -> 1501.5 | C7: Rp m | D7: Total sales booked in 2027.
A8: Gross profit FY 2027 | B8: =PnL!$D$23 -> 1018.05 | C8: Rp m | D8: Revenue minus delivery cost.
A9: Total fixed cost FY 2027 | B9: =PnL!$D$31 -> 632.159 | C9: Rp m | D9: Base + founders + sales + delivery steps.
A10: of which founder salaries | B10: =PnL!$D$28 -> 300 | C10: Rp m | D10: Both founders, from the start month in Inputs.
A11: Net profit FY 2027 | B11: =PnL!$D$35 -> 378.3835 | C11: Rp m | D11: After founder salaries and tax.
A12: Net margin FY 2027 | B12: =PnL!$D$36 -> 0.25200366 | C12: % | D12: Net profit / revenue.
A13: Meets your target margin? | B13: =IF(PnL!$D$36>=Inputs!$C$82,"Yes","No") -> Yes | D13: Target is set in Inputs.
A14: Break-even: BI work needed per month (in KPW-event equivalents) | B14: =IF(Unit_Economics!$G$5<=0,0,(PnL!$D$31/12-(PnL!$D$23-PnL!$D$6-PnL!$D$7+PnL!$D$15+PnL!$D$16)/12)/Unit_Economics!$G$5) -> 1.2984429 | C14: events | D14: With banks, EAP and B2C at plan, this many KPW-size BI events a month (or the same profit from Flagships) covers all 2027 fixed costs.
A15: B. Is cash safe? (Pillar 3)
A16: Lowest month-end cash (Oct 26 - Dec 27) | B16: =MIN(CashFlow!$E$21:$S$21) -> 203.52008 | C16: Rp m | D16: Must stay above zero.
A17: Month of lowest cash | B17: =INDEX(Volume!$E$4:$S$4,MATCH(MIN(CashFlow!$E$21:$S$21),CashFlow!$E$21:$S$21,0)) -> Oct-26 | D17: Where the squeeze is.
A18: Months below the cash floor | B18: =COUNTIF(CashFlow!$E$25:$S$25,0) -> 0 | C18: months | D18: Floor = 1 month fixed cost + delivery cost.
A19: Cash at end of 2027 | B19: =CashFlow!$D$21 -> 733.46125 | C19: Rp m
A20: Peak money owed by clients | B20: =CashFlow!$D$26 -> 130.95 | C20: Rp m | D20: Cash tied up in unpaid invoices.
A21: Runway at end of Dec 2026 if B2B stops | B21: =CashFlow!$G$21/(Capacity_OPEX!$H$32-((PnL!$D$10+PnL!$D$11-PnL!$D$19-PnL!$D$20)/12)) -> 7.9607976 | C21: months | D21: Months you survive on B2C alone with 2027 cost base.
A22: C. Can we deliver it? (Pillar 2)
A23: Peak facilitators needed in one month | B23: =Capacity_OPEX!$D$8 -> 7 | C23: people | D23: Compare with your plan of 11.
A24: Facilitators to certify by end 2027 | B24: =Capacity_OPEX!$D$9-Inputs!$C$35 -> 5 | C24: people
A25: Month the Project Manager is hired | B25: =IFERROR(INDEX(Volume!$E$4:$S$4,MATCH(1,Capacity_OPEX!$E$15:$S$15,0)),"Not needed") -> Dec-26 | D25: Triggered by the 3-month average of B2B events.
A26: D. What will investors ask? (risk)
A27: BI share of 2027 revenue | B27: =PnL!$D$41 -> 0.60727606 | C27: % | D27: Concentration risk. Lower is safer.
A28: B2B share of 2027 revenue | B28: =IF(PnL!$D$12=0,0,PnL!$D$42/PnL!$D$12) -> 0.91808192 | C28: %
A29: Q4 share of 2027 revenue | B29: =IF(PnL!$D$12=0,0,SUM(PnL!Q12:S12)/PnL!$D$12) -> 0.4015984 | C29: % | D29: Seasonality risk.
A30: Cost to win one new B2B client (CAC) | B30: =Unit_Economics!$B$13 -> 6 | C30: Rp m | D30: Sales spend / new clients.
A31: Memo: Coreitera revenue from TJ in 2027 | B31: =PnL!$D$43 -> 84 | C31: Rp m | D31: The 'tech' revenue line for the investor story.
A32: Memo: Theta revenue from TJ in 2027 | B32: =PnL!$D$44 -> 7.15 | C32: Rp m
A34: Scenario comparison (snapshot values - rebuilt each time the model is updated)
A35: Measure | B35: Old prices: Base | C35: New prices: Base | D35: New: No B2B Jan-Jun 27 | E35: New: BI -30% | F35: New: Worst case
A36: Revenue FY 2027 | B36: 1208 | C36: 1501.5 | D36: 1162.5 | E36: 1227.9525 | F36: 970.755
A37: Net profit FY 2027 | B37: 151.601 | C37: 378.3835 | D37: 142.8285 | E37: 252.63749 | F37: 73.834725
A38: Net margin FY 2027 | B38: 0.12549752 | C38: 0.25200366 | D38: 0.12286323 | E38: 0.20573881 | F38: 0.076059073
A39: Lowest month-end cash (Oct 26 - Dec 27) | B39: 203.52008 | C39: 203.52008 | D39: 179.52583 | E39: 199.44008 | F39: 161.00808
A40: Month of lowest cash | B40: Oct-26 | C40: Oct-26 | D40: Jul-27 | E40: Oct-26 | F40: Jul-27
A41: Months below the cash floor | B41: 0 | C41: 0 | D41: 0 | E41: 0 | F41: 0
...

Sheet Inputs
A1: Inputs and assumptions (all money in Rp million)
A2: Blue numbers are inputs you can change. Status: Known = you told us or it is in your v10 file; Your plan = your own budget; Estimate = industry estimate used until you give the real number (yellow-shaded, listed in the To_Fill sheet).
A4: Key | B4: Item | C4: Value | D4: Unit | E4: Status | F4: Source / logic
A5: 0. Scenario selector
A6: scen | B6: Active scenario (1-4) | C6: 1 | D6: number | E6: Known | F6: 1 = Base plan (v10 volumes). 2 = No new B2B event closes Jan-Jun 2027. 3 = BI cuts its volume by the % below. 4 = Both 2 and 3 (worst case).
A7: bi_cut | B7: BI volume cut used in scenarios 3 and 4 | C7: 0.3 | D7: % | E7: Known | F7: Stress test size. Change freely.
A8: 1. Prices (per event, or per month for EAP)
A9: p_flag | B9: Flagship regulator ToT (CBP Rupiah) | C9: 85 | D9: Rp m / event | E9: Known | F9: Your v10 file.
A10: p_kpw | B10: Regulator regional ToT (BI KPW and LPS) | C10: 20 | D10: Rp m / event | E10: Known | F10: Your v10 file.
A11: p_kcp | B11: Bank branch event (KCP) | C11: 35 | D11: Rp m / event | E11: Known | F11: Your v10 file.
A12: p_eap | B12: Bank EAP subscription | C12: 15 | D12: Rp m / month | E12: Known | F12: Your v10 file.
A13: p_b2ce | B13: B2C mass event | C13: 20 | D13: Rp m / event | E13: Known | F13: Your v10 file.
A14: p_b2cc | B14: B2C counseling client | C14: 1 | D14: Rp m / client | E14: Known | F14: Your v10 file (Rp 1,000,000 per session).
A15: 2. Delivery cost (cost of goods sold)
A16: c_flag | B16: Flagship delivery cost | C16: 25 | D16: Rp m / event | E16: Known | F16: Your v10 file: travel, hotel, materials, premium facilitator fees.
A17: c_kpw | B17: KPW / LPS delivery cost | C17: 8 | D17: Rp m / event | E17: Known | F17: Your v10 file. Covers about 2 handler fees only, so travel is assumed paid by the client (see below).
A18: c_kcp | B18: Bank KCP event delivery cost | C18: 12 | D18: Rp m / event | E18: Known | F18: Your v10 file.
A19: c_eap | B19: EAP delivery cost | C19: 5 | D19: Rp m / month | E19: Known | F19: Your v10 file: on-call tele-counseling retainer.
A20: c_b2ce | B20: B2C event delivery cost | C20: 8 | D20: Rp m / event | E20: Known | F20: Your v10 file: venue, ads, materials, fees.
A21: c_b2cc | B21: B2C counseling cost (psychologist fee) | C21: 0.4 | D21: % of price | E21: Known | F21: Your v10 file: Rp 400k of Rp 1m.
A22: travel_client | B22: Client pays travel for regional events? (1 = yes, 0 = no) | C22: 1 | D22: switch | E22: Estimate | F22: The Rp 8m KPW cost only covers 2 handler fees, so we assume BI pays travel.
A23: travel_pp | B23: Travel cost per handler per regional trip | C23: 3.5 | D23: Rp m / person | E23: Estimate | F23: Industry estimate: return flight ~Rp 2m + 2 hotel nights ~Rp 1m + per diem ~Rp 0.5m.
A24: regional_share | B24: Share of KPW / LPS events outside Jakarta | C24: 0.8 | D24: % | E24: Estimate | F24: Estimate: most KPW offices are outside Jakarta.
A25: 3. Delivery staffing (from your v10 file)
A26: h_flag | B26: Handlers per Flagship event | C26: 4 | D26: people | E26: Known | F26: 1 PM, 1 Lead Psychologist, 2 Facilitators.
A27: h_kpw | B27: Handlers per KPW / LPS event | C27: 2 | D27: people | E27: Known | F27: 1 Lead, 1 Facilitator.
A28: h_kcp | B28: Handlers per KCP event | C28: 2 | D28: people | E28: Known | F28: 1 Lead, 1 Facilitator.
A29: h_b2ce | B29: Handlers per B2C event | C29: 2 | D29: people | E29: Known | F29: 1 Lead, 1 Facilitator / Assistant.
A30: d_flag | B30: Days per Flagship event | C30: 3 | D30: days | E30: Estimate | F30: You said 2-3 day program; we use 3.
A31: d_kpw | B31: Days per KPW / LPS event | C31: 1 | D31: days | E31: Estimate | F31: Estimate.
A32: d_kcp | B32: Days per KCP event | C32: 1 | D32: days | E32: Estimate | F32: Estimate.
A33: d_b2ce | B33: Days per B2C event | C33: 1 | D33: days | E33: Estimate | F33: Estimate (weekend event).
A34: fac_cap | B34: Max events per facilitator per month | C34: 2 | D34: events | E34: Known | F34: Your v10 quality rule.
A35: fac_now | B35: Certified facilitators today | C35: 2 | D35: people | E35: Known | F35: You told us: 2 active core facilitators.
A36: fac_plan | B36: Your plan: facilitators certified by Nov 2026 | C36: 11 | D36: people | E36: Known | F36: Your earlier plan.
A37: cert_cost | B37: Cost to certify one new facilitator | C37: 2.5 | D37: Rp m / person | E37: Estimate | F37: Industry estimate: 2-day internal ToT, materials, observed practice event.
A38: 4. Fixed cost: base (your 2027 'bensin' budget, monthly)
A39: o_lead_mkt | B39: Lead Marketing | C39: 2.5 | D39: Rp m / month | E39: Known | F39: Your 2027 budget.
A40: o_socmed | B40: Social Media Specialist | C40: 1.5 | D40: Rp m / month | E40: Known | F40: Your 2027 budget.
A41: o_intern_mkt | B41: Marketing intern | C41: 1 | D41: Rp m / month | E41: Known | F41: Your 2027 budget.
...

Sheet Volume
A1: Event volume plan (from your v10 file, moved to Oct 2026 - Dec 2027)
A2: Rp million unless stated. Q4 2026 and FY 2027 columns are totals (or averages / peaks where stated).
A4: Line | B4: Unit | C4: Q4 2026 | D4: FY 2027 | E4: Oct-26 | F4: Nov-26 | G4: Dec-26 | H4: Jan-27 | I4: Feb-27 | J4: Mar-27 | K4: Apr-27 | L4: May-27 | M4: Jun-27 | N4: Jul-27 | O4: Aug-27 | P4: Sep-27 | Q4: Oct-27 | R4: Nov-27 | S4: Dec-27
A5: Timeline helpers
A6: Month number | B6: # | E6: 1 | F6: 2 | G6: 3 | H6: 4 | I6: 5 | J6: 6 | K6: 7 | L6: 8 | M6: 9 | N6: 10 | O6: 11 | P6: 12 | Q6: 13 | R6: 14 | S6: 15
A7: Is 2027? (1 = yes) | B7: flag | E7: 0 | F7: 0 | G7: 0 | H7: 1 | I7: 1 | J7: 1 | K7: 1 | L7: 1 | M7: 1 | N7: 1 | O7: 1 | P7: 1 | Q7: 1 | R7: 1 | S7: 1
A8: Is Jan-Jun 2027? (1 = yes) | B8: flag | E8: 0 | F8: 0 | G8: 0 | H8: 1 | I8: 1 | J8: 1 | K8: 1 | L8: 1 | M8: 1 | N8: 0 | O8: 0 | P8: 0 | Q8: 0 | R8: 0 | S8: 0
A9: Scenario switch: new B2B events allowed (1 = yes) | B9: flag | E9: =IF(AND(OR(Inputs!$C$6=2,Inputs!$C$6=4),E8=1),0,1) -> 1 | F9: =IF(AND(OR(Inputs!$C$6=2,Inputs!$C$6=4),F8=1),0,1) -> 1 | G9: =IF(AND(OR(Inputs!$C$6=2,Inputs!$C$6=4),G8=1),0,1) -> 1 | H9: =IF(AND(OR(Inputs!$C$6=2,Inputs!$C$6=4),H8=1),0,1) -> 1 | I9: =IF(AND(OR(Inputs!$C$6=2,Inputs!$C$6=4),I8=1),0,1) -> 1 | J9: =IF(AND(OR(Inputs!$C$6=2,Inputs!$C$6=4),J8=1),0,1) -> 1 | K9: =IF(AND(OR(Inputs!$C$6=2,Inputs!$C$6=4),K8=1),0,1) -> 1 | L9: =IF(AND(OR(Inputs!$C$6=2,Inputs!$C$6=4),L8=1),0,1) -> 1 | ... S9: =IF(AND(OR(Inputs!$C$6=2,Inputs!$C$6=4),S8=1),0,1) -> 1
A10: Scenario factor: BI volume | B10: x | E10: =IF(OR(Inputs!$C$6=3,Inputs!$C$6=4),1-Inputs!$C$7,1) -> 1 | F10: =IF(OR(Inputs!$C$6=3,Inputs!$C$6=4),1-Inputs!$C$7,1) -> 1 | G10: =IF(OR(Inputs!$C$6=3,Inputs!$C$6=4),1-Inputs!$C$7,1) -> 1 | H10: =IF(OR(Inputs!$C$6=3,Inputs!$C$6=4),1-Inputs!$C$7,1) -> 1 | I10: =IF(OR(Inputs!$C$6=3,Inputs!$C$6=4),1-Inputs!$C$7,1) -> 1 | J10: =IF(OR(Inputs!$C$6=3,Inputs!$C$6=4),1-Inputs!$C$7,1) -> 1 | K10: =IF(OR(Inputs!$C$6=3,Inputs!$C$6=4),1-Inputs!$C$7,1) -> 1 | L10: =IF(OR(Inputs!$C$6=3,Inputs!$C$6=4),1-Inputs!$C$7,1) -> 1 | ... S10: =IF(OR(Inputs!$C$6=3,Inputs!$C$6=4),1-Inputs!$C$7,1) -> 1
A11: New prices active this month? (1 = yes) | B11: flag | E11: =IF(AND(Inputs!$C$85=2,E6>=IFERROR(MATCH(Inputs!$C$86,$E$4:$S$4,0),99)),1,0) -> 0 | F11: =IF(AND(Inputs!$C$85=2,F6>=IFERROR(MATCH(Inputs!$C$86,$E$4:$S$4,0),99)),1,0) -> 0 | G11: =IF(AND(Inputs!$C$85=2,G6>=IFERROR(MATCH(Inputs!$C$86,$E$4:$S$4,0),99)),1,0) -> 0 | H11: =IF(AND(Inputs!$C$85=2,H6>=IFERROR(MATCH(Inputs!$C$86,$E$4:$S$4,0),99)),1,0) -> 1 | I11: =IF(AND(Inputs!$C$85=2,I6>=IFERROR(MATCH(Inputs!$C$86,$E$4:$S$4,0),99)),1,0) -> 1 | J11: =IF(AND(Inputs!$C$85=2,J6>=IFERROR(MATCH(Inputs!$C$86,$E$4:$S$4,0),99)),1,0) -> 1 | K11: =IF(AND(Inputs!$C$85=2,K6>=IFERROR(MATCH(Inputs!$C$86,$E$4:$S$4,0),99)),1,0) -> 1 | L11: =IF(AND(Inputs!$C$85=2,L6>=IFERROR(MATCH(Inputs!$C$86,$E$4:$S$4,0),99)),1,0) -> 1 | ... S11: =IF(AND(Inputs!$C$85=2,S6>=IFERROR(MATCH(Inputs!$C$86,$E$4:$S$4,0),99)),1,0) -> 1
A12: Price plan factor: B2B volume kept | B12: x | E12: =IF(E11=1,Inputs!$C$98,1) -> 1 | F12: =IF(F11=1,Inputs!$C$98,1) -> 1 | G12: =IF(G11=1,Inputs!$C$98,1) -> 1 | H12: =IF(H11=1,Inputs!$C$98,1) -> 1 | I12: =IF(I11=1,Inputs!$C$98,1) -> 1 | J12: =IF(J11=1,Inputs!$C$98,1) -> 1 | K12: =IF(K11=1,Inputs!$C$98,1) -> 1 | L12: =IF(L11=1,Inputs!$C$98,1) -> 1 | ... S12: =IF(S11=1,Inputs!$C$98,1) -> 1
A14: Base plan volumes (blue = your v10 plan; edit here)
A15: Flagship regulator ToT | B15: events | C15: =SUM(E15:G15) -> 1 | D15: =SUM(H15:S15) -> 5 | E15: 0 | F15: 1 | G15: 0 | H15: 0 | I15: 0 | J15: 1 | K15: 0 | L15: 1 | M15: 0 | N15: 1 | O15: 0 | P15: 1 | Q15: 0 | R15: 1 | S15: 0
A16: KPW / LPS regional ToT | B16: events | C16: =SUM(E16:G16) -> 10 | D16: =SUM(H16:S16) -> 17 | E16: 2 | F16: 3 | G16: 5 | H16: 0 | I16: 0 | J16: 1 | K16: 0 | L16: 1 | M16: 1 | N16: 1 | O16: 1 | P16: 2 | Q16: 2 | R16: 3 | S16: 5
A17: Bank KCP events | B17: events | C17: =SUM(E17:G17) -> 2 | D17: =SUM(H17:S17) -> 4 | E17: 1 | F17: 1 | G17: 0 | H17: 0 | I17: 0 | J17: 0 | K17: 1 | L17: 0 | M17: 0 | N17: 1 | O17: 0 | P17: 0 | Q17: 1 | R17: 1 | S17: 0
A18: Bank EAP contracts active | B18: contracts | C18: =MAX(E18:G18) -> 1 | D18: =MAX(H18:S18) -> 1 | E18: 1 | F18: 1 | G18: 1 | H18: 1 | I18: 1 | J18: 1 | K18: 1 | L18: 1 | M18: 1 | N18: 1 | O18: 1 | P18: 1 | Q18: 1 | R18: 1 | S18: 1
A19: B2C mass events | B19: events | C19: =SUM(E19:G19) -> 3 | D19: =SUM(H19:S19) -> 5 | E19: 1 | F19: 1 | G19: 1 | H19: 1 | I19: 1 | J19: 0 | K19: 0 | L19: 0 | M19: 0 | N19: 0 | O19: 0 | P19: 0 | Q19: 1 | R19: 1 | S19: 1
A20: B2C counseling clients | B20: clients | C20: =SUM(E20:G20) -> 6 | D20: =SUM(H20:S20) -> 23 | E20: 2 | F20: 2 | G20: 2 | H20: 3 | I20: 2 | J20: 1 | K20: 1 | L20: 0 | M20: 2 | N20: 1 | O20: 3 | P20: 4 | Q20: 2 | R20: 2 | S20: 2
A22: Volumes used in the model (after scenario)
A23: Flagship regulator ToT | B23: events | C23: =SUM(E23:G23) -> 1 | D23: =SUM(H23:S23) -> 5 | E23: =E15*E9*E12*E10 -> 0 | F23: =F15*F9*F12*F10 -> 1 | G23: =G15*G9*G12*G10 -> 0 | H23: =H15*H9*H12*H10 -> 0 | I23: =I15*I9*I12*I10 -> 0 | J23: =J15*J9*J12*J10 -> 1 | K23: =K15*K9*K12*K10 -> 0 | L23: =L15*L9*L12*L10 -> 1 | ... S23: =S15*S9*S12*S10 -> 0
A24: KPW / LPS regional ToT | B24: events | C24: =SUM(E24:G24) -> 10 | D24: =SUM(H24:S24) -> 17 | E24: =E16*E9*E12*(1-Inputs!$C$83*(1-E10)) -> 2 | F24: =F16*F9*F12*(1-Inputs!$C$83*(1-F10)) -> 3 | G24: =G16*G9*G12*(1-Inputs!$C$83*(1-G10)) -> 5 | H24: =H16*H9*H12*(1-Inputs!$C$83*(1-H10)) -> 0 | I24: =I16*I9*I12*(1-Inputs!$C$83*(1-I10)) -> 0 | J24: =J16*J9*J12*(1-Inputs!$C$83*(1-J10)) -> 1 | K24: =K16*K9*K12*(1-Inputs!$C$83*(1-K10)) -> 0 | L24: =L16*L9*L12*(1-Inputs!$C$83*(1-L10)) -> 1 | ... S24: =S16*S9*S12*(1-Inputs!$C$83*(1-S10)) -> 5
A25: Bank KCP events | B25: events | C25: =SUM(E25:G25) -> 2 | D25: =SUM(H25:S25) -> 4 | E25: =E17*E9*E12 -> 1 | F25: =F17*F9*F12 -> 1 | G25: =G17*G9*G12 -> 0 | H25: =H17*H9*H12 -> 0 | I25: =I17*I9*I12 -> 0 | J25: =J17*J9*J12 -> 0 | K25: =K17*K9*K12 -> 1 | L25: =L17*L9*L12 -> 0 | ... S25: =S17*S9*S12 -> 0
A26: Bank EAP contracts active (existing contract, not affected) | B26: contracts | C26: =MAX(E26:G26) -> 1 | D26: =MAX(H26:S26) -> 1 | E26: =E18 -> 1 | F26: =F18 -> 1 | G26: =G18 -> 1 | H26: =H18 -> 1 | I26: =I18 -> 1 | J26: =J18 -> 1 | K26: =K18 -> 1 | L26: =L18 -> 1 | ... S26: =S18 -> 1
A27: B2C mass events | B27: events | C27: =SUM(E27:G27) -> 3 | D27: =SUM(H27:S27) -> 5 | E27: =E19 -> 1 | F27: =F19 -> 1 | G27: =G19 -> 1 | H27: =H19 -> 1 | I27: =I19 -> 1 | J27: =J19 -> 0 | K27: =K19 -> 0 | L27: =L19 -> 0 | ... S27: =S19 -> 1
A28: B2C counseling clients | B28: clients | C28: =SUM(E28:G28) -> 6 | D28: =SUM(H28:S28) -> 23 | E28: =E20 -> 2 | F28: =F20 -> 2 | G28: =G20 -> 2 | H28: =H20 -> 3 | I28: =I20 -> 2 | J28: =J20 -> 1 | K28: =K20 -> 1 | L28: =L20 -> 0 | ... S28: =S20 -> 2
A29: Total B2B events (Flagship + KPW/LPS + KCP) | B29: events | C29: =SUM(E29:G29) -> 13 | D29: =SUM(H29:S29) -> 26 | E29: =E23+E24+E25 -> 3 | F29: =F23+F24+F25 -> 5 | G29: =G23+G24+G25 -> 5 | H29: =H23+H24+H25 -> 0 | I29: =I23+I24+I25 -> 0 | J29: =J23+J24+J25 -> 2 | K29: =K23+K24+K25 -> 1 | L29: =L23+L24+L25 -> 2 | ... S29: =S23+S24+S25 -> 5
A31: Notes: Oct-Dec 2026 uses your v10 Oct-Dec plan; 2027 uses your v10 Jan-Dec plan. EAP is set to 1 active contract in every month (v10 started it in May; please confirm it is live now).

Sheet Unit_Economics
A1: Pillar 1 - Unit economics and B2B customer acquisition cost (Rp million)
A3: Product | B3: Price | C3: Delivery cost | D3: Extra travel (if you pay) | E3: Coreitera fee (assessment cost) | F3: Total delivery cost | G3: Contribution (profit per event) | H3: Contribution % | I3: Price / external cost | J3: Meets your 3x rule? | K3: Handler-days | L3: Contribution per handler-day | M3: Coreitera revenue per event (memo) | N3: Old price (before new prices start) | O3: Old delivery cost
A4: Flagship regulator ToT | B4: =IF(Inputs!$C$85=2,Inputs!$C$87+Inputs!$C$93*Inputs!$C$63*Inputs!$C$92,Inputs!$C$9) -> 100 | C4: =Inputs!$C$16 -> 25 | D4: 0 | E4: =IF(Inputs!$C$85=2,Inputs!$C$93*Inputs!$C$63*Inputs!$C$62,IF(Inputs!$C$61=1,0,Inputs!$C$63*Inputs!$C$62)) -> 3 | F4: =C4+D4+E4 -> 28 | G4: =B4-F4 -> 72 | H4: =IF(B4=0,0,G4/B4) -> 0.72 | I4: =IF(C4+D4=0,0,B4/(C4+D4)) -> 4 | J4: =IF(I4>=3,"Yes","No - below 3x") -> Yes | K4: =Inputs!$C$26*Inputs!$C$30 -> 12 | L4: =IF(K4=0,0,G4/K4) -> 6 | M4: =Inputs!$C$63*Inputs!$C$62 -> 3 | N4: =Inputs!$C$9 -> 85 | O4: =C4+D4+IF(Inputs!$C$61=1,0,Inputs!$C$63*Inputs!$C$62) -> 25
A5: KPW / LPS regional ToT | B5: =IF(Inputs!$C$85=2,Inputs!$C$88+Inputs!$C$94*Inputs!$C$64*Inputs!$C$92,Inputs!$C$10) -> 28.5 | C5: =Inputs!$C$17 -> 8 | D5: =IF(Inputs!$C$22=1,0,Inputs!$C$27*Inputs!$C$23*Inputs!$C$24) -> 0 | E5: =IF(Inputs!$C$85=2,Inputs!$C$94*Inputs!$C$64*Inputs!$C$62,IF(Inputs!$C$61=1,0,Inputs!$C$64*Inputs!$C$62)) -> 2.25 | F5: =C5+D5+E5 -> 10.25 | G5: =B5-F5 -> 18.25 | H5: =IF(B5=0,0,G5/B5) -> 0.64035088 | I5: =IF(C5+D5=0,0,B5/(C5+D5)) -> 3.5625 | J5: =IF(I5>=3,"Yes","No - below 3x") -> Yes | K5: =Inputs!$C$27*Inputs!$C$31 -> 2 | L5: =IF(K5=0,0,G5/K5) -> 9.125 | M5: =Inputs!$C$64*Inputs!$C$62 -> 2.25 | N5: =Inputs!$C$10 -> 20 | O5: =C5+D5+IF(Inputs!$C$61=1,0,Inputs!$C$64*Inputs!$C$62) -> 8
A6: Bank KCP event | B6: =IF(Inputs!$C$85=2,(1-Inputs!$C$91)*Inputs!$C$89+Inputs!$C$91*Inputs!$C$90+Inputs!$C$95*Inputs!$C$65*Inputs!$C$92,Inputs!$C$11) -> 53.5 | C6: =Inputs!$C$18 -> 12 | D6: 0 | E6: =IF(Inputs!$C$85=2,Inputs!$C$95*Inputs!$C$65*Inputs!$C$62,IF(Inputs!$C$61=1,0,Inputs!$C$65*Inputs!$C$62)) -> 3 | F6: =C6+D6+E6 -> 15 | G6: =B6-F6 -> 38.5 | H6: =IF(B6=0,0,G6/B6) -> 0.71962617 | I6: =IF(C6+D6=0,0,B6/(C6+D6)) -> 4.4583333 | J6: =IF(I6>=3,"Yes","No - below 3x") -> Yes | K6: =Inputs!$C$28*Inputs!$C$32 -> 2 | L6: =IF(K6=0,0,G6/K6) -> 19.25 | M6: =Inputs!$C$65*Inputs!$C$62 -> 3 | N6: =Inputs!$C$11 -> 35 | O6: =C6+D6+IF(Inputs!$C$61=1,0,Inputs!$C$65*Inputs!$C$62) -> 12
A7: Bank EAP (per month) | B7: =Inputs!$C$12 -> 15 | C7: =Inputs!$C$19 -> 5 | D7: 0 | E7: 0 | F7: =C7+D7+E7 -> 5 | G7: =B7-F7 -> 10 | H7: =IF(B7=0,0,G7/B7) -> 0.66666667 | I7: =IF(C7+D7=0,0,B7/(C7+D7)) -> 3 | J7: =IF(I7>=3,"Yes","No - below 3x") -> Yes | K7: 0 | L7: =IF(K7=0,0,G7/K7) -> 0 | M7: 0 | N7: =Inputs!$C$12 -> 15 | O7: =C7+D7+0 -> 5
A8: B2C mass event | B8: =Inputs!$C$13 -> 20 | C8: =Inputs!$C$20 -> 8 | D8: 0 | E8: =IF(Inputs!$C$61=1,0,Inputs!$C$66*Inputs!$C$62) -> 0 | F8: =C8+D8+E8 -> 8 | G8: =B8-F8 -> 12 | H8: =IF(B8=0,0,G8/B8) -> 0.6 | I8: =IF(C8+D8=0,0,B8/(C8+D8)) -> 2.5 | J8: =IF(I8>=3,"Yes","No - below 3x") -> No - below 3x | K8: =Inputs!$C$29*Inputs!$C$33 -> 2 | L8: =IF(K8=0,0,G8/K8) -> 6 | M8: =Inputs!$C$66*Inputs!$C$62 -> 3.75 | N8: =Inputs!$C$13 -> 20 | O8: =C8+D8+IF(Inputs!$C$61=1,0,Inputs!$C$66*Inputs!$C$62) -> 8
A10: B2B customer acquisition cost (CAC)
A11: Sales cost per year (sales travel + Account Manager if hired; founder time not costed) | B11: =IF(Inputs!$C$52=1,(Inputs!$C$53+Inputs!$C$55)*12,Inputs!$C$55*12) -> 24
A12: New B2B clients won per year | B12: =Inputs!$C$70 -> 4
A13: CAC: cost to win one new B2B client | B13: =IF(B12=0,0,B11/B12) -> 6
A14: Events needed to pay back CAC: Flagship | B14: =IF(G4<=0,0,B13/G4) -> 0.083333333
A15: Events needed to pay back CAC: KPW / LPS | B15: =IF(G5<=0,0,B13/G5) -> 0.32876712
A16: Events needed to pay back CAC: Bank KCP | B16: =IF(G6<=0,0,B13/G6) -> 0.15584416
A17: Months of EAP needed to pay back CAC | B17: =IF(G7<=0,0,B13/G7) -> 0.6
A19: How to read: Contribution = price minus everything you pay to deliver that one event. It is what is left to pay fixed costs.
A20: Your pricing rule is price at least 3x the delivery cost paid outside the group (Coreitera fees stay inside). Rows marked 'No' break that rule.
A21: CAC counts only direct sales spend. Founder time is not costed here because founders are paid a fixed salary.
A22: Coreitera revenue per event is a memo: it is money paid between your own companies, so it cancels out in the combined profit.

Sheet Rate_Card
A1: Rate card - elite boutique pricing by client tier (Rp million)
A2: Rule: price close to the buyer's ceiling for regulators, and against the big-trainer alternative for banks. Never below 3x delivery cost. Prices here always show the new rate card, whatever the active price plan.
A4: Tier and product | B4: What caps the price | C4: Training price | D4: Days | E4: Price per day | F4: Assessment per participant | G4: Participants | H4: Package price (training + assessment) | I4: External delivery cost (excl. Coreitera) | J4: Price / external cost | K4: Meets 3x? | L4: Per day vs big-trainer rate | M4: Best contract shape
A5: Tier 1 regulator - Flagship ToT (BI, OJK, LPS) | B5: Budget ceiling per activity; past contracts set the anchor | C5: =Inputs!$C$87 -> 94 | D5: =Inputs!$C$30 -> 3 | E5: =IF(D5=0,0,C5/D5) -> 31.333333 | F5: =Inputs!$C$92*Inputs!$C$93 -> 0.15 | G5: =Inputs!$C$63 -> 40 | H5: =C5+F5*G5 -> 100 | I5: =Inputs!$C$16 -> 25 | J5: =IF(I5=0,0,H5/I5) -> 4 | K5: =IF(J5>=3,"Yes","No") -> Yes | L5: =IF((Inputs!$C$96*Inputs!$C$11)=0,0,E5/(Inputs!$C$96*Inputs!$C$11)) -> 0.35809524 | M5: Yearly framework contract with central procurement
A6: Tier 1 regulator - Regional ToT (BI KPW, LPS) | B6: Budget ceiling per activity | C6: =Inputs!$C$88 -> 24 | D6: =Inputs!$C$31 -> 1 | E6: =IF(D6=0,0,C6/D6) -> 24 | F6: =Inputs!$C$92*Inputs!$C$94 -> 0.15 | G6: =Inputs!$C$64 -> 30 | H6: =C6+F6*G6 -> 28.5 | I6: =Inputs!$C$17 -> 8 | J6: =IF(I6=0,0,H6/I6) -> 3.5625 | K6: =IF(J6>=3,"Yes","No") -> Yes | L6: =IF((Inputs!$C$96*Inputs!$C$11)=0,0,E6/(Inputs!$C$96*Inputs!$C$11)) -> 0.27428571 | M6: Framework + work order (SPK) per office
A7: State-owned bank (BRI, Mandiri, BNI, BTN) | B7: Vendor tender and price competition | C7: =Inputs!$C$89 -> 45 | D7: =Inputs!$C$32 -> 1 | E7: =IF(D7=0,0,C7/D7) -> 45 | F7: =Inputs!$C$92*Inputs!$C$95 -> 0.15 | G7: =Inputs!$C$65 -> 40 | H7: =C7+F7*G7 -> 51 | I7: =Inputs!$C$18 -> 12 | J7: =IF(I7=0,0,H7/I7) -> 4.25 | K7: =IF(J7>=3,"Yes","No") -> Yes | L7: =IF((Inputs!$C$96*Inputs!$C$11)=0,0,E7/(Inputs!$C$96*Inputs!$C$11)) -> 0.51428571 | M7: Multi-branch yearly framework (10+ groups), 30% down payment
A8: Private big bank (BCA and others) | B8: Value vs big trainers (2-3x your old rate) | C8: =Inputs!$C$90 -> 55 | D8: =Inputs!$C$32 -> 1 | E8: =IF(D8=0,0,C8/D8) -> 55 | F8: =Inputs!$C$92*Inputs!$C$95 -> 0.15 | G8: =Inputs!$C$65 -> 40 | H8: =C8+F8*G8 -> 61 | I8: =Inputs!$C$18 -> 12 | J8: =IF(I8=0,0,H8/I8) -> 5.0833333 | K8: =IF(J8>=3,"Yes","No") -> Yes | L8: =IF((Inputs!$C$96*Inputs!$C$11)=0,0,E8/(Inputs!$C$96*Inputs!$C$11)) -> 0.62857143 | M8: Annual learning partnership + EAP priced per employee
A9: Reference: big-trainer day rate charged to banks | B9: Your old bank rate x the multiple you gave (2-3x, midpoint). | E9: =(Inputs!$C$96*Inputs!$C$11) -> 87.5
A11: Bank packages (good / better / best) - per group per day
A12: Package | B12: What is included | C12: State-owned bank | E12: Private bank
A13: Essential | B13: Training day only | C13: =C7 -> 45 | E13: =C8 -> 55
A14: Signature (lead offer) | B14: Training + pre/post assessment + impact report | C14: =H7 -> 51 | E14: =H8 -> 61
A15: Elite | B15: Signature + cascade licence for trainers + 3 months follow-up | C15: =H7*(1+Inputs!$C$97) -> 66.3 | E15: =H8*(1+Inputs!$C$97) -> 79.3
A17: Volume-loss test: how many events can you lose and still earn more?
A18: Product | B18: Profit per event, old price | C18: Profit per event, new package | D18: Max share of events you can lose | E18: Meaning
A19: Flagship ToT | B19: =Inputs!$C$9-Inputs!$C$16 -> 60 | C19: =H5-I5-Inputs!$C$93*G5*Inputs!$C$62 -> 72 | D19: =IF(C19<=0,0,1-B19/C19) -> 0.16666667 | E19: ="Lose fewer than "&TEXT(D19,"0%")&" of these events and profit still goes up." -> Lose fewer than 17% of these events and profit still goes up.
A20: KPW / LPS ToT | B20: =Inputs!$C$10-Inputs!$C$17 -> 12 | C20: =H6-I6-Inputs!$C$94*G6*Inputs!$C$62 -> 18.25 | D20: =IF(C20<=0,0,1-B20/C20) -> 0.34246575 | E20: ="Lose fewer than "&TEXT(D20,"0%")&" of these events and profit still goes up." -> Lose fewer than 34% of these events and profit still goes up.
A21: Bank event (state-owned) | B21: =Inputs!$C$11-Inputs!$C$18 -> 23 | C21: =H7-I7-Inputs!$C$95*G7*Inputs!$C$62 -> 36 | D21: =IF(C21<=0,0,1-B21/C21) -> 0.36111111 | E21: ="Lose fewer than "&TEXT(D21,"0%")&" of these events and profit still goes up." -> Lose fewer than 36% of these events and profit still goes up.
A22: Bank event (private) | B22: =Inputs!$C$11-Inputs!$C$18 -> 23 | C22: =H8-I8-Inputs!$C$95*G8*Inputs!$C$62 -> 46 | D22: =IF(C22<=0,0,1-B22/C22) -> 0.5 | E22: ="Lose fewer than "&TEXT(D22,"0%")&" of these events and profit still goes up." -> Lose fewer than 50% of these events and profit still goes up.
A24: Pricing rules (all tiers)
A25: 1. Price units: per group per day (training), per participant (assessment), per employee per month (EAP), per year (cascade licence). Never one lump sum.
A26: 2. Floor: never below 3x the delivery cost paid outside the group. The Coreitera fee is excluded because it stays inside your own companies.
A27: 3. Pilot discount: at most 20%, once per client, recorded as a sales cost, and tied to a follow-on contract.
A28: 4. Volume discount: 5% for 5+ groups a year, 10% for 10+ groups. Never more than 10%.
A29: 5. Travel and venue: paid by the client, or billed at cost plus 10%.
A30: 6. Payment: 30% down payment for bank contracts above Rp100m. Regulators keep current terms.
A31: 7. Regulators: never raise the price of an old item. Add new items (assessment, licence, follow-up), which get a fresh budget ceiling.
A32: 8. Elite boutique position: always clearly below big trainers, never the cheapest. Compete on more services and a measured result.

Sheet Capacity_OPEX
A1: Pillar 2 - Capacity and step-function fixed costs
A2: Rp million unless stated. Q4 2026 and FY 2027 columns are totals (or averages / peaks where stated).
A4: Line | B4: Unit | C4: Q4 2026 | D4: FY 2027 | E4: Oct-26 | F4: Nov-26 | G4: Dec-26 | H4: Jan-27 | I4: Feb-27 | J4: Mar-27 | K4: Apr-27 | L4: May-27 | M4: Jun-27 | N4: Jul-27 | O4: Aug-27 | P4: Sep-27 | Q4: Oct-27 | R4: Nov-27 | S4: Dec-27
A5: Delivery capacity
A6: Handler placements (people x events) | B6: placements | C6: =SUM(E6:G6) -> 34 | D6: =SUM(H6:S6) -> 72 | E6: =Volume!E23*Inputs!$C$26+Volume!E24*Inputs!$C$27+Volume!E25*Inputs!$C$28+Volume!E27*Inputs!$C$29 -> 8 | F6: =Volume!F23*Inputs!$C$26+Volume!F24*Inputs!$C$27+Volume!F25*Inputs!$C$28+Volume!F27*Inputs!$C$29 -> 14 | G6: =Volume!G23*Inputs!$C$26+Volume!G24*Inputs!$C$27+Volume!G25*Inputs!$C$28+Volume!G27*Inputs!$C$29 -> 12 | H6: =Volume!H23*Inputs!$C$26+Volume!H24*Inputs!$C$27+Volume!H25*Inputs!$C$28+Volume!H27*Inputs!$C$29 -> 2 | I6: =Volume!I23*Inputs!$C$26+Volume!I24*Inputs!$C$27+Volume!I25*Inputs!$C$28+Volume!I27*Inputs!$C$29 -> 2 | J6: =Volume!J23*Inputs!$C$26+Volume!J24*Inputs!$C$27+Volume!J25*Inputs!$C$28+Volume!J27*Inputs!$C$29 -> 6 | K6: =Volume!K23*Inputs!$C$26+Volume!K24*Inputs!$C$27+Volume!K25*Inputs!$C$28+Volume!K27*Inputs!$C$29 -> 2 | L6: =Volume!L23*Inputs!$C$26+Volume!L24*Inputs!$C$27+Volume!L25*Inputs!$C$28+Volume!L27*Inputs!$C$29 -> 6 | ... S6: =Volume!S23*Inputs!$C$26+Volume!S24*Inputs!$C$27+Volume!S25*Inputs!$C$28+Volume!S27*Inputs!$C$29 -> 12
A7: Handler-days (placements x days per event) | B7: days | C7: =SUM(E7:G7) -> 42 | D7: =SUM(H7:S7) -> 112 | E7: =Volume!E23*Inputs!$C$26*Inputs!$C$30+Volume!E24*Inputs!$C$27*Inputs!$C$31+Volume!E25*Inputs!$C$28*Inputs!$C$32+Volume!E27*Inputs!$C$29*Inputs!$C$33 -> 8 | F7: =Volume!F23*Inputs!$C$26*Inputs!$C$30+Volume!F24*Inputs!$C$27*Inputs!$C$31+Volume!F25*Inputs!$C$28*Inputs!$C$32+Volume!F27*Inputs!$C$29*Inputs!$C$33 -> 22 | G7: =Volume!G23*Inputs!$C$26*Inputs!$C$30+Volume!G24*Inputs!$C$27*Inputs!$C$31+Volume!G25*Inputs!$C$28*Inputs!$C$32+Volume!G27*Inputs!$C$29*Inputs!$C$33 -> 12 | H7: =Volume!H23*Inputs!$C$26*Inputs!$C$30+Volume!H24*Inputs!$C$27*Inputs!$C$31+Volume!H25*Inputs!$C$28*Inputs!$C$32+Volume!H27*Inputs!$C$29*Inputs!$C$33 -> 2 | I7: =Volume!I23*Inputs!$C$26*Inputs!$C$30+Volume!I24*Inputs!$C$27*Inputs!$C$31+Volume!I25*Inputs!$C$28*Inputs!$C$32+Volume!I27*Inputs!$C$29*Inputs!$C$33 -> 2 | J7: =Volume!J23*Inputs!$C$26*Inputs!$C$30+Volume!J24*Inputs!$C$27*Inputs!$C$31+Volume!J25*Inputs!$C$28*Inputs!$C$32+Volume!J27*Inputs!$C$29*Inputs!$C$33 -> 14 | K7: =Volume!K23*Inputs!$C$26*Inputs!$C$30+Volume!K24*Inputs!$C$27*Inputs!$C$31+Volume!K25*Inputs!$C$28*Inputs!$C$32+Volume!K27*Inputs!$C$29*Inputs!$C$33 -> 2 | L7: =Volume!L23*Inputs!$C$26*Inputs!$C$30+Volume!L24*Inputs!$C$27*Inputs!$C$31+Volume!L25*Inputs!$C$28*Inputs!$C$32+Volume!L27*Inputs!$C$29*Inputs!$C$33 -> 14 | ... S7: =Volume!S23*Inputs!$C$26*Inputs!$C$30+Volume!S24*Inputs!$C$27*Inputs!$C$31+Volume!S25*Inputs!$C$28*Inputs!$C$32+Volume!S27*Inputs!$C$29*Inputs!$C$33 -> 12
A8: Facilitators needed this month (placements / max events each) | B8: people | C8: =MAX(E8:G8) -> 7 | D8: =MAX(H8:S8) -> 7 | E8: =ROUNDUP(E6/Inputs!$C$34,0) -> 4 | F8: =ROUNDUP(F6/Inputs!$C$34,0) -> 7 | G8: =ROUNDUP(G6/Inputs!$C$34,0) -> 6 | H8: =ROUNDUP(H6/Inputs!$C$34,0) -> 1 | I8: =ROUNDUP(I6/Inputs!$C$34,0) -> 1 | J8: =ROUNDUP(J6/Inputs!$C$34,0) -> 3 | K8: =ROUNDUP(K6/Inputs!$C$34,0) -> 1 | L8: =ROUNDUP(L6/Inputs!$C$34,0) -> 3 | ... S8: =ROUNDUP(S6/Inputs!$C$34,0) -> 6
A9: Certified facilitator pool (grows when needed, never shrinks) | B9: people | C9: =G9 -> 7 | D9: =S9 -> 7 | E9: =MAX(Inputs!$C$35,E8) -> 4 | F9: =MAX(E9,F8) -> 7 | G9: =MAX(F9,G8) -> 7 | H9: =MAX(G9,H8) -> 7 | I9: =MAX(H9,I8) -> 7 | J9: =MAX(I9,J8) -> 7 | K9: =MAX(J9,K8) -> 7 | L9: =MAX(K9,L8) -> 7 | M9: =MAX(L9,M8) -> 7 | ... S9: =MAX(R9,S8) -> 7
A10: New facilitators to certify this month | B10: people | C10: =SUM(E10:G10) -> 5 | D10: =SUM(H10:S10) -> 0 | E10: =E9-Inputs!$C$35 -> 2 | F10: =F9-E9 -> 3 | G10: =G9-F9 -> 0 | H10: =H9-G9 -> 0 | I10: =I9-H9 -> 0 | J10: =J9-I9 -> 0 | K10: =K9-J9 -> 0 | L10: =L9-K9 -> 0 | M10: =M9-L9 -> 0 | ... S10: =S9-R9 -> 0
A11: Your plan (11 by Nov 2026) minus need: spare facilitators | B11: people | C11: =MIN(E11:G11) -> 4 | D11: =MIN(H11:S11) -> 4 | E11: =Inputs!$C$36-E8 -> 7 | F11: =Inputs!$C$36-F8 -> 4 | G11: =Inputs!$C$36-G8 -> 5 | H11: =Inputs!$C$36-H8 -> 10 | I11: =Inputs!$C$36-I8 -> 10 | J11: =Inputs!$C$36-J8 -> 8 | K11: =Inputs!$C$36-K8 -> 10 | L11: =Inputs!$C$36-L8 -> 8 | ... S11: =Inputs!$C$36-S8 -> 5
A13: Step triggers
A14: B2B events, average of last 3 months | B14: events | C14: =MAX(E14:G14) -> 4.3333333 | D14: =MAX(H14:S14) -> 4.3333333 | E14: =AVERAGE(Volume!E29:E29) -> 3 | F14: =AVERAGE(Volume!E29:F29) -> 4 | G14: =AVERAGE(Volume!E29:G29) -> 4.3333333 | H14: =AVERAGE(Volume!F29:H29) -> 3.3333333 | I14: =AVERAGE(Volume!G29:I29) -> 1.6666667 | J14: =AVERAGE(Volume!H29:J29) -> 0.66666667 | K14: =AVERAGE(Volume!I29:K29) -> 1 | L14: =AVERAGE(Volume!J29:L29) -> 1.6666667 | M14: =AVERAGE(Volume!K29:M29) -> 1.3333333 | N14: =AVERAGE(Volume!L29:N29) -> 2 | ... S14: =AVERAGE(Volume!Q29:S29) -> 4.3333333
A15: Project Manager hired? (1 = yes; starts the month after the trigger) | B15: flag | C15: =G15 -> 1 | D15: =S15 -> 1 | E15: =0 -> 0 | F15: =IF(OR(E15=1,E14>=Inputs!$C$57),1,0) -> 0 | G15: =IF(OR(F15=1,F14>=Inputs!$C$57),1,0) -> 1 | H15: =IF(OR(G15=1,G14>=Inputs!$C$57),1,0) -> 1 | I15: =IF(OR(H15=1,H14>=Inputs!$C$57),1,0) -> 1 | J15: =IF(OR(I15=1,I14>=Inputs!$C$57),1,0) -> 1 | K15: =IF(OR(J15=1,J14>=Inputs!$C$57),1,0) -> 1 | L15: =IF(OR(K15=1,K14>=Inputs!$C$57),1,0) -> 1 | M15: =IF(OR(L15=1,L14>=Inputs!$C$57),1,0) -> 1 | ... S15: =IF(OR(R15=1,R14>=Inputs!$C$57),1,0) -> 1
A16: Account Manager active? (1 = yes) | B16: flag | C16: =G16 -> 0 | D16: =S16 -> 0 | E16: =IF(AND(Inputs!$C$52=1,Volume!E6>=IFERROR(MATCH(Inputs!$C$54,Volume!$E$4:$S$4,0),99)),1,0) -> 0 | F16: =IF(AND(Inputs!$C$52=1,Volume!F6>=IFERROR(MATCH(Inputs!$C$54,Volume!$E$4:$S$4,0),99)),1,0) -> 0 | G16: =IF(AND(Inputs!$C$52=1,Volume!G6>=IFERROR(MATCH(Inputs!$C$54,Volume!$E$4:$S$4,0),99)),1,0) -> 0 | H16: =IF(AND(Inputs!$C$52=1,Volume!H6>=IFERROR(MATCH(Inputs!$C$54,Volume!$E$4:$S$4,0),99)),1,0) -> 0 | I16: =IF(AND(Inputs!$C$52=1,Volume!I6>=IFERROR(MATCH(Inputs!$C$54,Volume!$E$4:$S$4,0),99)),1,0) -> 0 | J16: =IF(AND(Inputs!$C$52=1,Volume!J6>=IFERROR(MATCH(Inputs!$C$54,Volume!$E$4:$S$4,0),99)),1,0) -> 0 | K16: =IF(AND(Inputs!$C$52=1,Volume!K6>=IFERROR(MATCH(Inputs!$C$54,Volume!$E$4:$S$4,0),99)),1,0) -> 0 | L16: =IF(AND(Inputs!$C$52=1,Volume!L6>=IFERROR(MATCH(Inputs!$C$54,Volume!$E$4:$S$4,0),99)),1,0) -> 0 | ... S16: =IF(AND(Inputs!$C$52=1,Volume!S6>=IFERROR(MATCH(Inputs!$C$54,Volume!$E$4:$S$4,0),99)),1,0) -> 0
A17: Founder salaries active? (1 = yes) | B17: flag | C17: =G17 -> 0 | D17: =S17 -> 1 | E17: =IF(Volume!E6>=IFERROR(MATCH(Inputs!$C$51,Volume!$E$4:$S$4,0),99),1,0) -> 0 | F17: =IF(Volume!F6>=IFERROR(MATCH(Inputs!$C$51,Volume!$E$4:$S$4,0),99),1,0) -> 0 | G17: =IF(Volume!G6>=IFERROR(MATCH(Inputs!$C$51,Volume!$E$4:$S$4,0),99),1,0) -> 0 | H17: =IF(Volume!H6>=IFERROR(MATCH(Inputs!$C$51,Volume!$E$4:$S$4,0),99),1,0) -> 1 | I17: =IF(Volume!I6>=IFERROR(MATCH(Inputs!$C$51,Volume!$E$4:$S$4,0),99),1,0) -> 1 | J17: =IF(Volume!J6>=IFERROR(MATCH(Inputs!$C$51,Volume!$E$4:$S$4,0),99),1,0) -> 1 | K17: =IF(Volume!K6>=IFERROR(MATCH(Inputs!$C$51,Volume!$E$4:$S$4,0),99),1,0) -> 1 | L17: =IF(Volume!L6>=IFERROR(MATCH(Inputs!$C$51,Volume!$E$4:$S$4,0),99),1,0) -> 1 | ... S17: =IF(Volume!S6>=IFERROR(MATCH(Inputs!$C$51,Volume!$E$4:$S$4,0),99),1,0) -> 1
A18: Invoices to send this month | B18: invoices | C18: =MAX(E18:G18) -> 8.33 | D18: =MAX(H18:S18) -> 8.33 | E18: =Volume!E23+Volume!E24+Volume!E25+Volume!E26+Volume!E27+Inputs!$C$59 -> 6.33 | F18: =Volume!F23+Volume!F24+Volume!F25+Volume!F26+Volume!F27+Inputs!$C$59 -> 8.33 | G18: =Volume!G23+Volume!G24+Volume!G25+Volume!G26+Volume!G27+Inputs!$C$59 -> 8.33 | H18: =Volume!H23+Volume!H24+Volume!H25+Volume!H26+Volume!H27+Inputs!$C$59 -> 3.33 | I18: =Volume!I23+Volume!I24+Volume!I25+Volume!I26+Volume!I27+Inputs!$C$59 -> 3.33 | J18: =Volume!J23+Volume!J24+Volume!J25+Volume!J26+Volume!J27+Inputs!$C$59 -> 4.33 | K18: =Volume!K23+Volume!K24+Volume!K25+Volume!K26+Volume!K27+Inputs!$C$59 -> 3.33 | L18: =Volume!L23+Volume!L24+Volume!L25+Volume!L26+Volume!L27+Inputs!$C$59 -> 4.33 | ... S18: =Volume!S23+Volume!S24+Volume!S25+Volume!S26+Volume!S27+Inputs!$C$59 -> 8.33
A19: Second admin hired? (1 = yes; stays once hired) | B19: flag | C19: =G19 -> 0 | D19: =S19 -> 0 | E19: =IF(E18>Inputs!$C$58,1,0) -> 0 | F19: =IF(OR(E19=1,F18>Inputs!$C$58),1,0) -> 0 | G19: =IF(OR(F19=1,G18>Inputs!$C$58),1,0) -> 0 | H19: =IF(OR(G19=1,H18>Inputs!$C$58),1,0) -> 0 | I19: =IF(OR(H19=1,I18>Inputs!$C$58),1,0) -> 0 | J19: =IF(OR(I19=1,J18>Inputs!$C$58),1,0) -> 0 | K19: =IF(OR(J19=1,K18>Inputs!$C$58),1,0) -> 0 | L19: =IF(OR(K19=1,L18>Inputs!$C$58),1,0) -> 0 | M19: =IF(OR(L19=1,M18>Inputs!$C$58),1,0) -> 0 | ... S19: =IF(OR(R19=1,S18>Inputs!$C$58),1,0) -> 0
A21: Fixed costs per month (Rp million)
A22: L0 Base team (your 2027 list: 6 people) | B22: Rp m | C22: =SUM(E22:G22) -> 33.9 | D22: =SUM(H22:S22) -> 135.6 | E22: =Inputs!$C$39+Inputs!$C$40+Inputs!$C$41+Inputs!$C$42+Inputs!$C$43+Inputs!$C$44 -> 11.3 | F22: =Inputs!$C$39+Inputs!$C$40+Inputs!$C$41+Inputs!$C$42+Inputs!$C$43+Inputs!$C$44 -> 11.3 | G22: =Inputs!$C$39+Inputs!$C$40+Inputs!$C$41+Inputs!$C$42+Inputs!$C$43+Inputs!$C$44 -> 11.3 | H22: =Inputs!$C$39+Inputs!$C$40+Inputs!$C$41+Inputs!$C$42+Inputs!$C$43+Inputs!$C$44 -> 11.3 | I22: =Inputs!$C$39+Inputs!$C$40+Inputs!$C$41+Inputs!$C$42+Inputs!$C$43+Inputs!$C$44 -> 11.3 | J22: =Inputs!$C$39+Inputs!$C$40+Inputs!$C$41+Inputs!$C$42+Inputs!$C$43+Inputs!$C$44 -> 11.3 | K22: =Inputs!$C$39+Inputs!$C$40+Inputs!$C$41+Inputs!$C$42+Inputs!$C$43+Inputs!$C$44 -> 11.3 | L22: =Inputs!$C$39+Inputs!$C$40+Inputs!$C$41+Inputs!$C$42+Inputs!$C$43+Inputs!$C$44 -> 11.3 | ... S22: =Inputs!$C$39+Inputs!$C$40+Inputs!$C$41+Inputs!$C$42+Inputs!$C$43+Inputs!$C$44 -> 11.3
A23: L0 Software and IG ads | B23: Rp m | C23: =SUM(E23:G23) -> 6.23975 | D23: =SUM(H23:S23) -> 24.959 | E23: =Inputs!$C$45 -> 2.0799167 | F23: =Inputs!$C$45 -> 2.0799167 | G23: =Inputs!$C$45 -> 2.0799167 | H23: =Inputs!$C$45 -> 2.0799167 | I23: =Inputs!$C$45 -> 2.0799167 | J23: =Inputs!$C$45 -> 2.0799167 | K23: =Inputs!$C$45 -> 2.0799167 | L23: =Inputs!$C$45 -> 2.0799167 | ... S23: =Inputs!$C$45 -> 2.0799167
A24: L0 Office | B24: Rp m | C24: =SUM(E24:G24) -> 17.4 | D24: =SUM(H24:S24) -> 69.6 | E24: =Inputs!$C$46 -> 5.8 | F24: =Inputs!$C$46 -> 5.8 | G24: =Inputs!$C$46 -> 5.8 | H24: =Inputs!$C$46 -> 5.8 | I24: =Inputs!$C$46 -> 5.8 | J24: =Inputs!$C$46 -> 5.8 | K24: =Inputs!$C$46 -> 5.8 | L24: =Inputs!$C$46 -> 5.8 | ... S24: =Inputs!$C$46 -> 5.8
A25: L0 Accountant / tax (estimate) | B25: Rp m | C25: =SUM(E25:G25) -> 4.5 | D25: =SUM(H25:S25) -> 18 | E25: =Inputs!$C$47 -> 1.5 | F25: =Inputs!$C$47 -> 1.5 | G25: =Inputs!$C$47 -> 1.5 | H25: =Inputs!$C$47 -> 1.5 | I25: =Inputs!$C$47 -> 1.5 | J25: =Inputs!$C$47 -> 1.5 | K25: =Inputs!$C$47 -> 1.5 | L25: =Inputs!$C$47 -> 1.5 | ... S25: =Inputs!$C$47 -> 1.5
A26: Founder salaries | B26: Rp m | C26: =SUM(E26:G26) -> 0 | D26: =SUM(H26:S26) -> 300 | E26: =E17*(Inputs!$C$49+Inputs!$C$50) -> 0 | F26: =F17*(Inputs!$C$49+Inputs!$C$50) -> 0 | G26: =G17*(Inputs!$C$49+Inputs!$C$50) -> 0 | H26: =H17*(Inputs!$C$49+Inputs!$C$50) -> 25 | I26: =I17*(Inputs!$C$49+Inputs!$C$50) -> 25 | J26: =J17*(Inputs!$C$49+Inputs!$C$50) -> 25 | K26: =K17*(Inputs!$C$49+Inputs!$C$50) -> 25 | L26: =L17*(Inputs!$C$49+Inputs!$C$50) -> 25 | ... S26: =S17*(Inputs!$C$49+Inputs!$C$50) -> 25
A27: L1 Account Manager | B27: Rp m | C27: =SUM(E27:G27) -> 0 | D27: =SUM(H27:S27) -> 0 | E27: =E16*Inputs!$C$53 -> 0 | F27: =F16*Inputs!$C$53 -> 0 | G27: =G16*Inputs!$C$53 -> 0 | H27: =H16*Inputs!$C$53 -> 0 | I27: =I16*Inputs!$C$53 -> 0 | J27: =J16*Inputs!$C$53 -> 0 | K27: =K16*Inputs!$C$53 -> 0 | L27: =L16*Inputs!$C$53 -> 0 | ... S27: =S16*Inputs!$C$53 -> 0
A28: L1 Sales travel (founders or AM) | B28: Rp m | C28: =SUM(E28:G28) -> 0 | D28: =SUM(H28:S28) -> 24 | E28: =IF(Volume!E6>=IFERROR(MATCH(Inputs!$C$54,Volume!$E$4:$S$4,0),99),Inputs!$C$55,0) -> 0 | F28: =IF(Volume!F6>=IFERROR(MATCH(Inputs!$C$54,Volume!$E$4:$S$4,0),99),Inputs!$C$55,0) -> 0 | G28: =IF(Volume!G6>=IFERROR(MATCH(Inputs!$C$54,Volume!$E$4:$S$4,0),99),Inputs!$C$55,0) -> 0 | H28: =IF(Volume!H6>=IFERROR(MATCH(Inputs!$C$54,Volume!$E$4:$S$4,0),99),Inputs!$C$55,0) -> 2 | I28: =IF(Volume!I6>=IFERROR(MATCH(Inputs!$C$54,Volume!$E$4:$S$4,0),99),Inputs!$C$55,0) -> 2 | J28: =IF(Volume!J6>=IFERROR(MATCH(Inputs!$C$54,Volume!$E$4:$S$4,0),99),Inputs!$C$55,0) -> 2 | K28: =IF(Volume!K6>=IFERROR(MATCH(Inputs!$C$54,Volume!$E$4:$S$4,0),99),Inputs!$C$55,0) -> 2 | L28: =IF(Volume!L6>=IFERROR(MATCH(Inputs!$C$54,Volume!$E$4:$S$4,0),99),Inputs!$C$55,0) -> 2 | ... S28: =IF(Volume!S6>=IFERROR(MATCH(Inputs!$C$54,Volume!$E$4:$S$4,0),99),Inputs!$C$55,0) -> 2
A29: L2 Project Manager | B29: Rp m | C29: =SUM(E29:G29) -> 5 | D29: =SUM(H29:S29) -> 60 | E29: =E15*Inputs!$C$56 -> 0 | F29: =F15*Inputs!$C$56 -> 0 | G29: =G15*Inputs!$C$56 -> 5 | H29: =H15*Inputs!$C$56 -> 5 | I29: =I15*Inputs!$C$56 -> 5 | J29: =J15*Inputs!$C$56 -> 5 | K29: =K15*Inputs!$C$56 -> 5 | L29: =L15*Inputs!$C$56 -> 5 | ... S29: =S15*Inputs!$C$56 -> 5
A30: L2 Second admin | B30: Rp m | C30: =SUM(E30:G30) -> 0 | D30: =SUM(H30:S30) -> 0 | E30: =E19*Inputs!$C$43 -> 0 | F30: =F19*Inputs!$C$43 -> 0 | G30: =G19*Inputs!$C$43 -> 0 | H30: =H19*Inputs!$C$43 -> 0 | I30: =I19*Inputs!$C$43 -> 0 | J30: =J19*Inputs!$C$43 -> 0 | K30: =K19*Inputs!$C$43 -> 0 | L30: =L19*Inputs!$C$43 -> 0 | ... S30: =S19*Inputs!$C$43 -> 0
A31: L3 Facilitator certification (one-off) | B31: Rp m | C31: =SUM(E31:G31) -> 12.5 | D31: =SUM(H31:S31) -> 0 | E31: =E10*Inputs!$C$37 -> 5 | F31: =F10*Inputs!$C$37 -> 7.5 | G31: =G10*Inputs!$C$37 -> 0 | H31: =H10*Inputs!$C$37 -> 0 | I31: =I10*Inputs!$C$37 -> 0 | J31: =J10*Inputs!$C$37 -> 0 | K31: =K10*Inputs!$C$37 -> 0 | L31: =L10*Inputs!$C$37 -> 0 | ... S31: =S10*Inputs!$C$37 -> 0
A32: Total fixed cost | B32: Rp m | C32: =SUM(E32:G32) -> 79.53975 | D32: =SUM(H32:S32) -> 632.159 | E32: =SUM(E22:E31) -> 25.679917 | F32: =SUM(F22:F31) -> 28.179917 | G32: =SUM(G22:G31) -> 25.679917 | H32: =SUM(H22:H31) -> 52.679917 | I32: =SUM(I22:I31) -> 52.679917 | J32: =SUM(J22:J31) -> 52.679917 | K32: =SUM(K22:K31) -> 52.679917 | L32: =SUM(L22:L31) -> 52.679917 | ... S32: =SUM(S22:S31) -> 52.679917

Sheet PnL
A1: Profit and loss by month (Rp million) - money counted when the event is delivered
A2: Rp million unless stated. Q4 2026 and FY 2027 columns are totals (or averages / peaks where stated).
A4: Line | B4: Unit | C4: Q4 2026 | D4: FY 2027 | E4: Oct-26 | F4: Nov-26 | G4: Dec-26 | H4: Jan-27 | I4: Feb-27 | J4: Mar-27 | K4: Apr-27 | L4: May-27 | M4: Jun-27 | N4: Jul-27 | O4: Aug-27 | P4: Sep-27 | Q4: Oct-27 | R4: Nov-27 | S4: Dec-27
A5: Revenue
A6: Flagship regulator ToT | B6: Rp m | C6: =SUM(E6:G6) -> 85 | D6: =SUM(H6:S6) -> 500 | E6: =Volume!E23*IF(Volume!E11=1,Unit_Economics!$B$4,Unit_Economics!$N$4) -> 0 | F6: =Volume!F23*IF(Volume!F11=1,Unit_Economics!$B$4,Unit_Economics!$N$4) -> 85 | G6: =Volume!G23*IF(Volume!G11=1,Unit_Economics!$B$4,Unit_Economics!$N$4) -> 0 | H6: =Volume!H23*IF(Volume!H11=1,Unit_Economics!$B$4,Unit_Economics!$N$4) -> 0 | I6: =Volume!I23*IF(Volume!I11=1,Unit_Economics!$B$4,Unit_Economics!$N$4) -> 0 | J6: =Volume!J23*IF(Volume!J11=1,Unit_Economics!$B$4,Unit_Economics!$N$4) -> 100 | K6: =Volume!K23*IF(Volume!K11=1,Unit_Economics!$B$4,Unit_Economics!$N$4) -> 0 | L6: =Volume!L23*IF(Volume!L11=1,Unit_Economics!$B$4,Unit_Economics!$N$4) -> 100 | ... S6: =Volume!S23*IF(Volume!S11=1,Unit_Economics!$B$4,Unit_Economics!$N$4) -> 0
A7: KPW / LPS regional ToT | B7: Rp m | C7: =SUM(E7:G7) -> 200 | D7: =SUM(H7:S7) -> 484.5 | E7: =Volume!E24*IF(Volume!E11=1,Unit_Economics!$B$5,Unit_Economics!$N$5) -> 40 | F7: =Volume!F24*IF(Volume!F11=1,Unit_Economics!$B$5,Unit_Economics!$N$5) -> 60 | G7: =Volume!G24*IF(Volume!G11=1,Unit_Economics!$B$5,Unit_Economics!$N$5) -> 100 | H7: =Volume!H24*IF(Volume!H11=1,Unit_Economics!$B$5,Unit_Economics!$N$5) -> 0 | I7: =Volume!I24*IF(Volume!I11=1,Unit_Economics!$B$5,Unit_Economics!$N$5) -> 0 | J7: =Volume!J24*IF(Volume!J11=1,Unit_Economics!$B$5,Unit_Economics!$N$5) -> 28.5 | K7: =Volume!K24*IF(Volume!K11=1,Unit_Economics!$B$5,Unit_Economics!$N$5) -> 0 | L7: =Volume!L24*IF(Volume!L11=1,Unit_Economics!$B$5,Unit_Economics!$N$5) -> 28.5 | ... S7: =Volume!S24*IF(Volume!S11=1,Unit_Economics!$B$5,Unit_Economics!$N$5) -> 142.5
A8: Bank KCP events | B8: Rp m | C8: =SUM(E8:G8) -> 70 | D8: =SUM(H8:S8) -> 214 | E8: =Volume!E25*IF(Volume!E11=1,Unit_Economics!$B$6,Unit_Economics!$N$6) -> 35 | F8: =Volume!F25*IF(Volume!F11=1,Unit_Economics!$B$6,Unit_Economics!$N$6) -> 35 | G8: =Volume!G25*IF(Volume!G11=1,Unit_Economics!$B$6,Unit_Economics!$N$6) -> 0 | H8: =Volume!H25*IF(Volume!H11=1,Unit_Economics!$B$6,Unit_Economics!$N$6) -> 0 | I8: =Volume!I25*IF(Volume!I11=1,Unit_Economics!$B$6,Unit_Economics!$N$6) -> 0 | J8: =Volume!J25*IF(Volume!J11=1,Unit_Economics!$B$6,Unit_Economics!$N$6) -> 0 | K8: =Volume!K25*IF(Volume!K11=1,Unit_Economics!$B$6,Unit_Economics!$N$6) -> 53.5 | L8: =Volume!L25*IF(Volume!L11=1,Unit_Economics!$B$6,Unit_Economics!$N$6) -> 0 | ... S8: =Volume!S25*IF(Volume!S11=1,Unit_Economics!$B$6,Unit_Economics!$N$6) -> 0
A9: Bank EAP | B9: Rp m | C9: =SUM(E9:G9) -> 45 | D9: =SUM(H9:S9) -> 180 | E9: =Volume!E26*IF(Volume!E11=1,Unit_Economics!$B$7,Unit_Economics!$N$7) -> 15 | F9: =Volume!F26*IF(Volume!F11=1,Unit_Economics!$B$7,Unit_Economics!$N$7) -> 15 | G9: =Volume!G26*IF(Volume!G11=1,Unit_Economics!$B$7,Unit_Economics!$N$7) -> 15 | H9: =Volume!H26*IF(Volume!H11=1,Unit_Economics!$B$7,Unit_Economics!$N$7) -> 15 | I9: =Volume!I26*IF(Volume!I11=1,Unit_Economics!$B$7,Unit_Economics!$N$7) -> 15 | J9: =Volume!J26*IF(Volume!J11=1,Unit_Economics!$B$7,Unit_Economics!$N$7) -> 15 | K9: =Volume!K26*IF(Volume!K11=1,Unit_Economics!$B$7,Unit_Economics!$N$7) -> 15 | L9: =Volume!L26*IF(Volume!L11=1,Unit_Economics!$B$7,Unit_Economics!$N$7) -> 15 | ... S9: =Volume!S26*IF(Volume!S11=1,Unit_Economics!$B$7,Unit_Economics!$N$7) -> 15
A10: B2C mass events | B10: Rp m | C10: =SUM(E10:G10) -> 60 | D10: =SUM(H10:S10) -> 100 | E10: =Volume!E27*IF(Volume!E11=1,Unit_Economics!$B$8,Unit_Economics!$N$8) -> 20 | F10: =Volume!F27*IF(Volume!F11=1,Unit_Economics!$B$8,Unit_Economics!$N$8) -> 20 | G10: =Volume!G27*IF(Volume!G11=1,Unit_Economics!$B$8,Unit_Economics!$N$8) -> 20 | H10: =Volume!H27*IF(Volume!H11=1,Unit_Economics!$B$8,Unit_Economics!$N$8) -> 20 | I10: =Volume!I27*IF(Volume!I11=1,Unit_Economics!$B$8,Unit_Economics!$N$8) -> 20 | J10: =Volume!J27*IF(Volume!J11=1,Unit_Economics!$B$8,Unit_Economics!$N$8) -> 0 | K10: =Volume!K27*IF(Volume!K11=1,Unit_Economics!$B$8,Unit_Economics!$N$8) -> 0 | L10: =Volume!L27*IF(Volume!L11=1,Unit_Economics!$B$8,Unit_Economics!$N$8) -> 0 | ... S10: =Volume!S27*IF(Volume!S11=1,Unit_Economics!$B$8,Unit_Economics!$N$8) -> 20
A11: B2C counseling | B11: Rp m | C11: =SUM(E11:G11) -> 6 | D11: =SUM(H11:S11) -> 23 | E11: =Volume!E28*Inputs!$C$14 -> 2 | F11: =Volume!F28*Inputs!$C$14 -> 2 | G11: =Volume!G28*Inputs!$C$14 -> 2 | H11: =Volume!H28*Inputs!$C$14 -> 3 | I11: =Volume!I28*Inputs!$C$14 -> 2 | J11: =Volume!J28*Inputs!$C$14 -> 1 | K11: =Volume!K28*Inputs!$C$14 -> 1 | L11: =Volume!L28*Inputs!$C$14 -> 0 | ... S11: =Volume!S28*Inputs!$C$14 -> 2
A12: Total revenue | B12: Rp m | C12: =SUM(E12:G12) -> 466 | D12: =SUM(H12:S12) -> 1501.5 | E12: =SUM(E6:E11) -> 112 | F12: =SUM(F6:F11) -> 217 | G12: =SUM(G6:G11) -> 137 | H12: =SUM(H6:H11) -> 38 | I12: =SUM(I6:I11) -> 37 | J12: =SUM(J6:J11) -> 144.5 | K12: =SUM(K6:K11) -> 69.5 | L12: =SUM(L6:L11) -> 143.5 | ... S12: =SUM(S6:S11) -> 179.5
A14: Delivery cost
A15: Flagship | B15: Rp m | C15: =SUM(E15:G15) -> 25 | D15: =SUM(H15:S15) -> 140 | E15: =Volume!E23*IF(Volume!E11=1,Unit_Economics!$F$4,Unit_Economics!$O$4) -> 0 | F15: =Volume!F23*IF(Volume!F11=1,Unit_Economics!$F$4,Unit_Economics!$O$4) -> 25 | G15: =Volume!G23*IF(Volume!G11=1,Unit_Economics!$F$4,Unit_Economics!$O$4) -> 0 | H15: =Volume!H23*IF(Volume!H11=1,Unit_Economics!$F$4,Unit_Economics!$O$4) -> 0 | I15: =Volume!I23*IF(Volume!I11=1,Unit_Economics!$F$4,Unit_Economics!$O$4) -> 0 | J15: =Volume!J23*IF(Volume!J11=1,Unit_Economics!$F$4,Unit_Economics!$O$4) -> 28 | K15: =Volume!K23*IF(Volume!K11=1,Unit_Economics!$F$4,Unit_Economics!$O$4) -> 0 | L15: =Volume!L23*IF(Volume!L11=1,Unit_Economics!$F$4,Unit_Economics!$O$4) -> 28 | ... S15: =Volume!S23*IF(Volume!S11=1,Unit_Economics!$F$4,Unit_Economics!$O$4) -> 0
A16: KPW / LPS | B16: Rp m | C16: =SUM(E16:G16) -> 80 | D16: =SUM(H16:S16) -> 174.25 | E16: =Volume!E24*IF(Volume!E11=1,Unit_Economics!$F$5,Unit_Economics!$O$5) -> 16 | F16: =Volume!F24*IF(Volume!F11=1,Unit_Economics!$F$5,Unit_Economics!$O$5) -> 24 | G16: =Volume!G24*IF(Volume!G11=1,Unit_Economics!$F$5,Unit_Economics!$O$5) -> 40 | H16: =Volume!H24*IF(Volume!H11=1,Unit_Economics!$F$5,Unit_Economics!$O$5) -> 0 | I16: =Volume!I24*IF(Volume!I11=1,Unit_Economics!$F$5,Unit_Economics!$O$5) -> 0 | J16: =Volume!J24*IF(Volume!J11=1,Unit_Economics!$F$5,Unit_Economics!$O$5) -> 10.25 | K16: =Volume!K24*IF(Volume!K11=1,Unit_Economics!$F$5,Unit_Economics!$O$5) -> 0 | L16: =Volume!L24*IF(Volume!L11=1,Unit_Economics!$F$5,Unit_Economics!$O$5) -> 10.25 | ... S16: =Volume!S24*IF(Volume!S11=1,Unit_Economics!$F$5,Unit_Economics!$O$5) -> 51.25
A17: Bank KCP | B17: Rp m | C17: =SUM(E17:G17) -> 24 | D17: =SUM(H17:S17) -> 60 | E17: =Volume!E25*IF(Volume!E11=1,Unit_Economics!$F$6,Unit_Economics!$O$6) -> 12 | F17: =Volume!F25*IF(Volume!F11=1,Unit_Economics!$F$6,Unit_Economics!$O$6) -> 12 | G17: =Volume!G25*IF(Volume!G11=1,Unit_Economics!$F$6,Unit_Economics!$O$6) -> 0 | H17: =Volume!H25*IF(Volume!H11=1,Unit_Economics!$F$6,Unit_Economics!$O$6) -> 0 | I17: =Volume!I25*IF(Volume!I11=1,Unit_Economics!$F$6,Unit_Economics!$O$6) -> 0 | J17: =Volume!J25*IF(Volume!J11=1,Unit_Economics!$F$6,Unit_Economics!$O$6) -> 0 | K17: =Volume!K25*IF(Volume!K11=1,Unit_Economics!$F$6,Unit_Economics!$O$6) -> 15 | L17: =Volume!L25*IF(Volume!L11=1,Unit_Economics!$F$6,Unit_Economics!$O$6) -> 0 | ... S17: =Volume!S25*IF(Volume!S11=1,Unit_Economics!$F$6,Unit_Economics!$O$6) -> 0
A18: Bank EAP | B18: Rp m | C18: =SUM(E18:G18) -> 15 | D18: =SUM(H18:S18) -> 60 | E18: =Volume!E26*IF(Volume!E11=1,Unit_Economics!$F$7,Unit_Economics!$O$7) -> 5 | F18: =Volume!F26*IF(Volume!F11=1,Unit_Economics!$F$7,Unit_Economics!$O$7) -> 5 | G18: =Volume!G26*IF(Volume!G11=1,Unit_Economics!$F$7,Unit_Economics!$O$7) -> 5 | H18: =Volume!H26*IF(Volume!H11=1,Unit_Economics!$F$7,Unit_Economics!$O$7) -> 5 | I18: =Volume!I26*IF(Volume!I11=1,Unit_Economics!$F$7,Unit_Economics!$O$7) -> 5 | J18: =Volume!J26*IF(Volume!J11=1,Unit_Economics!$F$7,Unit_Economics!$O$7) -> 5 | K18: =Volume!K26*IF(Volume!K11=1,Unit_Economics!$F$7,Unit_Economics!$O$7) -> 5 | L18: =Volume!L26*IF(Volume!L11=1,Unit_Economics!$F$7,Unit_Economics!$O$7) -> 5 | ... S18: =Volume!S26*IF(Volume!S11=1,Unit_Economics!$F$7,Unit_Economics!$O$7) -> 5
A19: B2C events | B19: Rp m | C19: =SUM(E19:G19) -> 24 | D19: =SUM(H19:S19) -> 40 | E19: =Volume!E27*IF(Volume!E11=1,Unit_Economics!$F$8,Unit_Economics!$O$8) -> 8 | F19: =Volume!F27*IF(Volume!F11=1,Unit_Economics!$F$8,Unit_Economics!$O$8) -> 8 | G19: =Volume!G27*IF(Volume!G11=1,Unit_Economics!$F$8,Unit_Economics!$O$8) -> 8 | H19: =Volume!H27*IF(Volume!H11=1,Unit_Economics!$F$8,Unit_Economics!$O$8) -> 8 | I19: =Volume!I27*IF(Volume!I11=1,Unit_Economics!$F$8,Unit_Economics!$O$8) -> 8 | J19: =Volume!J27*IF(Volume!J11=1,Unit_Economics!$F$8,Unit_Economics!$O$8) -> 0 | K19: =Volume!K27*IF(Volume!K11=1,Unit_Economics!$F$8,Unit_Economics!$O$8) -> 0 | L19: =Volume!L27*IF(Volume!L11=1,Unit_Economics!$F$8,Unit_Economics!$O$8) -> 0 | ... S19: =Volume!S27*IF(Volume!S11=1,Unit_Economics!$F$8,Unit_Economics!$O$8) -> 8
A20: B2C counseling | B20: Rp m | C20: =SUM(E20:G20) -> 2.4 | D20: =SUM(H20:S20) -> 9.2 | E20: =E11*Inputs!$C$21 -> 0.8 | F20: =F11*Inputs!$C$21 -> 0.8 | G20: =G11*Inputs!$C$21 -> 0.8 | H20: =H11*Inputs!$C$21 -> 1.2 | I20: =I11*Inputs!$C$21 -> 0.8 | J20: =J11*Inputs!$C$21 -> 0.4 | K20: =K11*Inputs!$C$21 -> 0.4 | L20: =L11*Inputs!$C$21 -> 0 | ... S20: =S11*Inputs!$C$21 -> 0.8
A21: Total delivery cost | B21: Rp m | C21: =SUM(E21:G21) -> 170.4 | D21: =SUM(H21:S21) -> 483.45 | E21: =SUM(E15:E20) -> 41.8 | F21: =SUM(F15:F20) -> 74.8 | G21: =SUM(G15:G20) -> 53.8 | H21: =SUM(H15:H20) -> 14.2 | I21: =SUM(I15:I20) -> 13.8 | J21: =SUM(J15:J20) -> 43.65 | K21: =SUM(K15:K20) -> 20.4 | L21: =SUM(L15:L20) -> 43.25 | ... S21: =SUM(S15:S20) -> 65.05
A23: Gross profit | B23: Rp m | C23: =SUM(E23:G23) -> 295.6 | D23: =SUM(H23:S23) -> 1018.05 | E23: =E12-E21 -> 70.2 | F23: =F12-F21 -> 142.2 | G23: =G12-G21 -> 83.2 | H23: =H12-H21 -> 23.8 | I23: =I12-I21 -> 23.2 | J23: =J12-J21 -> 100.85 | K23: =K12-K21 -> 49.1 | L23: =L12-L21 -> 100.25 | ... S23: =S12-S21 -> 114.45
A24: Gross margin | B24: % | C24: =IF(C12=0,0,C23/C12) -> 0.63433476 | D24: =IF(D12=0,0,D23/D12) -> 0.67802198 | E24: =IF(E12=0,0,E23/E12) -> 0.62678571 | F24: =IF(F12=0,0,F23/F12) -> 0.65529954 | G24: =IF(G12=0,0,G23/G12) -> 0.60729927 | H24: =IF(H12=0,0,H23/H12) -> 0.62631579 | I24: =IF(I12=0,0,I23/I12) -> 0.62702703 | J24: =IF(J12=0,0,J23/J12) -> 0.69792388 | ... S24: =IF(S12=0,0,S23/S12) -> 0.63760446
A26: Fixed costs (from Capacity_OPEX)
A27: Base: team, software, office, accountant | B27: Rp m | C27: =SUM(E27:G27) -> 62.03975 | D27: =SUM(H27:S27) -> 248.159 | E27: =Capacity_OPEX!E22+Capacity_OPEX!E23+Capacity_OPEX!E24+Capacity_OPEX!E25 -> 20.679917 | F27: =Capacity_OPEX!F22+Capacity_OPEX!F23+Capacity_OPEX!F24+Capacity_OPEX!F25 -> 20.679917 | G27: =Capacity_OPEX!G22+Capacity_OPEX!G23+Capacity_OPEX!G24+Capacity_OPEX!G25 -> 20.679917 | H27: =Capacity_OPEX!H22+Capacity_OPEX!H23+Capacity_OPEX!H24+Capacity_OPEX!H25 -> 20.679917 | I27: =Capacity_OPEX!I22+Capacity_OPEX!I23+Capacity_OPEX!I24+Capacity_OPEX!I25 -> 20.679917 | J27: =Capacity_OPEX!J22+Capacity_OPEX!J23+Capacity_OPEX!J24+Capacity_OPEX!J25 -> 20.679917 | K27: =Capacity_OPEX!K22+Capacity_OPEX!K23+Capacity_OPEX!K24+Capacity_OPEX!K25 -> 20.679917 | L27: =Capacity_OPEX!L22+Capacity_OPEX!L23+Capacity_OPEX!L24+Capacity_OPEX!L25 -> 20.679917 | ... S27: =Capacity_OPEX!S22+Capacity_OPEX!S23+Capacity_OPEX!S24+Capacity_OPEX!S25 -> 20.679917
A28: Founder salaries | B28: Rp m | C28: =SUM(E28:G28) -> 0 | D28: =SUM(H28:S28) -> 300 | E28: =Capacity_OPEX!E26 -> 0 | F28: =Capacity_OPEX!F26 -> 0 | G28: =Capacity_OPEX!G26 -> 0 | H28: =Capacity_OPEX!H26 -> 25 | I28: =Capacity_OPEX!I26 -> 25 | J28: =Capacity_OPEX!J26 -> 25 | K28: =Capacity_OPEX!K26 -> 25 | L28: =Capacity_OPEX!L26 -> 25 | ... S28: =Capacity_OPEX!S26 -> 25
A29: B2B sales (Account Manager + travel) | B29: Rp m | C29: =SUM(E29:G29) -> 0 | D29: =SUM(H29:S29) -> 24 | E29: =Capacity_OPEX!E27+Capacity_OPEX!E28 -> 0 | F29: =Capacity_OPEX!F27+Capacity_OPEX!F28 -> 0 | G29: =Capacity_OPEX!G27+Capacity_OPEX!G28 -> 0 | H29: =Capacity_OPEX!H27+Capacity_OPEX!H28 -> 2 | I29: =Capacity_OPEX!I27+Capacity_OPEX!I28 -> 2 | J29: =Capacity_OPEX!J27+Capacity_OPEX!J28 -> 2 | K29: =Capacity_OPEX!K27+Capacity_OPEX!K28 -> 2 | L29: =Capacity_OPEX!L27+Capacity_OPEX!L28 -> 2 | ... S29: =Capacity_OPEX!S27+Capacity_OPEX!S28 -> 2
A30: Delivery capacity (PM, 2nd admin, certification) | B30: Rp m | C30: =SUM(E30:G30) -> 17.5 | D30: =SUM(H30:S30) -> 60 | E30: =Capacity_OPEX!E29+Capacity_OPEX!E30+Capacity_OPEX!E31 -> 5 | F30: =Capacity_OPEX!F29+Capacity_OPEX!F30+Capacity_OPEX!F31 -> 7.5 | G30: =Capacity_OPEX!G29+Capacity_OPEX!G30+Capacity_OPEX!G31 -> 5 | H30: =Capacity_OPEX!H29+Capacity_OPEX!H30+Capacity_OPEX!H31 -> 5 | I30: =Capacity_OPEX!I29+Capacity_OPEX!I30+Capacity_OPEX!I31 -> 5 | J30: =Capacity_OPEX!J29+Capacity_OPEX!J30+Capacity_OPEX!J31 -> 5 | K30: =Capacity_OPEX!K29+Capacity_OPEX!K30+Capacity_OPEX!K31 -> 5 | L30: =Capacity_OPEX!L29+Capacity_OPEX!L30+Capacity_OPEX!L31 -> 5 | ... S30: =Capacity_OPEX!S29+Capacity_OPEX!S30+Capacity_OPEX!S31 -> 5
A31: Total fixed cost | B31: Rp m | C31: =SUM(E31:G31) -> 79.53975 | D31: =SUM(H31:S31) -> 632.159 | E31: =SUM(E27:E30) -> 25.679917 | F31: =SUM(F27:F30) -> 28.179917 | G31: =SUM(G27:G30) -> 25.679917 | H31: =SUM(H27:H30) -> 52.679917 | I31: =SUM(I27:I30) -> 52.679917 | J31: =SUM(J27:J30) -> 52.679917 | K31: =SUM(K27:K30) -> 52.679917 | L31: =SUM(L27:L30) -> 52.679917 | ... S31: =SUM(S27:S30) -> 52.679917
A33: Profit before tax | B33: Rp m | C33: =SUM(E33:G33) -> 216.06025 | D33: =SUM(H33:S33) -> 385.891 | E33: =E23-E31 -> 44.520083 | F33: =F23-F31 -> 114.02008 | G33: =G23-G31 -> 57.520083 | H33: =H23-H31 -> -28.879917 | I33: =I23-I31 -> -29.479917 | J33: =J23-J31 -> 48.170083 | K33: =K23-K31 -> -3.5799167 | L33: =L23-L31 -> 47.570083 | ... S33: =S23-S31 -> 61.770083
A34: Income tax (final tax on revenue) | B34: Rp m | C34: =SUM(E34:G34) -> 2.33 | D34: =SUM(H34:S34) -> 7.5075 | E34: =E12*Inputs!$C$80 -> 0.56 | F34: =F12*Inputs!$C$80 -> 1.085 | G34: =G12*Inputs!$C$80 -> 0.685 | H34: =H12*Inputs!$C$80 -> 0.19 | I34: =I12*Inputs!$C$80 -> 0.185 | J34: =J12*Inputs!$C$80 -> 0.7225 | K34: =K12*Inputs!$C$80 -> 0.3475 | L34: =L12*Inputs!$C$80 -> 0.7175 | ... S34: =S12*Inputs!$C$80 -> 0.8975
A35: Net profit | B35: Rp m | C35: =SUM(E35:G35) -> 213.73025 | D35: =SUM(H35:S35) -> 378.3835 | E35: =E33-E34 -> 43.960083 | F35: =F33-F34 -> 112.93508 | G35: =G33-G34 -> 56.835083 | H35: =H33-H34 -> -29.069917 | I35: =I33-I34 -> -29.664917 | J35: =J33-J34 -> 47.447583 | K35: =K33-K34 -> -3.9274167 | L35: =L33-L34 -> 46.852583 | ... S35: =S33-S34 -> 60.872583
A36: Net margin | B36: % | C36: =IF(C12=0,0,C35/C12) -> 0.45864861 | D36: =IF(D12=0,0,D35/D12) -> 0.25200366 | E36: =IF(E12=0,0,E35/E12) -> 0.39250074 | F36: =IF(F12=0,0,F35/F12) -> 0.52043817 | G36: =IF(G12=0,0,G35/G12) -> 0.41485462 | H36: =IF(H12=0,0,H35/H12) -> -0.76499781 | I36: =IF(I12=0,0,I35/I12) -> -0.8017545 | J36: =IF(J12=0,0,J35/J12) -> 0.32835698 | ... S36: =IF(S12=0,0,S35/S12) -> 0.33912303
A37: Net profit if founders were not paid (for comparison) | B37: Rp m | C37: =SUM(E37:G37) -> 213.73025 | D37: =SUM(H37:S37) -> 678.3835 | E37: =E35+E28 -> 43.960083 | F37: =F35+F28 -> 112.93508 | G37: =G35+G28 -> 56.835083 | H37: =H35+H28 -> -4.0699167 | I37: =I35+I28 -> -4.6649167 | J37: =J35+J28 -> 72.447583 | K37: =K35+K28 -> 21.072583 | L37: =L35+L28 -> 71.852583 | ... S37: =S35+S28 -> 85.872583
A39: Concentration and memo lines
A40: Revenue from BI (Flagship + BI share of KPW/LPS) | B40: Rp m | C40: =SUM(E40:G40) -> 255 | D40: =SUM(H40:S40) -> 911.825 | E40: =E6+E7*Inputs!$C$83 -> 34 | F40: =F6+F7*Inputs!$C$83 -> 136 | G40: =G6+G7*Inputs!$C$83 -> 85 | H40: =H6+H7*Inputs!$C$83 -> 0 | I40: =I6+I7*Inputs!$C$83 -> 0 | J40: =J6+J7*Inputs!$C$83 -> 124.225 | K40: =K6+K7*Inputs!$C$83 -> 0 | L40: =L6+L7*Inputs!$C$83 -> 124.225 | ... S40: =S6+S7*Inputs!$C$83 -> 121.125
A41: BI share of revenue | B41: % | C41: =IF(C12=0,0,C40/C12) -> 0.5472103 | D41: =IF(D12=0,0,D40/D12) -> 0.60727606 | E41: =IF(E12=0,0,E40/E12) -> 0.30357143 | F41: =IF(F12=0,0,F40/F12) -> 0.62672811 | G41: =IF(G12=0,0,G40/G12) -> 0.62043796 | H41: =IF(H12=0,0,H40/H12) -> 0 | I41: =IF(I12=0,0,I40/I12) -> 0 | J41: =IF(J12=0,0,J40/J12) -> 0.85968858 | ... S41: =IF(S12=0,0,S40/S12) -> 0.67479109
A42: B2B revenue | B42: Rp m | C42: =SUM(E42:G42) -> 400 | D42: =SUM(H42:S42) -> 1378.5 | E42: =SUM(E6:E9) -> 90 | F42: =SUM(F6:F9) -> 195 | G42: =SUM(G6:G9) -> 115 | H42: =SUM(H6:H9) -> 15 | I42: =SUM(I6:I9) -> 15 | J42: =SUM(J6:J9) -> 143.5 | K42: =SUM(K6:K9) -> 68.5 | L42: =SUM(L6:L9) -> 143.5 | ... S42: =SUM(S6:S9) -> 157.5
