Workbook

Sheet Summary
A1: Teman Journey - 2027 plan: profitable with both founders paid
A2: Goal for 2027: a business that is profitable on its own and pays both founders. Investors come later, after scale. All money in Rp million.
A3: Active scenario: | B3: =CHOOSE(Inputs!$C$6,"1. Base plan","2. No new B2B deal Jan-Jun 2027","3. BI cuts volume","4. Worst case (2 + 3)") -> 1. Base plan
A4: Active price plan: | B4: =CHOOSE(Inputs!$C$85,"1. Current prices","2. New rate card") -> 2. New rate card
A5: Question | B5: Answer | C5: Unit | D5: What it means
A6: A. Is 2027 profitable?
A7: Revenue FY 2027 | B7: =PnL!$D$12 -> 1847 | C7: Rp m | D7: Total sales booked in 2027.
A8: Gross profit FY 2027 | B8: =PnL!$D$23 -> 1259.55 | C8: Rp m | D8: Revenue minus delivery cost.
A9: Total fixed cost FY 2027 | B9: =PnL!$D$31 -> 828.4326 | C9: Rp m | D9: Base + founders + sales + delivery steps.
A10: of which founder salaries | B10: =PnL!$D$28 -> 200 | C10: Rp m | D10: Both founders, from the start month in Inputs.
A11: Net profit FY 2027 | B11: =PnL!$D$35 -> 421.8824 | C11: Rp m | D11: After founder salaries and tax.
A12: Net margin FY 2027 | B12: =PnL!$D$36 -> 0.22841494 | C12: % | D12: Net profit / revenue.
A13: Meets your target margin? | B13: =IF(PnL!$D$36>=Inputs!$C$82,"Yes","No") -> Yes | D13: Target is set in Inputs.
A14: Break-even: BI work needed per month (in KPW-event equivalents) | B14: =IF(Unit_Economics!$G$5<=0,0,(PnL!$D$31/12-(PnL!$D$23-PnL!$D$6-PnL!$D$7+PnL!$D$15+PnL!$D$16)/12)/Unit_Economics!$G$5) -> 1.0919297 | C14: events | D14: With banks, EAP and B2C at plan, this many KPW-size BI events a month (or the same profit from Flagships) covers all 2027 fixed costs.
A15: B. Is cash safe? (Pillar 3)
A16: Lowest month-end cash (Oct 26 - Dec 27) | B16: =MIN(CashFlow!$E$21:$S$21) -> 107.88688 | C16: Rp m | D16: Must stay above zero.
A17: Month of lowest cash | B17: =INDEX(Volume!$E$4:$S$4,MATCH(MIN(CashFlow!$E$21:$S$21),CashFlow!$E$21:$S$21,0)) -> Apr-27 | D17: Where the squeeze is.
A18: Months below the cash floor | B18: =COUNTIF(CashFlow!$E$25:$S$25,0) -> 1 | C18: months | D18: Floor = 1 month fixed cost + delivery cost.
A19: Cash at end of 2027 | B19: =CashFlow!$D$21 -> 446.10265 | C19: Rp m
A20: Peak money owed by clients | B20: =CashFlow!$D$26 -> 219.8 | C20: Rp m | D20: Cash tied up in unpaid invoices.
A21: Runway at end of Dec 2026 if B2B stops | B21: =CashFlow!$G$21/(Capacity_OPEX!$H$32-((PnL!$D$10+PnL!$D$11-PnL!$D$19-PnL!$D$20)/12)) -> 4.5821482 | C21: months | D21: Months you survive on B2C alone with 2027 cost base.
A22: C. Can we deliver it? (Pillar 2)
A23: Peak facilitators needed in one month | B23: =Capacity_OPEX!$D$8 -> 8 | C23: people | D23: Compare with your plan of 11.
A24: Facilitators to certify by end 2027 | B24: =Capacity_OPEX!$D$9-Inputs!$C$35 -> 6 | C24: people
A25: Month the Project Manager is hired | B25: =IFERROR(INDEX(Volume!$E$4:$S$4,MATCH(1,Capacity_OPEX!$E$15:$S$15,0)),"Not needed") -> Dec-27 | D25: Triggered by the 3-month average of B2B events.
A26: D. What will investors ask? (risk)
A27: BI share of 2027 revenue | B27: =PnL!$D$41 -> 0.49367894 | C27: % | D27: Concentration risk. Lower is safer.
A28: B2B share of 2027 revenue | B28: =IF(PnL!$D$12=0,0,PnL!$D$42/PnL!$D$12) -> 0.95506226 | C28: %
A29: Q4 share of 2027 revenue | B29: =IF(PnL!$D$12=0,0,SUM(PnL!Q12:S12)/PnL!$D$12) -> 0.4621007 | C29: % | D29: Seasonality risk.
A30: Cost to win one new B2B client (CAC) | B30: =Unit_Economics!$B$13 -> 6 | C30: Rp m | D30: Sales spend / new clients.
A31: Memo: Coreitera revenue from TJ in 2027 | B31: =PnL!$D$43 -> 85.5 | C31: Rp m | D31: The 'tech' revenue line for the investor story.
A32: Memo: Theta revenue from TJ in 2027 | B32: =PnL!$D$44 -> 14.65 | C32: Rp m
A34: Scenario comparison (v14 values from Excel; refresh with analysis/excel_runner.py, then rebuild)
A35: Measure | B35: Old timing, today's pay | C35: Real timing, today's pay | D35: Plan, founders paid from Jan | E35: Plan, founders from May (ours) | F35: Our plan, BI buys 30% less
A36: Revenue FY 2027 | B36: 1501.5 | C36: 1461.5 | D36: 1847 | E36: 1847 | F36: 1573.4525
A37: Net profit FY 2027 | B37: 378.3835 | C37: 402.0835 | D37: 321.8824 | E37: 421.8824 | F37: 243.63639
A38: Net margin FY 2027 | B38: 0.25200366 | C38: 0.275117 | D38: 0.17427309 | E38: 0.22841494 | F38: 0.15484191
A39: Lowest month-end cash (Oct 26 - Dec 27) | B39: 203.52008 | C39: 92.338083 | D39: 7.8868833 | E39: 107.88688 | F39: 63.318746
A40: Month of lowest cash | B40: Oct-26 | C40: Apr-27 | D40: Apr-27 | E40: Apr-27 | F40: Jul-27
A41: Months below the cash floor | B41: 0 | C41: 0 | D41: 10 | E41: 1 | F41: 6
...

Sheet Outlook
A1: Outlook: sales, costs and cash each month (Rp million)
A2: Read the bars against the line: when the grey cost bar is taller than the blue sales bar, cash goes down. Cash is paid later than sales, because clients pay 0 to 60 days after the event.
A4: Month | B4: =Volume!E4 -> Oct-26 | C4: =Volume!F4 -> Nov-26 | D4: =Volume!G4 -> Dec-26 | E4: =Volume!H4 -> Jan-27 | F4: =Volume!I4 -> Feb-27 | G4: =Volume!J4 -> Mar-27 | H4: =Volume!K4 -> Apr-27 | I4: =Volume!L4 -> May-27 | ... P4: =Volume!S4 -> Dec-27
A5: Sales (revenue) | B5: =PnL!E12 -> 17 | C5: =PnL!F12 -> 17 | D5: =PnL!G12 -> 17 | E5: =PnL!H12 -> 18 | F5: =PnL!I12 -> 17 | G5: =PnL!J12 -> 144.5 | H5: =PnL!K12 -> 84.5 | I5: =PnL!L12 -> 158.5 | ... P5: =PnL!S12 -> 263
A6: Delivery cost | B6: =PnL!E21 -> 5.8 | C6: =PnL!F21 -> 5.8 | D6: =PnL!G21 -> 5.8 | E6: =PnL!H21 -> 6.2 | F6: =PnL!I21 -> 5.8 | G6: =PnL!J21 -> 43.65 | H6: =PnL!K21 -> 25.4 | I6: =PnL!L21 -> 48.25 | ... P6: =PnL!S21 -> 90.05
A7: Fixed cost | B7: =PnL!E31 -> 20.679917 | C7: =PnL!F31 -> 20.679917 | D7: =PnL!G31 -> 20.679917 | E7: =PnL!H31 -> 40.462717 | F7: =PnL!I31 -> 40.462717 | G7: =PnL!J31 -> 42.962717 | H7: =PnL!K31 -> 48.782717 | I7: =PnL!L31 -> 73.782717 | ... P7: =PnL!S31 -> 86.782717
A8: Tax | B8: =PnL!E34 -> 0.085 | C8: =PnL!F34 -> 0.085 | D8: =PnL!G34 -> 0.085 | E8: =PnL!H34 -> 0.09 | F8: =PnL!I34 -> 0.085 | G8: =PnL!J34 -> 0.7225 | H8: =PnL!K34 -> 0.4225 | I8: =PnL!L34 -> 0.7925 | ... P8: =PnL!S34 -> 1.315
A9: Total cost | B9: =B6+B7+B8 -> 26.564917 | C9: =C6+C7+C8 -> 26.564917 | D9: =D6+D7+D8 -> 26.564917 | E9: =E6+E7+E8 -> 46.752717 | F9: =F6+F7+F8 -> 46.347717 | G9: =G6+G7+G8 -> 87.335217 | H9: =H6+H7+H8 -> 74.605217 | I9: =I6+I7+I8 -> 122.82522 | ... P9: =P6+P7+P8 -> 178.14772
A10: Net profit | B10: =PnL!E35 -> -9.5649167 | C10: =PnL!F35 -> -9.5649167 | D10: =PnL!G35 -> -9.5649167 | E10: =PnL!H35 -> -28.752717 | F10: =PnL!I35 -> -29.347717 | G10: =PnL!J35 -> 57.164783 | H10: =PnL!K35 -> 9.8947833 | I10: =PnL!L35 -> 35.674783 | ... P10: =PnL!S35 -> 84.852283
A11: Cash in | B11: =CashFlow!E11 -> 2 | C11: =CashFlow!F11 -> 17 | D11: =CashFlow!G11 -> 17 | E11: =CashFlow!H11 -> 18 | F11: =CashFlow!I11 -> 17 | G11: =CashFlow!J11 -> 98.8 | H11: =CashFlow!K11 -> 62.4 | I11: =CashFlow!L11 -> 149.55 | ... P11: =CashFlow!S11 -> 324.4
A12: Cash out | B12: =CashFlow!E17 -> 26.479917 | C12: =CashFlow!F17 -> 26.564917 | D12: =CashFlow!G17 -> 26.564917 | E12: =CashFlow!H17 -> 46.747717 | F12: =CashFlow!I17 -> 46.352717 | G12: =CashFlow!J17 -> 86.697717 | H12: =CashFlow!K17 -> 74.905217 | I12: =CashFlow!L17 -> 122.45522 | ... P12: =CashFlow!S17 -> 178.63022
A13: Cash at end of month | B13: =CashFlow!E21 -> 185.52008 | C13: =CashFlow!F21 -> 175.95517 | D13: =CashFlow!G21 -> 166.39025 | E13: =CashFlow!H21 -> 137.64253 | F13: =CashFlow!I21 -> 108.28982 | G13: =CashFlow!J21 -> 120.3921 | H13: =CashFlow!K21 -> 107.88688 | I13: =CashFlow!L21 -> 134.98167 | ... P13: =CashFlow!S21 -> 446.10265
A14: Cash floor (1 month of costs) | B14: =CashFlow!E24 -> 26.479917 | C14: =CashFlow!F24 -> 26.479917 | D14: =CashFlow!G24 -> 26.479917 | E14: =CashFlow!H24 -> 46.662717 | F14: =CashFlow!I24 -> 46.262717 | G14: =CashFlow!J24 -> 86.612717 | H14: =CashFlow!K24 -> 74.182717 | I14: =CashFlow!L24 -> 122.03272 | ... P14: =CashFlow!S24 -> 176.83272
A15: Above the floor? (1 = yes) | B15: =CashFlow!E25 -> 1 | C15: =CashFlow!F25 -> 1 | D15: =CashFlow!G25 -> 1 | E15: =CashFlow!H25 -> 1 | F15: =CashFlow!I25 -> 1 | G15: =CashFlow!J25 -> 1 | H15: =CashFlow!K25 -> 1 | I15: =CashFlow!L25 -> 1 | ... P15: =CashFlow!S25 -> 1

Sheet Inputs
A1: Inputs and assumptions (all money in Rp million)
A2: Blue numbers are inputs you can change. Status: Known = you told us or it is in your v10 file; Your plan = your own budget; Estimate = industry estimate used until you give the real number (yellow-shaded, listed in the To_Fill sheet).
A4: Key | B4: Item | C4: Value | D4: Unit | E4: Status | F4: Source / logic
A5: 0. Scenario selector
A6: scen | B6: Active scenario (1-4) | C6: 1 | D6: number | E6: Known | F6: 1 = Base plan (v10 volumes). 2 = No new B2B event closes Jan-Jun 2027. 3 = BI cuts its volume by the % below. 4 = Both 2 and 3 (worst case).
A7: bi_cut | B7: BI volume cut used in scenarios 3 and 4 | C7: 0.3 | D7: % | E7: Known | F7: Stress test size. Change freely.
A8: 1. Prices (per event, or per month for EAP)
A9: p_flag | B9: Flagship regulator ToT (CBP Rupiah) | C9: 85 | D9: Rp m / event | E9: Known | F9: Your v10 file.
A10: p_kpw | B10: Regulator regional ToT (BI KPW and LPS) | C10: 20 | D10: Rp m / event | E10: Known | F10: Your v10 file.
A11: p_kcp | B11: Bank branch event (KCP) | C11: 35 | D11: Rp m / event | E11: Known | F11: Your v10 file.
A12: p_eap | B12: Bank EAP subscription | C12: 15 | D12: Rp m / month | E12: Known | F12: Your v10 file.
A13: p_b2ce | B13: B2C mass event | C13: 20 | D13: Rp m / event | E13: Known | F13: Your v10 file.
A14: p_b2cc | B14: B2C counseling client | C14: 1 | D14: Rp m / client | E14: Known | F14: Your v10 file (Rp 1,000,000 per session).
A15: 2. Delivery cost (cost of goods sold)
A16: c_flag | B16: Flagship delivery cost | C16: 25 | D16: Rp m / event | E16: Known | F16: Your v10 file: travel, hotel, materials, premium facilitator fees.
A17: c_kpw | B17: KPW / LPS delivery cost | C17: 8 | D17: Rp m / event | E17: Known | F17: Your v10 file. Covers about 2 handler fees only, so travel is assumed paid by the client (see below).
A18: c_kcp | B18: Bank KCP event delivery cost | C18: 12 | D18: Rp m / event | E18: Known | F18: Your v10 file.
A19: c_eap | B19: EAP delivery cost | C19: 5 | D19: Rp m / month | E19: Known | F19: Your v10 file: on-call tele-counseling retainer.
A20: c_b2ce | B20: B2C event delivery cost | C20: 8 | D20: Rp m / event | E20: Known | F20: Your v10 file: venue, ads, materials, fees.
A21: c_b2cc | B21: B2C counseling cost (psychologist fee) | C21: 0.4 | D21: % of price | E21: Known | F21: Your v10 file: Rp 400k of Rp 1m.
A22: travel_client | B22: Client pays travel for regional events? (1 = yes, 0 = no) | C22: 1 | D22: switch | E22: Estimate | F22: The Rp 8m KPW cost only covers 2 handler fees, so we assume BI pays travel.
A23: travel_pp | B23: Travel cost per handler per regional trip | C23: 3.5 | D23: Rp m / person | E23: Estimate | F23: Industry estimate: return flight ~Rp 2m + 2 hotel nights ~Rp 1m + per diem ~Rp 0.5m.
A24: regional_share | B24: Share of KPW / LPS events outside Jakarta | C24: 0.8 | D24: % | E24: Estimate | F24: Estimate: most KPW offices are outside Jakarta.
A25: 3. Delivery staffing (from your v10 file)
A26: h_flag | B26: Handlers per Flagship event | C26: 4 | D26: people | E26: Known | F26: 1 PM, 1 Lead Psychologist, 2 Facilitators.
A27: h_kpw | B27: Handlers per KPW / LPS event | C27: 2 | D27: people | E27: Known | F27: 1 Lead, 1 Facilitator.
A28: h_kcp | B28: Handlers per KCP event | C28: 2 | D28: people | E28: Known | F28: 1 Lead, 1 Facilitator.
A29: h_b2ce | B29: Handlers per B2C event | C29: 2 | D29: people | E29: Known | F29: 1 Lead, 1 Facilitator / Assistant.
A30: d_flag | B30: Days per Flagship event | C30: 3 | D30: days | E30: Estimate | F30: You said 2-3 day program; we use 3.
A31: d_kpw | B31: Days per KPW / LPS event | C31: 1 | D31: days | E31: Estimate | F31: Estimate.
A32: d_kcp | B32: Days per KCP event | C32: 1 | D32: days | E32: Estimate | F32: Estimate.
A33: d_b2ce | B33: Days per B2C event | C33: 1 | D33: days | E33: Estimate | F33: Estimate (weekend event).
A34: fac_cap | B34: Max events per facilitator per month | C34: 2 | D34: events | E34: Known | F34: Your v10 quality rule.
A35: fac_now | B35: Certified facilitators today | C35: 2 | D35: people | E35: Known | F35: You told us: 2 active core facilitators.
A36: fac_plan | B36: Your plan: facilitators certified by Nov 2026 | C36: 11 | D36: people | E36: Known | F36: Your earlier plan.
A37: cert_cost | B37: Cost to certify one new facilitator | C37: 2.5 | D37: Rp m / person | E37: Estimate | F37: Industry estimate: 2-day internal ToT, materials, observed practice event.
A38: 4. Fixed cost: base (your 2027 'bensin' budget, monthly)
A39: o_lead_mkt | B39: Lead Marketing | C39: 2.5 | D39: Rp m / month | E39: Known | F39: Your 2027 budget.
A40: o_socmed | B40: Social Media Specialist | C40: 1.5 | D40: Rp m / month | E40: Known | F40: Your 2027 budget.
A41: o_intern_mkt | B41: Marketing intern | C41: 1 | D41: Rp m / month | E41: Known | F41: Your 2027 budget.
...

Sheet Volume
A1: Event volume plan (from your v10 file, moved to Oct 2026 - Dec 2027)
A2: Rp million unless stated. Q4 2026 and FY 2027 columns are totals (or averages / peaks where stated).
A4: Line | B4: Unit | C4: Q4 2026 | D4: FY 2027 | E4: Oct-26 | F4: Nov-26 | G4: Dec-26 | H4: Jan-27 | I4: Feb-27 | J4: Mar-27 | K4: Apr-27 | L4: May-27 | M4: Jun-27 | N4: Jul-27 | O4: Aug-27 | P4: Sep-27 | Q4: Oct-27 | R4: Nov-27 | S4: Dec-27
A5: Timeline helpers
A6: Month number | B6: # | E6: 1 | F6: 2 | G6: 3 | H6: 4 | I6: 5 | J6: 6 | K6: 7 | L6: 8 | M6: 9 | N6: 10 | O6: 11 | P6: 12 | Q6: 13 | R6: 14 | S6: 15
A7: Is 2027? (1 = yes) | B7: flag | E7: 0 | F7: 0 | G7: 0 | H7: 1 | I7: 1 | J7: 1 | K7: 1 | L7: 1 | M7: 1 | N7: 1 | O7: 1 | P7: 1 | Q7: 1 | R7: 1 | S7: 1
A8: Is Jan-Jun 2027? (1 = yes) | B8: flag | E8: 0 | F8: 0 | G8: 0 | H8: 1 | I8: 1 | J8: 1 | K8: 1 | L8: 1 | M8: 1 | N8: 0 | O8: 0 | P8: 0 | Q8: 0 | R8: 0 | S8: 0
A9: Scenario switch: new B2B events allowed (1 = yes) | B9: flag | E9: =IF(AND(OR(Inputs!$C$6=2,Inputs!$C$6=4),E8=1),0,1) -> 1 | F9: =IF(AND(OR(Inputs!$C$6=2,Inputs!$C$6=4),F8=1),0,1) -> 1 | G9: =IF(AND(OR(Inputs!$C$6=2,Inputs!$C$6=4),G8=1),0,1) -> 1 | H9: =IF(AND(OR(Inputs!$C$6=2,Inputs!$C$6=4),H8=1),0,1) -> 1 | I9: =IF(AND(OR(Inputs!$C$6=2,Inputs!$C$6=4),I8=1),0,1) -> 1 | J9: =IF(AND(OR(Inputs!$C$6=2,Inputs!$C$6=4),J8=1),0,1) -> 1 | K9: =IF(AND(OR(Inputs!$C$6=2,Inputs!$C$6=4),K8=1),0,1) -> 1 | L9: =IF(AND(OR(Inputs!$C$6=2,Inputs!$C$6=4),L8=1),0,1) -> 1 | ... S9: =IF(AND(OR(Inputs!$C$6=2,Inputs!$C$6=4),S8=1),0,1) -> 1
A10: Scenario factor: BI volume | B10: x | E10: =IF(OR(Inputs!$C$6=3,Inputs!$C$6=4),1-Inputs!$C$7,1) -> 1 | F10: =IF(OR(Inputs!$C$6=3,Inputs!$C$6=4),1-Inputs!$C$7,1) -> 1 | G10: =IF(OR(Inputs!$C$6=3,Inputs!$C$6=4),1-Inputs!$C$7,1) -> 1 | H10: =IF(OR(Inputs!$C$6=3,Inputs!$C$6=4),1-Inputs!$C$7,1) -> 1 | I10: =IF(OR(Inputs!$C$6=3,Inputs!$C$6=4),1-Inputs!$C$7,1) -> 1 | J10: =IF(OR(Inputs!$C$6=3,Inputs!$C$6=4),1-Inputs!$C$7,1) -> 1 | K10: =IF(OR(Inputs!$C$6=3,Inputs!$C$6=4),1-Inputs!$C$7,1) -> 1 | L10: =IF(OR(Inputs!$C$6=3,Inputs!$C$6=4),1-Inputs!$C$7,1) -> 1 | ... S10: =IF(OR(Inputs!$C$6=3,Inputs!$C$6=4),1-Inputs!$C$7,1) -> 1
A11: New prices active this month? (1 = yes) | B11: flag | E11: =IF(AND(Inputs!$C$85=2,E6>=IFERROR(MATCH(Inputs!$C$86,$E$4:$S$4,0),99)),1,0) -> 0 | F11: =IF(AND(Inputs!$C$85=2,F6>=IFERROR(MATCH(Inputs!$C$86,$E$4:$S$4,0),99)),1,0) -> 0 | G11: =IF(AND(Inputs!$C$85=2,G6>=IFERROR(MATCH(Inputs!$C$86,$E$4:$S$4,0),99)),1,0) -> 0 | H11: =IF(AND(Inputs!$C$85=2,H6>=IFERROR(MATCH(Inputs!$C$86,$E$4:$S$4,0),99)),1,0) -> 1 | I11: =IF(AND(Inputs!$C$85=2,I6>=IFERROR(MATCH(Inputs!$C$86,$E$4:$S$4,0),99)),1,0) -> 1 | J11: =IF(AND(Inputs!$C$85=2,J6>=IFERROR(MATCH(Inputs!$C$86,$E$4:$S$4,0),99)),1,0) -> 1 | K11: =IF(AND(Inputs!$C$85=2,K6>=IFERROR(MATCH(Inputs!$C$86,$E$4:$S$4,0),99)),1,0) -> 1 | L11: =IF(AND(Inputs!$C$85=2,L6>=IFERROR(MATCH(Inputs!$C$86,$E$4:$S$4,0),99)),1,0) -> 1 | ... S11: =IF(AND(Inputs!$C$85=2,S6>=IFERROR(MATCH(Inputs!$C$86,$E$4:$S$4,0),99)),1,0) -> 1
A12: Price plan factor: B2B volume kept | B12: x | E12: =IF(E11=1,Inputs!$C$98,1) -> 1 | F12: =IF(F11=1,Inputs!$C$98,1) -> 1 | G12: =IF(G11=1,Inputs!$C$98,1) -> 1 | H12: =IF(H11=1,Inputs!$C$98,1) -> 1 | I12: =IF(I11=1,Inputs!$C$98,1) -> 1 | J12: =IF(J11=1,Inputs!$C$98,1) -> 1 | K12: =IF(K11=1,Inputs!$C$98,1) -> 1 | L12: =IF(L11=1,Inputs!$C$98,1) -> 1 | ... S12: =IF(S11=1,Inputs!$C$98,1) -> 1
A14: Base plan volumes (blue = your v10 plan; edit here)
A15: Flagship regulator ToT | B15: events | C15: =SUM(E15:G15) -> 1 | D15: =SUM(H15:S15) -> 5 | E15: 0 | F15: 1 | G15: 0 | H15: 0 | I15: 0 | J15: 1 | K15: 0 | L15: 1 | M15: 0 | N15: 1 | O15: 0 | P15: 1 | Q15: 0 | R15: 1 | S15: 0
A16: KPW / LPS regional ToT | B16: events | C16: =SUM(E16:G16) -> 10 | D16: =SUM(H16:S16) -> 17 | E16: 2 | F16: 3 | G16: 5 | H16: 0 | I16: 0 | J16: 1 | K16: 0 | L16: 1 | M16: 1 | N16: 1 | O16: 1 | P16: 2 | Q16: 2 | R16: 3 | S16: 5
A17: Bank KCP events | B17: events | C17: =SUM(E17:G17) -> 2 | D17: =SUM(H17:S17) -> 4 | E17: 1 | F17: 1 | G17: 0 | H17: 0 | I17: 0 | J17: 0 | K17: 1 | L17: 0 | M17: 0 | N17: 1 | O17: 0 | P17: 0 | Q17: 1 | R17: 1 | S17: 0
A18: Bank EAP contracts active | B18: contracts | C18: =MAX(E18:G18) -> 1 | D18: =MAX(H18:S18) -> 1 | E18: 1 | F18: 1 | G18: 1 | H18: 1 | I18: 1 | J18: 1 | K18: 1 | L18: 1 | M18: 1 | N18: 1 | O18: 1 | P18: 1 | Q18: 1 | R18: 1 | S18: 1
A19: B2C mass events | B19: events | C19: =SUM(E19:G19) -> 3 | D19: =SUM(H19:S19) -> 5 | E19: 1 | F19: 1 | G19: 1 | H19: 1 | I19: 1 | J19: 0 | K19: 0 | L19: 0 | M19: 0 | N19: 0 | O19: 0 | P19: 0 | Q19: 1 | R19: 1 | S19: 1
A20: B2C counseling clients | B20: clients | C20: =SUM(E20:G20) -> 6 | D20: =SUM(H20:S20) -> 23 | E20: 2 | F20: 2 | G20: 2 | H20: 3 | I20: 2 | J20: 1 | K20: 1 | L20: 0 | M20: 2 | N20: 1 | O20: 3 | P20: 4 | Q20: 2 | R20: 2 | S20: 2
A22: Volumes used in the model (after scenario)
A23: Flagship regulator ToT | B23: events | C23: =SUM(E23:G23) -> 0 | D23: =SUM(H23:S23) -> 5 | E23: =E15*E9*E12*E10*(1-E34) -> 0 | F23: =F15*F9*F12*F10*(1-F34) -> 0 | G23: =G15*G9*G12*G10*(1-G34) -> 0 | H23: =H15*H9*H12*H10*(1-H34) -> 0 | I23: =I15*I9*I12*I10*(1-I34) -> 0 | J23: =J15*J9*J12*J10*(1-J34) -> 1 | K23: =K15*K9*K12*K10*(1-K34) -> 0 | L23: =L15*L9*L12*L10*(1-L34) -> 1 | ... S23: =S15*S9*S12*S10*(1-S34) -> 0
A24: KPW / LPS regional ToT | B24: events | C24: =SUM(E24:G24) -> 0 | D24: =SUM(H24:S24) -> 17 | E24: =E16*E9*E12*(1-Inputs!$C$83*(1-E10))*(1-E34) -> 0 | F24: =F16*F9*F12*(1-Inputs!$C$83*(1-F10))*(1-F34) -> 0 | G24: =G16*G9*G12*(1-Inputs!$C$83*(1-G10))*(1-G34) -> 0 | H24: =H16*H9*H12*(1-Inputs!$C$83*(1-H10))*(1-H34) -> 0 | I24: =I16*I9*I12*(1-Inputs!$C$83*(1-I10))*(1-I34) -> 0 | J24: =J16*J9*J12*(1-Inputs!$C$83*(1-J10))*(1-J34) -> 1 | K24: =K16*K9*K12*(1-Inputs!$C$83*(1-K10))*(1-K34) -> 0 | L24: =L16*L9*L12*(1-Inputs!$C$83*(1-L10))*(1-L34) -> 1 | ... S24: =S16*S9*S12*(1-Inputs!$C$83*(1-S10))*(1-S34) -> 5
A25: Bank KCP events (incl. growth-plan bank days) | B25: events | C25: =SUM(E25:G25) -> 0 | D25: =SUM(H25:S25) -> 7 | E25: =E17*E9*E12*(1-E34)+E36 -> 0 | F25: =F17*F9*F12*(1-F34)+F36 -> 0 | G25: =G17*G9*G12*(1-G34)+G36 -> 0 | H25: =H17*H9*H12*(1-H34)+H36 -> 0 | I25: =I17*I9*I12*(1-I34)+I36 -> 0 | J25: =J17*J9*J12*(1-J34)+J36 -> 0 | K25: =K17*K9*K12*(1-K34)+K36 -> 1 | L25: =L17*L9*L12*(1-L34)+L36 -> 0 | ... S25: =S17*S9*S12*(1-S34)+S36 -> 1
A26: Bank EAP contracts active (existing + growth plan) | B26: contracts | C26: =MAX(E26:G26) -> 1 | D26: =MAX(H26:S26) -> 3 | E26: =E18+E35 -> 1 | F26: =F18+F35 -> 1 | G26: =G18+G35 -> 1 | H26: =H18+H35 -> 1 | I26: =I18+I35 -> 1 | J26: =J18+J35 -> 1 | K26: =K18+K35 -> 2 | L26: =L18+L35 -> 2 | ... S26: =S18+S35 -> 3
A27: B2C mass events | B27: events | C27: =SUM(E27:G27) -> 0 | D27: =SUM(H27:S27) -> 3 | E27: =E19*(1-E34*Inputs!$C$103) -> 0 | F27: =F19*(1-F34*Inputs!$C$103) -> 0 | G27: =G19*(1-G34*Inputs!$C$103) -> 0 | H27: =H19*(1-H34*Inputs!$C$103) -> 0 | I27: =I19*(1-I34*Inputs!$C$103) -> 0 | J27: =J19*(1-J34*Inputs!$C$103) -> 0 | K27: =K19*(1-K34*Inputs!$C$103) -> 0 | L27: =L19*(1-L34*Inputs!$C$103) -> 0 | ... S27: =S19*(1-S34*Inputs!$C$103) -> 1
A28: B2C counseling clients | B28: clients | C28: =SUM(E28:G28) -> 6 | D28: =SUM(H28:S28) -> 23 | E28: =E20 -> 2 | F28: =F20 -> 2 | G28: =G20 -> 2 | H28: =H20 -> 3 | I28: =I20 -> 2 | J28: =J20 -> 1 | K28: =K20 -> 1 | L28: =L20 -> 0 | ... S28: =S20 -> 2
A29: Total B2B events (Flagship + KPW/LPS + KCP) | B29: events | C29: =SUM(E29:G29) -> 0 | D29: =SUM(H29:S29) -> 29 | E29: =E23+E24+E25 -> 0 | F29: =F23+F24+F25 -> 0 | G29: =G23+G24+G25 -> 0 | H29: =H23+H24+H25 -> 0 | I29: =I23+I24+I25 -> 0 | J29: =J23+J24+J25 -> 2 | K29: =K23+K24+K25 -> 1 | L29: =L23+L24+L25 -> 2 | ... S29: =S23+S24+S25 -> 6
A31: Notes: v14 adds the timing switch (no new sales before the first delivery month) and the growth plan (new EAP contracts and bank days). Change them in Inputs sections 11 and 12.
A33: Timing and growth plan (v14)
A34: Pipeline gap: no new sales yet (1 = yes) | B34: flag | C34: =MAX(E34:G34) -> 1 | D34: =MAX(H34:S34) -> 1 | E34: =IF(AND(Inputs!$C$101=1,E6<IFERROR(MATCH(Inputs!$C$102,$E$4:$S$4,0),1)),1,0) -> 1 | F34: =IF(AND(Inputs!$C$101=1,F6<IFERROR(MATCH(Inputs!$C$102,$E$4:$S$4,0),1)),1,0) -> 1 | G34: =IF(AND(Inputs!$C$101=1,G6<IFERROR(MATCH(Inputs!$C$102,$E$4:$S$4,0),1)),1,0) -> 1 | H34: =IF(AND(Inputs!$C$101=1,H6<IFERROR(MATCH(Inputs!$C$102,$E$4:$S$4,0),1)),1,0) -> 1 | I34: =IF(AND(Inputs!$C$101=1,I6<IFERROR(MATCH(Inputs!$C$102,$E$4:$S$4,0),1)),1,0) -> 1 | J34: =IF(AND(Inputs!$C$101=1,J6<IFERROR(MATCH(Inputs!$C$102,$E$4:$S$4,0),1)),1,0) -> 0 | K34: =IF(AND(Inputs!$C$101=1,K6<IFERROR(MATCH(Inputs!$C$102,$E$4:$S$4,0),1)),1,0) -> 0 | L34: =IF(AND(Inputs!$C$101=1,L6<IFERROR(MATCH(Inputs!$C$102,$E$4:$S$4,0),1)),1,0) -> 0 | ... S34: =IF(AND(Inputs!$C$101=1,S6<IFERROR(MATCH(Inputs!$C$102,$E$4:$S$4,0),1)),1,0) -> 0
A35: New EAP contracts active (growth plan) | B35: contracts | C35: =MAX(E35:G35) -> 0 | D35: =MAX(H35:S35) -> 2 | E35: =Inputs!$C$105*(IF(E6>=IFERROR(MATCH(Inputs!$C$114,$E$4:$S$4,0),99),1,0)+IF(E6>=IFERROR(MATCH(Inputs!$C$115,$E$4:$S$4,0),99),1,0)) -> 0 | F35: =Inputs!$C$105*(IF(F6>=IFERROR(MATCH(Inputs!$C$114,$E$4:$S$4,0),99),1,0)+IF(F6>=IFERROR(MATCH(Inputs!$C$115,$E$4:$S$4,0),99),1,0)) -> 0 | G35: =Inputs!$C$105*(IF(G6>=IFERROR(MATCH(Inputs!$C$114,$E$4:$S$4,0),99),1,0)+IF(G6>=IFERROR(MATCH(Inputs!$C$115,$E$4:$S$4,0),99),1,0)) -> 0 | H35: =Inputs!$C$105*(IF(H6>=IFERROR(MATCH(Inputs!$C$114,$E$4:$S$4,0),99),1,0)+IF(H6>=IFERROR(MATCH(Inputs!$C$115,$E$4:$S$4,0),99),1,0)) -> 0 | I35: =Inputs!$C$105*(IF(I6>=IFERROR(MATCH(Inputs!$C$114,$E$4:$S$4,0),99),1,0)+IF(I6>=IFERROR(MATCH(Inputs!$C$115,$E$4:$S$4,0),99),1,0)) -> 0 | J35: =Inputs!$C$105*(IF(J6>=IFERROR(MATCH(Inputs!$C$114,$E$4:$S$4,0),99),1,0)+IF(J6>=IFERROR(MATCH(Inputs!$C$115,$E$4:$S$4,0),99),1,0)) -> 0 | K35: =Inputs!$C$105*(IF(K6>=IFERROR(MATCH(Inputs!$C$114,$E$4:$S$4,0),99),1,0)+IF(K6>=IFERROR(MATCH(Inputs!$C$115,$E$4:$S$4,0),99),1,0)) -> 1 | L35: =Inputs!$C$105*(IF(L6>=IFERROR(MATCH(Inputs!$C$114,$E$4:$S$4,0),99),1,0)+IF(L6>=IFERROR(MATCH(Inputs!$C$115,$E$4:$S$4,0),99),1,0)) -> 1 | ... S35: =Inputs!$C$105*(IF(S6>=IFERROR(MATCH(Inputs!$C$114,$E$4:$S$4,0),99),1,0)+IF(S6>=IFERROR(MATCH(Inputs!$C$115,$E$4:$S$4,0),99),1,0)) -> 2
A36: Bank training days (growth plan) | B36: days | C36: =SUM(E36:G36) -> 0 | D36: =SUM(H36:S36) -> 3 | E36: =Inputs!$C$105*IF(E6>=IFERROR(MATCH(Inputs!$C$118,$E$4:$S$4,0),99),Inputs!$C$119,0)*(1-E34) -> 0 | F36: =Inputs!$C$105*IF(F6>=IFERROR(MATCH(Inputs!$C$118,$E$4:$S$4,0),99),Inputs!$C$119,0)*(1-F34) -> 0 | G36: =Inputs!$C$105*IF(G6>=IFERROR(MATCH(Inputs!$C$118,$E$4:$S$4,0),99),Inputs!$C$119,0)*(1-G34) -> 0 | H36: =Inputs!$C$105*IF(H6>=IFERROR(MATCH(Inputs!$C$118,$E$4:$S$4,0),99),Inputs!$C$119,0)*(1-H34) -> 0 | I36: =Inputs!$C$105*IF(I6>=IFERROR(MATCH(Inputs!$C$118,$E$4:$S$4,0),99),Inputs!$C$119,0)*(1-I34) -> 0 | J36: =Inputs!$C$105*IF(J6>=IFERROR(MATCH(Inputs!$C$118,$E$4:$S$4,0),99),Inputs!$C$119,0)*(1-J34) -> 0 | K36: =Inputs!$C$105*IF(K6>=IFERROR(MATCH(Inputs!$C$118,$E$4:$S$4,0),99),Inputs!$C$119,0)*(1-K34) -> 0 | L36: =Inputs!$C$105*IF(L6>=IFERROR(MATCH(Inputs!$C$118,$E$4:$S$4,0),99),Inputs!$C$119,0)*(1-L34) -> 0 | ... S36: =Inputs!$C$105*IF(S6>=IFERROR(MATCH(Inputs!$C$118,$E$4:$S$4,0),99),Inputs!$C$119,0)*(1-S34) -> 1

Sheet Unit_Economics
A1: Pillar 1 - Unit economics and B2B customer acquisition cost (Rp million)
A3: Product | B3: Price | C3: Delivery cost | D3: Extra travel (if you pay) | E3: Coreitera fee (assessment cost) | F3: Total delivery cost | G3: Contribution (profit per event) | H3: Contribution % | I3: Price / external cost | J3: Meets your 3x rule? | K3: Handler-days | L3: Contribution per handler-day | M3: Coreitera revenue per event (memo) | N3: Old price (before new prices start) | O3: Old delivery cost
A4: Flagship regulator ToT | B4: =IF(Inputs!$C$85=2,Inputs!$C$87+Inputs!$C$93*Inputs!$C$63*Inputs!$C$92,Inputs!$C$9) -> 100 | C4: =Inputs!$C$16 -> 25 | D4: 0 | E4: =IF(Inputs!$C$85=2,Inputs!$C$93*Inputs!$C$63*Inputs!$C$62,IF(Inputs!$C$61=1,0,Inputs!$C$63*Inputs!$C$62)) -> 3 | F4: =C4+D4+E4 -> 28 | G4: =B4-F4 -> 72 | H4: =IF(B4=0,0,G4/B4) -> 0.72 | I4: =IF(C4+D4=0,0,B4/(C4+D4)) -> 4 | J4: =IF(I4>=3,"Yes","No - below 3x") -> Yes | K4: =Inputs!$C$26*Inputs!$C$30 -> 12 | L4: =IF(K4=0,0,G4/K4) -> 6 | M4: =Inputs!$C$63*Inputs!$C$62 -> 3 | N4: =Inputs!$C$9 -> 85 | O4: =C4+D4+IF(Inputs!$C$61=1,0,Inputs!$C$63*Inputs!$C$62) -> 25
A5: KPW / LPS regional ToT | B5: =IF(Inputs!$C$85=2,Inputs!$C$88+Inputs!$C$94*Inputs!$C$64*Inputs!$C$92,Inputs!$C$10) -> 28.5 | C5: =Inputs!$C$17 -> 8 | D5: =IF(Inputs!$C$22=1,0,Inputs!$C$27*Inputs!$C$23*Inputs!$C$24) -> 0 | E5: =IF(Inputs!$C$85=2,Inputs!$C$94*Inputs!$C$64*Inputs!$C$62,IF(Inputs!$C$61=1,0,Inputs!$C$64*Inputs!$C$62)) -> 2.25 | F5: =C5+D5+E5 -> 10.25 | G5: =B5-F5 -> 18.25 | H5: =IF(B5=0,0,G5/B5) -> 0.64035088 | I5: =IF(C5+D5=0,0,B5/(C5+D5)) -> 3.5625 | J5: =IF(I5>=3,"Yes","No - below 3x") -> Yes | K5: =Inputs!$C$27*Inputs!$C$31 -> 2 | L5: =IF(K5=0,0,G5/K5) -> 9.125 | M5: =Inputs!$C$64*Inputs!$C$62 -> 2.25 | N5: =Inputs!$C$10 -> 20 | O5: =C5+D5+IF(Inputs!$C$61=1,0,Inputs!$C$64*Inputs!$C$62) -> 8
A6: Bank KCP event | B6: =IF(Inputs!$C$85=2,(1-Inputs!$C$91)*Inputs!$C$89+Inputs!$C$91*Inputs!$C$90+Inputs!$C$95*Inputs!$C$65*Inputs!$C$92,Inputs!$C$11) -> 53.5 | C6: =Inputs!$C$18 -> 12 | D6: 0 | E6: =IF(Inputs!$C$85=2,Inputs!$C$95*Inputs!$C$65*Inputs!$C$62,IF(Inputs!$C$61=1,0,Inputs!$C$65*Inputs!$C$62)) -> 3 | F6: =C6+D6+E6 -> 15 | G6: =B6-F6 -> 38.5 | H6: =IF(B6=0,0,G6/B6) -> 0.71962617 | I6: =IF(C6+D6=0,0,B6/(C6+D6)) -> 4.4583333 | J6: =IF(I6>=3,"Yes","No - below 3x") -> Yes | K6: =Inputs!$C$28*Inputs!$C$32 -> 2 | L6: =IF(K6=0,0,G6/K6) -> 19.25 | M6: =Inputs!$C$65*Inputs!$C$62 -> 3 | N6: =Inputs!$C$11 -> 35 | O6: =C6+D6+IF(Inputs!$C$61=1,0,Inputs!$C$65*Inputs!$C$62) -> 12
A7: Bank EAP (per month) | B7: =Inputs!$C$12 -> 15 | C7: =Inputs!$C$19 -> 5 | D7: 0 | E7: 0 | F7: =C7+D7+E7 -> 5 | G7: =B7-F7 -> 10 | H7: =IF(B7=0,0,G7/B7) -> 0.66666667 | I7: =IF(C7+D7=0,0,B7/(C7+D7)) -> 3 | J7: =IF(I7>=3,"Yes","No - below 3x") -> Yes | K7: 0 | L7: =IF(K7=0,0,G7/K7) -> 0 | M7: 0 | N7: =Inputs!$C$12 -> 15 | O7: =C7+D7+0 -> 5
A8: B2C mass event | B8: =Inputs!$C$13 -> 20 | C8: =Inputs!$C$20 -> 8 | D8: 0 | E8: =IF(Inputs!$C$61=1,0,Inputs!$C$66*Inputs!$C$62) -> 0 | F8: =C8+D8+E8 -> 8 | G8: =B8-F8 -> 12 | H8: =IF(B8=0,0,G8/B8) -> 0.6 | I8: =IF(C8+D8=0,0,B8/(C8+D8)) -> 2.5 | J8: =IF(I8>=3,"Yes","No - below 3x") -> No - below 3x | K8: =Inputs!$C$29*Inputs!$C$33 -> 2 | L8: =IF(K8=0,0,G8/K8) -> 6 | M8: =Inputs!$C$66*Inputs!$C$62 -> 3.75 | N8: =Inputs!$C$13 -> 20 | O8: =C8+D8+IF(Inputs!$C$61=1,0,Inputs!$C$66*Inputs!$C$62) -> 8
A10: B2B customer acquisition cost (CAC)
A11: Sales cost per year (sales travel + Account Manager if hired; founder time not costed) | B11: =IF(Inputs!$C$52=1,(Inputs!$C$53+Inputs!$C$55)*12,Inputs!$C$55*12) -> 24
A12: New B2B clients won per year | B12: =Inputs!$C$70 -> 4
A13: CAC: cost to win one new B2B client | B13: =IF(B12=0,0,B11/B12) -> 6
A14: Events needed to pay back CAC: Flagship | B14: =IF(G4<=0,0,B13/G4) -> 0.083333333
A15: Events needed to pay back CAC: KPW / LPS | B15: =IF(G5<=0,0,B13/G5) -> 0.32876712
A16: Events needed to pay back CAC: Bank KCP | B16: =IF(G6<=0,0,B13/G6) -> 0.15584416
A17: Months of EAP needed to pay back CAC | B17: =IF(G7<=0,0,B13/G7) -> 0.6
A19: How to read: Contribution = price minus everything you pay to deliver that one event. It is what is left to pay fixed costs.
A20: Your pricing rule is price at least 3x the delivery cost paid outside the group (Coreitera fees stay inside). Rows marked 'No' break that rule.
A21: CAC counts only direct sales spend. Founder time is not costed here because founders are paid a fixed salary.
A22: Coreitera revenue per event is a memo: it is money paid between your own companies, so it cancels out in the combined profit.

Sheet Rate_Card
A1: Rate card - elite boutique pricing by client tier (Rp million)
A2: Rule: price close to the buyer's ceiling for regulators, and against the big-trainer alternative for banks. Never below 3x delivery cost. Prices here always show the new rate card, whatever the active price plan.
A4: Tier and product | B4: What caps the price | C4: Training price | D4: Days | E4: Price per day | F4: Assessment per participant | G4: Participants | H4: Package price (training + assessment) | I4: External delivery cost (excl. Coreitera) | J4: Price / external cost | K4: Meets 3x? | L4: Per day vs big-trainer rate | M4: Best contract shape
A5: Tier 1 regulator - Flagship ToT (BI, OJK, LPS) | B5: Budget ceiling per activity; past contracts set the anchor | C5: =Inputs!$C$87 -> 94 | D5: =Inputs!$C$30 -> 3 | E5: =IF(D5=0,0,C5/D5) -> 31.333333 | F5: =Inputs!$C$92*Inputs!$C$93 -> 0.15 | G5: =Inputs!$C$63 -> 40 | H5: =C5+F5*G5 -> 100 | I5: =Inputs!$C$16 -> 25 | J5: =IF(I5=0,0,H5/I5) -> 4 | K5: =IF(J5>=3,"Yes","No") -> Yes | L5: =IF((Inputs!$C$96*Inputs!$C$11)=0,0,E5/(Inputs!$C$96*Inputs!$C$11)) -> 0.35809524 | M5: Yearly framework contract with central procurement
A6: Tier 1 regulator - Regional ToT (BI KPW, LPS) | B6: Budget ceiling per activity | C6: =Inputs!$C$88 -> 24 | D6: =Inputs!$C$31 -> 1 | E6: =IF(D6=0,0,C6/D6) -> 24 | F6: =Inputs!$C$92*Inputs!$C$94 -> 0.15 | G6: =Inputs!$C$64 -> 30 | H6: =C6+F6*G6 -> 28.5 | I6: =Inputs!$C$17 -> 8 | J6: =IF(I6=0,0,H6/I6) -> 3.5625 | K6: =IF(J6>=3,"Yes","No") -> Yes | L6: =IF((Inputs!$C$96*Inputs!$C$11)=0,0,E6/(Inputs!$C$96*Inputs!$C$11)) -> 0.27428571 | M6: Framework + work order (SPK) per office
A7: State-owned bank (BRI, Mandiri, BNI, BTN) | B7: Vendor tender and price competition | C7: =Inputs!$C$89 -> 45 | D7: =Inputs!$C$32 -> 1 | E7: =IF(D7=0,0,C7/D7) -> 45 | F7: =Inputs!$C$92*Inputs!$C$95 -> 0.15 | G7: =Inputs!$C$65 -> 40 | H7: =C7+F7*G7 -> 51 | I7: =Inputs!$C$18 -> 12 | J7: =IF(I7=0,0,H7/I7) -> 4.25 | K7: =IF(J7>=3,"Yes","No") -> Yes | L7: =IF((Inputs!$C$96*Inputs!$C$11)=0,0,E7/(Inputs!$C$96*Inputs!$C$11)) -> 0.51428571 | M7: Multi-branch yearly framework (10+ groups), 30% down payment
A8: Private big bank (BCA and others) | B8: Value vs big trainers (2-3x your old rate) | C8: =Inputs!$C$90 -> 55 | D8: =Inputs!$C$32 -> 1 | E8: =IF(D8=0,0,C8/D8) -> 55 | F8: =Inputs!$C$92*Inputs!$C$95 -> 0.15 | G8: =Inputs!$C$65 -> 40 | H8: =C8+F8*G8 -> 61 | I8: =Inputs!$C$18 -> 12 | J8: =IF(I8=0,0,H8/I8) -> 5.0833333 | K8: =IF(J8>=3,"Yes","No") -> Yes | L8: =IF((Inputs!$C$96*Inputs!$C$11)=0,0,E8/(Inputs!$C$96*Inputs!$C$11)) -> 0.62857143 | M8: Annual learning partnership + EAP priced per employee
A9: Reference: big-trainer day rate charged to banks | B9: Your old bank rate x the multiple you gave (2-3x, midpoint). | E9: =(Inputs!$C$96*Inputs!$C$11) -> 87.5
A11: Bank packages (good / better / best) - per group per day
A12: Package | B12: What is included | C12: State-owned bank | E12: Private bank
A13: Essential | B13: Training day only | C13: =C7 -> 45 | E13: =C8 -> 55
A14: Signature (lead offer) | B14: Training + pre/post assessment + impact report | C14: =H7 -> 51 | E14: =H8 -> 61
A15: Elite | B15: Signature + cascade licence for trainers + 3 months follow-up | C15: =H7*(1+Inputs!$C$97) -> 66.3 | E15: =H8*(1+Inputs!$C$97) -> 79.3
A17: Volume-loss test: how many events can you lose and still earn more?
A18: Product | B18: Profit per event, old price | C18: Profit per event, new package | D18: Max share of events you can lose | E18: Meaning
A19: Flagship ToT | B19: =Inputs!$C$9-Inputs!$C$16 -> 60 | C19: =H5-I5-Inputs!$C$93*G5*Inputs!$C$62 -> 72 | D19: =IF(C19<=0,0,1-B19/C19) -> 0.16666667 | E19: ="Lose fewer than "&TEXT(D19,"0%")&" of these events and profit still goes up." -> Lose fewer than 17% of these events and profit still goes up.
A20: KPW / LPS ToT | B20: =Inputs!$C$10-Inputs!$C$17 -> 12 | C20: =H6-I6-Inputs!$C$94*G6*Inputs!$C$62 -> 18.25 | D20: =IF(C20<=0,0,1-B20/C20) -> 0.34246575 | E20: ="Lose fewer than "&TEXT(D20,"0%")&" of these events and profit still goes up." -> Lose fewer than 34% of these events and profit still goes up.
A21: Bank event (state-owned) | B21: =Inputs!$C$11-Inputs!$C$18 -> 23 | C21: =H7-I7-Inputs!$C$95*G7*Inputs!$C$62 -> 36 | D21: =IF(C21<=0,0,1-B21/C21) -> 0.36111111 | E21: ="Lose fewer than "&TEXT(D21,"0%")&" of these events and profit still goes up." -> Lose fewer than 36% of these events and profit still goes up.
A22: Bank event (private) | B22: =Inputs!$C$11-Inputs!$C$18 -> 23 | C22: =H8-I8-Inputs!$C$95*G8*Inputs!$C$62 -> 46 | D22: =IF(C22<=0,0,1-B22/C22) -> 0.5 | E22: ="Lose fewer than "&TEXT(D22,"0%")&" of these events and profit still goes up." -> Lose fewer than 50% of these events and profit still goes up.
A24: Pricing rules (all tiers)
A25: 1. Price units: per group per day (training), per participant (assessment), per employee per month (EAP), per year (cascade licence). Never one lump sum.
A26: 2. Floor: never below 3x the delivery cost paid outside the group. The Coreitera fee is excluded because it stays inside your own companies.
A27: 3. Pilot discount: at most 20%, once per client, recorded as a sales cost, and tied to a follow-on contract.
A28: 4. Volume discount: 5% for 5+ groups a year, 10% for 10+ groups. Never more than 10%.
A29: 5. Travel and venue: paid by the client, or billed at cost plus 10%.
A30: 6. Payment: 30% down payment for bank contracts above Rp100m. Regulators keep current terms.
A31: 7. Regulators: never raise the price of an old item. Add new items (assessment, licence, follow-up), which get a fresh budget ceiling.
A32: 8. Elite boutique position: always clearly below big trainers, never the cheapest. Compete on more services and a measured result.

Sheet Capacity_OPEX
A1: Pillar 2 - Capacity and step-function fixed costs
A2: Rp million unless stated. Q4 2026 and FY 2027 columns are totals (or averages / peaks where stated).
A4: Line | B4: Unit | C4: Q4 2026 | D4: FY 2027 | E4: Oct-26 | F4: Nov-26 | G4: Dec-26 | H4: Jan-27 | I4: Feb-27 | J4: Mar-27 | K4: Apr-27 | L4: May-27 | M4: Jun-27 | N4: Jul-27 | O4: Aug-27 | P4: Sep-27 | Q4: Oct-27 | R4: Nov-27 | S4: Dec-27
A5: Delivery capacity
A6: Handler placements (people x events) | B6: placements | C6: =SUM(E6:G6) -> 0 | D6: =SUM(H6:S6) -> 74 | E6: =Volume!E23*Inputs!$C$26+Volume!E24*Inputs!$C$27+Volume!E25*Inputs!$C$28+Volume!E27*Inputs!$C$29 -> 0 | F6: =Volume!F23*Inputs!$C$26+Volume!F24*Inputs!$C$27+Volume!F25*Inputs!$C$28+Volume!F27*Inputs!$C$29 -> 0 | G6: =Volume!G23*Inputs!$C$26+Volume!G24*Inputs!$C$27+Volume!G25*Inputs!$C$28+Volume!G27*Inputs!$C$29 -> 0 | H6: =Volume!H23*Inputs!$C$26+Volume!H24*Inputs!$C$27+Volume!H25*Inputs!$C$28+Volume!H27*Inputs!$C$29 -> 0 | I6: =Volume!I23*Inputs!$C$26+Volume!I24*Inputs!$C$27+Volume!I25*Inputs!$C$28+Volume!I27*Inputs!$C$29 -> 0 | J6: =Volume!J23*Inputs!$C$26+Volume!J24*Inputs!$C$27+Volume!J25*Inputs!$C$28+Volume!J27*Inputs!$C$29 -> 6 | K6: =Volume!K23*Inputs!$C$26+Volume!K24*Inputs!$C$27+Volume!K25*Inputs!$C$28+Volume!K27*Inputs!$C$29 -> 2 | L6: =Volume!L23*Inputs!$C$26+Volume!L24*Inputs!$C$27+Volume!L25*Inputs!$C$28+Volume!L27*Inputs!$C$29 -> 6 | ... S6: =Volume!S23*Inputs!$C$26+Volume!S24*Inputs!$C$27+Volume!S25*Inputs!$C$28+Volume!S27*Inputs!$C$29 -> 14
A7: Handler-days (placements x days per event) | B7: days | C7: =SUM(E7:G7) -> 0 | D7: =SUM(H7:S7) -> 114 | E7: =Volume!E23*Inputs!$C$26*Inputs!$C$30+Volume!E24*Inputs!$C$27*Inputs!$C$31+Volume!E25*Inputs!$C$28*Inputs!$C$32+Volume!E27*Inputs!$C$29*Inputs!$C$33 -> 0 | F7: =Volume!F23*Inputs!$C$26*Inputs!$C$30+Volume!F24*Inputs!$C$27*Inputs!$C$31+Volume!F25*Inputs!$C$28*Inputs!$C$32+Volume!F27*Inputs!$C$29*Inputs!$C$33 -> 0 | G7: =Volume!G23*Inputs!$C$26*Inputs!$C$30+Volume!G24*Inputs!$C$27*Inputs!$C$31+Volume!G25*Inputs!$C$28*Inputs!$C$32+Volume!G27*Inputs!$C$29*Inputs!$C$33 -> 0 | H7: =Volume!H23*Inputs!$C$26*Inputs!$C$30+Volume!H24*Inputs!$C$27*Inputs!$C$31+Volume!H25*Inputs!$C$28*Inputs!$C$32+Volume!H27*Inputs!$C$29*Inputs!$C$33 -> 0 | I7: =Volume!I23*Inputs!$C$26*Inputs!$C$30+Volume!I24*Inputs!$C$27*Inputs!$C$31+Volume!I25*Inputs!$C$28*Inputs!$C$32+Volume!I27*Inputs!$C$29*Inputs!$C$33 -> 0 | J7: =Volume!J23*Inputs!$C$26*Inputs!$C$30+Volume!J24*Inputs!$C$27*Inputs!$C$31+Volume!J25*Inputs!$C$28*Inputs!$C$32+Volume!J27*Inputs!$C$29*Inputs!$C$33 -> 14 | K7: =Volume!K23*Inputs!$C$26*Inputs!$C$30+Volume!K24*Inputs!$C$27*Inputs!$C$31+Volume!K25*Inputs!$C$28*Inputs!$C$32+Volume!K27*Inputs!$C$29*Inputs!$C$33 -> 2 | L7: =Volume!L23*Inputs!$C$26*Inputs!$C$30+Volume!L24*Inputs!$C$27*Inputs!$C$31+Volume!L25*Inputs!$C$28*Inputs!$C$32+Volume!L27*Inputs!$C$29*Inputs!$C$33 -> 14 | ... S7: =Volume!S23*Inputs!$C$26*Inputs!$C$30+Volume!S24*Inputs!$C$27*Inputs!$C$31+Volume!S25*Inputs!$C$28*Inputs!$C$32+Volume!S27*Inputs!$C$29*Inputs!$C$33 -> 14
A8: Facilitators needed this month (placements / max events each) | B8: people | C8: =MAX(E8:G8) -> 0 | D8: =MAX(H8:S8) -> 8 | E8: =ROUNDUP(E6/Inputs!$C$34,0) -> 0 | F8: =ROUNDUP(F6/Inputs!$C$34,0) -> 0 | G8: =ROUNDUP(G6/Inputs!$C$34,0) -> 0 | H8: =ROUNDUP(H6/Inputs!$C$34,0) -> 0 | I8: =ROUNDUP(I6/Inputs!$C$34,0) -> 0 | J8: =ROUNDUP(J6/Inputs!$C$34,0) -> 3 | K8: =ROUNDUP(K6/Inputs!$C$34,0) -> 1 | L8: =ROUNDUP(L6/Inputs!$C$34,0) -> 3 | ... S8: =ROUNDUP(S6/Inputs!$C$34,0) -> 7
A9: Certified facilitator pool (grows when needed, never shrinks) | B9: people | C9: =G9 -> 2 | D9: =S9 -> 8 | E9: =MAX(Inputs!$C$35,E8) -> 2 | F9: =MAX(E9,F8) -> 2 | G9: =MAX(F9,G8) -> 2 | H9: =MAX(G9,H8) -> 2 | I9: =MAX(H9,I8) -> 2 | J9: =MAX(I9,J8) -> 3 | K9: =MAX(J9,K8) -> 3 | L9: =MAX(K9,L8) -> 3 | M9: =MAX(L9,M8) -> 3 | ... S9: =MAX(R9,S8) -> 8
A10: New facilitators to certify this month | B10: people | C10: =SUM(E10:G10) -> 0 | D10: =SUM(H10:S10) -> 6 | E10: =E9-Inputs!$C$35 -> 0 | F10: =F9-E9 -> 0 | G10: =G9-F9 -> 0 | H10: =H9-G9 -> 0 | I10: =I9-H9 -> 0 | J10: =J9-I9 -> 1 | K10: =K9-J9 -> 0 | L10: =L9-K9 -> 0 | M10: =M9-L9 -> 0 | ... S10: =S9-R9 -> 0
A11: Your plan (11 by Nov 2026) minus need: spare facilitators | B11: people | C11: =MIN(E11:G11) -> 11 | D11: =MIN(H11:S11) -> 3 | E11: =Inputs!$C$36-E8 -> 11 | F11: =Inputs!$C$36-F8 -> 11 | G11: =Inputs!$C$36-G8 -> 11 | H11: =Inputs!$C$36-H8 -> 11 | I11: =Inputs!$C$36-I8 -> 11 | J11: =Inputs!$C$36-J8 -> 8 | K11: =Inputs!$C$36-K8 -> 10 | L11: =Inputs!$C$36-L8 -> 8 | ... S11: =Inputs!$C$36-S8 -> 4
A13: Step triggers
A14: B2B events, average of last 3 months | B14: events | C14: =MAX(E14:G14) -> 0 | D14: =MAX(H14:S14) -> 5.3333333 | E14: =AVERAGE(Volume!E29:E29) -> 0 | F14: =AVERAGE(Volume!E29:F29) -> 0 | G14: =AVERAGE(Volume!E29:G29) -> 0 | H14: =AVERAGE(Volume!F29:H29) -> 0 | I14: =AVERAGE(Volume!G29:I29) -> 0 | J14: =AVERAGE(Volume!H29:J29) -> 0.66666667 | K14: =AVERAGE(Volume!I29:K29) -> 1 | L14: =AVERAGE(Volume!J29:L29) -> 1.6666667 | M14: =AVERAGE(Volume!K29:M29) -> 1.3333333 | N14: =AVERAGE(Volume!L29:N29) -> 2 | ... S14: =AVERAGE(Volume!Q29:S29) -> 5.3333333
A15: Project Manager hired? (1 = yes; starts the month after the trigger) | B15: flag | C15: =G15 -> 0 | D15: =S15 -> 1 | E15: =0 -> 0 | F15: =IF(OR(E15=1,E14>=Inputs!$C$57),1,0) -> 0 | G15: =IF(OR(F15=1,F14>=Inputs!$C$57),1,0) -> 0 | H15: =IF(OR(G15=1,G14>=Inputs!$C$57),1,0) -> 0 | I15: =IF(OR(H15=1,H14>=Inputs!$C$57),1,0) -> 0 | J15: =IF(OR(I15=1,I14>=Inputs!$C$57),1,0) -> 0 | K15: =IF(OR(J15=1,J14>=Inputs!$C$57),1,0) -> 0 | L15: =IF(OR(K15=1,K14>=Inputs!$C$57),1,0) -> 0 | M15: =IF(OR(L15=1,L14>=Inputs!$C$57),1,0) -> 0 | ... S15: =IF(OR(R15=1,R14>=Inputs!$C$57),1,0) -> 1
A16: Account Manager active? (1 = yes) | B16: flag | C16: =G16 -> 0 | D16: =S16 -> 0 | E16: =IF(AND(Inputs!$C$52=1,Volume!E6>=IFERROR(MATCH(Inputs!$C$54,Volume!$E$4:$S$4,0),99)),1,0) -> 0 | F16: =IF(AND(Inputs!$C$52=1,Volume!F6>=IFERROR(MATCH(Inputs!$C$54,Volume!$E$4:$S$4,0),99)),1,0) -> 0 | G16: =IF(AND(Inputs!$C$52=1,Volume!G6>=IFERROR(MATCH(Inputs!$C$54,Volume!$E$4:$S$4,0),99)),1,0) -> 0 | H16: =IF(AND(Inputs!$C$52=1,Volume!H6>=IFERROR(MATCH(Inputs!$C$54,Volume!$E$4:$S$4,0),99)),1,0) -> 0 | I16: =IF(AND(Inputs!$C$52=1,Volume!I6>=IFERROR(MATCH(Inputs!$C$54,Volume!$E$4:$S$4,0),99)),1,0) -> 0 | J16: =IF(AND(Inputs!$C$52=1,Volume!J6>=IFERROR(MATCH(Inputs!$C$54,Volume!$E$4:$S$4,0),99)),1,0) -> 0 | K16: =IF(AND(Inputs!$C$52=1,Volume!K6>=IFERROR(MATCH(Inputs!$C$54,Volume!$E$4:$S$4,0),99)),1,0) -> 0 | L16: =IF(AND(Inputs!$C$52=1,Volume!L6>=IFERROR(MATCH(Inputs!$C$54,Volume!$E$4:$S$4,0),99)),1,0) -> 0 | ... S16: =IF(AND(Inputs!$C$52=1,Volume!S6>=IFERROR(MATCH(Inputs!$C$54,Volume!$E$4:$S$4,0),99)),1,0) -> 0
A17: Founder salaries active? (1 = yes) | B17: flag | C17: =G17 -> 0 | D17: =S17 -> 1 | E17: =IF(Volume!E6>=IFERROR(MATCH(Inputs!$C$51,Volume!$E$4:$S$4,0),99),1,0) -> 0 | F17: =IF(Volume!F6>=IFERROR(MATCH(Inputs!$C$51,Volume!$E$4:$S$4,0),99),1,0) -> 0 | G17: =IF(Volume!G6>=IFERROR(MATCH(Inputs!$C$51,Volume!$E$4:$S$4,0),99),1,0) -> 0 | H17: =IF(Volume!H6>=IFERROR(MATCH(Inputs!$C$51,Volume!$E$4:$S$4,0),99),1,0) -> 0 | I17: =IF(Volume!I6>=IFERROR(MATCH(Inputs!$C$51,Volume!$E$4:$S$4,0),99),1,0) -> 0 | J17: =IF(Volume!J6>=IFERROR(MATCH(Inputs!$C$51,Volume!$E$4:$S$4,0),99),1,0) -> 0 | K17: =IF(Volume!K6>=IFERROR(MATCH(Inputs!$C$51,Volume!$E$4:$S$4,0),99),1,0) -> 0 | L17: =IF(Volume!L6>=IFERROR(MATCH(Inputs!$C$51,Volume!$E$4:$S$4,0),99),1,0) -> 1 | ... S17: =IF(Volume!S6>=IFERROR(MATCH(Inputs!$C$51,Volume!$E$4:$S$4,0),99),1,0) -> 1
A18: Invoices to send this month | B18: invoices | C18: =MAX(E18:G18) -> 2.33 | D18: =MAX(H18:S18) -> 11.33 | E18: =Volume!E23+Volume!E24+Volume!E25+Volume!E26+Volume!E27+Inputs!$C$59 -> 2.33 | F18: =Volume!F23+Volume!F24+Volume!F25+Volume!F26+Volume!F27+Inputs!$C$59 -> 2.33 | G18: =Volume!G23+Volume!G24+Volume!G25+Volume!G26+Volume!G27+Inputs!$C$59 -> 2.33 | H18: =Volume!H23+Volume!H24+Volume!H25+Volume!H26+Volume!H27+Inputs!$C$59 -> 2.33 | I18: =Volume!I23+Volume!I24+Volume!I25+Volume!I26+Volume!I27+Inputs!$C$59 -> 2.33 | J18: =Volume!J23+Volume!J24+Volume!J25+Volume!J26+Volume!J27+Inputs!$C$59 -> 4.33 | K18: =Volume!K23+Volume!K24+Volume!K25+Volume!K26+Volume!K27+Inputs!$C$59 -> 4.33 | L18: =Volume!L23+Volume!L24+Volume!L25+Volume!L26+Volume!L27+Inputs!$C$59 -> 5.33 | ... S18: =Volume!S23+Volume!S24+Volume!S25+Volume!S26+Volume!S27+Inputs!$C$59 -> 11.33
A19: Second admin hired? (1 = yes; stays once hired) | B19: flag | C19: =G19 -> 0 | D19: =S19 -> 0 | E19: =IF(E18>Inputs!$C$58,1,0) -> 0 | F19: =IF(OR(E19=1,F18>Inputs!$C$58),1,0) -> 0 | G19: =IF(OR(F19=1,G18>Inputs!$C$58),1,0) -> 0 | H19: =IF(OR(G19=1,H18>Inputs!$C$58),1,0) -> 0 | I19: =IF(OR(H19=1,I18>Inputs!$C$58),1,0) -> 0 | J19: =IF(OR(I19=1,J18>Inputs!$C$58),1,0) -> 0 | K19: =IF(OR(J19=1,K18>Inputs!$C$58),1,0) -> 0 | L19: =IF(OR(K19=1,L18>Inputs!$C$58),1,0) -> 0 | M19: =IF(OR(L19=1,M18>Inputs!$C$58),1,0) -> 0 | ... S19: =IF(OR(R19=1,S18>Inputs!$C$58),1,0) -> 0
A21: Fixed costs per month (Rp million)
A22: L0 Base team (your 2027 list: 6 people) | B22: Rp m | C22: =SUM(E22:G22) -> 33.9 | D22: =SUM(H22:S22) -> 135.6 | E22: =Inputs!$C$39+Inputs!$C$40+Inputs!$C$41+Inputs!$C$42+Inputs!$C$43+Inputs!$C$44 -> 11.3 | F22: =Inputs!$C$39+Inputs!$C$40+Inputs!$C$41+Inputs!$C$42+Inputs!$C$43+Inputs!$C$44 -> 11.3 | G22: =Inputs!$C$39+Inputs!$C$40+Inputs!$C$41+Inputs!$C$42+Inputs!$C$43+Inputs!$C$44 -> 11.3 | H22: =Inputs!$C$39+Inputs!$C$40+Inputs!$C$41+Inputs!$C$42+Inputs!$C$43+Inputs!$C$44 -> 11.3 | I22: =Inputs!$C$39+Inputs!$C$40+Inputs!$C$41+Inputs!$C$42+Inputs!$C$43+Inputs!$C$44 -> 11.3 | J22: =Inputs!$C$39+Inputs!$C$40+Inputs!$C$41+Inputs!$C$42+Inputs!$C$43+Inputs!$C$44 -> 11.3 | K22: =Inputs!$C$39+Inputs!$C$40+Inputs!$C$41+Inputs!$C$42+Inputs!$C$43+Inputs!$C$44 -> 11.3 | L22: =Inputs!$C$39+Inputs!$C$40+Inputs!$C$41+Inputs!$C$42+Inputs!$C$43+Inputs!$C$44 -> 11.3 | ... S22: =Inputs!$C$39+Inputs!$C$40+Inputs!$C$41+Inputs!$C$42+Inputs!$C$43+Inputs!$C$44 -> 11.3
A23: L0 Software and IG ads | B23: Rp m | C23: =SUM(E23:G23) -> 6.23975 | D23: =SUM(H23:S23) -> 24.959 | E23: =Inputs!$C$45 -> 2.0799167 | F23: =Inputs!$C$45 -> 2.0799167 | G23: =Inputs!$C$45 -> 2.0799167 | H23: =Inputs!$C$45 -> 2.0799167 | I23: =Inputs!$C$45 -> 2.0799167 | J23: =Inputs!$C$45 -> 2.0799167 | K23: =Inputs!$C$45 -> 2.0799167 | L23: =Inputs!$C$45 -> 2.0799167 | ... S23: =Inputs!$C$45 -> 2.0799167
A24: L0 Office | B24: Rp m | C24: =SUM(E24:G24) -> 17.4 | D24: =SUM(H24:S24) -> 69.6 | E24: =Inputs!$C$46 -> 5.8 | F24: =Inputs!$C$46 -> 5.8 | G24: =Inputs!$C$46 -> 5.8 | H24: =Inputs!$C$46 -> 5.8 | I24: =Inputs!$C$46 -> 5.8 | J24: =Inputs!$C$46 -> 5.8 | K24: =Inputs!$C$46 -> 5.8 | L24: =Inputs!$C$46 -> 5.8 | ... S24: =Inputs!$C$46 -> 5.8
A25: L0 Accountant / tax (estimate) | B25: Rp m | C25: =SUM(E25:G25) -> 4.5 | D25: =SUM(H25:S25) -> 18 | E25: =Inputs!$C$47 -> 1.5 | F25: =Inputs!$C$47 -> 1.5 | G25: =Inputs!$C$47 -> 1.5 | H25: =Inputs!$C$47 -> 1.5 | I25: =Inputs!$C$47 -> 1.5 | J25: =Inputs!$C$47 -> 1.5 | K25: =Inputs!$C$47 -> 1.5 | L25: =Inputs!$C$47 -> 1.5 | ... S25: =Inputs!$C$47 -> 1.5
A26: Founder salaries | B26: Rp m | C26: =SUM(E26:G26) -> 0 | D26: =SUM(H26:S26) -> 200 | E26: =E17*(Inputs!$C$49+Inputs!$C$50) -> 0 | F26: =F17*(Inputs!$C$49+Inputs!$C$50) -> 0 | G26: =G17*(Inputs!$C$49+Inputs!$C$50) -> 0 | H26: =H17*(Inputs!$C$49+Inputs!$C$50) -> 0 | I26: =I17*(Inputs!$C$49+Inputs!$C$50) -> 0 | J26: =J17*(Inputs!$C$49+Inputs!$C$50) -> 0 | K26: =K17*(Inputs!$C$49+Inputs!$C$50) -> 0 | L26: =L17*(Inputs!$C$49+Inputs!$C$50) -> 25 | ... S26: =S17*(Inputs!$C$49+Inputs!$C$50) -> 25
A27: L1 Account Manager | B27: Rp m | C27: =SUM(E27:G27) -> 0 | D27: =SUM(H27:S27) -> 0 | E27: =E16*Inputs!$C$53 -> 0 | F27: =F16*Inputs!$C$53 -> 0 | G27: =G16*Inputs!$C$53 -> 0 | H27: =H16*Inputs!$C$53 -> 0 | I27: =I16*Inputs!$C$53 -> 0 | J27: =J16*Inputs!$C$53 -> 0 | K27: =K16*Inputs!$C$53 -> 0 | L27: =L16*Inputs!$C$53 -> 0 | ... S27: =S16*Inputs!$C$53 -> 0
A28: L1 Sales travel (founders or AM) | B28: Rp m | C28: =SUM(E28:G28) -> 0 | D28: =SUM(H28:S28) -> 24 | E28: =IF(Volume!E6>=IFERROR(MATCH(Inputs!$C$54,Volume!$E$4:$S$4,0),99),Inputs!$C$55,0) -> 0 | F28: =IF(Volume!F6>=IFERROR(MATCH(Inputs!$C$54,Volume!$E$4:$S$4,0),99),Inputs!$C$55,0) -> 0 | G28: =IF(Volume!G6>=IFERROR(MATCH(Inputs!$C$54,Volume!$E$4:$S$4,0),99),Inputs!$C$55,0) -> 0 | H28: =IF(Volume!H6>=IFERROR(MATCH(Inputs!$C$54,Volume!$E$4:$S$4,0),99),Inputs!$C$55,0) -> 2 | I28: =IF(Volume!I6>=IFERROR(MATCH(Inputs!$C$54,Volume!$E$4:$S$4,0),99),Inputs!$C$55,0) -> 2 | J28: =IF(Volume!J6>=IFERROR(MATCH(Inputs!$C$54,Volume!$E$4:$S$4,0),99),Inputs!$C$55,0) -> 2 | K28: =IF(Volume!K6>=IFERROR(MATCH(Inputs!$C$54,Volume!$E$4:$S$4,0),99),Inputs!$C$55,0) -> 2 | L28: =IF(Volume!L6>=IFERROR(MATCH(Inputs!$C$54,Volume!$E$4:$S$4,0),99),Inputs!$C$55,0) -> 2 | ... S28: =IF(Volume!S6>=IFERROR(MATCH(Inputs!$C$54,Volume!$E$4:$S$4,0),99),Inputs!$C$55,0) -> 2
A29: L2 Project Manager | B29: Rp m | C29: =SUM(E29:G29) -> 0 | D29: =SUM(H29:S29) -> 5 | E29: =E15*Inputs!$C$56 -> 0 | F29: =F15*Inputs!$C$56 -> 0 | G29: =G15*Inputs!$C$56 -> 0 | H29: =H15*Inputs!$C$56 -> 0 | I29: =I15*Inputs!$C$56 -> 0 | J29: =J15*Inputs!$C$56 -> 0 | K29: =K15*Inputs!$C$56 -> 0 | L29: =L15*Inputs!$C$56 -> 0 | ... S29: =S15*Inputs!$C$56 -> 5
A30: L2 Second admin | B30: Rp m | C30: =SUM(E30:G30) -> 0 | D30: =SUM(H30:S30) -> 0 | E30: =E19*Inputs!$C$43 -> 0 | F30: =F19*Inputs!$C$43 -> 0 | G30: =G19*Inputs!$C$43 -> 0 | H30: =H19*Inputs!$C$43 -> 0 | I30: =I19*Inputs!$C$43 -> 0 | J30: =J19*Inputs!$C$43 -> 0 | K30: =K19*Inputs!$C$43 -> 0 | L30: =L19*Inputs!$C$43 -> 0 | ... S30: =S19*Inputs!$C$43 -> 0
A31: L3 Facilitator certification (one-off) | B31: Rp m | C31: =SUM(E31:G31) -> 0 | D31: =SUM(H31:S31) -> 15 | E31: =E10*Inputs!$C$37 -> 0 | F31: =F10*Inputs!$C$37 -> 0 | G31: =G10*Inputs!$C$37 -> 0 | H31: =H10*Inputs!$C$37 -> 0 | I31: =I10*Inputs!$C$37 -> 0 | J31: =J10*Inputs!$C$37 -> 2.5 | K31: =K10*Inputs!$C$37 -> 0 | L31: =L10*Inputs!$C$37 -> 0 | ... S31: =S10*Inputs!$C$37 -> 0
A32: Total fixed cost | B32: Rp m | C32: =SUM(E32:G32) -> 62.03975 | D32: =SUM(H32:S32) -> 828.4326 | E32: =SUM(E22:E31)+E41 -> 20.679917 | F32: =SUM(F22:F31)+F41 -> 20.679917 | G32: =SUM(G22:G31)+G41 -> 20.679917 | H32: =SUM(H22:H31)+H41 -> 40.462717 | I32: =SUM(I22:I31)+I41 -> 40.462717 | J32: =SUM(J22:J31)+J41 -> 42.962717 | K32: =SUM(K22:K31)+K41 -> 48.782717 | L32: =SUM(L22:L31)+L41 -> 73.782717 | ... S32: =SUM(S22:S31)+S41 -> 86.782717
A34: Growth plan fixed costs (v14)
A35: Fair pay active? (1 = yes) | B35: flag | C35: =MAX(E35:G35) -> 0 | D35: =MAX(H35:S35) -> 1 | E35: =Inputs!$C$105*Inputs!$C$106*IF(Volume!E6>=IFERROR(MATCH(Inputs!$C$107,Volume!$E$4:$S$4,0),99),1,0) -> 0 | F35: =Inputs!$C$105*Inputs!$C$106*IF(Volume!F6>=IFERROR(MATCH(Inputs!$C$107,Volume!$E$4:$S$4,0),99),1,0) -> 0 | G35: =Inputs!$C$105*Inputs!$C$106*IF(Volume!G6>=IFERROR(MATCH(Inputs!$C$107,Volume!$E$4:$S$4,0),99),1,0) -> 0 | H35: =Inputs!$C$105*Inputs!$C$106*IF(Volume!H6>=IFERROR(MATCH(Inputs!$C$107,Volume!$E$4:$S$4,0),99),1,0) -> 1 | I35: =Inputs!$C$105*Inputs!$C$106*IF(Volume!I6>=IFERROR(MATCH(Inputs!$C$107,Volume!$E$4:$S$4,0),99),1,0) -> 1 | J35: =Inputs!$C$105*Inputs!$C$106*IF(Volume!J6>=IFERROR(MATCH(Inputs!$C$107,Volume!$E$4:$S$4,0),99),1,0) -> 1 | K35: =Inputs!$C$105*Inputs!$C$106*IF(Volume!K6>=IFERROR(MATCH(Inputs!$C$107,Volume!$E$4:$S$4,0),99),1,0) -> 1 | L35: =Inputs!$C$105*Inputs!$C$106*IF(Volume!L6>=IFERROR(MATCH(Inputs!$C$107,Volume!$E$4:$S$4,0),99),1,0) -> 1 | ... S35: =Inputs!$C$105*Inputs!$C$106*IF(Volume!S6>=IFERROR(MATCH(Inputs!$C$107,Volume!$E$4:$S$4,0),99),1,0) -> 1
A36: Full-time psychologist active? (starts with EAP contract 2) | B36: flag | C36: =MAX(E36:G36) -> 0 | D36: =MAX(H36:S36) -> 1 | E36: =Inputs!$C$105*Inputs!$C$106*IF(Volume!E6>=IFERROR(MATCH(Inputs!$C$114,Volume!$E$4:$S$4,0),99),1,0) -> 0 | F36: =Inputs!$C$105*Inputs!$C$106*IF(Volume!F6>=IFERROR(MATCH(Inputs!$C$114,Volume!$E$4:$S$4,0),99),1,0) -> 0 | G36: =Inputs!$C$105*Inputs!$C$106*IF(Volume!G6>=IFERROR(MATCH(Inputs!$C$114,Volume!$E$4:$S$4,0),99),1,0) -> 0 | H36: =Inputs!$C$105*Inputs!$C$106*IF(Volume!H6>=IFERROR(MATCH(Inputs!$C$114,Volume!$E$4:$S$4,0),99),1,0) -> 0 | I36: =Inputs!$C$105*Inputs!$C$106*IF(Volume!I6>=IFERROR(MATCH(Inputs!$C$114,Volume!$E$4:$S$4,0),99),1,0) -> 0 | J36: =Inputs!$C$105*Inputs!$C$106*IF(Volume!J6>=IFERROR(MATCH(Inputs!$C$114,Volume!$E$4:$S$4,0),99),1,0) -> 0 | K36: =Inputs!$C$105*Inputs!$C$106*IF(Volume!K6>=IFERROR(MATCH(Inputs!$C$114,Volume!$E$4:$S$4,0),99),1,0) -> 1 | L36: =Inputs!$C$105*Inputs!$C$106*IF(Volume!L6>=IFERROR(MATCH(Inputs!$C$114,Volume!$E$4:$S$4,0),99),1,0) -> 1 | ... S36: =Inputs!$C$105*Inputs!$C$106*IF(Volume!S6>=IFERROR(MATCH(Inputs!$C$114,Volume!$E$4:$S$4,0),99),1,0) -> 1
A37: Fair-pay uplift: admin, social media, lead marketing | B37: Rp m | C37: =SUM(E37:G37) -> 0 | D37: =SUM(H37:S37) -> 177.3936 | E37: =E35*((Inputs!$C$109+Inputs!$C$110+Inputs!$C$111)*(1+Inputs!$C$108)-(Inputs!$C$43+Inputs!$C$40+Inputs!$C$39)) -> 0 | F37: =F35*((Inputs!$C$109+Inputs!$C$110+Inputs!$C$111)*(1+Inputs!$C$108)-(Inputs!$C$43+Inputs!$C$40+Inputs!$C$39)) -> 0 | G37: =G35*((Inputs!$C$109+Inputs!$C$110+Inputs!$C$111)*(1+Inputs!$C$108)-(Inputs!$C$43+Inputs!$C$40+Inputs!$C$39)) -> 0 | H37: =H35*((Inputs!$C$109+Inputs!$C$110+Inputs!$C$111)*(1+Inputs!$C$108)-(Inputs!$C$43+Inputs!$C$40+Inputs!$C$39)) -> 14.7828 | I37: =I35*((Inputs!$C$109+Inputs!$C$110+Inputs!$C$111)*(1+Inputs!$C$108)-(Inputs!$C$43+Inputs!$C$40+Inputs!$C$39)) -> 14.7828 | J37: =J35*((Inputs!$C$109+Inputs!$C$110+Inputs!$C$111)*(1+Inputs!$C$108)-(Inputs!$C$43+Inputs!$C$40+Inputs!$C$39)) -> 14.7828 | K37: =K35*((Inputs!$C$109+Inputs!$C$110+Inputs!$C$111)*(1+Inputs!$C$108)-(Inputs!$C$43+Inputs!$C$40+Inputs!$C$39)) -> 14.7828 | L37: =L35*((Inputs!$C$109+Inputs!$C$110+Inputs!$C$111)*(1+Inputs!$C$108)-(Inputs!$C$43+Inputs!$C$40+Inputs!$C$39)) -> 14.7828 | ... S37: =S35*((Inputs!$C$109+Inputs!$C$110+Inputs!$C$111)*(1+Inputs!$C$108)-(Inputs!$C$43+Inputs!$C$40+Inputs!$C$39)) -> 14.7828
A38: Fair-pay uplift: full-time psychologist | B38: Rp m | C38: =SUM(E38:G38) -> 0 | D38: =SUM(H38:S38) -> 74.88 | E38: =E36*(Inputs!$C$112*(1+Inputs!$C$108)-Inputs!$C$42) -> 0 | F38: =F36*(Inputs!$C$112*(1+Inputs!$C$108)-Inputs!$C$42) -> 0 | G38: =G36*(Inputs!$C$112*(1+Inputs!$C$108)-Inputs!$C$42) -> 0 | H38: =H36*(Inputs!$C$112*(1+Inputs!$C$108)-Inputs!$C$42) -> 0 | I38: =I36*(Inputs!$C$112*(1+Inputs!$C$108)-Inputs!$C$42) -> 0 | J38: =J36*(Inputs!$C$112*(1+Inputs!$C$108)-Inputs!$C$42) -> 0 | K38: =K36*(Inputs!$C$112*(1+Inputs!$C$108)-Inputs!$C$42) -> 8.32 | L38: =L36*(Inputs!$C$112*(1+Inputs!$C$108)-Inputs!$C$42) -> 8.32 | ... S38: =S36*(Inputs!$C$112*(1+Inputs!$C$108)-Inputs!$C$42) -> 8.32
A39: Extra IG ads and content | B39: Rp m | C39: =SUM(E39:G39) -> 0 | D39: =SUM(H39:S39) -> 36 | E39: =E35*Inputs!$C$113 -> 0 | F39: =F35*Inputs!$C$113 -> 0 | G39: =G35*Inputs!$C$113 -> 0 | H39: =H35*Inputs!$C$113 -> 3 | I39: =I35*Inputs!$C$113 -> 3 | J39: =J35*Inputs!$C$113 -> 3 | K39: =K35*Inputs!$C$113 -> 3 | L39: =L35*Inputs!$C$113 -> 3 | ... S39: =S35*Inputs!$C$113 -> 3
A40: Sales co-founder | B40: Rp m | C40: =SUM(E40:G40) -> 0 | D40: =SUM(H40:S40) -> 48 | E40: =Inputs!$C$105*IF(Volume!E6>=IFERROR(MATCH(Inputs!$C$117,Volume!$E$4:$S$4,0),99),Inputs!$C$116,0) -> 0 | F40: =Inputs!$C$105*IF(Volume!F6>=IFERROR(MATCH(Inputs!$C$117,Volume!$E$4:$S$4,0),99),Inputs!$C$116,0) -> 0 | G40: =Inputs!$C$105*IF(Volume!G6>=IFERROR(MATCH(Inputs!$C$117,Volume!$E$4:$S$4,0),99),Inputs!$C$116,0) -> 0 | H40: =Inputs!$C$105*IF(Volume!H6>=IFERROR(MATCH(Inputs!$C$117,Volume!$E$4:$S$4,0),99),Inputs!$C$116,0) -> 0 | I40: =Inputs!$C$105*IF(Volume!I6>=IFERROR(MATCH(Inputs!$C$117,Volume!$E$4:$S$4,0),99),Inputs!$C$116,0) -> 0 | J40: =Inputs!$C$105*IF(Volume!J6>=IFERROR(MATCH(Inputs!$C$117,Volume!$E$4:$S$4,0),99),Inputs!$C$116,0) -> 0 | K40: =Inputs!$C$105*IF(Volume!K6>=IFERROR(MATCH(Inputs!$C$117,Volume!$E$4:$S$4,0),99),Inputs!$C$116,0) -> 0 | L40: =Inputs!$C$105*IF(Volume!L6>=IFERROR(MATCH(Inputs!$C$117,Volume!$E$4:$S$4,0),99),Inputs!$C$116,0) -> 0 | ... S40: =Inputs!$C$105*IF(Volume!S6>=IFERROR(MATCH(Inputs!$C$117,Volume!$E$4:$S$4,0),99),Inputs!$C$116,0) -> 8
A41: Growth plan fixed cost | B41: Rp m | C41: =SUM(E41:G41) -> 0 | D41: =SUM(H41:S41) -> 336.2736 | E41: =SUM(E37:E40) -> 0 | F41: =SUM(F37:F40) -> 0 | G41: =SUM(G37:G40) -> 0 | H41: =SUM(H37:H40) -> 17.7828 | I41: =SUM(I37:I40) -> 17.7828 | J41: =SUM(J37:J40) -> 17.7828 | K41: =SUM(K37:K40) -> 26.1028 | L41: =SUM(L37:L40) -> 26.1028 | ... S41: =SUM(S37:S40) -> 34.1028

Sheet PnL
A1: Profit and loss by month (Rp million) - money counted when the event is delivered
A2: Rp million unless stated. Q4 2026 and FY 2027 columns are totals (or averages / peaks where stated).
A4: Line | B4: Unit | C4: Q4 2026 | D4: FY 2027 | E4: Oct-26 | F4: Nov-26 | G4: Dec-26 | H4: Jan-27 | I4: Feb-27 | J4: Mar-27 | K4: Apr-27 | L4: May-27 | M4: Jun-27 | N4: Jul-27 | O4: Aug-27 | P4: Sep-27 | Q4: Oct-27 | R4: Nov-27 | S4: Dec-27
A5: Revenue
A6: Flagship regulator ToT | B6: Rp m | C6: =SUM(E6:G6) -> 0 | D6: =SUM(H6:S6) -> 500 | E6: =Volume!E23*IF(Volume!E11=1,Unit_Economics!$B$4,Unit_Economics!$N$4) -> 0 | F6: =Volume!F23*IF(Volume!F11=1,Unit_Economics!$B$4,Unit_Economics!$N$4) -> 0 | G6: =Volume!G23*IF(Volume!G11=1,Unit_Economics!$B$4,Unit_Economics!$N$4) -> 0 | H6: =Volume!H23*IF(Volume!H11=1,Unit_Economics!$B$4,Unit_Economics!$N$4) -> 0 | I6: =Volume!I23*IF(Volume!I11=1,Unit_Economics!$B$4,Unit_Economics!$N$4) -> 0 | J6: =Volume!J23*IF(Volume!J11=1,Unit_Economics!$B$4,Unit_Economics!$N$4) -> 100 | K6: =Volume!K23*IF(Volume!K11=1,Unit_Economics!$B$4,Unit_Economics!$N$4) -> 0 | L6: =Volume!L23*IF(Volume!L11=1,Unit_Economics!$B$4,Unit_Economics!$N$4) -> 100 | ... S6: =Volume!S23*IF(Volume!S11=1,Unit_Economics!$B$4,Unit_Economics!$N$4) -> 0
A7: KPW / LPS regional ToT | B7: Rp m | C7: =SUM(E7:G7) -> 0 | D7: =SUM(H7:S7) -> 484.5 | E7: =Volume!E24*IF(Volume!E11=1,Unit_Economics!$B$5,Unit_Economics!$N$5) -> 0 | F7: =Volume!F24*IF(Volume!F11=1,Unit_Economics!$B$5,Unit_Economics!$N$5) -> 0 | G7: =Volume!G24*IF(Volume!G11=1,Unit_Economics!$B$5,Unit_Economics!$N$5) -> 0 | H7: =Volume!H24*IF(Volume!H11=1,Unit_Economics!$B$5,Unit_Economics!$N$5) -> 0 | I7: =Volume!I24*IF(Volume!I11=1,Unit_Economics!$B$5,Unit_Economics!$N$5) -> 0 | J7: =Volume!J24*IF(Volume!J11=1,Unit_Economics!$B$5,Unit_Economics!$N$5) -> 28.5 | K7: =Volume!K24*IF(Volume!K11=1,Unit_Economics!$B$5,Unit_Economics!$N$5) -> 0 | L7: =Volume!L24*IF(Volume!L11=1,Unit_Economics!$B$5,Unit_Economics!$N$5) -> 28.5 | ... S7: =Volume!S24*IF(Volume!S11=1,Unit_Economics!$B$5,Unit_Economics!$N$5) -> 142.5
A8: Bank KCP events | B8: Rp m | C8: =SUM(E8:G8) -> 0 | D8: =SUM(H8:S8) -> 374.5 | E8: =Volume!E25*IF(Volume!E11=1,Unit_Economics!$B$6,Unit_Economics!$N$6) -> 0 | F8: =Volume!F25*IF(Volume!F11=1,Unit_Economics!$B$6,Unit_Economics!$N$6) -> 0 | G8: =Volume!G25*IF(Volume!G11=1,Unit_Economics!$B$6,Unit_Economics!$N$6) -> 0 | H8: =Volume!H25*IF(Volume!H11=1,Unit_Economics!$B$6,Unit_Economics!$N$6) -> 0 | I8: =Volume!I25*IF(Volume!I11=1,Unit_Economics!$B$6,Unit_Economics!$N$6) -> 0 | J8: =Volume!J25*IF(Volume!J11=1,Unit_Economics!$B$6,Unit_Economics!$N$6) -> 0 | K8: =Volume!K25*IF(Volume!K11=1,Unit_Economics!$B$6,Unit_Economics!$N$6) -> 53.5 | L8: =Volume!L25*IF(Volume!L11=1,Unit_Economics!$B$6,Unit_Economics!$N$6) -> 0 | ... S8: =Volume!S25*IF(Volume!S11=1,Unit_Economics!$B$6,Unit_Economics!$N$6) -> 53.5
A9: Bank EAP | B9: Rp m | C9: =SUM(E9:G9) -> 45 | D9: =SUM(H9:S9) -> 405 | E9: =Volume!E26*IF(Volume!E11=1,Unit_Economics!$B$7,Unit_Economics!$N$7) -> 15 | F9: =Volume!F26*IF(Volume!F11=1,Unit_Economics!$B$7,Unit_Economics!$N$7) -> 15 | G9: =Volume!G26*IF(Volume!G11=1,Unit_Economics!$B$7,Unit_Economics!$N$7) -> 15 | H9: =Volume!H26*IF(Volume!H11=1,Unit_Economics!$B$7,Unit_Economics!$N$7) -> 15 | I9: =Volume!I26*IF(Volume!I11=1,Unit_Economics!$B$7,Unit_Economics!$N$7) -> 15 | J9: =Volume!J26*IF(Volume!J11=1,Unit_Economics!$B$7,Unit_Economics!$N$7) -> 15 | K9: =Volume!K26*IF(Volume!K11=1,Unit_Economics!$B$7,Unit_Economics!$N$7) -> 30 | L9: =Volume!L26*IF(Volume!L11=1,Unit_Economics!$B$7,Unit_Economics!$N$7) -> 30 | ... S9: =Volume!S26*IF(Volume!S11=1,Unit_Economics!$B$7,Unit_Economics!$N$7) -> 45
A10: B2C mass events | B10: Rp m | C10: =SUM(E10:G10) -> 0 | D10: =SUM(H10:S10) -> 60 | E10: =Volume!E27*IF(Volume!E11=1,Unit_Economics!$B$8,Unit_Economics!$N$8) -> 0 | F10: =Volume!F27*IF(Volume!F11=1,Unit_Economics!$B$8,Unit_Economics!$N$8) -> 0 | G10: =Volume!G27*IF(Volume!G11=1,Unit_Economics!$B$8,Unit_Economics!$N$8) -> 0 | H10: =Volume!H27*IF(Volume!H11=1,Unit_Economics!$B$8,Unit_Economics!$N$8) -> 0 | I10: =Volume!I27*IF(Volume!I11=1,Unit_Economics!$B$8,Unit_Economics!$N$8) -> 0 | J10: =Volume!J27*IF(Volume!J11=1,Unit_Economics!$B$8,Unit_Economics!$N$8) -> 0 | K10: =Volume!K27*IF(Volume!K11=1,Unit_Economics!$B$8,Unit_Economics!$N$8) -> 0 | L10: =Volume!L27*IF(Volume!L11=1,Unit_Economics!$B$8,Unit_Economics!$N$8) -> 0 | ... S10: =Volume!S27*IF(Volume!S11=1,Unit_Economics!$B$8,Unit_Economics!$N$8) -> 20
