Workbook

Sheet Ringkasan
A1: RINGKASAN - BI KPw Sibolga (INTERNAL, bukan untuk klien)
B3: Sapa | C3: Tumbuh | D3: Seperjalanan | E3: Berbagi | F3: Penyuluhan
A4: Harga Welcoming | B4: =Sapa!B9 -> 7500000 | C4: =Tumbuh!B9 -> 14000000 | D4: =Seperjalanan!B9 -> 23000000 | E4: =Berbagi!B9 -> 20000000 | F4: =Penyuluhan!B9 -> 20000000
A5: Jumlah Biaya (honor sesi Rp350k) | B5: =Sapa!F20 -> 5925000 | C5: =Tumbuh!F20 -> 10700000 | D5: =Seperjalanan!F23 -> 16640000 | E5: =Berbagi!F23 -> 18740000 | F5: =Penyuluhan!F23 -> 16640000
A6: After PPh 23 | B6: =Sapa!B33 -> 7350000 | C6: =Tumbuh!B33 -> 13720000 | D6: =Seperjalanan!B36 -> 22540000 | E6: =Berbagi!B36 -> 19600000 | F6: =Penyuluhan!B36 -> 19600000
A7: AFTER COST (semua sesi dibayar honor) | B7: =Sapa!B34 -> 1425000 | C7: =Tumbuh!B34 -> 3020000 | D7: =Seperjalanan!B37 -> 5900000 | E7: =Berbagi!B37 -> 860000 | F7: =Penyuluhan!B37 -> 2960000
A8: AFTER COST (in-house, honor sesi Rp0) | B8: =Sapa!B35 -> 6675000 | C8: =Tumbuh!B35 -> 11420000 | D8: =Seperjalanan!B38 -> 18500000 | E8: =Berbagi!B38 -> 13460000 | F8: =Penyuluhan!B38 -> 15560000
A9: % biaya operasional 3 bulan (Rp60jt) tertutup - in-house | B9: =Sapa!B37 -> 0.11125 | C9: =Tumbuh!B37 -> 0.19033333 | D9: =Seperjalanan!B40 -> 0.30833333 | E9: =Berbagi!B40 -> 0.22433333 | F9: =Penyuluhan!B40 -> 0.25933333
A10: % biaya operasional 3 bulan tertutup - semua sesi dibayar honor | B10: =Sapa!B39 -> 0.02375 | C10: =Tumbuh!B39 -> 0.050333333 | D10: =Seperjalanan!B42 -> 0.098333333 | E10: =Berbagi!B42 -> 0.014333333 | F10: =Penyuluhan!B42 -> 0.049333333
A11: Kontribusi laba per bulan (in-house) | B11: =Sapa!B38 -> 2225000 | C11: =Tumbuh!B38 -> 3806666.7 | D11: =Seperjalanan!B41 -> 6166666.7 | E11: =Berbagi!B41 -> 4486666.7 | F11: =Penyuluhan!B41 -> 5186666.7
A12: Cash saat SPK (DP 50% after PPh) | B12: =Sapa!B33*0.5 -> 3675000 | C12: =Tumbuh!B33*0.5 -> 6860000 | D12: =Seperjalanan!B36*0.5 -> 11270000 | E12: =Berbagi!B36*0.5 -> 9800000 | F12: =Penyuluhan!B36*0.5 -> 9800000
A15: Catatan: template ini mengikuti format costing Teman Journey (Jumlah Biaya, margin 30-150%, Nilai Akhir, After PPh, After Cost). Margin = markup terhadap biaya.
A16: Jika semua sesi dibayar honor, laba sangat tipis; laba nyata untuk kas bergantung pada sesi dikerjakan Vania/Kia dengan gaji tetap.
A17: Berbagi = isi Seperjalanan; BI membayar harga tanpa webinar, webinar tetap diberikan dan biaya produksinya ditanggung TJ.
A18: Penyuluhan = Seperjalanan tanpa webinar premium; 2 penyuluhan 30 menit internal, terbuka untuk umum, gratis untuk BI (nilainya tetap dihitung). Seperjalanan = webinar premium privat + 2 penyuluhan gratis yang sama.

Sheet Assumptions
A1: Assumptions (blue = input) - INTERNAL
A3: Harga sesi reguler | B3: 500000 | C3: Given
A4: Harga sesi tambahan | B4: 500000 | C4: Raised from Rp450k so Sapa (Rp500k/sesi) is not cheaper than add-ons; Kia to confirm
A5: Honorarium psikolog per sesi konseling | B5: 350000 | C5: Given by Kia: Rp350k per session
A6: Admin & platform per sesi | B6: 35000 | C6: ASSUMPTION
A7: MHCU per orang per putaran | B7: 70000 | C7: Given by Kia
A8: Laporan agregat (per program) | B8: 750000 | C8: ASSUMPTION
A9: Kontrak & materai | B9: 150000 | C9: ASSUMPTION
A10: PIC / Project Officer fee per program | B10: 0 | C10: Fill in if Vania/PO is paid per project (template pays PO)
A11: Honorarium psikoedukasi (narasumber) | B11: 0 | C11: Fill in; Kia delivers, set 0 = in opex
A12: PPh 23 | B12: 0.02 | C12: Withheld by BI (matches your sheet: 93,000,000 -> 91,140,000)
A13: Sesi per pegawai | B13: 3 | C13: ASSUMPTION
A14: Biaya operasional bulanan | B14: 20000000 | C14: Given
... A25: Penyuluhan: host/moderator per sesi | B25: 0 | C25: Kia & Rana host themselves during work hours (internal)

Sheet Sapa
A1: INTERNAL COSTING - Paket Sapa - BI KPw Sibolga (Konseling Online, 3 bulan)
A3: Input paket
A4: Jumlah sesi | B4: 15 | D4: Nilai normal (reguler) | E4: =B4*Assumptions!$B$3+B5*Assumptions!$B$16+B6*Assumptions!$B$17+B8*Assumptions!$B$18 -> 7500000
A5: Putaran MHCU | B5: 0 | D5: Hemat untuk BI (Rp) | E5: =E4-B9 -> 0
A6: Laporan agregat (1=ya) | B6: 0 | D6: Hemat untuk BI (%) | E6: =E5/E4 -> 0
A7: Hasil MHCU individual (1=ya) | B7: 0 | D7: Harga paket per sesi konseling | E7: =B9/B4 -> 500000
A8: Sesi psikoedukasi | B8: 0
A9: Harga Welcoming Package | B9: 7500000
A10: Pegawai terlayani (sesi / sesi per pegawai) | B10: =B4/Assumptions!$B$13 -> 5
A12: Kategori | B12: Item | C12: Keterangan | D12: Qty | E12: Harga satuan | F12: Total
A13: Konseling | B13: Honorarium psikolog konseling | C13: sesi 60 menit | D13: =B4 -> 15 | E13: =Assumptions!$B$5 -> 350000 | F13: =D13*E13 -> 5250000
A14: Konseling | B14: Admin & platform (jadwal, reminder, Zoom) | C14: sesi | D14: =B4 -> 15 | E14: =Assumptions!$B$6 -> 35000 | F14: =D14*E14 -> 525000
A15: MHCU | B15: MHCU (putaran x pegawai) | C15: orang x putaran | D15: =B5*B10 -> 0 | E15: =Assumptions!$B$7 -> 70000 | F15: =D15*E15 -> 0
A16: Laporan | B16: Laporan agregat anonim | C16: program | D16: =B6 -> 0 | E16: =Assumptions!$B$8 -> 750000 | F16: =D16*E16 -> 0
A17: Psikoedukasi | B17: Narasumber psikoedukasi online | C17: sesi | D17: =B8 -> 0 | E17: =Assumptions!$B$11 -> 0 | F17: =D17*E17 -> 0
A18: Lain-lain | B18: PIC / Project Officer | C18: program | D18: 1 | E18: =Assumptions!$B$10 -> 0 | F18: =D18*E18 -> 0
A19: Lain-lain | B19: Kontrak & materai | C19: deal | D19: 1 | E19: =Assumptions!$B$9 -> 150000 | F19: =D19*E19 -> 150000
E20: Jumlah Biaya | F20: =SUM(F13:F19) -> 5925000
E21: Total cost per peserta | F21: =F20/B10 -> 1185000
A23: Margin (markup) | B23: Total Harga Program | C23: Harga per Peserta | D23: Margin (Rp)
A24: 0.3 | B24: =$F$20*(1+A24) -> 7702500 | C24: =B24/$B$10 -> 1540500 | D24: =B24-$F$20 -> 1777500
A25: 0.4 | B25: =$F$20*(1+A25) -> 8295000 | C25: =B25/$B$10 -> 1659000 | D25: =B25-$F$20 -> 2370000
A26: 0.5 | B26: =$F$20*(1+A26) -> 8887500 | C26: =B26/$B$10 -> 1777500 | D26: =B26-$F$20 -> 2962500
A27: 0.8 | B27: =$F$20*(1+A27) -> 10665000 | C27: =B27/$B$10 -> 2133000 | D27: =B27-$F$20 -> 4740000
A28: 1 | B28: =$F$20*(1+A28) -> 11850000 | C28: =B28/$B$10 -> 2370000 | D28: =B28-$F$20 -> 5925000
A29: 1.5 | B29: =$F$20*(1+A29) -> 14812500 | C29: =B29/$B$10 -> 2962500 | D29: =B29-$F$20 -> 8887500
A30: Harga Welcoming | B30: =B9 -> 7500000 | C30: =B30/B10 -> 1500000 | D30: =B30-F20 -> 1575000 | E30: =D30/F20 -> 0.26582278 | F30: <- markup vs biaya
A32: NILAI AKHIR | B32: =B9 -> 7500000
A33: AFTER PAJAK PPH | B33: =B9*(1-Assumptions!$B$12) -> 7350000
A34: AFTER COST | B34: =B33-F20 -> 1425000
A35: AFTER COST - jika sesi oleh Vania/Kia (gaji tetap, honor sesi Rp0) | B35: =B34+F13 -> 6675000
A36: Biaya operasional selama masa paket (Rp20jt x 3 bulan) | B36: =Assumptions!$B$14*Assumptions!$B$19 -> 60000000
A37: % biaya operasional 3 bulan tertutup (in-house) | B37: =B35/B36 -> 0.11125
A38: Kontribusi laba per bulan (in-house) | B38: =B35/Assumptions!$B$19 -> 2225000
A39: % biaya operasional 3 bulan tertutup (semua sesi dibayar honor) | B39: =B34/B36 -> 0.02375
A41: Untuk Proposal
A42: Kategori | B42: Fasilitas yang didapatkan | C42: Harga Program
A43: Konseling | B43: =B4&" sesi konseling online (60 menit) - ~"&TEXT(B10,"0")&" pegawai x "&Assumptions!$B$13&" sesi" -> 15 sesi konseling online (60 menit) - ~5 pegawai x 3 sesi | C43: 7500000
A44: Ketentuan | B44: Berlaku 3 bulan sejak SPK; SPK paling lambat 31 Okt 2026

Sheet Tumbuh
A1: INTERNAL COSTING - Paket Tumbuh - BI KPw Sibolga (Konseling Online, 3 bulan)
A3: Input paket
A4: Jumlah sesi | B4: 24 | D4: Nilai normal (reguler) | E4: =B4*Assumptions!$B$3+B5*Assumptions!$B$16+B6*Assumptions!$B$17+B8*Assumptions!$B$18 -> 16500000
A5: Putaran MHCU | B5: 1 | D5: Hemat untuk BI (Rp) | E5: =E4-B9 -> 2500000
A6: Laporan agregat (1=ya) | B6: 1 | D6: Hemat untuk BI (%) | E6: =E5/E4 -> 0.15151515
A7: Hasil MHCU individual (1=ya) | B7: 0 | D7: Harga paket per sesi konseling | E7: =B9/B4 -> 583333.33
A8: Sesi psikoedukasi | B8: 0
A9: Harga Welcoming Package | B9: 14000000
A10: Pegawai terlayani (sesi / sesi per pegawai) | B10: =B4/Assumptions!$B$13 -> 8
A12: Kategori | B12: Item | C12: Keterangan | D12: Qty | E12: Harga satuan | F12: Total
A13: Konseling | B13: Honorarium psikolog konseling | C13: sesi 60 menit | D13: =B4 -> 24 | E13: =Assumptions!$B$5 -> 350000 | F13: =D13*E13 -> 8400000
A14: Konseling | B14: Admin & platform (jadwal, reminder, Zoom) | C14: sesi | D14: =B4 -> 24 | E14: =Assumptions!$B$6 -> 35000 | F14: =D14*E14 -> 840000
A15: MHCU | B15: MHCU (putaran x pegawai) | C15: orang x putaran | D15: =B5*B10 -> 8 | E15: =Assumptions!$B$7 -> 70000 | F15: =D15*E15 -> 560000
A16: Laporan | B16: Laporan agregat anonim | C16: program | D16: =B6 -> 1 | E16: =Assumptions!$B$8 -> 750000 | F16: =D16*E16 -> 750000
A17: Psikoedukasi | B17: Narasumber psikoedukasi online | C17: sesi | D17: =B8 -> 0 | E17: =Assumptions!$B$11 -> 0 | F17: =D17*E17 -> 0
A18: Lain-lain | B18: PIC / Project Officer | C18: program | D18: 1 | E18: =Assumptions!$B$10 -> 0 | F18: =D18*E18 -> 0
A19: Lain-lain | B19: Kontrak & materai | C19: deal | D19: 1 | E19: =Assumptions!$B$9 -> 150000 | F19: =D19*E19 -> 150000
E20: Jumlah Biaya | F20: =SUM(F13:F19) -> 10700000
E21: Total cost per peserta | F21: =F20/B10 -> 1337500
A23: Margin (markup) | B23: Total Harga Program | C23: Harga per Peserta | D23: Margin (Rp)
A24: 0.3 | B24: =$F$20*(1+A24) -> 13910000 | C24: =B24/$B$10 -> 1738750 | D24: =B24-$F$20 -> 3210000
A25: 0.4 | B25: =$F$20*(1+A25) -> 14980000 | C25: =B25/$B$10 -> 1872500 | D25: =B25-$F$20 -> 4280000
A26: 0.5 | B26: =$F$20*(1+A26) -> 16050000 | C26: =B26/$B$10 -> 2006250 | D26: =B26-$F$20 -> 5350000
A27: 0.8 | B27: =$F$20*(1+A27) -> 19260000 | C27: =B27/$B$10 -> 2407500 | D27: =B27-$F$20 -> 8560000
A28: 1 | B28: =$F$20*(1+A28) -> 21400000 | C28: =B28/$B$10 -> 2675000 | D28: =B28-$F$20 -> 10700000
A29: 1.5 | B29: =$F$20*(1+A29) -> 26750000 | C29: =B29/$B$10 -> 3343750 | D29: =B29-$F$20 -> 16050000
A30: Harga Welcoming | B30: =B9 -> 14000000 | C30: =B30/B10 -> 1750000 | D30: =B30-F20 -> 3300000 | E30: =D30/F20 -> 0.30841121 | F30: <- markup vs biaya
A32: NILAI AKHIR | B32: =B9 -> 14000000
A33: AFTER PAJAK PPH | B33: =B9*(1-Assumptions!$B$12) -> 13720000
A34: AFTER COST | B34: =B33-F20 -> 3020000
A35: AFTER COST - jika sesi oleh Vania/Kia (gaji tetap, honor sesi Rp0) | B35: =B34+F13 -> 11420000
A36: Biaya operasional selama masa paket (Rp20jt x 3 bulan) | B36: =Assumptions!$B$14*Assumptions!$B$19 -> 60000000
A37: % biaya operasional 3 bulan tertutup (in-house) | B37: =B35/B36 -> 0.19033333
A38: Kontribusi laba per bulan (in-house) | B38: =B35/Assumptions!$B$19 -> 3806666.7
A39: % biaya operasional 3 bulan tertutup (semua sesi dibayar honor) | B39: =B34/B36 -> 0.050333333
A41: Untuk Proposal
A42: Kategori | B42: Fasilitas yang didapatkan | C42: Harga Program
A43: Konseling | B43: =B4&" sesi konseling online (60 menit) - ~"&TEXT(B10,"0")&" pegawai x "&Assumptions!$B$13&" sesi" -> 24 sesi konseling online (60 menit) - ~8 pegawai x 3 sesi | C43: 14000000
A44: Screening | B44: =B5&"x MHCU ("&IF(B5=2,"pre & post","baseline")&")" -> 1x MHCU (baseline)
A45: Laporan | B45: Laporan agregat anonim
...

Sheet Seperjalanan
A1: INTERNAL COSTING - Paket Seperjalanan - BI KPw Sibolga (Konseling Online + webinar premium + 2x penyuluhan gratis, 3 bulan)
A3: Input paket
A4: Jumlah sesi | B4: 36 | D4: Nilai normal (reguler) | E4: =B4*Assumptions!$B$3+B5*Assumptions!$B$16+B6*Assumptions!$B$17+B8*Assumptions!$B$18+E10 -> 30000000
A5: Putaran MHCU | B5: 2 | D5: Hemat untuk BI (Rp) | E5: =E4-B9 -> 7000000
A6: Laporan agregat (1=ya) | B6: 1 | D6: Hemat untuk BI (%) | E6: =E5/E4 -> 0.23333333
A7: Hasil MHCU individual (1=ya) | B7: 1 | D7: Harga paket per sesi konseling | E7: =B9/B4 -> 638888.89
A8: Sesi webinar premium (privat untuk BI) | B8: 1 | D8: Sesi penyuluhan gratis (30 menit) | E8: 2
A9: Harga Welcoming Package | B9: 23000000 | D9: Nilai 1 penyuluhan (porsi harga webinar) | E9: =Penyuluhan!E9 -> 0.33333333
A10: Pegawai terlayani (sesi / sesi per pegawai) | B10: =B4/Assumptions!$B$13 -> 12 | D10: Nilai penyuluhan yang diberikan gratis | E10: =E8*E9*Assumptions!$B$18 -> 2000000
A12: Kategori | B12: Item | C12: Keterangan | D12: Qty | E12: Harga satuan | F12: Total
A13: Konseling | B13: Honorarium psikolog konseling | C13: sesi 60 menit | D13: =B4 -> 36 | E13: =Assumptions!$B$5 -> 350000 | F13: =D13*E13 -> 12600000
A14: Konseling | B14: Admin & platform (jadwal, reminder, Zoom) | C14: sesi | D14: =B4 -> 36 | E14: =Assumptions!$B$6 -> 35000 | F14: =D14*E14 -> 1260000
A15: MHCU | B15: MHCU (putaran x pegawai) | C15: orang x putaran | D15: =B5*B10 -> 24 | E15: =Assumptions!$B$7 -> 70000 | F15: =D15*E15 -> 1680000
A16: Laporan | B16: Laporan agregat anonim | C16: program | D16: =B6 -> 1 | E16: =Assumptions!$B$8 -> 750000 | F16: =D16*E16 -> 750000
A17: Psikoedukasi | B17: Narasumber webinar premium online | C17: sesi | D17: =B8 -> 1 | E17: =Assumptions!$B$11 -> 0 | F17: =D17*E17 -> 0
A18: Penyuluhan (TJ) | B18: Penyuluhan: platform | C18: sesi | D18: =E8 -> 2 | E18: =Assumptions!$B$23 -> 0 | F18: =D18*E18 -> 0
A19: Penyuluhan (TJ) | B19: Penyuluhan: materi ringkas & poster | C19: sesi | D19: =E8 -> 2 | E19: =Assumptions!$B$24 -> 100000 | F19: =D19*E19 -> 200000
A20: Penyuluhan (TJ) | B20: Penyuluhan: host/moderator | C20: sesi | D20: =E8 -> 2 | E20: =Assumptions!$B$25 -> 0 | F20: =D20*E20 -> 0
A21: Lain-lain | B21: PIC / Project Officer | C21: program | D21: 1 | E21: =Assumptions!$B$10 -> 0 | F21: =D21*E21 -> 0
A22: Lain-lain | B22: Kontrak & materai | C22: deal | D22: 1 | E22: =Assumptions!$B$9 -> 150000 | F22: =D22*E22 -> 150000
E23: Jumlah Biaya | F23: =SUM(F13:F22) -> 16640000
E24: Total cost per peserta | F24: =F23/B10 -> 1386666.7
A26: Margin (markup) | B26: Total Harga Program | C26: Harga per Peserta | D26: Margin (Rp)
A27: 0.3 | B27: =$F$23*(1+A27) -> 21632000 | C27: =B27/$B$10 -> 1802666.7 | D27: =B27-$F$23 -> 4992000
A28: 0.4 | B28: =$F$23*(1+A28) -> 23296000 | C28: =B28/$B$10 -> 1941333.3 | D28: =B28-$F$23 -> 6656000
A29: 0.5 | B29: =$F$23*(1+A29) -> 24960000 | C29: =B29/$B$10 -> 2080000 | D29: =B29-$F$23 -> 8320000
A30: 0.8 | B30: =$F$23*(1+A30) -> 29952000 | C30: =B30/$B$10 -> 2496000 | D30: =B30-$F$23 -> 13312000
A31: 1 | B31: =$F$23*(1+A31) -> 33280000 | C31: =B31/$B$10 -> 2773333.3 | D31: =B31-$F$23 -> 16640000
A32: 1.5 | B32: =$F$23*(1+A32) -> 41600000 | C32: =B32/$B$10 -> 3466666.7 | D32: =B32-$F$23 -> 24960000
A33: Harga Welcoming | B33: =B9 -> 23000000 | C33: =B33/B10 -> 1916666.7 | D33: =B33-F23 -> 6360000 | E33: =D33/F23 -> 0.38221154 | F33: <- markup vs biaya
A35: NILAI AKHIR | B35: =B9 -> 23000000
A36: AFTER PAJAK PPH | B36: =B9*(1-Assumptions!$B$12) -> 22540000
A37: AFTER COST | B37: =B36-F23 -> 5900000
A38: AFTER COST - jika sesi oleh Vania/Kia (gaji tetap, honor sesi Rp0) | B38: =B37+F13 -> 18500000
A39: Biaya operasional selama masa paket (Rp20jt x 3 bulan) | B39: =Assumptions!$B$14*Assumptions!$B$19 -> 60000000
A40: % biaya operasional 3 bulan tertutup (in-house) | B40: =B38/B39 -> 0.30833333
A41: Kontribusi laba per bulan (in-house) | B41: =B38/Assumptions!$B$19 -> 6166666.7
A42: % biaya operasional 3 bulan tertutup (semua sesi dibayar honor) | B42: =B37/B39 -> 0.098333333
A44: Untuk Proposal
A45: Kategori | B45: Fasilitas yang didapatkan | C45: Harga Program
...

Sheet Berbagi
A1: INTERNAL COSTING - Paket Berbagi - BI KPw Sibolga (Seperjalanan + webinar ditanggung TJ, 3 bulan)
A3: Input paket
A4: Jumlah sesi | B4: 36 | D4: Nilai normal (reguler) | E4: =B4*Assumptions!$B$3+B5*Assumptions!$B$16+B6*Assumptions!$B$17+B8*Assumptions!$B$18 -> 28000000
A5: Putaran MHCU | B5: 2 | D5: Hemat untuk BI (Rp) | E5: =E4-B9 -> 8000000
A6: Laporan agregat (1=ya) | B6: 1 | D6: Hemat untuk BI (%) | E6: =E5/E4 -> 0.28571429
A7: Hasil MHCU individual (1=ya) | B7: 1 | D7: Harga paket per sesi konseling | E7: =B9/B4 -> 555555.56
A8: Sesi psikoedukasi | B8: 1
A9: Harga Welcoming Package | B9: 20000000 | C9: Harga Seperjalanan Rp23jt dikurangi nilai normal webinar Rp3jt: BI membayar versi tanpa webinar, webinar diberikan TJ
A10: Pegawai terlayani (sesi / sesi per pegawai) | B10: =B4/Assumptions!$B$13 -> 12
A12: Kategori | B12: Item | C12: Keterangan | D12: Qty | E12: Harga satuan | F12: Total
A13: Konseling | B13: Honorarium psikolog konseling | C13: sesi 60 menit | D13: =B4 -> 36 | E13: =Assumptions!$B$5 -> 350000 | F13: =D13*E13 -> 12600000
A14: Konseling | B14: Admin & platform (jadwal, reminder, Zoom) | C14: sesi | D14: =B4 -> 36 | E14: =Assumptions!$B$6 -> 35000 | F14: =D14*E14 -> 1260000
A15: MHCU | B15: MHCU (putaran x pegawai) | C15: orang x putaran | D15: =B5*B10 -> 24 | E15: =Assumptions!$B$7 -> 70000 | F15: =D15*E15 -> 1680000
A16: Laporan | B16: Laporan agregat anonim | C16: program | D16: =B6 -> 1 | E16: =Assumptions!$B$8 -> 750000 | F16: =D16*E16 -> 750000
A17: Psikoedukasi | B17: Narasumber webinar psikoedukasi online | C17: sesi | D17: =B8 -> 1 | E17: =Assumptions!$B$11 -> 0 | F17: =D17*E17 -> 0
A18: Webinar (TJ) | B18: Platform webinar kapasitas besar | C18: event | D18: =B8 -> 1 | E18: =Assumptions!$B$20 -> 1300000 | F18: =D18*E18 -> 1300000
A19: Webinar (TJ) | B19: Desain poster, materi & e-sertifikat | C19: event | D19: =B8 -> 1 | E19: =Assumptions!$B$21 -> 500000 | F19: =D19*E19 -> 500000
A20: Webinar (TJ) | B20: Host/moderator & operator teknis | C20: event | D20: =B8 -> 1 | E20: =Assumptions!$B$22 -> 500000 | F20: =D20*E20 -> 500000
A21: Lain-lain | B21: PIC / Project Officer | C21: program | D21: 1 | E21: =Assumptions!$B$10 -> 0 | F21: =D21*E21 -> 0
A22: Lain-lain | B22: Kontrak & materai | C22: deal | D22: 1 | E22: =Assumptions!$B$9 -> 150000 | F22: =D22*E22 -> 150000
E23: Jumlah Biaya | F23: =SUM(F13:F22) -> 18740000
E24: Total cost per peserta | F24: =F23/B10 -> 1561666.7
A26: Margin (markup) | B26: Total Harga Program | C26: Harga per Peserta | D26: Margin (Rp)
A27: 0.3 | B27: =$F$23*(1+A27) -> 24362000 | C27: =B27/$B$10 -> 2030166.7 | D27: =B27-$F$23 -> 5622000
A28: 0.4 | B28: =$F$23*(1+A28) -> 26236000 | C28: =B28/$B$10 -> 2186333.3 | D28: =B28-$F$23 -> 7496000
A29: 0.5 | B29: =$F$23*(1+A29) -> 28110000 | C29: =B29/$B$10 -> 2342500 | D29: =B29-$F$23 -> 9370000
A30: 0.8 | B30: =$F$23*(1+A30) -> 33732000 | C30: =B30/$B$10 -> 2811000 | D30: =B30-$F$23 -> 14992000
A31: 1 | B31: =$F$23*(1+A31) -> 37480000 | C31: =B31/$B$10 -> 3123333.3 | D31: =B31-$F$23 -> 18740000
A32: 1.5 | B32: =$F$23*(1+A32) -> 46850000 | C32: =B32/$B$10 -> 3904166.7 | D32: =B32-$F$23 -> 28110000
A33: Harga Welcoming | B33: =B9 -> 20000000 | C33: =B33/B10 -> 1666666.7 | D33: =B33-F23 -> 1260000 | E33: =D33/F23 -> 0.067235859 | F33: <- markup vs biaya
D34: Investasi TJ untuk webinar
A35: NILAI AKHIR | B35: =B9 -> 20000000 | D35: Biaya produksi webinar ditanggung TJ | E35: =SUM(F17:F20) -> 2300000
A36: AFTER PAJAK PPH | B36: =B9*(1-Assumptions!$B$12) -> 19600000 | D36: Nilai normal webinar yang diberikan gratis | E36: =B8*Assumptions!$B$18 -> 3000000
A37: AFTER COST | B37: =B36-F23 -> 860000 | D37: AFTER COST vs Seperjalanan (honor dibayar) | E37: =B37-Seperjalanan!B37 -> -5040000
A38: AFTER COST - jika sesi oleh Vania/Kia (gaji tetap, honor sesi Rp0) | B38: =B37+F13 -> 13460000 | D38: AFTER COST vs Seperjalanan (in-house) | E38: =B38-Seperjalanan!B38 -> -5040000
A39: Biaya operasional selama masa paket (Rp20jt x 3 bulan) | B39: =Assumptions!$B$14*Assumptions!$B$19 -> 60000000
A40: % biaya operasional 3 bulan tertutup (in-house) | B40: =B38/B39 -> 0.22433333
A41: Kontribusi laba per bulan (in-house) | B41: =B38/Assumptions!$B$19 -> 4486666.7
A42: % biaya operasional 3 bulan tertutup (semua sesi dibayar honor) | B42: =B37/B39 -> 0.014333333
A44: Untuk Proposal
...

Sheet Penyuluhan
A1: INTERNAL COSTING - Paket Penyuluhan - BI KPw Sibolga (Seperjalanan tanpa webinar + 2x penyuluhan gratis, 3 bulan)
A3: Input paket
A4: Jumlah sesi | B4: 36 | D4: Nilai normal (reguler) | E4: =B4*Assumptions!$B$3+B5*Assumptions!$B$16+B6*Assumptions!$B$17+B8*Assumptions!$B$18*E9 -> 27000000
A5: Putaran MHCU | B5: 2 | D5: Hemat untuk BI (Rp) | E5: =E4-B9 -> 7000000
A6: Laporan agregat (1=ya) | B6: 1 | D6: Hemat untuk BI (%) | E6: =E5/E4 -> 0.25925926
A7: Hasil MHCU individual (1=ya) | B7: 1 | D7: Harga paket per sesi konseling | E7: =B9/B4 -> 555555.56
A8: Sesi penyuluhan (30 menit, jam kerja, gratis untuk BI) | B8: 2 | D8: Harga dasar paket (tanpa webinar) | E8: 20000000
A9: Harga Welcoming Package | B9: =E8+E10*E11 -> 20000000 | C9: Harga dasar (Seperjalanan tanpa webinar); penyuluhan gratis untuk BI tapi nilainya tetap dihitung di Nilai normal | D9: Nilai 1 penyuluhan (porsi harga webinar) | E9: 0.33333333
A10: Pegawai terlayani (sesi / sesi per pegawai) | B10: =B4/Assumptions!$B$13 -> 12 | D10: Nilai penyuluhan yang diberikan gratis | E10: =B8*E9*Assumptions!$B$18 -> 2000000
D11: Porsi nilai penyuluhan yang ditagih ke BI | E11: 0
A12: Kategori | B12: Item | C12: Keterangan | D12: Qty | E12: Harga satuan | F12: Total
A13: Konseling | B13: Honorarium psikolog konseling | C13: sesi 60 menit | D13: =B4 -> 36 | E13: =Assumptions!$B$5 -> 350000 | F13: =D13*E13 -> 12600000
A14: Konseling | B14: Admin & platform (jadwal, reminder, Zoom) | C14: sesi | D14: =B4 -> 36 | E14: =Assumptions!$B$6 -> 35000 | F14: =D14*E14 -> 1260000
A15: MHCU | B15: MHCU (putaran x pegawai) | C15: orang x putaran | D15: =B5*B10 -> 24 | E15: =Assumptions!$B$7 -> 70000 | F15: =D15*E15 -> 1680000
A16: Laporan | B16: Laporan agregat anonim | C16: program | D16: =B6 -> 1 | E16: =Assumptions!$B$8 -> 750000 | F16: =D16*E16 -> 750000
A17: Penyuluhan | B17: Narasumber penyuluhan (Kia & Rana, internal) | C17: sesi 30 menit | D17: =B8 -> 2 | E17: =Assumptions!$B$11 -> 0 | F17: =D17*E17 -> 0
A18: Penyuluhan (TJ) | B18: Platform penyuluhan | C18: sesi | D18: =B8 -> 2 | E18: =Assumptions!$B$23 -> 0 | F18: =D18*E18 -> 0
A19: Penyuluhan (TJ) | B19: Materi ringkas & poster | C19: sesi | D19: =B8 -> 2 | E19: =Assumptions!$B$24 -> 100000 | F19: =D19*E19 -> 200000
A20: Penyuluhan (TJ) | B20: Host/moderator | C20: sesi | D20: =B8 -> 2 | E20: =Assumptions!$B$25 -> 0 | F20: =D20*E20 -> 0
A21: Lain-lain | B21: PIC / Project Officer | C21: program | D21: 1 | E21: =Assumptions!$B$10 -> 0 | F21: =D21*E21 -> 0
A22: Lain-lain | B22: Kontrak & materai | C22: deal | D22: 1 | E22: =Assumptions!$B$9 -> 150000 | F22: =D22*E22 -> 150000
E23: Jumlah Biaya | F23: =SUM(F13:F22) -> 16640000
E24: Total cost per peserta | F24: =F23/B10 -> 1386666.7
A26: Margin (markup) | B26: Total Harga Program | C26: Harga per Peserta | D26: Margin (Rp)
A27: 0.3 | B27: =$F$23*(1+A27) -> 21632000 | C27: =B27/$B$10 -> 1802666.7 | D27: =B27-$F$23 -> 4992000
A28: 0.4 | B28: =$F$23*(1+A28) -> 23296000 | C28: =B28/$B$10 -> 1941333.3 | D28: =B28-$F$23 -> 6656000
A29: 0.5 | B29: =$F$23*(1+A29) -> 24960000 | C29: =B29/$B$10 -> 2080000 | D29: =B29-$F$23 -> 8320000
A30: 0.8 | B30: =$F$23*(1+A30) -> 29952000 | C30: =B30/$B$10 -> 2496000 | D30: =B30-$F$23 -> 13312000
A31: 1 | B31: =$F$23*(1+A31) -> 33280000 | C31: =B31/$B$10 -> 2773333.3 | D31: =B31-$F$23 -> 16640000
A32: 1.5 | B32: =$F$23*(1+A32) -> 41600000 | C32: =B32/$B$10 -> 3466666.7 | D32: =B32-$F$23 -> 24960000
A33: Harga Welcoming | B33: =B9 -> 20000000 | C33: =B33/B10 -> 1666666.7 | D33: =B33-F23 -> 3360000 | E33: =D33/F23 -> 0.20192308 | F33: <- markup vs biaya
D34: Penyuluhan: tagihan vs biaya
A35: NILAI AKHIR | B35: =B9 -> 20000000 | D35: Nilai penyuluhan diberikan gratis | E35: =E10 -> 2000000
A36: AFTER PAJAK PPH | B36: =B9*(1-Assumptions!$B$12) -> 19600000 | D36: Biaya produksi penyuluhan (TJ) | E36: =SUM(F17:F20) -> 200000
A37: AFTER COST | B37: =B36-F23 -> 2960000 | D37: AFTER COST vs Seperjalanan (honor dibayar) | E37: =B37-Seperjalanan!B37 -> -2940000
A38: AFTER COST - jika sesi oleh Vania/Kia (gaji tetap, honor sesi Rp0) | B38: =B37+F13 -> 15560000 | D38: AFTER COST vs Berbagi (honor dibayar) | E38: =B37-Berbagi!B37 -> 2100000
A39: Biaya operasional selama masa paket (Rp20jt x 3 bulan) | B39: =Assumptions!$B$14*Assumptions!$B$19 -> 60000000
A40: % biaya operasional 3 bulan tertutup (in-house) | B40: =B38/B39 -> 0.25933333
A41: Kontribusi laba per bulan (in-house) | B41: =B38/Assumptions!$B$19 -> 5186666.7
A42: % biaya operasional 3 bulan tertutup (semua sesi dibayar honor) | B42: =B37/B39 -> 0.049333333
...
