Workbook

Sheet 1. Ringkasan Internal
A1: RINGKASAN INTERNAL - untuk keputusan (JANGAN dibagikan ke klien)
A2: Satu halaman: apakah harga sehat, berapa harga yang sebaiknya, dan apa dampaknya ke kas.
B4: Indikator | C4: Jeda | D4: Jeda Tahunan (per term) | E4: Tumbuh | F4: Seperjalanan | G4: Penyuluhan (opsi 4)
B5: APAKAH HARGA SEKARANG SEHAT?
B6: Harga sekarang | C6: ='Analisis Lengkap'!C6 -> 12000000 | D6: ='Analisis Lengkap'!D6 -> 11000000 | E6: ='Analisis Lengkap'!E6 -> 20000000 | F6: ='Analisis Lengkap'!F6 -> 31500000 | G6: ='Analisis Lengkap'!G6 -> 23500000
B7: Total biaya | C7: ='Analisis Lengkap'!C15 -> 7665000 | D7: ='Analisis Lengkap'!D15 -> 8745000 | E7: ='Analisis Lengkap'!E15 -> 12600000 | F7: ='Analisis Lengkap'!F15 -> 20070000 | G7: ='Analisis Lengkap'!G15 -> 17110000
B8: Laba bersih | C8: ='Analisis Lengkap'!C18 -> 4335000 | D8: ='Analisis Lengkap'!D18 -> 2255000 | E8: ='Analisis Lengkap'!E18 -> 7400000 | F8: ='Analisis Lengkap'!F18 -> 11430000 | G8: ='Analisis Lengkap'!G18 -> 6390000
B9: Margin bersih | C9: ='Analisis Lengkap'!C19 -> 0.36125 | D9: ='Analisis Lengkap'!D19 -> 0.205 | E9: ='Analisis Lengkap'!E19 -> 0.37 | F9: ='Analisis Lengkap'!F19 -> 0.36285714 | G9: ='Analisis Lengkap'!G19 -> 0.27191489
B10: Posisi vs standar 15%-26% | C10: =IF('Analisis Lengkap'!C19<'Input Tarif'!$D$25,"Di bawah minimum",IF('Analisis Lengkap'!C19<='Input Tarif'!$D$26,"Dalam rentang sehat","Di atas ideal")) -> Di atas ideal | D10: =IF('Analisis Lengkap'!D19<'Input Tarif'!$D$25,"Di bawah minimum",IF('Analisis Lengkap'!D19<='Input Tarif'!$D$26,"Dalam rentang sehat","Di atas ideal")) -> Dalam rentang sehat | E10: =IF('Analisis Lengkap'!E19<'Input Tarif'!$D$25,"Di bawah minimum",IF('Analisis Lengkap'!E19<='Input Tarif'!$D$26,"Dalam rentang sehat","Di atas ideal")) -> Di atas ideal | F10: =IF('Analisis Lengkap'!F19<'Input Tarif'!$D$25,"Di bawah minimum",IF('Analisis Lengkap'!F19<='Input Tarif'!$D$26,"Dalam rentang sehat","Di atas ideal")) -> Di atas ideal | G10: =IF('Analisis Lengkap'!G19<'Input Tarif'!$D$25,"Di bawah minimum",IF('Analisis Lengkap'!G19<='Input Tarif'!$D$26,"Dalam rentang sehat","Di atas ideal")) -> Di atas ideal
B11: BERAPA HARGA YANG SEBAIKNYA?
B12: Harga minimum (15%) | C12: ='Analisis Lengkap'!C33 -> 9000000 | D12: ='Analisis Lengkap'!D33 -> 10500000 | E12: ='Analisis Lengkap'!E33 -> 15000000 | F12: ='Analisis Lengkap'!F33 -> 23500000 | G12: ='Analisis Lengkap'!G33 -> 20500000
B13: Harga ideal (26%) | C13: ='Analisis Lengkap'!C34 -> 10500000 | D13: ='Analisis Lengkap'!D34 -> 12000000 | E13: ='Analisis Lengkap'!E34 -> 17000000 | F13: ='Analisis Lengkap'!F34 -> 27000000 | G13: ='Analisis Lengkap'!G34 -> 23500000
B14: Harga rekomendasi | C14: ='Analisis Lengkap'!C36 -> 12000000 | D14: ='Analisis Lengkap'!D36 -> 11000000 | E14: ='Analisis Lengkap'!E36 -> 20000000 | F14: ='Analisis Lengkap'!F36 -> 31500000 | G14: ='Analisis Lengkap'!G36 -> 23500000
B15: Kenaikan yang dibutuhkan | C15: ='Analisis Lengkap'!C37 -> 0 | D15: ='Analisis Lengkap'!D37 -> 0 | E15: ='Analisis Lengkap'!E37 -> 0 | F15: ='Analisis Lengkap'!F37 -> 0 | G15: ='Analisis Lengkap'!G37 -> 0
B16: Laba bersih di harga rekomendasi | C16: ='Analisis Lengkap'!C39 -> 4335000 | D16: ='Analisis Lengkap'!D39 -> 2255000 | E16: ='Analisis Lengkap'!E39 -> 7400000 | F16: ='Analisis Lengkap'!F39 -> 11430000 | G16: ='Analisis Lengkap'!G39 -> 6390000
B17: Atau: hemat biaya (tanpa naik harga) utk 15% | C17: ='Analisis Lengkap'!C41 -> 0 | D17: ='Analisis Lengkap'!D41 -> 0 | E17: ='Analisis Lengkap'!E41 -> 0 | F17: ='Analisis Lengkap'!F41 -> 0 | G17: ='Analisis Lengkap'!G41 -> 0
B18: DAMPAK KE KAS & OPERASIONAL
B19: Kas masuk saat SPK (DP, setelah PPh) | C19: ='Analisis Lengkap'!C26 -> 5880000 | D19: ='Analisis Lengkap'!D26 -> 5390000 | E19: ='Analisis Lengkap'!E26 -> 9800000 | F19: ='Analisis Lengkap'!F26 -> 15435000 | G19: ='Analisis Lengkap'!G26 -> 11515000
B20: Laba per bulan (harga sekarang) | C20: ='Analisis Lengkap'!C27 -> 1445000 | D20: ='Analisis Lengkap'!D27 -> 751666.67 | E20: ='Analisis Lengkap'!E27 -> 2466666.7 | F20: ='Analisis Lengkap'!F27 -> 3810000 | G20: ='Analisis Lengkap'!G27 -> 2130000
B21: % opex 3 bulan yang tertutup | C21: ='Analisis Lengkap'!C28 -> 0.07225 | D21: ='Analisis Lengkap'!D28 -> 0.037583333 | E21: ='Analisis Lengkap'!E28 -> 0.12333333 | F21: ='Analisis Lengkap'!F28 -> 0.1905 | G21: ='Analisis Lengkap'!G28 -> 0.1065
B22: Laba jika semua sesi oleh Vania/Kia | C22: ='Analisis Lengkap'!C24 -> 9585000 | D22: ='Analisis Lengkap'!D24 -> 7505000 | E22: ='Analisis Lengkap'!E24 -> 15800000 | F22: ='Analisis Lengkap'!F24 -> 24030000 | G22: ='Analisis Lengkap'!G24 -> 18990000
B23: KEPUTUSAN
B24: Rekomendasi | C24: ='Analisis Lengkap'!C42 -> Harga sekarang sudah sehat - pertahankan | D24: ='Analisis Lengkap'!D42 -> Harga sekarang sudah sehat - pertahankan | E24: ='Analisis Lengkap'!E42 -> Harga sekarang sudah sehat - pertahankan | F24: ='Analisis Lengkap'!F42 -> Harga sekarang sudah sehat - pertahankan | G24: ='Analisis Lengkap'!G42 -> Harga sekarang sudah sehat - pertahankan
B26: Cara baca: merah = harga belum menutup standar minimum margin 15%. Ikuti baris 'Harga rekomendasi', atau hemat biaya sebesar angka di bawahnya.
B27: Angka di sini otomatis mengikuti 'Analisis Lengkap'. Ubah tarif di 'Input Tarif' dan kuantitas/harga/target di 'Desain Program'.

Sheet 2. Ringkasan Klien
A1: Welcoming Package - Employee Wellbeing Program
A2: Bank Indonesia KPw Sibolga | PT Indo Medika Resolusi (Teman Journey) | Dapat dibagikan ke klien
B4: Yang Anda dapatkan | C4: Paket Jeda | D4: Paket Jeda Tahunan (per term) | E4: Paket Tumbuh | F4: Paket Seperjalanan | G4: Paket Penyuluhan (opsi 4)
B5: LAYANAN
B6: Konseling psikologi online (60 menit) | C6: ='Desain Program'!D8&" sesi" -> 15 sesi | D6: ='Desain Program'!E8&" sesi" -> 15 sesi | E6: ='Desain Program'!F8&" sesi" -> 24 sesi | F6: ='Desain Program'!G8&" sesi" -> 36 sesi | G6: ='Desain Program'!H8&" sesi" -> 36 sesi
B7: Perkiraan pegawai terlayani | C7: ="± "&TEXT('Desain Program'!D9,"0")&" pegawai (3 sesi/orang)" -> ± 5 pegawai (3 sesi/orang) | D7: ="± "&TEXT('Desain Program'!E9,"0")&" pegawai (3 sesi/orang)" -> ± 5 pegawai (3 sesi/orang) | E7: ="± "&TEXT('Desain Program'!F9,"0")&" pegawai (3 sesi/orang)" -> ± 8 pegawai (3 sesi/orang) | F7: ="± "&TEXT('Desain Program'!G9,"0")&" pegawai (3 sesi/orang)" -> ± 12 pegawai (3 sesi/orang) | G7: ="± "&TEXT('Desain Program'!H9,"0")&" pegawai (3 sesi/orang)" -> ± 12 pegawai (3 sesi/orang)
B8: Mental Health Check-Up (MHCU) | C8: =IF('Desain Program'!D10=0,"-",'Desain Program'!D10&"x ("&IF('Desain Program'!D10>=2,"pre & post","baseline")&")") -> - | D8: =IF('Desain Program'!E10=0,"-",'Desain Program'!E10&"x ("&IF('Desain Program'!E10>=2,"pre & post","baseline")&")") -> 1x (baseline) | E8: =IF('Desain Program'!F10=0,"-",'Desain Program'!F10&"x ("&IF('Desain Program'!F10>=2,"pre & post","baseline")&")") -> 1x (baseline) | F8: =IF('Desain Program'!G10=0,"-",'Desain Program'!G10&"x ("&IF('Desain Program'!G10>=2,"pre & post","baseline")&")") -> 2x (pre & post) | G8: =IF('Desain Program'!H10=0,"-",'Desain Program'!H10&"x ("&IF('Desain Program'!H10>=2,"pre & post","baseline")&")") -> 2x (pre & post)
B9: Laporan agregat anonim untuk manajemen | C9: =IF('Desain Program'!D11=1,IF('Desain Program'!D10>=2,"Ya, dengan perbandingan pre/post","Ya"),"-") -> - | D9: =IF('Desain Program'!E11=1,IF('Desain Program'!E10>=2,"Ya, dengan perbandingan pre/post","Ya"),"-") -> Ya | E9: =IF('Desain Program'!F11=1,IF('Desain Program'!F10>=2,"Ya, dengan perbandingan pre/post","Ya"),"-") -> Ya | F9: =IF('Desain Program'!G11=1,IF('Desain Program'!G10>=2,"Ya, dengan perbandingan pre/post","Ya"),"-") -> Ya, dengan perbandingan pre/post | G9: =IF('Desain Program'!H11=1,IF('Desain Program'!H10>=2,"Ya, dengan perbandingan pre/post","Ya"),"-") -> Ya, dengan perbandingan pre/post
B10: Hasil MHCU individual untuk pegawai | C10: =IF('Desain Program'!D12=1,"Ya","-") -> - | D10: =IF('Desain Program'!E12=1,"Ya","-") -> - | E10: =IF('Desain Program'!F12=1,"Ya","-") -> - | F10: =IF('Desain Program'!G12=1,"Ya","-") -> Ya | G10: =IF('Desain Program'!H12=1,"Ya","-") -> Ya
B11: Psikoedukasi oleh psikolog | C11: =IF('Desain Program'!D13+'Desain Program'!D14+'Desain Program'!D15=0,"-",IF('Desain Program'!D14>0,'Desain Program'!D14&" seminar offline",IF('Desain Program'!D13>0,'Desain Program'!D13&" webinar online",""))&IF('Desain Program'!D15>0,IF('Desain Program'!D13+'Desain Program'!D14>0," + ","")&'Desain Program'!D15&" penyuluhan gratis (30 menit, terbuka untuk umum)","")) -> 1 webinar online | D11: =IF('Desain Program'!E13+'Desain Program'!E14+'Desain Program'!E15=0,"-",IF('Desain Program'!E14>0,'Desain Program'!E14&" seminar offline",IF('Desain Program'!E13>0,'Desain Program'!E13&" webinar online",""))&IF('Desain Program'!E15>0,IF('Desain Program'!E13+'Desain Program'!E14>0," + ","")&'Desain Program'!E15&" penyuluhan gratis (30 menit, terbuka untuk umum)","")) -> 1 webinar online | E11: =IF('Desain Program'!F13+'Desain Program'!F14+'Desain Program'!F15=0,"-",IF('Desain Program'!F14>0,'Desain Program'!F14&" seminar offline",IF('Desain Program'!F13>0,'Desain Program'!F13&" webinar online",""))&IF('Desain Program'!F15>0,IF('Desain Program'!F13+'Desain Program'!F14>0," + ","")&'Desain Program'!F15&" penyuluhan gratis (30 menit, terbuka untuk umum)","")) -> 1 webinar online | F11: =IF('Desain Program'!G13+'Desain Program'!G14+'Desain Program'!G15=0,"-",IF('Desain Program'!G14>0,'Desain Program'!G14&" seminar offline",IF('Desain Program'!G13>0,'Desain Program'!G13&" webinar online",""))&IF('Desain Program'!G15>0,IF('Desain Program'!G13+'Desain Program'!G14>0," + ","")&'Desain Program'!G15&" penyuluhan gratis (30 menit, terbuka untuk umum)","")) -> 1 seminar offline | G11: =IF('Desain Program'!H13+'Desain Program'!H14+'Desain Program'!H15=0,"-",IF('Desain Program'!H14>0,'Desain Program'!H14&" seminar offline",IF('Desain Program'!H13>0,'Desain Program'!H13&" webinar online",""))&IF('Desain Program'!H15>0,IF('Desain Program'!H13+'Desain Program'!H14>0," + ","")&'Desain Program'!H15&" penyuluhan gratis (30 menit, terbuka untuk umum)","")) -> 2 penyuluhan gratis (30 menit, terbuka untuk umum)
B12: Masa berlaku | C12: ='Input Tarif'!$D$19&" bulan sejak SPK" -> 3 bulan sejak SPK | D12: ="Kuota per "&'Input Tarif'!$D$19&" bulan, kontrak 1 tahun (4 term)" -> Kuota per 3 bulan, kontrak 1 tahun (4 term) | E12: ='Input Tarif'!$D$19&" bulan sejak SPK" -> 3 bulan sejak SPK | F12: ='Input Tarif'!$D$19&" bulan sejak SPK" -> 3 bulan sejak SPK | G12: ='Input Tarif'!$D$19&" bulan sejak SPK" -> 3 bulan sejak SPK
B13: INVESTASI
B14: Nilai layanan (harga reguler) | C14: =IF('Analisis Lengkap'!C30>'Analisis Lengkap'!C6,'Analisis Lengkap'!C30,"-") -> - | D14: =IF('Analisis Lengkap'!D30>'Analisis Lengkap'!D6,'Analisis Lengkap'!D30,"-") -> 15000000 | E14: =IF('Analisis Lengkap'!E30>'Analisis Lengkap'!E6,'Analisis Lengkap'!E30,"-") -> - | F14: =IF('Analisis Lengkap'!F30>'Analisis Lengkap'!F6,'Analisis Lengkap'!F30,"-") -> - | G14: =IF('Analisis Lengkap'!G30>'Analisis Lengkap'!G6,'Analisis Lengkap'!G30,"-") -> 27000000
B15: Harga Welcoming Package | C15: ='Analisis Lengkap'!C6 -> 12000000 | D15: ='Analisis Lengkap'!D6 -> 11000000 | E15: ='Analisis Lengkap'!E6 -> 20000000 | F15: ='Analisis Lengkap'!F6 -> 31500000 | G15: ='Analisis Lengkap'!G6 -> 23500000
B16: Anda hemat | C16: =IF('Analisis Lengkap'!C30-'Analisis Lengkap'!C6>0,"Rp"&TEXT('Analisis Lengkap'!C30-'Analisis Lengkap'!C6,"#,##0")&" ("&TEXT(1-'Analisis Lengkap'!C6/'Analisis Lengkap'!C30,"0%")&")","-") -> - | D16: =IF('Analisis Lengkap'!D30-'Analisis Lengkap'!D6>0,"Rp"&TEXT('Analisis Lengkap'!D30-'Analisis Lengkap'!D6,"#,##0")&" ("&TEXT(1-'Analisis Lengkap'!D6/'Analisis Lengkap'!D30,"0%")&")","-") -> Rp4000000,0 (27%) | E16: =IF('Analisis Lengkap'!E30-'Analisis Lengkap'!E6>0,"Rp"&TEXT('Analisis Lengkap'!E30-'Analisis Lengkap'!E6,"#,##0")&" ("&TEXT(1-'Analisis Lengkap'!E6/'Analisis Lengkap'!E30,"0%")&")","-") -> - | F16: =IF('Analisis Lengkap'!F30-'Analisis Lengkap'!F6>0,"Rp"&TEXT('Analisis Lengkap'!F30-'Analisis Lengkap'!F6,"#,##0")&" ("&TEXT(1-'Analisis Lengkap'!F6/'Analisis Lengkap'!F30,"0%")&")","-") -> - | G16: =IF('Analisis Lengkap'!G30-'Analisis Lengkap'!G6>0,"Rp"&TEXT('Analisis Lengkap'!G30-'Analisis Lengkap'!G6,"#,##0")&" ("&TEXT(1-'Analisis Lengkap'!G6/'Analisis Lengkap'!G30,"0%")&")","-") -> Rp3500000,0 (13%)
B17: Setara per bulan | C17: ='Analisis Lengkap'!C7 -> 4000000 | D17: ='Analisis Lengkap'!D7 -> 3666666.7 | E17: ='Analisis Lengkap'!E7 -> 6666666.7 | F17: ='Analisis Lengkap'!F7 -> 10500000 | G17: ='Analisis Lengkap'!G7 -> 7833333.3
B18: Setara per pegawai | C18: ='Analisis Lengkap'!C6/'Desain Program'!D9 -> 2400000 | D18: ='Analisis Lengkap'!D6/'Desain Program'!E9 -> 2200000 | E18: ='Analisis Lengkap'!E6/'Desain Program'!F9 -> 2500000 | F18: ='Analisis Lengkap'!F6/'Desain Program'!G9 -> 2625000 | G18: ='Analisis Lengkap'!G6/'Desain Program'!H9 -> 1958333.3
B20: KETENTUAN
B21: Batas penandatanganan SPK | C21: 31 Oktober 2026
B22: Pembayaran | C22: ="Paket 3 bulan: DP "&TEXT('Input Tarif'!$D$21,"0%")&" saat SPK, pelunasan setelah laporan akhir. Jeda Tahunan: 2x per semester (Rp22.000.000 di awal tiap semester, total Rp44.000.000/tahun)" -> Paket 3 bulan: DP 50% saat SPK, pelunasan setelah laporan akhir. Jeda Tahunan: 2x per semester (Rp22.000.000 di awal tiap semester, total Rp44.000.000/tahun)
B23: Pajak | C23: Teman Journey non-PKP (tanpa PPN); PPh 23 dipotong oleh pemberi kerja
B24: Sesi tambahan | C24: ="Rp"&TEXT('Input Tarif'!$D$17,"#,##0")&" per sesi" -> Rp500000,0 per sesi
B25: Kerahasiaan | C25: Manajemen hanya menerima data agregat anonim. Hasil MHCU individual (Seperjalanan) hanya diberikan ke pegawai yang bersangkutan
B26: Penyelenggara | C26: PT Indo Medika Resolusi (Teman Journey) - info@temanjourney.id

Sheet Analisis Lengkap
A1: ANALISIS LENGKAP - BI KPw Sibolga (INTERNAL)
A2: Margin = laba bersih / harga jual. Target margin diatur di sheet 'Desain Program'.
B4: Indikator | C4: Jeda | D4: Jeda Tahunan (per term) | E4: Tumbuh | F4: Seperjalanan | G4: Penyuluhan (opsi 4)
B5: HARGA
B6: Harga jual | C6: ='Desain Program'!D5 -> 12000000 | D6: ='Desain Program'!E5 -> 11000000 | E6: ='Desain Program'!F5 -> 20000000 | F6: ='Desain Program'!G5 -> 31500000 | G6: ='Desain Program'!H5 -> 23500000
B7: Setara per bulan | C7: ='Desain Program'!D5/'Input Tarif'!$D$19 -> 4000000 | D7: ='Desain Program'!E5/'Input Tarif'!$D$19 -> 3666666.7 | E7: ='Desain Program'!F5/'Input Tarif'!$D$19 -> 6666666.7 | F7: ='Desain Program'!G5/'Input Tarif'!$D$19 -> 10500000 | G7: ='Desain Program'!H5/'Input Tarif'!$D$19 -> 7833333.3
B8: Jumlah sesi / pegawai terlayani | C8: =TEXT('Desain Program'!D8,"0")&" sesi / "&TEXT('Desain Program'!D9,"0")&" org" -> 15 sesi / 5 org | D8: =TEXT('Desain Program'!E8,"0")&" sesi / "&TEXT('Desain Program'!E9,"0")&" org" -> 15 sesi / 5 org | E8: =TEXT('Desain Program'!F8,"0")&" sesi / "&TEXT('Desain Program'!F9,"0")&" org" -> 24 sesi / 8 org | F8: =TEXT('Desain Program'!G8,"0")&" sesi / "&TEXT('Desain Program'!G9,"0")&" org" -> 36 sesi / 12 org | G8: =TEXT('Desain Program'!H8,"0")&" sesi / "&TEXT('Desain Program'!H9,"0")&" org" -> 36 sesi / 12 org
B9: BIAYA PER KATEGORI
B10: A. Delivery konseling | C10: ='Rincian Biaya'!D8 -> 5775000 | D10: ='Rincian Biaya'!E8 -> 5775000 | E10: ='Rincian Biaya'!F8 -> 9240000 | F10: ='Rincian Biaya'!G8 -> 13860000 | G10: ='Rincian Biaya'!H8 -> 13860000
B11: B. Asesmen | C11: ='Rincian Biaya'!D13 -> 0 | D11: ='Rincian Biaya'!E13 -> 1100000 | E11: ='Rincian Biaya'!F13 -> 1310000 | F11: ='Rincian Biaya'!G13 -> 2430000 | G11: ='Rincian Biaya'!H13 -> 2430000
B12: C. Psikoedukasi | C12: ='Rincian Biaya'!D19 -> 1500000 | D12: ='Rincian Biaya'!E19 -> 1500000 | E12: ='Rincian Biaya'!F19 -> 1500000 | F12: ='Rincian Biaya'!G19 -> 3000000 | G12: ='Rincian Biaya'!H19 -> 200000
B13: D. Administrasi proyek | C13: ='Rincian Biaya'!D23 -> 150000 | D13: ='Rincian Biaya'!E23 -> 150000 | E13: ='Rincian Biaya'!F23 -> 150000 | F13: ='Rincian Biaya'!G23 -> 150000 | G13: ='Rincian Biaya'!H23 -> 150000
B14: E. Pajak & overhead | C14: ='Rincian Biaya'!D28 -> 240000 | D14: ='Rincian Biaya'!E28 -> 220000 | E14: ='Rincian Biaya'!F28 -> 400000 | F14: ='Rincian Biaya'!G28 -> 630000 | G14: ='Rincian Biaya'!H28 -> 470000
B15: Total biaya | C15: ='Rincian Biaya'!D30 -> 7665000 | D15: ='Rincian Biaya'!E30 -> 8745000 | E15: ='Rincian Biaya'!F30 -> 12600000 | F15: ='Rincian Biaya'!G30 -> 20070000 | G15: ='Rincian Biaya'!H30 -> 17110000
B16: Biaya sebagai % harga | C16: =IF('Desain Program'!D5=0,0,'Rincian Biaya'!D30/'Desain Program'!D5) -> 0.63875 | D16: =IF('Desain Program'!E5=0,0,'Rincian Biaya'!E30/'Desain Program'!E5) -> 0.795 | E16: =IF('Desain Program'!F5=0,0,'Rincian Biaya'!F30/'Desain Program'!F5) -> 0.63 | F16: =IF('Desain Program'!G5=0,0,'Rincian Biaya'!G30/'Desain Program'!G5) -> 0.63714286 | G16: =IF('Desain Program'!H5=0,0,'Rincian Biaya'!H30/'Desain Program'!H5) -> 0.72808511
B17: LABA & MARGIN
B18: Laba bersih | C18: ='Desain Program'!D5-'Rincian Biaya'!D30 -> 4335000 | D18: ='Desain Program'!E5-'Rincian Biaya'!E30 -> 2255000 | E18: ='Desain Program'!F5-'Rincian Biaya'!F30 -> 7400000 | F18: ='Desain Program'!G5-'Rincian Biaya'!G30 -> 11430000 | G18: ='Desain Program'!H5-'Rincian Biaya'!H30 -> 6390000
B19: Margin bersih aktual | C19: =IF('Desain Program'!D5=0,0,('Desain Program'!D5-'Rincian Biaya'!D30)/'Desain Program'!D5) -> 0.36125 | D19: =IF('Desain Program'!E5=0,0,('Desain Program'!E5-'Rincian Biaya'!E30)/'Desain Program'!E5) -> 0.205 | E19: =IF('Desain Program'!F5=0,0,('Desain Program'!F5-'Rincian Biaya'!F30)/'Desain Program'!F5) -> 0.37 | F19: =IF('Desain Program'!G5=0,0,('Desain Program'!G5-'Rincian Biaya'!G30)/'Desain Program'!G5) -> 0.36285714 | G19: =IF('Desain Program'!H5=0,0,('Desain Program'!H5-'Rincian Biaya'!H30)/'Desain Program'!H5) -> 0.27191489
B20: Target margin | C20: ='Desain Program'!D6 -> 0.36 | D20: ='Desain Program'!E6 -> 0.2 | E20: ='Desain Program'!F6 -> 0.36 | F20: ='Desain Program'!G6 -> 0.36 | G20: ='Desain Program'!H6 -> 0.26
B21: Harga minimum utk capai target | C21: =('Rincian Biaya'!D30-'Rincian Biaya'!D26-'Rincian Biaya'!D27)/(1-'Input Tarif'!$D$13-'Input Tarif'!$D$14-'Desain Program'!D6) -> 11975806 | D21: =('Rincian Biaya'!E30-'Rincian Biaya'!E26-'Rincian Biaya'!E27)/(1-'Input Tarif'!$D$13-'Input Tarif'!$D$14-'Desain Program'!E6) -> 10929487 | E21: =('Rincian Biaya'!F30-'Rincian Biaya'!F26-'Rincian Biaya'!F27)/(1-'Input Tarif'!$D$13-'Input Tarif'!$D$14-'Desain Program'!F6) -> 19677419 | F21: =('Rincian Biaya'!G30-'Rincian Biaya'!G26-'Rincian Biaya'!G27)/(1-'Input Tarif'!$D$13-'Input Tarif'!$D$14-'Desain Program'!G6) -> 31354839 | G21: =('Rincian Biaya'!H30-'Rincian Biaya'!H26-'Rincian Biaya'!H27)/(1-'Input Tarif'!$D$13-'Input Tarif'!$D$14-'Desain Program'!H6) -> 23111111
B22: Selisih harga jual vs harga minimum | C22: ='Desain Program'!D5-('Rincian Biaya'!D30-'Rincian Biaya'!D26-'Rincian Biaya'!D27)/(1-'Input Tarif'!$D$13-'Input Tarif'!$D$14-'Desain Program'!D6) -> 24193.548 | D22: ='Desain Program'!E5-('Rincian Biaya'!E30-'Rincian Biaya'!E26-'Rincian Biaya'!E27)/(1-'Input Tarif'!$D$13-'Input Tarif'!$D$14-'Desain Program'!E6) -> 70512.821 | E22: ='Desain Program'!F5-('Rincian Biaya'!F30-'Rincian Biaya'!F26-'Rincian Biaya'!F27)/(1-'Input Tarif'!$D$13-'Input Tarif'!$D$14-'Desain Program'!F6) -> 322580.65 | F22: ='Desain Program'!G5-('Rincian Biaya'!G30-'Rincian Biaya'!G26-'Rincian Biaya'!G27)/(1-'Input Tarif'!$D$13-'Input Tarif'!$D$14-'Desain Program'!G6) -> 145161.29 | G22: ='Desain Program'!H5-('Rincian Biaya'!H30-'Rincian Biaya'!H26-'Rincian Biaya'!H27)/(1-'Input Tarif'!$D$13-'Input Tarif'!$D$14-'Desain Program'!H6) -> 388888.89
B23: Status | C23: =IF(C22>=0,"Memenuhi target","Di bawah target") -> Memenuhi target | D23: =IF(D22>=0,"Memenuhi target","Di bawah target") -> Memenuhi target | E23: =IF(E22>=0,"Memenuhi target","Di bawah target") -> Memenuhi target | F23: =IF(F22>=0,"Memenuhi target","Di bawah target") -> Memenuhi target | G23: =IF(G22>=0,"Memenuhi target","Di bawah target") -> Memenuhi target
B24: Laba bersih jika semua sesi in-house | C24: ='Desain Program'!D5-'Rincian Biaya'!D30+'Rincian Biaya'!D6 -> 9585000 | D24: ='Desain Program'!E5-'Rincian Biaya'!E30+'Rincian Biaya'!E6 -> 7505000 | E24: ='Desain Program'!F5-'Rincian Biaya'!F30+'Rincian Biaya'!F6 -> 15800000 | F24: ='Desain Program'!G5-'Rincian Biaya'!G30+'Rincian Biaya'!G6 -> 24030000 | G24: ='Desain Program'!H5-'Rincian Biaya'!H30+'Rincian Biaya'!H6 -> 18990000
B25: KAS & KONTRIBUSI
B26: Kas diterima saat SPK (DP, setelah PPh) | C26: ='Desain Program'!D5*'Input Tarif'!$D$21*(1-'Input Tarif'!$D$13) -> 5880000 | D26: ='Desain Program'!E5*'Input Tarif'!$D$21*(1-'Input Tarif'!$D$13) -> 5390000 | E26: ='Desain Program'!F5*'Input Tarif'!$D$21*(1-'Input Tarif'!$D$13) -> 9800000 | F26: ='Desain Program'!G5*'Input Tarif'!$D$21*(1-'Input Tarif'!$D$13) -> 15435000 | G26: ='Desain Program'!H5*'Input Tarif'!$D$21*(1-'Input Tarif'!$D$13) -> 11515000
B27: Laba bersih per bulan | C27: =('Desain Program'!D5-'Rincian Biaya'!D30)/'Input Tarif'!$D$19 -> 1445000 | D27: =('Desain Program'!E5-'Rincian Biaya'!E30)/'Input Tarif'!$D$19 -> 751666.67 | E27: =('Desain Program'!F5-'Rincian Biaya'!F30)/'Input Tarif'!$D$19 -> 2466666.7 | F27: =('Desain Program'!G5-'Rincian Biaya'!G30)/'Input Tarif'!$D$19 -> 3810000 | G27: =('Desain Program'!H5-'Rincian Biaya'!H30)/'Input Tarif'!$D$19 -> 2130000
B28: % opex masa paket yang tertutup | C28: =('Desain Program'!D5-'Rincian Biaya'!D30)/('Input Tarif'!$D$20*'Input Tarif'!$D$19) -> 0.07225 | D28: =('Desain Program'!E5-'Rincian Biaya'!E30)/('Input Tarif'!$D$20*'Input Tarif'!$D$19) -> 0.037583333 | E28: =('Desain Program'!F5-'Rincian Biaya'!F30)/('Input Tarif'!$D$20*'Input Tarif'!$D$19) -> 0.12333333 | F28: =('Desain Program'!G5-'Rincian Biaya'!G30)/('Input Tarif'!$D$20*'Input Tarif'!$D$19) -> 0.1905 | G28: =('Desain Program'!H5-'Rincian Biaya'!H30)/('Input Tarif'!$D$20*'Input Tarif'!$D$19) -> 0.1065
B29: NILAI UNTUK PROPOSAL
B30: Nilai normal (harga reguler) | C30: ='Desain Program'!D8*'Input Tarif'!$D$17+'Desain Program'!D10*'Input Tarif'!$D$22+'Desain Program'!D11*'Input Tarif'!$D$23+('Desain Program'!D13+'Desain Program'!D14)*'Input Tarif'!$D$24+'Desain Program'!D15*'Input Tarif'!$D$28 -> 10500000 | D30: ='Desain Program'!E8*'Input Tarif'!$D$17+'Desain Program'!E10*'Input Tarif'!$D$22+'Desain Program'!E11*'Input Tarif'!$D$23+('Desain Program'!E13+'Desain Program'!E14)*'Input Tarif'!$D$24+'Desain Program'!E15*'Input Tarif'!$D$28 -> 15000000 | E30: ='Desain Program'!F8*'Input Tarif'!$D$17+'Desain Program'!F10*'Input Tarif'!$D$22+'Desain Program'!F11*'Input Tarif'!$D$23+('Desain Program'!F13+'Desain Program'!F14)*'Input Tarif'!$D$24+'Desain Program'!F15*'Input Tarif'!$D$28 -> 19500000 | F30: ='Desain Program'!G8*'Input Tarif'!$D$17+'Desain Program'!G10*'Input Tarif'!$D$22+'Desain Program'!G11*'Input Tarif'!$D$23+('Desain Program'!G13+'Desain Program'!G14)*'Input Tarif'!$D$24+'Desain Program'!G15*'Input Tarif'!$D$28 -> 28000000 | G30: ='Desain Program'!H8*'Input Tarif'!$D$17+'Desain Program'!H10*'Input Tarif'!$D$22+'Desain Program'!H11*'Input Tarif'!$D$23+('Desain Program'!H13+'Desain Program'!H14)*'Input Tarif'!$D$24+'Desain Program'!H15*'Input Tarif'!$D$28 -> 27000000
B31: Hemat untuk BI | C31: =IF(C30=0,0,1-C6/C30) -> -0.14285714 | D31: =IF(D30=0,0,1-D6/D30) -> 0.26666667 | E31: =IF(E30=0,0,1-E6/E30) -> -0.025641026 | F31: =IF(F30=0,0,1-F6/F30) -> -0.125 | G31: =IF(G30=0,0,1-G6/G30) -> 0.12962963
B32: REKOMENDASI HARGA
B33: Harga minimum (margin 15%) | C33: =CEILING(('Rincian Biaya'!D30-'Rincian Biaya'!D26-'Rincian Biaya'!D27)/(1-'Input Tarif'!$D$13-'Input Tarif'!$D$14-'Input Tarif'!$D$25),'Input Tarif'!$D$27) -> 9000000 | D33: =CEILING(('Rincian Biaya'!E30-'Rincian Biaya'!E26-'Rincian Biaya'!E27)/(1-'Input Tarif'!$D$13-'Input Tarif'!$D$14-'Input Tarif'!$D$25),'Input Tarif'!$D$27) -> 10500000 | E33: =CEILING(('Rincian Biaya'!F30-'Rincian Biaya'!F26-'Rincian Biaya'!F27)/(1-'Input Tarif'!$D$13-'Input Tarif'!$D$14-'Input Tarif'!$D$25),'Input Tarif'!$D$27) -> 15000000 | F33: =CEILING(('Rincian Biaya'!G30-'Rincian Biaya'!G26-'Rincian Biaya'!G27)/(1-'Input Tarif'!$D$13-'Input Tarif'!$D$14-'Input Tarif'!$D$25),'Input Tarif'!$D$27) -> 23500000 | G33: =CEILING(('Rincian Biaya'!H30-'Rincian Biaya'!H26-'Rincian Biaya'!H27)/(1-'Input Tarif'!$D$13-'Input Tarif'!$D$14-'Input Tarif'!$D$25),'Input Tarif'!$D$27) -> 20500000
B34: Harga ideal (margin 26%) | C34: =CEILING(('Rincian Biaya'!D30-'Rincian Biaya'!D26-'Rincian Biaya'!D27)/(1-'Input Tarif'!$D$13-'Input Tarif'!$D$14-'Input Tarif'!$D$26),'Input Tarif'!$D$27) -> 10500000 | D34: =CEILING(('Rincian Biaya'!E30-'Rincian Biaya'!E26-'Rincian Biaya'!E27)/(1-'Input Tarif'!$D$13-'Input Tarif'!$D$14-'Input Tarif'!$D$26),'Input Tarif'!$D$27) -> 12000000 | E34: =CEILING(('Rincian Biaya'!F30-'Rincian Biaya'!F26-'Rincian Biaya'!F27)/(1-'Input Tarif'!$D$13-'Input Tarif'!$D$14-'Input Tarif'!$D$26),'Input Tarif'!$D$27) -> 17000000 | F34: =CEILING(('Rincian Biaya'!G30-'Rincian Biaya'!G26-'Rincian Biaya'!G27)/(1-'Input Tarif'!$D$13-'Input Tarif'!$D$14-'Input Tarif'!$D$26),'Input Tarif'!$D$27) -> 27000000 | G34: =CEILING(('Rincian Biaya'!H30-'Rincian Biaya'!H26-'Rincian Biaya'!H27)/(1-'Input Tarif'!$D$13-'Input Tarif'!$D$14-'Input Tarif'!$D$26),'Input Tarif'!$D$27) -> 23500000
B35: Margin dipakai untuk rekomendasi | C35: =MAX('Input Tarif'!$D$25,MIN('Input Tarif'!$D$26,'Desain Program'!D6)) -> 0.26 | D35: =MAX('Input Tarif'!$D$25,MIN('Input Tarif'!$D$26,'Desain Program'!E6)) -> 0.2 | E35: =MAX('Input Tarif'!$D$25,MIN('Input Tarif'!$D$26,'Desain Program'!F6)) -> 0.26 | F35: =MAX('Input Tarif'!$D$25,MIN('Input Tarif'!$D$26,'Desain Program'!G6)) -> 0.26 | G35: =MAX('Input Tarif'!$D$25,MIN('Input Tarif'!$D$26,'Desain Program'!H6)) -> 0.26
B36: HARGA REKOMENDASI | C36: =MAX(C6,CEILING(('Rincian Biaya'!D30-'Rincian Biaya'!D26-'Rincian Biaya'!D27)/(1-'Input Tarif'!$D$13-'Input Tarif'!$D$14-C35),'Input Tarif'!$D$27)) -> 12000000 | D36: =MAX(D6,CEILING(('Rincian Biaya'!E30-'Rincian Biaya'!E26-'Rincian Biaya'!E27)/(1-'Input Tarif'!$D$13-'Input Tarif'!$D$14-D35),'Input Tarif'!$D$27)) -> 11000000 | E36: =MAX(E6,CEILING(('Rincian Biaya'!F30-'Rincian Biaya'!F26-'Rincian Biaya'!F27)/(1-'Input Tarif'!$D$13-'Input Tarif'!$D$14-E35),'Input Tarif'!$D$27)) -> 20000000 | F36: =MAX(F6,CEILING(('Rincian Biaya'!G30-'Rincian Biaya'!G26-'Rincian Biaya'!G27)/(1-'Input Tarif'!$D$13-'Input Tarif'!$D$14-F35),'Input Tarif'!$D$27)) -> 31500000 | G36: =MAX(G6,CEILING(('Rincian Biaya'!H30-'Rincian Biaya'!H26-'Rincian Biaya'!H27)/(1-'Input Tarif'!$D$13-'Input Tarif'!$D$14-G35),'Input Tarif'!$D$27)) -> 23500000
B37: Perubahan vs harga sekarang | C37: =C36-C6 -> 0 | D37: =D36-D6 -> 0 | E37: =E36-E6 -> 0 | F37: =F36-F6 -> 0 | G37: =G36-G6 -> 0
B38: Margin bersih pada harga rekomendasi | C38: =(C36*(1-'Input Tarif'!$D$13-'Input Tarif'!$D$14)-('Rincian Biaya'!D30-'Rincian Biaya'!D26-'Rincian Biaya'!D27))/C36 -> 0.36125 | D38: =(D36*(1-'Input Tarif'!$D$13-'Input Tarif'!$D$14)-('Rincian Biaya'!E30-'Rincian Biaya'!E26-'Rincian Biaya'!E27))/D36 -> 0.205 | E38: =(E36*(1-'Input Tarif'!$D$13-'Input Tarif'!$D$14)-('Rincian Biaya'!F30-'Rincian Biaya'!F26-'Rincian Biaya'!F27))/E36 -> 0.37 | F38: =(F36*(1-'Input Tarif'!$D$13-'Input Tarif'!$D$14)-('Rincian Biaya'!G30-'Rincian Biaya'!G26-'Rincian Biaya'!G27))/F36 -> 0.36285714 | G38: =(G36*(1-'Input Tarif'!$D$13-'Input Tarif'!$D$14)-('Rincian Biaya'!H30-'Rincian Biaya'!H26-'Rincian Biaya'!H27))/G36 -> 0.27191489
B39: Laba bersih pada harga rekomendasi | C39: =C36*(1-'Input Tarif'!$D$13-'Input Tarif'!$D$14)-('Rincian Biaya'!D30-'Rincian Biaya'!D26-'Rincian Biaya'!D27) -> 4335000 | D39: =D36*(1-'Input Tarif'!$D$13-'Input Tarif'!$D$14)-('Rincian Biaya'!E30-'Rincian Biaya'!E26-'Rincian Biaya'!E27) -> 2255000 | E39: =E36*(1-'Input Tarif'!$D$13-'Input Tarif'!$D$14)-('Rincian Biaya'!F30-'Rincian Biaya'!F26-'Rincian Biaya'!F27) -> 7400000 | F39: =F36*(1-'Input Tarif'!$D$13-'Input Tarif'!$D$14)-('Rincian Biaya'!G30-'Rincian Biaya'!G26-'Rincian Biaya'!G27) -> 11430000 | G39: =G36*(1-'Input Tarif'!$D$13-'Input Tarif'!$D$14)-('Rincian Biaya'!H30-'Rincian Biaya'!H26-'Rincian Biaya'!H27) -> 6390000
B40: Setara per bulan (harga rekomendasi) | C40: =C36/'Input Tarif'!$D$19 -> 4000000 | D40: =D36/'Input Tarif'!$D$19 -> 3666666.7 | E40: =E36/'Input Tarif'!$D$19 -> 6666666.7 | F40: =F36/'Input Tarif'!$D$19 -> 10500000 | G40: =G36/'Input Tarif'!$D$19 -> 7833333.3
B41: Alternatif: penghematan biaya agar margin 15% tanpa naik harga | C41: =MAX(0,('Rincian Biaya'!D30-'Rincian Biaya'!D26-'Rincian Biaya'!D27)-'Desain Program'!D5*(1-'Input Tarif'!$D$13-'Input Tarif'!$D$14-'Input Tarif'!$D$25)) -> 0 | D41: =MAX(0,('Rincian Biaya'!E30-'Rincian Biaya'!E26-'Rincian Biaya'!E27)-'Desain Program'!E5*(1-'Input Tarif'!$D$13-'Input Tarif'!$D$14-'Input Tarif'!$D$25)) -> 0 | E41: =MAX(0,('Rincian Biaya'!F30-'Rincian Biaya'!F26-'Rincian Biaya'!F27)-'Desain Program'!F5*(1-'Input Tarif'!$D$13-'Input Tarif'!$D$14-'Input Tarif'!$D$25)) -> 0 | F41: =MAX(0,('Rincian Biaya'!G30-'Rincian Biaya'!G26-'Rincian Biaya'!G27)-'Desain Program'!G5*(1-'Input Tarif'!$D$13-'Input Tarif'!$D$14-'Input Tarif'!$D$25)) -> 0 | G41: =MAX(0,('Rincian Biaya'!H30-'Rincian Biaya'!H26-'Rincian Biaya'!H27)-'Desain Program'!H5*(1-'Input Tarif'!$D$13-'Input Tarif'!$D$14-'Input Tarif'!$D$25)) -> 0
...

Sheet Input Tarif
A1: INPUT TARIF & ASUMSI
A2: Ubah hanya sel biru berlatar kuning. Semua angka lain dihitung otomatis. Kolom 'Review CFO' = catatan kewajaran tarif.
A4: Kategori | B4: Komponen | C4: Satuan | D4: Tarif / Nilai | E4: Sumber | F4: Review CFO
A5: A. Delivery konseling | B5: Honor psikolog per sesi konseling | C5: Rp / sesi 60 menit | D5: 350000 | E5: Kia | F5: TINGGI: 70% dari harga reguler Rp500rb. Praktik umum bagi hasil associate 50-60% (Rp250-300rb). Untuk Vania (gaji tetap), gunakan biaya internal per sesi = gaji / kapasitas sesi, bukan Rp350rb.
A6: A. Delivery konseling | B6: Admin & platform | C6: Rp / sesi | D6: 35000 | E6: Asumsi | F6: AGAK TINGGI bila Zoom & tools sudah dibayar bulanan (masuk opex). Biaya marginal realistis Rp10-15rb/sesi (reminder, penjadwalan).
A7: B. Asesmen | B7: MHCU (alat ukur + skoring) | C7: Rp / orang / putaran | D7: 70000 | E7: Kia | F7: WAJAR jika termasuk interpretasi psikolog. Jika memakai alat ukur bebas lisensi (mis. DASS-21, Copenhagen Burnout Inventory) dan skoring otomatis, biaya bisa ditekan.
A8: B. Asesmen | B8: Laporan agregat anonim | C8: Rp / program | D8: 750000 | E8: Asumsi | F8: WAJAR (± 0,5-1 hari kerja psikolog). Bisa dibuat template agar program berikutnya lebih murah.
A9: C. Psikoedukasi | B9: Webinar online oleh psikolog | C9: Rp / sesi | D9: 1500000 | E9: Kia | F9: WAJAR untuk narasumber eksternal. Jika dibawakan Kia/Vania (gaji/opex), biaya marginal mendekati Rp0-500rb (moderator, materi).
A10: C. Psikoedukasi | B10: Seminar offline oleh psikolog | C10: Rp / sesi | D10: 3000000 | E10: Kia | F10: KEMUNGKINAN TERLALU RENDAH jika narasumber berangkat dari Jakarta: tiket ke Sibolga (via Medan) + hotel + uang harian bisa melebihi Rp3jt sebelum honor. Cek ulang, atau pakai psikolog mitra di Sumut.
A11: D. Administrasi proyek | B11: PIC / Project Officer | C11: Rp / program | D11: 0 | E11: Belum ada | F11: KURANG: koordinasi jadwal 12 pegawai x 3 bulan tetap memakan waktu. Pertimbangkan Rp300-500rb/program agar margin tidak semu.
A12: D. Administrasi proyek | B12: Kontrak, materai, invoice | C12: Rp / program | D12: 150000 | E12: Asumsi | F12: WAJAR.
A13: E. Pajak & overhead | B13: PPh 23 dipotong BI | C13: % dari harga | D13: 0.02 | E13: Ketentuan | F13: Non-PKP: tidak ada PPN. PPh 23 = kredit pajak, tapi mengurangi kas.
A14: E. Pajak & overhead | B14: Alokasi overhead kantor | C14: % dari harga | D14: 0 | E14: Belum diisi | F14: DISARANKAN 10-15% agar laba mencerminkan kontribusi nyata terhadap opex Rp20jt/bulan.
A15: C. Psikoedukasi | B15: Penyuluhan internal 30 menit (Kia & Rana) | C15: Rp / sesi | D15: 100000 | E15: Asumsi | F15: MURAH karena internal: narasumber Kia & Rana (gaji/opex), platform Zoom + YouTube Live Rp0, terbuka untuk umum. Rp100rb = materi ringkas & poster dari template.
A16: Parameter umum
B17: Harga reguler per sesi | C17: Rp / sesi | D17: 500000 | E17: Kia
B18: Sesi konseling per pegawai | C18: sesi | D18: 3 | E18: Asumsi praktik konseling singkat
B19: Masa paket | C19: bulan | D19: 3 | E19: Kia
B20: Biaya operasional bulanan Teman Journey | C20: Rp / bulan | D20: 20000000 | E20: Kia
B21: DP saat SPK | C21: % dari harga | D21: 0.5 | E21: Ketentuan proposal
B22: Nilai normal 1 putaran MHCU (untuk proposal) | C22: Rp | D22: 2500000 | E22: Nilai jual, bukan biaya
B23: Nilai normal laporan agregat (untuk proposal) | C23: Rp | D23: 2000000 | E23: Nilai jual, bukan biaya
B24: Nilai normal 1 sesi psikoedukasi (untuk proposal) | C24: Rp | D24: 3000000 | E24: Nilai jual, bukan biaya
B25: Standar margin bersih minimum | C25: % dari harga | D25: 0.15 | E25: Kebijakan Teman Journey
B26: Standar margin bersih maksimum / ideal | C26: % dari harga | D26: 0.26 | E26: Kebijakan Teman Journey
B27: Pembulatan harga rekomendasi | C27: Rp | D27: 500000 | E27: Dibulatkan ke atas
B28: Nilai normal 1 penyuluhan 30 menit (untuk proposal) | C28: Rp | D28: =D24/3 -> 1000000 | E28: 1/3 nilai 1 sesi psikoedukasi; nilai jual, bukan biaya

Sheet Desain Program
A1: DESAIN PROGRAM (isi per paket)
A2: Kuantitas layanan, harga jual, dan TARGET MARGIN bisa diatur per program.
A4: Bagian | B4: Parameter | C4: Satuan | D4: Jeda | E4: Jeda Tahunan (per term) | F4: Tumbuh | G4: Seperjalanan | H4: Penyuluhan (opsi 4)
A5: Harga & target | B5: Harga jual (proposal) | C5: Rp | D5: 12000000 | E5: 11000000 | F5: 20000000 | G5: 31500000 | H5: 23500000
A6: Harga & target | B6: Target margin bersih | C6: % dari harga | D6: 0.36 | E6: 0.2 | F6: 0.36 | G6: 0.36 | H6: 0.26
A7: Harga & target | B7: % sesi oleh psikolog berbayar | C7: % | D7: 1 | E7: 1 | F7: 1 | G7: 1 | H7: 1
A8: Layanan | B8: Jumlah sesi konseling | C8: sesi | D8: 15 | E8: 15 | F8: 24 | G8: 36 | H8: 36
A9: Layanan | B9: Pegawai terlayani | C9: orang | D9: =D8/'Input Tarif'!$D$18 -> 5 | E9: =E8/'Input Tarif'!$D$18 -> 5 | F9: =F8/'Input Tarif'!$D$18 -> 8 | G9: =G8/'Input Tarif'!$D$18 -> 12 | H9: =H8/'Input Tarif'!$D$18 -> 12
A10: Layanan | B10: Putaran MHCU | C10: putaran | D10: 0 | E10: 1 | F10: 1 | G10: 2 | H10: 2
A11: Layanan | B11: Laporan agregat (1=ya) | C11: flag | D11: 0 | E11: 1 | F11: 1 | G11: 1 | H11: 1
A12: Layanan | B12: Hasil MHCU individual (1=ya) | C12: flag | D12: 0 | E12: 0 | F12: 0 | G12: 1 | H12: 1
A13: Layanan | B13: Psikoedukasi online (webinar) | C13: sesi | D13: 1 | E13: 1 | F13: 1 | G13: 0 | H13: 0
A14: Layanan | B14: Psikoedukasi offline (seminar) | C14: sesi | D14: 0 | E14: 0 | F14: 0 | G14: 1 | H14: 0
A15: Layanan | B15: Penyuluhan internal gratis (30 menit, terbuka untuk umum) | C15: sesi | D15: 0 | E15: 0 | F15: 0 | G15: 0 | H15: 2
A17: Catatan: '% sesi oleh psikolog berbayar' = 100% berarti semua sesi dibayar honor (skenario konservatif). Isi 0% jika semua sesi dibawakan Vania/Kia (gaji tetap).
A18: Opsi 4 'Penyuluhan' = isi Seperjalanan tanpa seminar offline (tidak ada biaya perjalanan ke Sibolga), diganti 2 penyuluhan internal 30 menit yang gratis untuk BI dan terbuka untuk umum. Harga Rp23,5jt = harga ideal margin 26% (dibulatkan ke atas Rp500rb), di bawah nilai normal Rp27jt sehingga BI melihat penghematan; nilai penyuluhan tetap dihitung di Nilai normal.

Sheet Rincian Biaya
A1: RINCIAN BIAYA PER KATEGORI
A2: Biaya = kuantitas (Desain Program) x tarif (Input Tarif). Jangan ketik angka di sini.
A4: Kategori | B4: Komponen | C4: Dasar perhitungan | D4: Jeda | E4: Jeda Tahunan (per term) | F4: Tumbuh | G4: Seperjalanan | H4: Penyuluhan (opsi 4)
A5: A. Delivery konseling
B6: Honor psikolog | C6: sesi x % berbayar x tarif | D6: ='Desain Program'!D8*'Desain Program'!D7*'Input Tarif'!$D$5 -> 5250000 | E6: ='Desain Program'!E8*'Desain Program'!E7*'Input Tarif'!$D$5 -> 5250000 | F6: ='Desain Program'!F8*'Desain Program'!F7*'Input Tarif'!$D$5 -> 8400000 | G6: ='Desain Program'!G8*'Desain Program'!G7*'Input Tarif'!$D$5 -> 12600000 | H6: ='Desain Program'!H8*'Desain Program'!H7*'Input Tarif'!$D$5 -> 12600000
B7: Admin & platform | C7: sesi x tarif | D7: ='Desain Program'!D8*'Input Tarif'!$D$6 -> 525000 | E7: ='Desain Program'!E8*'Input Tarif'!$D$6 -> 525000 | F7: ='Desain Program'!F8*'Input Tarif'!$D$6 -> 840000 | G7: ='Desain Program'!G8*'Input Tarif'!$D$6 -> 1260000 | H7: ='Desain Program'!H8*'Input Tarif'!$D$6 -> 1260000
B8: Subtotal A. Delivery konseling | D8: =SUM(D6:D7) -> 5775000 | E8: =SUM(E6:E7) -> 5775000 | F8: =SUM(F6:F7) -> 9240000 | G8: =SUM(G6:G7) -> 13860000 | H8: =SUM(H6:H7) -> 13860000
A10: B. Asesmen
B11: MHCU | C11: putaran x pegawai x tarif | D11: ='Desain Program'!D10*'Desain Program'!D9*'Input Tarif'!$D$7 -> 0 | E11: ='Desain Program'!E10*'Desain Program'!E9*'Input Tarif'!$D$7 -> 350000 | F11: ='Desain Program'!F10*'Desain Program'!F9*'Input Tarif'!$D$7 -> 560000 | G11: ='Desain Program'!G10*'Desain Program'!G9*'Input Tarif'!$D$7 -> 1680000 | H11: ='Desain Program'!H10*'Desain Program'!H9*'Input Tarif'!$D$7 -> 1680000
B12: Laporan agregat | C12: flag x tarif | D12: ='Desain Program'!D11*'Input Tarif'!$D$8 -> 0 | E12: ='Desain Program'!E11*'Input Tarif'!$D$8 -> 750000 | F12: ='Desain Program'!F11*'Input Tarif'!$D$8 -> 750000 | G12: ='Desain Program'!G11*'Input Tarif'!$D$8 -> 750000 | H12: ='Desain Program'!H11*'Input Tarif'!$D$8 -> 750000
B13: Subtotal B. Asesmen | D13: =SUM(D11:D12) -> 0 | E13: =SUM(E11:E12) -> 1100000 | F13: =SUM(F11:F12) -> 1310000 | G13: =SUM(G11:G12) -> 2430000 | H13: =SUM(H11:H12) -> 2430000
A15: C. Psikoedukasi
B16: Webinar online | C16: sesi x tarif | D16: ='Desain Program'!D13*'Input Tarif'!$D$9 -> 1500000 | E16: ='Desain Program'!E13*'Input Tarif'!$D$9 -> 1500000 | F16: ='Desain Program'!F13*'Input Tarif'!$D$9 -> 1500000 | G16: ='Desain Program'!G13*'Input Tarif'!$D$9 -> 0 | H16: ='Desain Program'!H13*'Input Tarif'!$D$9 -> 0
B17: Seminar offline | C17: sesi x tarif | D17: ='Desain Program'!D14*'Input Tarif'!$D$10 -> 0 | E17: ='Desain Program'!E14*'Input Tarif'!$D$10 -> 0 | F17: ='Desain Program'!F14*'Input Tarif'!$D$10 -> 0 | G17: ='Desain Program'!G14*'Input Tarif'!$D$10 -> 3000000 | H17: ='Desain Program'!H14*'Input Tarif'!$D$10 -> 0
B18: Penyuluhan internal | C18: sesi x tarif | D18: ='Desain Program'!D15*'Input Tarif'!$D$15 -> 0 | E18: ='Desain Program'!E15*'Input Tarif'!$D$15 -> 0 | F18: ='Desain Program'!F15*'Input Tarif'!$D$15 -> 0 | G18: ='Desain Program'!G15*'Input Tarif'!$D$15 -> 0 | H18: ='Desain Program'!H15*'Input Tarif'!$D$15 -> 200000
B19: Subtotal C. Psikoedukasi | D19: =SUM(D16:D18) -> 1500000 | E19: =SUM(E16:E18) -> 1500000 | F19: =SUM(F16:F18) -> 1500000 | G19: =SUM(G16:G18) -> 3000000 | H19: =SUM(H16:H18) -> 200000
A20: D. Administrasi proyek
B21: PIC / Project Officer | C21: per program | D21: ='Input Tarif'!$D$11 -> 0 | E21: ='Input Tarif'!$D$11 -> 0 | F21: ='Input Tarif'!$D$11 -> 0 | G21: ='Input Tarif'!$D$11 -> 0 | H21: ='Input Tarif'!$D$11 -> 0
B22: Kontrak, materai, invoice | C22: per program | D22: ='Input Tarif'!$D$12 -> 150000 | E22: ='Input Tarif'!$D$12 -> 150000 | F22: ='Input Tarif'!$D$12 -> 150000 | G22: ='Input Tarif'!$D$12 -> 150000 | H22: ='Input Tarif'!$D$12 -> 150000
B23: Subtotal D. Administrasi proyek | D23: =SUM(D21:D22) -> 150000 | E23: =SUM(E21:E22) -> 150000 | F23: =SUM(F21:F22) -> 150000 | G23: =SUM(G21:G22) -> 150000 | H23: =SUM(H21:H22) -> 150000
A25: E. Pajak & overhead
B26: PPh 23 | C26: harga x % | D26: ='Desain Program'!D5*'Input Tarif'!$D$13 -> 240000 | E26: ='Desain Program'!E5*'Input Tarif'!$D$13 -> 220000 | F26: ='Desain Program'!F5*'Input Tarif'!$D$13 -> 400000 | G26: ='Desain Program'!G5*'Input Tarif'!$D$13 -> 630000 | H26: ='Desain Program'!H5*'Input Tarif'!$D$13 -> 470000
B27: Alokasi overhead | C27: harga x % | D27: ='Desain Program'!D5*'Input Tarif'!$D$14 -> 0 | E27: ='Desain Program'!E5*'Input Tarif'!$D$14 -> 0 | F27: ='Desain Program'!F5*'Input Tarif'!$D$14 -> 0 | G27: ='Desain Program'!G5*'Input Tarif'!$D$14 -> 0 | H27: ='Desain Program'!H5*'Input Tarif'!$D$14 -> 0
B28: Subtotal E. Pajak & overhead | D28: =SUM(D26:D27) -> 240000 | E28: =SUM(E26:E27) -> 220000 | F28: =SUM(F26:F27) -> 400000 | G28: =SUM(G26:G27) -> 630000 | H28: =SUM(H26:H27) -> 470000
B30: TOTAL BIAYA (A s/d E) | D30: =D8+D13+D19+D23+D28 -> 7665000 | E30: =E8+E13+E19+E23+E28 -> 8745000 | F30: =F8+F13+F19+F23+F28 -> 12600000 | G30: =G8+G13+G19+G23+G28 -> 20070000 | H30: =H8+H13+H19+H23+H28 -> 17110000
