Workbook

Sheet 1. Ringkasan Internal
A1: RINGKASAN INTERNAL - untuk keputusan (JANGAN dibagikan ke klien)
A2: Satu halaman: apakah harga sehat, berapa harga yang sebaiknya, dan apa dampaknya ke kas.
B4: Indikator | C4: Jeda | D4: Jeda Tahunan (per term) | E4: Tumbuh | F4: Seperjalanan | G4: Jeda tanpa psikoedukasi | H4: Jeda Tahunan tanpa psikoedukasi (per term) | I4: Tumbuh tanpa psikoedukasi | J4: Seperjalanan tanpa psikoedukasi
B5: APAKAH HARGA SEKARANG SEHAT?
B6: Harga sekarang | C6: ='Analisis Lengkap'!C6 -> 12000000 | D6: ='Analisis Lengkap'!D6 -> 11000000 | E6: ='Analisis Lengkap'!E6 -> 20000000 | F6: ='Analisis Lengkap'!F6 -> 31500000 | G6: ='Analisis Lengkap'!G6 -> 11500000 | H6: ='Analisis Lengkap'!H6 -> 10500000 | I6: ='Analisis Lengkap'!I6 -> 17500000 | J6: ='Analisis Lengkap'!J6 -> 28500000
B7: Total biaya | C7: ='Analisis Lengkap'!C15 -> 7665000 | D7: ='Analisis Lengkap'!D15 -> 8920000 | E7: ='Analisis Lengkap'!E15 -> 12880000 | F7: ='Analisis Lengkap'!F15 -> 20910000 | G7: ='Analisis Lengkap'!G15 -> 6155000 | H7: ='Analisis Lengkap'!H15 -> 7410000 | I7: ='Analisis Lengkap'!I15 -> 11330000 | J7: ='Analisis Lengkap'!J15 -> 17850000
B8: Laba bersih | C8: ='Analisis Lengkap'!C18 -> 4335000 | D8: ='Analisis Lengkap'!D18 -> 2080000 | E8: ='Analisis Lengkap'!E18 -> 7120000 | F8: ='Analisis Lengkap'!F18 -> 10590000 | G8: ='Analisis Lengkap'!G18 -> 5345000 | H8: ='Analisis Lengkap'!H18 -> 3090000 | I8: ='Analisis Lengkap'!I18 -> 6170000 | J8: ='Analisis Lengkap'!J18 -> 10650000
B9: Margin bersih | C9: ='Analisis Lengkap'!C19 -> 0.36125 | D9: ='Analisis Lengkap'!D19 -> 0.18909091 | E9: ='Analisis Lengkap'!E19 -> 0.356 | F9: ='Analisis Lengkap'!F19 -> 0.33619048 | G9: ='Analisis Lengkap'!G19 -> 0.46478261 | H9: ='Analisis Lengkap'!H19 -> 0.29428571 | I9: ='Analisis Lengkap'!I19 -> 0.35257143 | J9: ='Analisis Lengkap'!J19 -> 0.37368421
B10: Posisi vs standar 15%-26% | C10: =IF('Analisis Lengkap'!C19<'Input Tarif'!$D$25,"Di bawah minimum",IF('Analisis Lengkap'!C19<='Input Tarif'!$D$26,"Dalam rentang sehat","Di atas ideal")) -> Di atas ideal | D10: =IF('Analisis Lengkap'!D19<'Input Tarif'!$D$25,"Di bawah minimum",IF('Analisis Lengkap'!D19<='Input Tarif'!$D$26,"Dalam rentang sehat","Di atas ideal")) -> Dalam rentang sehat | E10: =IF('Analisis Lengkap'!E19<'Input Tarif'!$D$25,"Di bawah minimum",IF('Analisis Lengkap'!E19<='Input Tarif'!$D$26,"Dalam rentang sehat","Di atas ideal")) -> Di atas ideal | F10: =IF('Analisis Lengkap'!F19<'Input Tarif'!$D$25,"Di bawah minimum",IF('Analisis Lengkap'!F19<='Input Tarif'!$D$26,"Dalam rentang sehat","Di atas ideal")) -> Di atas ideal | G10: =IF('Analisis Lengkap'!G19<'Input Tarif'!$D$25,"Di bawah minimum",IF('Analisis Lengkap'!G19<='Input Tarif'!$D$26,"Dalam rentang sehat","Di atas ideal")) -> Di atas ideal | H10: =IF('Analisis Lengkap'!H19<'Input Tarif'!$D$25,"Di bawah minimum",IF('Analisis Lengkap'!H19<='Input Tarif'!$D$26,"Dalam rentang sehat","Di atas ideal")) -> Di atas ideal | I10: =IF('Analisis Lengkap'!I19<'Input Tarif'!$D$25,"Di bawah minimum",IF('Analisis Lengkap'!I19<='Input Tarif'!$D$26,"Dalam rentang sehat","Di atas ideal")) -> Di atas ideal | J10: =IF('Analisis Lengkap'!J19<'Input Tarif'!$D$25,"Di bawah minimum",IF('Analisis Lengkap'!J19<='Input Tarif'!$D$26,"Dalam rentang sehat","Di atas ideal")) -> Di atas ideal
B11: BERAPA HARGA YANG SEBAIKNYA?
B12: Harga minimum (15%) | C12: ='Analisis Lengkap'!C33 -> 9000000 | D12: ='Analisis Lengkap'!D33 -> 10500000 | E12: ='Analisis Lengkap'!E33 -> 15500000 | F12: ='Analisis Lengkap'!F33 -> 24500000 | G12: ='Analisis Lengkap'!G33 -> 7500000 | H12: ='Analisis Lengkap'!H33 -> 9000000 | I12: ='Analisis Lengkap'!I33 -> 13500000 | J12: ='Analisis Lengkap'!J33 -> 21000000
B13: Harga ideal (26%) | C13: ='Analisis Lengkap'!C34 -> 10500000 | D13: ='Analisis Lengkap'!D34 -> 12500000 | E13: ='Analisis Lengkap'!E34 -> 17500000 | F13: ='Analisis Lengkap'!F34 -> 28500000 | G13: ='Analisis Lengkap'!G34 -> 8500000 | H13: ='Analisis Lengkap'!H34 -> 10000000 | I13: ='Analisis Lengkap'!I34 -> 15500000 | J13: ='Analisis Lengkap'!J34 -> 24000000
B14: Harga margin 36% (pembanding) | C14: ='Analisis Lengkap'!C43 -> 12000000 | D14: ='Analisis Lengkap'!D43 -> 14500000 | E14: ='Analisis Lengkap'!E43 -> 20500000 | F14: ='Analisis Lengkap'!F43 -> 33000000 | G14: ='Analisis Lengkap'!G43 -> 10000000 | H14: ='Analisis Lengkap'!H43 -> 12000000 | I14: ='Analisis Lengkap'!I43 -> 18000000 | J14: ='Analisis Lengkap'!J43 -> 28000000
B15: Harga rekomendasi | C15: ='Analisis Lengkap'!C36 -> 12000000 | D15: ='Analisis Lengkap'!D36 -> 11500000 | E15: ='Analisis Lengkap'!E36 -> 20000000 | F15: ='Analisis Lengkap'!F36 -> 31500000 | G15: ='Analisis Lengkap'!G36 -> 11500000 | H15: ='Analisis Lengkap'!H36 -> 10500000 | I15: ='Analisis Lengkap'!I36 -> 17500000 | J15: ='Analisis Lengkap'!J36 -> 28500000
B16: Kenaikan yang dibutuhkan | C16: ='Analisis Lengkap'!C37 -> 0 | D16: ='Analisis Lengkap'!D37 -> 500000 | E16: ='Analisis Lengkap'!E37 -> 0 | F16: ='Analisis Lengkap'!F37 -> 0 | G16: ='Analisis Lengkap'!G37 -> 0 | H16: ='Analisis Lengkap'!H37 -> 0 | I16: ='Analisis Lengkap'!I37 -> 0 | J16: ='Analisis Lengkap'!J37 -> 0
B17: Laba bersih di harga rekomendasi | C17: ='Analisis Lengkap'!C39 -> 4335000 | D17: ='Analisis Lengkap'!D39 -> 2570000 | E17: ='Analisis Lengkap'!E39 -> 7120000 | F17: ='Analisis Lengkap'!F39 -> 10590000 | G17: ='Analisis Lengkap'!G39 -> 5345000 | H17: ='Analisis Lengkap'!H39 -> 3090000 | I17: ='Analisis Lengkap'!I39 -> 6170000 | J17: ='Analisis Lengkap'!J39 -> 10650000
B18: Atau: hemat biaya (tanpa naik harga) utk 15% | C18: ='Analisis Lengkap'!C41 -> 0 | D18: ='Analisis Lengkap'!D41 -> 0 | E18: ='Analisis Lengkap'!E41 -> 0 | F18: ='Analisis Lengkap'!F41 -> 0 | G18: ='Analisis Lengkap'!G41 -> 0 | H18: ='Analisis Lengkap'!H41 -> 0 | I18: ='Analisis Lengkap'!I41 -> 0 | J18: ='Analisis Lengkap'!J41 -> 0
B19: DAMPAK KE KAS & OPERASIONAL
B20: Kas masuk saat SPK (DP, setelah PPh) | C20: ='Analisis Lengkap'!C26 -> 5880000 | D20: ='Analisis Lengkap'!D26 -> 5390000 | E20: ='Analisis Lengkap'!E26 -> 9800000 | F20: ='Analisis Lengkap'!F26 -> 15435000 | G20: ='Analisis Lengkap'!G26 -> 5635000 | H20: ='Analisis Lengkap'!H26 -> 5145000 | I20: ='Analisis Lengkap'!I26 -> 8575000 | J20: ='Analisis Lengkap'!J26 -> 13965000
B21: Laba per bulan (harga sekarang) | C21: ='Analisis Lengkap'!C27 -> 1445000 | D21: ='Analisis Lengkap'!D27 -> 693333.33 | E21: ='Analisis Lengkap'!E27 -> 2373333.3 | F21: ='Analisis Lengkap'!F27 -> 3530000 | G21: ='Analisis Lengkap'!G27 -> 1781666.7 | H21: ='Analisis Lengkap'!H27 -> 1030000 | I21: ='Analisis Lengkap'!I27 -> 2056666.7 | J21: ='Analisis Lengkap'!J27 -> 3550000
B22: % opex 3 bulan yang tertutup | C22: ='Analisis Lengkap'!C28 -> 0.07225 | D22: ='Analisis Lengkap'!D28 -> 0.034666667 | E22: ='Analisis Lengkap'!E28 -> 0.11866667 | F22: ='Analisis Lengkap'!F28 -> 0.1765 | G22: ='Analisis Lengkap'!G28 -> 0.089083333 | H22: ='Analisis Lengkap'!H28 -> 0.0515 | I22: ='Analisis Lengkap'!I28 -> 0.10283333 | J22: ='Analisis Lengkap'!J28 -> 0.1775
B23: Laba jika semua sesi oleh Vania/Kia | C23: ='Analisis Lengkap'!C24 -> 9585000 | D23: ='Analisis Lengkap'!D24 -> 7330000 | E23: ='Analisis Lengkap'!E24 -> 15520000 | F23: ='Analisis Lengkap'!F24 -> 23190000 | G23: ='Analisis Lengkap'!G24 -> 10595000 | H23: ='Analisis Lengkap'!H24 -> 8340000 | I23: ='Analisis Lengkap'!I24 -> 14570000 | J23: ='Analisis Lengkap'!J24 -> 23250000
B24: KEPUTUSAN
B25: Rekomendasi | C25: ='Analisis Lengkap'!C42 -> Harga sekarang sudah sehat - pertahankan | D25: ='Analisis Lengkap'!D42 -> Naikkan Rp500000,0 (jadi Rp11500000,0), atau hemat biaya Rp,0 untuk minimal 15% | E25: ='Analisis Lengkap'!E42 -> Harga sekarang sudah sehat - pertahankan | F25: ='Analisis Lengkap'!F42 -> Harga sekarang sudah sehat - pertahankan | G25: ='Analisis Lengkap'!G42 -> Harga sekarang sudah sehat - pertahankan | H25: ='Analisis Lengkap'!H42 -> Harga sekarang sudah sehat - pertahankan | I25: ='Analisis Lengkap'!I42 -> Harga sekarang sudah sehat - pertahankan | J25: ='Analisis Lengkap'!J42 -> Harga sekarang sudah sehat - pertahankan
B27: Cara baca: merah = harga belum menutup standar minimum margin 15%. Ikuti baris 'Harga rekomendasi', atau hemat biaya sebesar angka di bawahnya.
B28: Angka di sini otomatis mengikuti 'Analisis Lengkap'. Ubah tarif di 'Input Tarif' dan kuantitas/harga/target di 'Desain Program'.

Sheet 2. Ringkasan Klien
A1: Welcoming Package - Employee Wellbeing Program
A2: Bank Indonesia KPw Sibolga | PT Indo Medika Resolusi (Teman Journey) | Dapat dibagikan ke klien
B4: Yang Anda dapatkan | C4: Paket Jeda | D4: Paket Jeda Tahunan (per term) | E4: Paket Tumbuh | F4: Paket Seperjalanan | G4: Paket Jeda tanpa psikoedukasi | H4: Paket Jeda Tahunan tanpa psikoedukasi (per term) | I4: Paket Tumbuh tanpa psikoedukasi | J4: Paket Seperjalanan tanpa psikoedukasi
B5: LAYANAN
B6: Konseling psikologi online (60 menit) | C6: ='Desain Program'!D8&" sesi" -> 15 sesi | D6: ='Desain Program'!E8&" sesi" -> 15 sesi | E6: ='Desain Program'!F8&" sesi" -> 24 sesi | F6: ='Desain Program'!G8&" sesi" -> 36 sesi | G6: ='Desain Program'!H8&" sesi" -> 15 sesi | H6: ='Desain Program'!I8&" sesi" -> 15 sesi | I6: ='Desain Program'!J8&" sesi" -> 24 sesi | J6: ='Desain Program'!K8&" sesi" -> 36 sesi
B7: Perkiraan pegawai terlayani | C7: ="± "&TEXT('Desain Program'!D9,"0")&" pegawai (3 sesi/orang)" -> ± 5 pegawai (3 sesi/orang) | D7: ="± "&TEXT('Desain Program'!E9,"0")&" pegawai (3 sesi/orang)" -> ± 5 pegawai (3 sesi/orang) | E7: ="± "&TEXT('Desain Program'!F9,"0")&" pegawai (3 sesi/orang)" -> ± 8 pegawai (3 sesi/orang) | F7: ="± "&TEXT('Desain Program'!G9,"0")&" pegawai (3 sesi/orang)" -> ± 12 pegawai (3 sesi/orang) | G7: ="± "&TEXT('Desain Program'!H9,"0")&" pegawai (3 sesi/orang)" -> ± 5 pegawai (3 sesi/orang) | H7: ="± "&TEXT('Desain Program'!I9,"0")&" pegawai (3 sesi/orang)" -> ± 5 pegawai (3 sesi/orang) | I7: ="± "&TEXT('Desain Program'!J9,"0")&" pegawai (3 sesi/orang)" -> ± 8 pegawai (3 sesi/orang) | J7: ="± "&TEXT('Desain Program'!K9,"0")&" pegawai (3 sesi/orang)" -> ± 12 pegawai (3 sesi/orang)
B8: Mental Health Check-Up (MHCU) | C8: =IF('Desain Program'!D10=0,"-",'Desain Program'!D10&"x ("&IF('Desain Program'!D10>=2,"pre & post","baseline")&") untuk setiap pegawai yang konseling") -> - | D8: =IF('Desain Program'!E10=0,"-",'Desain Program'!E10&"x ("&IF('Desain Program'!E10>=2,"pre & post","baseline")&") untuk setiap pegawai yang konseling") -> 1x (baseline) untuk setiap pegawai yang konseling | E8: =IF('Desain Program'!F10=0,"-",'Desain Program'!F10&"x ("&IF('Desain Program'!F10>=2,"pre & post","baseline")&") untuk setiap pegawai yang konseling") -> 1x (baseline) untuk setiap pegawai yang konseling | F8: =IF('Desain Program'!G10=0,"-",'Desain Program'!G10&"x ("&IF('Desain Program'!G10>=2,"pre & post","baseline")&") untuk setiap pegawai yang konseling") -> 2x (pre & post) untuk setiap pegawai yang konseling | G8: =IF('Desain Program'!H10=0,"-",'Desain Program'!H10&"x ("&IF('Desain Program'!H10>=2,"pre & post","baseline")&") untuk setiap pegawai yang konseling") -> - | H8: =IF('Desain Program'!I10=0,"-",'Desain Program'!I10&"x ("&IF('Desain Program'!I10>=2,"pre & post","baseline")&") untuk setiap pegawai yang konseling") -> 1x (baseline) untuk setiap pegawai yang konseling | I8: =IF('Desain Program'!J10=0,"-",'Desain Program'!J10&"x ("&IF('Desain Program'!J10>=2,"pre & post","baseline")&") untuk setiap pegawai yang konseling") -> 1x (baseline) untuk setiap pegawai yang konseling | J8: =IF('Desain Program'!K10=0,"-",'Desain Program'!K10&"x ("&IF('Desain Program'!K10>=2,"pre & post","baseline")&") untuk setiap pegawai yang konseling") -> 2x (pre & post) untuk setiap pegawai yang konseling
B9: Laporan agregat anonim untuk manajemen | C9: =IF('Desain Program'!D11=1,IF('Desain Program'!D10>=2,"Ya, dengan perbandingan pre/post","Ya"),"-") -> - | D9: =IF('Desain Program'!E11=1,IF('Desain Program'!E10>=2,"Ya, dengan perbandingan pre/post","Ya"),"-") -> Ya | E9: =IF('Desain Program'!F11=1,IF('Desain Program'!F10>=2,"Ya, dengan perbandingan pre/post","Ya"),"-") -> Ya | F9: =IF('Desain Program'!G11=1,IF('Desain Program'!G10>=2,"Ya, dengan perbandingan pre/post","Ya"),"-") -> Ya, dengan perbandingan pre/post | G9: =IF('Desain Program'!H11=1,IF('Desain Program'!H10>=2,"Ya, dengan perbandingan pre/post","Ya"),"-") -> - | H9: =IF('Desain Program'!I11=1,IF('Desain Program'!I10>=2,"Ya, dengan perbandingan pre/post","Ya"),"-") -> Ya | I9: =IF('Desain Program'!J11=1,IF('Desain Program'!J10>=2,"Ya, dengan perbandingan pre/post","Ya"),"-") -> Ya | J9: =IF('Desain Program'!K11=1,IF('Desain Program'!K10>=2,"Ya, dengan perbandingan pre/post","Ya"),"-") -> Ya, dengan perbandingan pre/post
B10: Hasil MHCU individual untuk pegawai | C10: =IF('Desain Program'!D12=1,"Ya","-") -> - | D10: =IF('Desain Program'!E12=1,"Ya","-") -> - | E10: =IF('Desain Program'!F12=1,"Ya","-") -> - | F10: =IF('Desain Program'!G12=1,"Ya","-") -> Ya | G10: =IF('Desain Program'!H12=1,"Ya","-") -> - | H10: =IF('Desain Program'!I12=1,"Ya","-") -> - | I10: =IF('Desain Program'!J12=1,"Ya","-") -> - | J10: =IF('Desain Program'!K12=1,"Ya","-") -> Ya
B11: Psikoedukasi oleh psikolog | C11: =IF('Desain Program'!D14>0,'Desain Program'!D14&" seminar offline",IF('Desain Program'!D13>0,'Desain Program'!D13&" webinar online","-")) -> 1 webinar online | D11: =IF('Desain Program'!E14>0,'Desain Program'!E14&" seminar offline",IF('Desain Program'!E13>0,'Desain Program'!E13&" webinar online","-")) -> 1 webinar online | E11: =IF('Desain Program'!F14>0,'Desain Program'!F14&" seminar offline",IF('Desain Program'!F13>0,'Desain Program'!F13&" webinar online","-")) -> 1 webinar online | F11: =IF('Desain Program'!G14>0,'Desain Program'!G14&" seminar offline",IF('Desain Program'!G13>0,'Desain Program'!G13&" webinar online","-")) -> 1 seminar offline | G11: =IF('Desain Program'!H14>0,'Desain Program'!H14&" seminar offline",IF('Desain Program'!H13>0,'Desain Program'!H13&" webinar online","-")) -> - | H11: =IF('Desain Program'!I14>0,'Desain Program'!I14&" seminar offline",IF('Desain Program'!I13>0,'Desain Program'!I13&" webinar online","-")) -> - | I11: =IF('Desain Program'!J14>0,'Desain Program'!J14&" seminar offline",IF('Desain Program'!J13>0,'Desain Program'!J13&" webinar online","-")) -> - | J11: =IF('Desain Program'!K14>0,'Desain Program'!K14&" seminar offline",IF('Desain Program'!K13>0,'Desain Program'!K13&" webinar online","-")) -> -
B12: Masa berlaku | C12: ='Input Tarif'!$D$19&" bulan sejak SPK" -> 3 bulan sejak SPK | D12: ="Kuota per "&'Input Tarif'!$D$19&" bulan, kontrak 1 tahun (4 term)" -> Kuota per 3 bulan, kontrak 1 tahun (4 term) | E12: ='Input Tarif'!$D$19&" bulan sejak SPK" -> 3 bulan sejak SPK | F12: ='Input Tarif'!$D$19&" bulan sejak SPK" -> 3 bulan sejak SPK | G12: ='Input Tarif'!$D$19&" bulan sejak SPK" -> 3 bulan sejak SPK | H12: ="Kuota per "&'Input Tarif'!$D$19&" bulan, kontrak 1 tahun (4 term)" -> Kuota per 3 bulan, kontrak 1 tahun (4 term) | I12: ='Input Tarif'!$D$19&" bulan sejak SPK" -> 3 bulan sejak SPK | J12: ='Input Tarif'!$D$19&" bulan sejak SPK" -> 3 bulan sejak SPK
B13: INVESTASI
B14: Nilai layanan (harga reguler) | C14: =IF('Analisis Lengkap'!C30>'Analisis Lengkap'!C6,'Analisis Lengkap'!C30,"-") -> - | D14: =IF('Analisis Lengkap'!D30>'Analisis Lengkap'!D6,'Analisis Lengkap'!D30,"-") -> 15000000 | E14: =IF('Analisis Lengkap'!E30>'Analisis Lengkap'!E6,'Analisis Lengkap'!E30,"-") -> - | F14: =IF('Analisis Lengkap'!F30>'Analisis Lengkap'!F6,'Analisis Lengkap'!F30,"-") -> - | G14: =IF('Analisis Lengkap'!G30>'Analisis Lengkap'!G6,'Analisis Lengkap'!G30,"-") -> - | H14: =IF('Analisis Lengkap'!H30>'Analisis Lengkap'!H6,'Analisis Lengkap'!H30,"-") -> 12000000 | I14: =IF('Analisis Lengkap'!I30>'Analisis Lengkap'!I6,'Analisis Lengkap'!I30,"-") -> - | J14: =IF('Analisis Lengkap'!J30>'Analisis Lengkap'!J6,'Analisis Lengkap'!J30,"-") -> -
B15: Harga Welcoming Package | C15: ='Analisis Lengkap'!C6 -> 12000000 | D15: ='Analisis Lengkap'!D6 -> 11000000 | E15: ='Analisis Lengkap'!E6 -> 20000000 | F15: ='Analisis Lengkap'!F6 -> 31500000 | G15: ='Analisis Lengkap'!G6 -> 11500000 | H15: ='Analisis Lengkap'!H6 -> 10500000 | I15: ='Analisis Lengkap'!I6 -> 17500000 | J15: ='Analisis Lengkap'!J6 -> 28500000
B16: Anda hemat | C16: =IF('Analisis Lengkap'!C30-'Analisis Lengkap'!C6>0,"Rp"&TEXT('Analisis Lengkap'!C30-'Analisis Lengkap'!C6,"#,##0")&" ("&TEXT(1-'Analisis Lengkap'!C6/'Analisis Lengkap'!C30,"0%")&")","-") -> - | D16: =IF('Analisis Lengkap'!D30-'Analisis Lengkap'!D6>0,"Rp"&TEXT('Analisis Lengkap'!D30-'Analisis Lengkap'!D6,"#,##0")&" ("&TEXT(1-'Analisis Lengkap'!D6/'Analisis Lengkap'!D30,"0%")&")","-") -> Rp4000000,0 (27%) | E16: =IF('Analisis Lengkap'!E30-'Analisis Lengkap'!E6>0,"Rp"&TEXT('Analisis Lengkap'!E30-'Analisis Lengkap'!E6,"#,##0")&" ("&TEXT(1-'Analisis Lengkap'!E6/'Analisis Lengkap'!E30,"0%")&")","-") -> - | F16: =IF('Analisis Lengkap'!F30-'Analisis Lengkap'!F6>0,"Rp"&TEXT('Analisis Lengkap'!F30-'Analisis Lengkap'!F6,"#,##0")&" ("&TEXT(1-'Analisis Lengkap'!F6/'Analisis Lengkap'!F30,"0%")&")","-") -> - | G16: =IF('Analisis Lengkap'!G30-'Analisis Lengkap'!G6>0,"Rp"&TEXT('Analisis Lengkap'!G30-'Analisis Lengkap'!G6,"#,##0")&" ("&TEXT(1-'Analisis Lengkap'!G6/'Analisis Lengkap'!G30,"0%")&")","-") -> - | H16: =IF('Analisis Lengkap'!H30-'Analisis Lengkap'!H6>0,"Rp"&TEXT('Analisis Lengkap'!H30-'Analisis Lengkap'!H6,"#,##0")&" ("&TEXT(1-'Analisis Lengkap'!H6/'Analisis Lengkap'!H30,"0%")&")","-") -> Rp1500000,0 (13%) | I16: =IF('Analisis Lengkap'!I30-'Analisis Lengkap'!I6>0,"Rp"&TEXT('Analisis Lengkap'!I30-'Analisis Lengkap'!I6,"#,##0")&" ("&TEXT(1-'Analisis Lengkap'!I6/'Analisis Lengkap'!I30,"0%")&")","-") -> - | J16: =IF('Analisis Lengkap'!J30-'Analisis Lengkap'!J6>0,"Rp"&TEXT('Analisis Lengkap'!J30-'Analisis Lengkap'!J6,"#,##0")&" ("&TEXT(1-'Analisis Lengkap'!J6/'Analisis Lengkap'!J30,"0%")&")","-") -> -
B17: Setara per bulan | C17: ='Analisis Lengkap'!C7 -> 4000000 | D17: ='Analisis Lengkap'!D7 -> 3666666.7 | E17: ='Analisis Lengkap'!E7 -> 6666666.7 | F17: ='Analisis Lengkap'!F7 -> 10500000 | G17: ='Analisis Lengkap'!G7 -> 3833333.3 | H17: ='Analisis Lengkap'!H7 -> 3500000 | I17: ='Analisis Lengkap'!I7 -> 5833333.3 | J17: ='Analisis Lengkap'!J7 -> 9500000
B18: Setara per pegawai | C18: ='Analisis Lengkap'!C6/'Desain Program'!D9 -> 2400000 | D18: ='Analisis Lengkap'!D6/'Desain Program'!E9 -> 2200000 | E18: ='Analisis Lengkap'!E6/'Desain Program'!F9 -> 2500000 | F18: ='Analisis Lengkap'!F6/'Desain Program'!G9 -> 2625000 | G18: ='Analisis Lengkap'!G6/'Desain Program'!H9 -> 2300000 | H18: ='Analisis Lengkap'!H6/'Desain Program'!I9 -> 2100000 | I18: ='Analisis Lengkap'!I6/'Desain Program'!J9 -> 2187500 | J18: ='Analisis Lengkap'!J6/'Desain Program'!K9 -> 2375000
B20: KETENTUAN
B21: Batas penandatanganan SPK | C21: 31 Oktober 2026
B22: Pembayaran | C22: ="Paket 3 bulan: DP "&TEXT('Input Tarif'!$D$21,"0%")&" saat SPK, pelunasan setelah laporan akhir. Jeda Tahunan: 2x per semester (Rp22.000.000 di awal tiap semester, total Rp44.000.000/tahun)" -> Paket 3 bulan: DP 50% saat SPK, pelunasan setelah laporan akhir. Jeda Tahunan: 2x per semester (Rp22.000.000 di awal tiap semester, total Rp44.000.000/tahun)
B23: Pajak | C23: Teman Journey non-PKP (tanpa PPN); PPh 23 dipotong oleh pemberi kerja
B24: Sesi tambahan | C24: ="Rp"&TEXT('Input Tarif'!$D$17,"#,##0")&" per sesi" -> Rp500000,0 per sesi
B25: Kerahasiaan | C25: Manajemen hanya menerima data agregat anonim. Hasil MHCU individual (Seperjalanan) hanya diberikan ke pegawai yang bersangkutan
B26: Penyelenggara | C26: PT Indo Medika Resolusi (Teman Journey) - info@temanjourney.id

Sheet Analisis Lengkap
A1: ANALISIS LENGKAP - BI KPw Sibolga (INTERNAL)
A2: Margin = laba bersih / harga jual. Target margin diatur di sheet 'Desain Program'.
B4: Indikator | C4: Jeda | D4: Jeda Tahunan (per term) | E4: Tumbuh | F4: Seperjalanan | G4: Jeda tanpa psikoedukasi | H4: Jeda Tahunan tanpa psikoedukasi (per term) | I4: Tumbuh tanpa psikoedukasi | J4: Seperjalanan tanpa psikoedukasi
B5: HARGA
B6: Harga jual | C6: ='Desain Program'!D5 -> 12000000 | D6: ='Desain Program'!E5 -> 11000000 | E6: ='Desain Program'!F5 -> 20000000 | F6: ='Desain Program'!G5 -> 31500000 | G6: ='Desain Program'!H5 -> 11500000 | H6: ='Desain Program'!I5 -> 10500000 | I6: ='Desain Program'!J5 -> 17500000 | J6: ='Desain Program'!K5 -> 28500000
B7: Setara per bulan | C7: ='Desain Program'!D5/'Input Tarif'!$D$19 -> 4000000 | D7: ='Desain Program'!E5/'Input Tarif'!$D$19 -> 3666666.7 | E7: ='Desain Program'!F5/'Input Tarif'!$D$19 -> 6666666.7 | F7: ='Desain Program'!G5/'Input Tarif'!$D$19 -> 10500000 | G7: ='Desain Program'!H5/'Input Tarif'!$D$19 -> 3833333.3 | H7: ='Desain Program'!I5/'Input Tarif'!$D$19 -> 3500000 | I7: ='Desain Program'!J5/'Input Tarif'!$D$19 -> 5833333.3 | J7: ='Desain Program'!K5/'Input Tarif'!$D$19 -> 9500000
B8: Jumlah sesi / pegawai terlayani | C8: =TEXT('Desain Program'!D8,"0")&" sesi / "&TEXT('Desain Program'!D9,"0")&" org" -> 15 sesi / 5 org | D8: =TEXT('Desain Program'!E8,"0")&" sesi / "&TEXT('Desain Program'!E9,"0")&" org" -> 15 sesi / 5 org | E8: =TEXT('Desain Program'!F8,"0")&" sesi / "&TEXT('Desain Program'!F9,"0")&" org" -> 24 sesi / 8 org | F8: =TEXT('Desain Program'!G8,"0")&" sesi / "&TEXT('Desain Program'!G9,"0")&" org" -> 36 sesi / 12 org | G8: =TEXT('Desain Program'!H8,"0")&" sesi / "&TEXT('Desain Program'!H9,"0")&" org" -> 15 sesi / 5 org | H8: =TEXT('Desain Program'!I8,"0")&" sesi / "&TEXT('Desain Program'!I9,"0")&" org" -> 15 sesi / 5 org | I8: =TEXT('Desain Program'!J8,"0")&" sesi / "&TEXT('Desain Program'!J9,"0")&" org" -> 24 sesi / 8 org | J8: =TEXT('Desain Program'!K8,"0")&" sesi / "&TEXT('Desain Program'!K9,"0")&" org" -> 36 sesi / 12 org
B9: BIAYA PER KATEGORI
B10: A. Delivery konseling | C10: ='Rincian Biaya'!D8 -> 5775000 | D10: ='Rincian Biaya'!E8 -> 5775000 | E10: ='Rincian Biaya'!F8 -> 9240000 | F10: ='Rincian Biaya'!G8 -> 13860000 | G10: ='Rincian Biaya'!H8 -> 5775000 | H10: ='Rincian Biaya'!I8 -> 5775000 | I10: ='Rincian Biaya'!J8 -> 9240000 | J10: ='Rincian Biaya'!K8 -> 13860000
B11: B. Asesmen | C11: ='Rincian Biaya'!D13 -> 0 | D11: ='Rincian Biaya'!E13 -> 1275000 | E11: ='Rincian Biaya'!F13 -> 1590000 | F11: ='Rincian Biaya'!G13 -> 3270000 | G11: ='Rincian Biaya'!H13 -> 0 | H11: ='Rincian Biaya'!I13 -> 1275000 | I11: ='Rincian Biaya'!J13 -> 1590000 | J11: ='Rincian Biaya'!K13 -> 3270000
B12: C. Psikoedukasi | C12: ='Rincian Biaya'!D18 -> 1500000 | D12: ='Rincian Biaya'!E18 -> 1500000 | E12: ='Rincian Biaya'!F18 -> 1500000 | F12: ='Rincian Biaya'!G18 -> 3000000 | G12: ='Rincian Biaya'!H18 -> 0 | H12: ='Rincian Biaya'!I18 -> 0 | I12: ='Rincian Biaya'!J18 -> 0 | J12: ='Rincian Biaya'!K18 -> 0
B13: D. Administrasi proyek | C13: ='Rincian Biaya'!D23 -> 150000 | D13: ='Rincian Biaya'!E23 -> 150000 | E13: ='Rincian Biaya'!F23 -> 150000 | F13: ='Rincian Biaya'!G23 -> 150000 | G13: ='Rincian Biaya'!H23 -> 150000 | H13: ='Rincian Biaya'!I23 -> 150000 | I13: ='Rincian Biaya'!J23 -> 150000 | J13: ='Rincian Biaya'!K23 -> 150000
B14: E. Pajak & overhead | C14: ='Rincian Biaya'!D28 -> 240000 | D14: ='Rincian Biaya'!E28 -> 220000 | E14: ='Rincian Biaya'!F28 -> 400000 | F14: ='Rincian Biaya'!G28 -> 630000 | G14: ='Rincian Biaya'!H28 -> 230000 | H14: ='Rincian Biaya'!I28 -> 210000 | I14: ='Rincian Biaya'!J28 -> 350000 | J14: ='Rincian Biaya'!K28 -> 570000
B15: Total biaya | C15: ='Rincian Biaya'!D30 -> 7665000 | D15: ='Rincian Biaya'!E30 -> 8920000 | E15: ='Rincian Biaya'!F30 -> 12880000 | F15: ='Rincian Biaya'!G30 -> 20910000 | G15: ='Rincian Biaya'!H30 -> 6155000 | H15: ='Rincian Biaya'!I30 -> 7410000 | I15: ='Rincian Biaya'!J30 -> 11330000 | J15: ='Rincian Biaya'!K30 -> 17850000
B16: Biaya sebagai % harga | C16: =IF('Desain Program'!D5=0,0,'Rincian Biaya'!D30/'Desain Program'!D5) -> 0.63875 | D16: =IF('Desain Program'!E5=0,0,'Rincian Biaya'!E30/'Desain Program'!E5) -> 0.81090909 | E16: =IF('Desain Program'!F5=0,0,'Rincian Biaya'!F30/'Desain Program'!F5) -> 0.644 | F16: =IF('Desain Program'!G5=0,0,'Rincian Biaya'!G30/'Desain Program'!G5) -> 0.66380952 | G16: =IF('Desain Program'!H5=0,0,'Rincian Biaya'!H30/'Desain Program'!H5) -> 0.53521739 | H16: =IF('Desain Program'!I5=0,0,'Rincian Biaya'!I30/'Desain Program'!I5) -> 0.70571429 | I16: =IF('Desain Program'!J5=0,0,'Rincian Biaya'!J30/'Desain Program'!J5) -> 0.64742857 | J16: =IF('Desain Program'!K5=0,0,'Rincian Biaya'!K30/'Desain Program'!K5) -> 0.62631579
B17: LABA & MARGIN
B18: Laba bersih | C18: ='Desain Program'!D5-'Rincian Biaya'!D30 -> 4335000 | D18: ='Desain Program'!E5-'Rincian Biaya'!E30 -> 2080000 | E18: ='Desain Program'!F5-'Rincian Biaya'!F30 -> 7120000 | F18: ='Desain Program'!G5-'Rincian Biaya'!G30 -> 10590000 | G18: ='Desain Program'!H5-'Rincian Biaya'!H30 -> 5345000 | H18: ='Desain Program'!I5-'Rincian Biaya'!I30 -> 3090000 | I18: ='Desain Program'!J5-'Rincian Biaya'!J30 -> 6170000 | J18: ='Desain Program'!K5-'Rincian Biaya'!K30 -> 10650000
B19: Margin bersih aktual | C19: =IF('Desain Program'!D5=0,0,('Desain Program'!D5-'Rincian Biaya'!D30)/'Desain Program'!D5) -> 0.36125 | D19: =IF('Desain Program'!E5=0,0,('Desain Program'!E5-'Rincian Biaya'!E30)/'Desain Program'!E5) -> 0.18909091 | E19: =IF('Desain Program'!F5=0,0,('Desain Program'!F5-'Rincian Biaya'!F30)/'Desain Program'!F5) -> 0.356 | F19: =IF('Desain Program'!G5=0,0,('Desain Program'!G5-'Rincian Biaya'!G30)/'Desain Program'!G5) -> 0.33619048 | G19: =IF('Desain Program'!H5=0,0,('Desain Program'!H5-'Rincian Biaya'!H30)/'Desain Program'!H5) -> 0.46478261 | H19: =IF('Desain Program'!I5=0,0,('Desain Program'!I5-'Rincian Biaya'!I30)/'Desain Program'!I5) -> 0.29428571 | I19: =IF('Desain Program'!J5=0,0,('Desain Program'!J5-'Rincian Biaya'!J30)/'Desain Program'!J5) -> 0.35257143 | J19: =IF('Desain Program'!K5=0,0,('Desain Program'!K5-'Rincian Biaya'!K30)/'Desain Program'!K5) -> 0.37368421
B20: Target margin | C20: ='Desain Program'!D6 -> 0.36 | D20: ='Desain Program'!E6 -> 0.2 | E20: ='Desain Program'!F6 -> 0.36 | F20: ='Desain Program'!G6 -> 0.36 | G20: ='Desain Program'!H6 -> 0.36 | H20: ='Desain Program'!I6 -> 0.2 | I20: ='Desain Program'!J6 -> 0.36 | J20: ='Desain Program'!K6 -> 0.36
B21: Harga minimum utk capai target | C21: =('Rincian Biaya'!D30-'Rincian Biaya'!D26-'Rincian Biaya'!D27)/(1-'Input Tarif'!$D$13-'Input Tarif'!$D$14-'Desain Program'!D6) -> 11975806 | D21: =('Rincian Biaya'!E30-'Rincian Biaya'!E26-'Rincian Biaya'!E27)/(1-'Input Tarif'!$D$13-'Input Tarif'!$D$14-'Desain Program'!E6) -> 11153846 | E21: =('Rincian Biaya'!F30-'Rincian Biaya'!F26-'Rincian Biaya'!F27)/(1-'Input Tarif'!$D$13-'Input Tarif'!$D$14-'Desain Program'!F6) -> 20129032 | F21: =('Rincian Biaya'!G30-'Rincian Biaya'!G26-'Rincian Biaya'!G27)/(1-'Input Tarif'!$D$13-'Input Tarif'!$D$14-'Desain Program'!G6) -> 32709677 | G21: =('Rincian Biaya'!H30-'Rincian Biaya'!H26-'Rincian Biaya'!H27)/(1-'Input Tarif'!$D$13-'Input Tarif'!$D$14-'Desain Program'!H6) -> 9556451.6 | H21: =('Rincian Biaya'!I30-'Rincian Biaya'!I26-'Rincian Biaya'!I27)/(1-'Input Tarif'!$D$13-'Input Tarif'!$D$14-'Desain Program'!I6) -> 9230769.2 | I21: =('Rincian Biaya'!J30-'Rincian Biaya'!J26-'Rincian Biaya'!J27)/(1-'Input Tarif'!$D$13-'Input Tarif'!$D$14-'Desain Program'!J6) -> 17709677 | J21: =('Rincian Biaya'!K30-'Rincian Biaya'!K26-'Rincian Biaya'!K27)/(1-'Input Tarif'!$D$13-'Input Tarif'!$D$14-'Desain Program'!K6) -> 27870968
B22: Selisih harga jual vs harga minimum | C22: ='Desain Program'!D5-('Rincian Biaya'!D30-'Rincian Biaya'!D26-'Rincian Biaya'!D27)/(1-'Input Tarif'!$D$13-'Input Tarif'!$D$14-'Desain Program'!D6) -> 24193.548 | D22: ='Desain Program'!E5-('Rincian Biaya'!E30-'Rincian Biaya'!E26-'Rincian Biaya'!E27)/(1-'Input Tarif'!$D$13-'Input Tarif'!$D$14-'Desain Program'!E6) -> -153846.15 | E22: ='Desain Program'!F5-('Rincian Biaya'!F30-'Rincian Biaya'!F26-'Rincian Biaya'!F27)/(1-'Input Tarif'!$D$13-'Input Tarif'!$D$14-'Desain Program'!F6) -> -129032.26 | F22: ='Desain Program'!G5-('Rincian Biaya'!G30-'Rincian Biaya'!G26-'Rincian Biaya'!G27)/(1-'Input Tarif'!$D$13-'Input Tarif'!$D$14-'Desain Program'!G6) -> -1209677.4 | G22: ='Desain Program'!H5-('Rincian Biaya'!H30-'Rincian Biaya'!H26-'Rincian Biaya'!H27)/(1-'Input Tarif'!$D$13-'Input Tarif'!$D$14-'Desain Program'!H6) -> 1943548.4 | H22: ='Desain Program'!I5-('Rincian Biaya'!I30-'Rincian Biaya'!I26-'Rincian Biaya'!I27)/(1-'Input Tarif'!$D$13-'Input Tarif'!$D$14-'Desain Program'!I6) -> 1269230.8 | I22: ='Desain Program'!J5-('Rincian Biaya'!J30-'Rincian Biaya'!J26-'Rincian Biaya'!J27)/(1-'Input Tarif'!$D$13-'Input Tarif'!$D$14-'Desain Program'!J6) -> -209677.42 | J22: ='Desain Program'!K5-('Rincian Biaya'!K30-'Rincian Biaya'!K26-'Rincian Biaya'!K27)/(1-'Input Tarif'!$D$13-'Input Tarif'!$D$14-'Desain Program'!K6) -> 629032.26
B23: Status | C23: =IF(C22>=0,"Memenuhi target","Di bawah target") -> Memenuhi target | D23: =IF(D22>=0,"Memenuhi target","Di bawah target") -> Di bawah target | E23: =IF(E22>=0,"Memenuhi target","Di bawah target") -> Di bawah target | F23: =IF(F22>=0,"Memenuhi target","Di bawah target") -> Di bawah target | G23: =IF(G22>=0,"Memenuhi target","Di bawah target") -> Memenuhi target | H23: =IF(H22>=0,"Memenuhi target","Di bawah target") -> Memenuhi target | I23: =IF(I22>=0,"Memenuhi target","Di bawah target") -> Di bawah target | J23: =IF(J22>=0,"Memenuhi target","Di bawah target") -> Memenuhi target
B24: Laba bersih jika semua sesi in-house | C24: ='Desain Program'!D5-'Rincian Biaya'!D30+'Rincian Biaya'!D6 -> 9585000 | D24: ='Desain Program'!E5-'Rincian Biaya'!E30+'Rincian Biaya'!E6 -> 7330000 | E24: ='Desain Program'!F5-'Rincian Biaya'!F30+'Rincian Biaya'!F6 -> 15520000 | F24: ='Desain Program'!G5-'Rincian Biaya'!G30+'Rincian Biaya'!G6 -> 23190000 | G24: ='Desain Program'!H5-'Rincian Biaya'!H30+'Rincian Biaya'!H6 -> 10595000 | H24: ='Desain Program'!I5-'Rincian Biaya'!I30+'Rincian Biaya'!I6 -> 8340000 | I24: ='Desain Program'!J5-'Rincian Biaya'!J30+'Rincian Biaya'!J6 -> 14570000 | J24: ='Desain Program'!K5-'Rincian Biaya'!K30+'Rincian Biaya'!K6 -> 23250000
B25: KAS & KONTRIBUSI
B26: Kas diterima saat SPK (DP, setelah PPh) | C26: ='Desain Program'!D5*'Input Tarif'!$D$21*(1-'Input Tarif'!$D$13) -> 5880000 | D26: ='Desain Program'!E5*'Input Tarif'!$D$21*(1-'Input Tarif'!$D$13) -> 5390000 | E26: ='Desain Program'!F5*'Input Tarif'!$D$21*(1-'Input Tarif'!$D$13) -> 9800000 | F26: ='Desain Program'!G5*'Input Tarif'!$D$21*(1-'Input Tarif'!$D$13) -> 15435000 | G26: ='Desain Program'!H5*'Input Tarif'!$D$21*(1-'Input Tarif'!$D$13) -> 5635000 | H26: ='Desain Program'!I5*'Input Tarif'!$D$21*(1-'Input Tarif'!$D$13) -> 5145000 | I26: ='Desain Program'!J5*'Input Tarif'!$D$21*(1-'Input Tarif'!$D$13) -> 8575000 | J26: ='Desain Program'!K5*'Input Tarif'!$D$21*(1-'Input Tarif'!$D$13) -> 13965000
B27: Laba bersih per bulan | C27: =('Desain Program'!D5-'Rincian Biaya'!D30)/'Input Tarif'!$D$19 -> 1445000 | D27: =('Desain Program'!E5-'Rincian Biaya'!E30)/'Input Tarif'!$D$19 -> 693333.33 | E27: =('Desain Program'!F5-'Rincian Biaya'!F30)/'Input Tarif'!$D$19 -> 2373333.3 | F27: =('Desain Program'!G5-'Rincian Biaya'!G30)/'Input Tarif'!$D$19 -> 3530000 | G27: =('Desain Program'!H5-'Rincian Biaya'!H30)/'Input Tarif'!$D$19 -> 1781666.7 | H27: =('Desain Program'!I5-'Rincian Biaya'!I30)/'Input Tarif'!$D$19 -> 1030000 | I27: =('Desain Program'!J5-'Rincian Biaya'!J30)/'Input Tarif'!$D$19 -> 2056666.7 | J27: =('Desain Program'!K5-'Rincian Biaya'!K30)/'Input Tarif'!$D$19 -> 3550000
B28: % opex masa paket yang tertutup | C28: =('Desain Program'!D5-'Rincian Biaya'!D30)/('Input Tarif'!$D$20*'Input Tarif'!$D$19) -> 0.07225 | D28: =('Desain Program'!E5-'Rincian Biaya'!E30)/('Input Tarif'!$D$20*'Input Tarif'!$D$19) -> 0.034666667 | E28: =('Desain Program'!F5-'Rincian Biaya'!F30)/('Input Tarif'!$D$20*'Input Tarif'!$D$19) -> 0.11866667 | F28: =('Desain Program'!G5-'Rincian Biaya'!G30)/('Input Tarif'!$D$20*'Input Tarif'!$D$19) -> 0.1765 | G28: =('Desain Program'!H5-'Rincian Biaya'!H30)/('Input Tarif'!$D$20*'Input Tarif'!$D$19) -> 0.089083333 | H28: =('Desain Program'!I5-'Rincian Biaya'!I30)/('Input Tarif'!$D$20*'Input Tarif'!$D$19) -> 0.0515 | I28: =('Desain Program'!J5-'Rincian Biaya'!J30)/('Input Tarif'!$D$20*'Input Tarif'!$D$19) -> 0.10283333 | J28: =('Desain Program'!K5-'Rincian Biaya'!K30)/('Input Tarif'!$D$20*'Input Tarif'!$D$19) -> 0.1775
B29: NILAI UNTUK PROPOSAL
B30: Nilai normal (harga reguler) | C30: ='Desain Program'!D8*'Input Tarif'!$D$17+'Desain Program'!D10*'Input Tarif'!$D$22+'Desain Program'!D11*'Input Tarif'!$D$23+('Desain Program'!D13+'Desain Program'!D14)*'Input Tarif'!$D$24 -> 10500000 | D30: ='Desain Program'!E8*'Input Tarif'!$D$17+'Desain Program'!E10*'Input Tarif'!$D$22+'Desain Program'!E11*'Input Tarif'!$D$23+('Desain Program'!E13+'Desain Program'!E14)*'Input Tarif'!$D$24 -> 15000000 | E30: ='Desain Program'!F8*'Input Tarif'!$D$17+'Desain Program'!F10*'Input Tarif'!$D$22+'Desain Program'!F11*'Input Tarif'!$D$23+('Desain Program'!F13+'Desain Program'!F14)*'Input Tarif'!$D$24 -> 19500000 | F30: ='Desain Program'!G8*'Input Tarif'!$D$17+'Desain Program'!G10*'Input Tarif'!$D$22+'Desain Program'!G11*'Input Tarif'!$D$23+('Desain Program'!G13+'Desain Program'!G14)*'Input Tarif'!$D$24 -> 28000000 | G30: ='Desain Program'!H8*'Input Tarif'!$D$17+'Desain Program'!H10*'Input Tarif'!$D$22+'Desain Program'!H11*'Input Tarif'!$D$23+('Desain Program'!H13+'Desain Program'!H14)*'Input Tarif'!$D$24 -> 7500000 | H30: ='Desain Program'!I8*'Input Tarif'!$D$17+'Desain Program'!I10*'Input Tarif'!$D$22+'Desain Program'!I11*'Input Tarif'!$D$23+('Desain Program'!I13+'Desain Program'!I14)*'Input Tarif'!$D$24 -> 12000000 | I30: ='Desain Program'!J8*'Input Tarif'!$D$17+'Desain Program'!J10*'Input Tarif'!$D$22+'Desain Program'!J11*'Input Tarif'!$D$23+('Desain Program'!J13+'Desain Program'!J14)*'Input Tarif'!$D$24 -> 16500000 | J30: ='Desain Program'!K8*'Input Tarif'!$D$17+'Desain Program'!K10*'Input Tarif'!$D$22+'Desain Program'!K11*'Input Tarif'!$D$23+('Desain Program'!K13+'Desain Program'!K14)*'Input Tarif'!$D$24 -> 25000000
B31: Hemat untuk BI | C31: =IF(C30=0,0,1-C6/C30) -> -0.14285714 | D31: =IF(D30=0,0,1-D6/D30) -> 0.26666667 | E31: =IF(E30=0,0,1-E6/E30) -> -0.025641026 | F31: =IF(F30=0,0,1-F6/F30) -> -0.125 | G31: =IF(G30=0,0,1-G6/G30) -> -0.53333333 | H31: =IF(H30=0,0,1-H6/H30) -> 0.125 | I31: =IF(I30=0,0,1-I6/I30) -> -0.060606061 | J31: =IF(J30=0,0,1-J6/J30) -> -0.14
B32: REKOMENDASI HARGA
B33: Harga minimum (margin 15%) | C33: =CEILING(('Rincian Biaya'!D30-'Rincian Biaya'!D26-'Rincian Biaya'!D27)/(1-'Input Tarif'!$D$13-'Input Tarif'!$D$14-'Input Tarif'!$D$25),'Input Tarif'!$D$27) -> 9000000 | D33: =CEILING(('Rincian Biaya'!E30-'Rincian Biaya'!E26-'Rincian Biaya'!E27)/(1-'Input Tarif'!$D$13-'Input Tarif'!$D$14-'Input Tarif'!$D$25),'Input Tarif'!$D$27) -> 10500000 | E33: =CEILING(('Rincian Biaya'!F30-'Rincian Biaya'!F26-'Rincian Biaya'!F27)/(1-'Input Tarif'!$D$13-'Input Tarif'!$D$14-'Input Tarif'!$D$25),'Input Tarif'!$D$27) -> 15500000 | F33: =CEILING(('Rincian Biaya'!G30-'Rincian Biaya'!G26-'Rincian Biaya'!G27)/(1-'Input Tarif'!$D$13-'Input Tarif'!$D$14-'Input Tarif'!$D$25),'Input Tarif'!$D$27) -> 24500000 | G33: =CEILING(('Rincian Biaya'!H30-'Rincian Biaya'!H26-'Rincian Biaya'!H27)/(1-'Input Tarif'!$D$13-'Input Tarif'!$D$14-'Input Tarif'!$D$25),'Input Tarif'!$D$27) -> 7500000 | H33: =CEILING(('Rincian Biaya'!I30-'Rincian Biaya'!I26-'Rincian Biaya'!I27)/(1-'Input Tarif'!$D$13-'Input Tarif'!$D$14-'Input Tarif'!$D$25),'Input Tarif'!$D$27) -> 9000000 | I33: =CEILING(('Rincian Biaya'!J30-'Rincian Biaya'!J26-'Rincian Biaya'!J27)/(1-'Input Tarif'!$D$13-'Input Tarif'!$D$14-'Input Tarif'!$D$25),'Input Tarif'!$D$27) -> 13500000 | J33: =CEILING(('Rincian Biaya'!K30-'Rincian Biaya'!K26-'Rincian Biaya'!K27)/(1-'Input Tarif'!$D$13-'Input Tarif'!$D$14-'Input Tarif'!$D$25),'Input Tarif'!$D$27) -> 21000000
B34: Harga ideal (margin 26%) | C34: =CEILING(('Rincian Biaya'!D30-'Rincian Biaya'!D26-'Rincian Biaya'!D27)/(1-'Input Tarif'!$D$13-'Input Tarif'!$D$14-'Input Tarif'!$D$26),'Input Tarif'!$D$27) -> 10500000 | D34: =CEILING(('Rincian Biaya'!E30-'Rincian Biaya'!E26-'Rincian Biaya'!E27)/(1-'Input Tarif'!$D$13-'Input Tarif'!$D$14-'Input Tarif'!$D$26),'Input Tarif'!$D$27) -> 12500000 | E34: =CEILING(('Rincian Biaya'!F30-'Rincian Biaya'!F26-'Rincian Biaya'!F27)/(1-'Input Tarif'!$D$13-'Input Tarif'!$D$14-'Input Tarif'!$D$26),'Input Tarif'!$D$27) -> 17500000 | F34: =CEILING(('Rincian Biaya'!G30-'Rincian Biaya'!G26-'Rincian Biaya'!G27)/(1-'Input Tarif'!$D$13-'Input Tarif'!$D$14-'Input Tarif'!$D$26),'Input Tarif'!$D$27) -> 28500000 | G34: =CEILING(('Rincian Biaya'!H30-'Rincian Biaya'!H26-'Rincian Biaya'!H27)/(1-'Input Tarif'!$D$13-'Input Tarif'!$D$14-'Input Tarif'!$D$26),'Input Tarif'!$D$27) -> 8500000 | H34: =CEILING(('Rincian Biaya'!I30-'Rincian Biaya'!I26-'Rincian Biaya'!I27)/(1-'Input Tarif'!$D$13-'Input Tarif'!$D$14-'Input Tarif'!$D$26),'Input Tarif'!$D$27) -> 10000000 | I34: =CEILING(('Rincian Biaya'!J30-'Rincian Biaya'!J26-'Rincian Biaya'!J27)/(1-'Input Tarif'!$D$13-'Input Tarif'!$D$14-'Input Tarif'!$D$26),'Input Tarif'!$D$27) -> 15500000 | J34: =CEILING(('Rincian Biaya'!K30-'Rincian Biaya'!K26-'Rincian Biaya'!K27)/(1-'Input Tarif'!$D$13-'Input Tarif'!$D$14-'Input Tarif'!$D$26),'Input Tarif'!$D$27) -> 24000000
B35: Margin dipakai untuk rekomendasi | C35: =MAX('Input Tarif'!$D$25,MIN('Input Tarif'!$D$26,'Desain Program'!D6)) -> 0.26 | D35: =MAX('Input Tarif'!$D$25,MIN('Input Tarif'!$D$26,'Desain Program'!E6)) -> 0.2 | E35: =MAX('Input Tarif'!$D$25,MIN('Input Tarif'!$D$26,'Desain Program'!F6)) -> 0.26 | F35: =MAX('Input Tarif'!$D$25,MIN('Input Tarif'!$D$26,'Desain Program'!G6)) -> 0.26 | G35: =MAX('Input Tarif'!$D$25,MIN('Input Tarif'!$D$26,'Desain Program'!H6)) -> 0.26 | H35: =MAX('Input Tarif'!$D$25,MIN('Input Tarif'!$D$26,'Desain Program'!I6)) -> 0.2 | I35: =MAX('Input Tarif'!$D$25,MIN('Input Tarif'!$D$26,'Desain Program'!J6)) -> 0.26 | J35: =MAX('Input Tarif'!$D$25,MIN('Input Tarif'!$D$26,'Desain Program'!K6)) -> 0.26
B36: HARGA REKOMENDASI | C36: =MAX(C6,CEILING(('Rincian Biaya'!D30-'Rincian Biaya'!D26-'Rincian Biaya'!D27)/(1-'Input Tarif'!$D$13-'Input Tarif'!$D$14-C35),'Input Tarif'!$D$27)) -> 12000000 | D36: =MAX(D6,CEILING(('Rincian Biaya'!E30-'Rincian Biaya'!E26-'Rincian Biaya'!E27)/(1-'Input Tarif'!$D$13-'Input Tarif'!$D$14-D35),'Input Tarif'!$D$27)) -> 11500000 | E36: =MAX(E6,CEILING(('Rincian Biaya'!F30-'Rincian Biaya'!F26-'Rincian Biaya'!F27)/(1-'Input Tarif'!$D$13-'Input Tarif'!$D$14-E35),'Input Tarif'!$D$27)) -> 20000000 | F36: =MAX(F6,CEILING(('Rincian Biaya'!G30-'Rincian Biaya'!G26-'Rincian Biaya'!G27)/(1-'Input Tarif'!$D$13-'Input Tarif'!$D$14-F35),'Input Tarif'!$D$27)) -> 31500000 | G36: =MAX(G6,CEILING(('Rincian Biaya'!H30-'Rincian Biaya'!H26-'Rincian Biaya'!H27)/(1-'Input Tarif'!$D$13-'Input Tarif'!$D$14-G35),'Input Tarif'!$D$27)) -> 11500000 | H36: =MAX(H6,CEILING(('Rincian Biaya'!I30-'Rincian Biaya'!I26-'Rincian Biaya'!I27)/(1-'Input Tarif'!$D$13-'Input Tarif'!$D$14-H35),'Input Tarif'!$D$27)) -> 10500000 | I36: =MAX(I6,CEILING(('Rincian Biaya'!J30-'Rincian Biaya'!J26-'Rincian Biaya'!J27)/(1-'Input Tarif'!$D$13-'Input Tarif'!$D$14-I35),'Input Tarif'!$D$27)) -> 17500000 | J36: =MAX(J6,CEILING(('Rincian Biaya'!K30-'Rincian Biaya'!K26-'Rincian Biaya'!K27)/(1-'Input Tarif'!$D$13-'Input Tarif'!$D$14-J35),'Input Tarif'!$D$27)) -> 28500000
B37: Perubahan vs harga sekarang | C37: =C36-C6 -> 0 | D37: =D36-D6 -> 500000 | E37: =E36-E6 -> 0 | F37: =F36-F6 -> 0 | G37: =G36-G6 -> 0 | H37: =H36-H6 -> 0 | I37: =I36-I6 -> 0 | J37: =J36-J6 -> 0
B38: Margin bersih pada harga rekomendasi | C38: =(C36*(1-'Input Tarif'!$D$13-'Input Tarif'!$D$14)-('Rincian Biaya'!D30-'Rincian Biaya'!D26-'Rincian Biaya'!D27))/C36 -> 0.36125 | D38: =(D36*(1-'Input Tarif'!$D$13-'Input Tarif'!$D$14)-('Rincian Biaya'!E30-'Rincian Biaya'!E26-'Rincian Biaya'!E27))/D36 -> 0.22347826 | E38: =(E36*(1-'Input Tarif'!$D$13-'Input Tarif'!$D$14)-('Rincian Biaya'!F30-'Rincian Biaya'!F26-'Rincian Biaya'!F27))/E36 -> 0.356 | F38: =(F36*(1-'Input Tarif'!$D$13-'Input Tarif'!$D$14)-('Rincian Biaya'!G30-'Rincian Biaya'!G26-'Rincian Biaya'!G27))/F36 -> 0.33619048 | G38: =(G36*(1-'Input Tarif'!$D$13-'Input Tarif'!$D$14)-('Rincian Biaya'!H30-'Rincian Biaya'!H26-'Rincian Biaya'!H27))/G36 -> 0.46478261 | H38: =(H36*(1-'Input Tarif'!$D$13-'Input Tarif'!$D$14)-('Rincian Biaya'!I30-'Rincian Biaya'!I26-'Rincian Biaya'!I27))/H36 -> 0.29428571 | I38: =(I36*(1-'Input Tarif'!$D$13-'Input Tarif'!$D$14)-('Rincian Biaya'!J30-'Rincian Biaya'!J26-'Rincian Biaya'!J27))/I36 -> 0.35257143 | J38: =(J36*(1-'Input Tarif'!$D$13-'Input Tarif'!$D$14)-('Rincian Biaya'!K30-'Rincian Biaya'!K26-'Rincian Biaya'!K27))/J36 -> 0.37368421
B39: Laba bersih pada harga rekomendasi | C39: =C36*(1-'Input Tarif'!$D$13-'Input Tarif'!$D$14)-('Rincian Biaya'!D30-'Rincian Biaya'!D26-'Rincian Biaya'!D27) -> 4335000 | D39: =D36*(1-'Input Tarif'!$D$13-'Input Tarif'!$D$14)-('Rincian Biaya'!E30-'Rincian Biaya'!E26-'Rincian Biaya'!E27) -> 2570000 | E39: =E36*(1-'Input Tarif'!$D$13-'Input Tarif'!$D$14)-('Rincian Biaya'!F30-'Rincian Biaya'!F26-'Rincian Biaya'!F27) -> 7120000 | F39: =F36*(1-'Input Tarif'!$D$13-'Input Tarif'!$D$14)-('Rincian Biaya'!G30-'Rincian Biaya'!G26-'Rincian Biaya'!G27) -> 10590000 | G39: =G36*(1-'Input Tarif'!$D$13-'Input Tarif'!$D$14)-('Rincian Biaya'!H30-'Rincian Biaya'!H26-'Rincian Biaya'!H27) -> 5345000 | H39: =H36*(1-'Input Tarif'!$D$13-'Input Tarif'!$D$14)-('Rincian Biaya'!I30-'Rincian Biaya'!I26-'Rincian Biaya'!I27) -> 3090000 | I39: =I36*(1-'Input Tarif'!$D$13-'Input Tarif'!$D$14)-('Rincian Biaya'!J30-'Rincian Biaya'!J26-'Rincian Biaya'!J27) -> 6170000 | J39: =J36*(1-'Input Tarif'!$D$13-'Input Tarif'!$D$14)-('Rincian Biaya'!K30-'Rincian Biaya'!K26-'Rincian Biaya'!K27) -> 10650000
B40: Setara per bulan (harga rekomendasi) | C40: =C36/'Input Tarif'!$D$19 -> 4000000 | D40: =D36/'Input Tarif'!$D$19 -> 3833333.3 | E40: =E36/'Input Tarif'!$D$19 -> 6666666.7 | F40: =F36/'Input Tarif'!$D$19 -> 10500000 | G40: =G36/'Input Tarif'!$D$19 -> 3833333.3 | H40: =H36/'Input Tarif'!$D$19 -> 3500000 | I40: =I36/'Input Tarif'!$D$19 -> 5833333.3 | J40: =J36/'Input Tarif'!$D$19 -> 9500000
B41: Alternatif: penghematan biaya agar margin 15% tanpa naik harga | C41: =MAX(0,('Rincian Biaya'!D30-'Rincian Biaya'!D26-'Rincian Biaya'!D27)-'Desain Program'!D5*(1-'Input Tarif'!$D$13-'Input Tarif'!$D$14-'Input Tarif'!$D$25)) -> 0 | D41: =MAX(0,('Rincian Biaya'!E30-'Rincian Biaya'!E26-'Rincian Biaya'!E27)-'Desain Program'!E5*(1-'Input Tarif'!$D$13-'Input Tarif'!$D$14-'Input Tarif'!$D$25)) -> 0 | E41: =MAX(0,('Rincian Biaya'!F30-'Rincian Biaya'!F26-'Rincian Biaya'!F27)-'Desain Program'!F5*(1-'Input Tarif'!$D$13-'Input Tarif'!$D$14-'Input Tarif'!$D$25)) -> 0 | F41: =MAX(0,('Rincian Biaya'!G30-'Rincian Biaya'!G26-'Rincian Biaya'!G27)-'Desain Program'!G5*(1-'Input Tarif'!$D$13-'Input Tarif'!$D$14-'Input Tarif'!$D$25)) -> 0 | G41: =MAX(0,('Rincian Biaya'!H30-'Rincian Biaya'!H26-'Rincian Biaya'!H27)-'Desain Program'!H5*(1-'Input Tarif'!$D$13-'Input Tarif'!$D$14-'Input Tarif'!$D$25)) -> 0 | H41: =MAX(0,('Rincian Biaya'!I30-'Rincian Biaya'!I26-'Rincian Biaya'!I27)-'Desain Program'!I5*(1-'Input Tarif'!$D$13-'Input Tarif'!$D$14-'Input Tarif'!$D$25)) -> 0 | I41: =MAX(0,('Rincian Biaya'!J30-'Rincian Biaya'!J26-'Rincian Biaya'!J27)-'Desain Program'!J5*(1-'Input Tarif'!$D$13-'Input Tarif'!$D$14-'Input Tarif'!$D$25)) -> 0 | J41: =MAX(0,('Rincian Biaya'!K30-'Rincian Biaya'!K26-'Rincian Biaya'!K27)-'Desain Program'!K5*(1-'Input Tarif'!$D$13-'Input Tarif'!$D$14-'Input Tarif'!$D$25)) -> 0
...

Sheet Input Tarif
A1: INPUT TARIF & ASUMSI
A2: Ubah hanya sel biru berlatar kuning. Semua angka lain dihitung otomatis. Kolom 'Review CFO' = catatan kewajaran tarif.
A4: Kategori | B4: Komponen | C4: Satuan | D4: Tarif / Nilai | E4: Sumber | F4: Review CFO
A5: A. Delivery konseling | B5: Honor psikolog per sesi konseling | C5: Rp / sesi 60 menit | D5: 350000 | E5: Kia | F5: TINGGI: 70% dari harga reguler Rp500rb. Praktik umum bagi hasil associate 50-60% (Rp250-300rb). Untuk Vania (gaji tetap), gunakan biaya internal per sesi = gaji / kapasitas sesi, bukan Rp350rb.
A6: A. Delivery konseling | B6: Admin & platform | C6: Rp / sesi | D6: 35000 | E6: Asumsi | F6: AGAK TINGGI bila Zoom & tools sudah dibayar bulanan (masuk opex). Biaya marginal realistis Rp10-15rb/sesi (reminder, penjadwalan).
A7: B. Asesmen | B7: MHCU (alat ukur + skoring) | C7: Rp / orang / putaran | D7: 35000 | E7: Coreitera (tes saja; dinegosiasi turun dari Rp70rb ke Rp35rb/tes, 16 Okt 2026) | F7: WAJAR jika termasuk interpretasi psikolog. Jika memakai alat ukur bebas lisensi (mis. DASS-21, Copenhagen Burnout Inventory) dan skoring otomatis, biaya bisa ditekan.
A8: B. Asesmen | B8: Laporan agregat anonim | C8: Rp / program | D8: 750000 | E8: Asumsi | F8: WAJAR (± 0,5-1 hari kerja psikolog). Bisa dibuat template agar program berikutnya lebih murah.
A9: C. Psikoedukasi | B9: Webinar online oleh psikolog | C9: Rp / sesi | D9: 1500000 | E9: Kia | F9: WAJAR untuk narasumber eksternal. Jika dibawakan Kia/Vania (gaji/opex), biaya marginal mendekati Rp0-500rb (moderator, materi).
A10: C. Psikoedukasi | B10: Seminar offline oleh psikolog | C10: Rp / sesi | D10: 3000000 | E10: Kia | F10: KEMUNGKINAN TERLALU RENDAH jika narasumber berangkat dari Jakarta: tiket ke Sibolga (via Medan) + hotel + uang harian bisa melebihi Rp3jt sebelum honor. Cek ulang, atau pakai psikolog mitra di Sumut.
A11: D. Administrasi proyek | B11: PIC / Project Officer | C11: Rp / program | D11: 0 | E11: Belum ada | F11: KURANG: koordinasi jadwal 12 pegawai x 3 bulan tetap memakan waktu. Pertimbangkan Rp300-500rb/program agar margin tidak semu.
A12: D. Administrasi proyek | B12: Kontrak, materai, invoice | C12: Rp / program | D12: 150000 | E12: Asumsi | F12: WAJAR.
A13: E. Pajak & overhead | B13: PPh 23 dipotong BI | C13: % dari harga | D13: 0.02 | E13: Ketentuan | F13: Non-PKP: tidak ada PPN. PPh 23 = kredit pajak, tapi mengurangi kas.
A14: E. Pajak & overhead | B14: Alokasi overhead kantor | C14: % dari harga | D14: 0 | E14: Belum diisi | F14: DISARANKAN 10-15% agar laba mencerminkan kontribusi nyata terhadap opex Rp20jt/bulan.
A16: Parameter umum
B17: Harga reguler per sesi | C17: Rp / sesi | D17: 500000 | E17: Kia
B18: Sesi konseling per pegawai | C18: sesi | D18: 3 | E18: Asumsi praktik konseling singkat
B19: Masa paket | C19: bulan | D19: 3 | E19: Kia
B20: Biaya operasional bulanan Teman Journey | C20: Rp / bulan | D20: 20000000 | E20: Kia
B21: DP saat SPK | C21: % dari harga | D21: 0.5 | E21: Ketentuan proposal
B22: Nilai normal 1 putaran MHCU (untuk proposal) | C22: Rp | D22: 2500000 | E22: Nilai jual, bukan biaya
B23: Nilai normal laporan agregat (untuk proposal) | C23: Rp | D23: 2000000 | E23: Nilai jual, bukan biaya
B24: Nilai normal 1 sesi psikoedukasi (untuk proposal) | C24: Rp | D24: 3000000 | E24: Nilai jual, bukan biaya
B25: Standar margin bersih minimum | C25: % dari harga | D25: 0.15 | E25: Kebijakan Teman Journey
B26: Standar margin bersih maksimum / ideal | C26: % dari harga | D26: 0.26 | E26: Kebijakan Teman Journey
B27: Pembulatan harga rekomendasi | C27: Rp | D27: 500000 | E27: Dibulatkan ke atas
B28: Margin bersih pembanding (tinggi) | C28: % dari harga | D28: 0.36 | E28: Pembanding: harga Jeda, Tumbuh, Seperjalanan saat ini setara margin ini

Sheet Desain Program
A1: DESAIN PROGRAM (isi per paket)
A2: Kuantitas layanan, harga jual, dan TARGET MARGIN bisa diatur per program.
A4: Bagian | B4: Parameter | C4: Satuan | D4: Jeda | E4: Jeda Tahunan (per term) | F4: Tumbuh | G4: Seperjalanan | H4: Jeda tanpa psikoedukasi | I4: Jeda Tahunan tanpa psikoedukasi (per term) | J4: Tumbuh tanpa psikoedukasi | K4: Seperjalanan tanpa psikoedukasi
A5: Harga & target | B5: Harga jual (proposal) | C5: Rp | D5: 12000000 | E5: 11000000 | F5: 20000000 | G5: 31500000 | H5: 11500000 | I5: 10500000 | J5: 17500000 | K5: 28500000
A6: Harga & target | B6: Target margin bersih | C6: % dari harga | D6: 0.36 | E6: 0.2 | F6: 0.36 | G6: 0.36 | H6: =D6 -> 0.36 | I6: =E6 -> 0.2 | J6: =F6 -> 0.36 | K6: =G6 -> 0.36
A7: Harga & target | B7: % sesi oleh psikolog berbayar | C7: % | D7: 1 | E7: 1 | F7: 1 | G7: 1 | H7: =D7 -> 1 | I7: =E7 -> 1 | J7: =F7 -> 1 | K7: =G7 -> 1
A8: Layanan | B8: Jumlah sesi konseling | C8: sesi | D8: 15 | E8: 15 | F8: 24 | G8: 36 | H8: =D8 -> 15 | I8: =E8 -> 15 | J8: =F8 -> 24 | K8: =G8 -> 36
A9: Layanan | B9: Pegawai terlayani | C9: orang | D9: =D8/'Input Tarif'!$D$18 -> 5 | E9: =E8/'Input Tarif'!$D$18 -> 5 | F9: =F8/'Input Tarif'!$D$18 -> 8 | G9: =G8/'Input Tarif'!$D$18 -> 12 | H9: =H8/'Input Tarif'!$D$18 -> 5 | I9: =I8/'Input Tarif'!$D$18 -> 5 | J9: =J8/'Input Tarif'!$D$18 -> 8 | K9: =K8/'Input Tarif'!$D$18 -> 12
A10: Layanan | B10: Putaran MHCU | C10: putaran | D10: 0 | E10: 1 | F10: 1 | G10: 2 | H10: =D10 -> 0 | I10: =E10 -> 1 | J10: =F10 -> 1 | K10: =G10 -> 2
A11: Layanan | B11: Laporan agregat (1=ya) | C11: flag | D11: 0 | E11: 1 | F11: 1 | G11: 1 | H11: =D11 -> 0 | I11: =E11 -> 1 | J11: =F11 -> 1 | K11: =G11 -> 1
A12: Layanan | B12: Hasil MHCU individual (1=ya) | C12: flag | D12: 0 | E12: 0 | F12: 0 | G12: 1 | H12: =D12 -> 0 | I12: =E12 -> 0 | J12: =F12 -> 0 | K12: =G12 -> 1
A13: Layanan | B13: Psikoedukasi online (webinar) | C13: sesi | D13: 1 | E13: 1 | F13: 1 | G13: 0 | H13: 0 | I13: 0 | J13: 0 | K13: 0
A14: Layanan | B14: Psikoedukasi offline (seminar) | C14: sesi | D14: 0 | E14: 0 | F14: 0 | G14: 1 | H14: 0 | I14: 0 | J14: 0 | K14: 0
A15: Layanan | B15: Peserta MHCU (maks: 1 orang per sesi kuota) | C15: orang | D15: =D8 -> 15 | E15: =E8 -> 15 | F15: =F8 -> 24 | G15: =G8 -> 36 | H15: =D15 -> 15 | I15: =E15 -> 15 | J15: =F15 -> 24 | K15: =G15 -> 36
A16: Catatan: '% sesi oleh psikolog berbayar' = 100% berarti semua sesi dibayar honor (skenario konservatif). Isi 0% jika semua sesi dibawakan Vania/Kia (gaji tetap).
A17: Kolom H-K = paket yang sama tanpa psikoedukasi (webinar/seminar = 0). Harga H5:K5 diisi manual (keputusan Galih, 16 Okt 2026): Jeda Rp11,5jt, Jeda Tahunan Rp10,5jt/term, Tumbuh Rp17,5jt, Seperjalanan Rp28,5jt. Kuantitas lain mengikuti kolom paket asli.
A18: Baris 15: MHCU hanya untuk pegawai yang konseling. Skenario terburuk: setiap pegawai hanya pakai 1 sesi, jadi peserta MHCU = jumlah sesi kuota (Tumbuh maks 24, Seperjalanan maks 36 x pre & post = Rp140rb/orang). Jeda Tahunan: hanya yang baru pertama kali konseling, maks 15 per term.

Sheet Rincian Biaya
A1: RINCIAN BIAYA PER KATEGORI
A2: Biaya = kuantitas (Desain Program) x tarif (Input Tarif). Jangan ketik angka di sini.
A4: Kategori | B4: Komponen | C4: Dasar perhitungan | D4: Jeda | E4: Jeda Tahunan (per term) | F4: Tumbuh | G4: Seperjalanan | H4: Jeda tanpa psikoedukasi | I4: Jeda Tahunan tanpa psikoedukasi (per term) | J4: Tumbuh tanpa psikoedukasi | K4: Seperjalanan tanpa psikoedukasi
A5: A. Delivery konseling
B6: Honor psikolog | C6: sesi x % berbayar x tarif | D6: ='Desain Program'!D8*'Desain Program'!D7*'Input Tarif'!$D$5 -> 5250000 | E6: ='Desain Program'!E8*'Desain Program'!E7*'Input Tarif'!$D$5 -> 5250000 | F6: ='Desain Program'!F8*'Desain Program'!F7*'Input Tarif'!$D$5 -> 8400000 | G6: ='Desain Program'!G8*'Desain Program'!G7*'Input Tarif'!$D$5 -> 12600000 | H6: ='Desain Program'!H8*'Desain Program'!H7*'Input Tarif'!$D$5 -> 5250000 | I6: ='Desain Program'!I8*'Desain Program'!I7*'Input Tarif'!$D$5 -> 5250000 | J6: ='Desain Program'!J8*'Desain Program'!J7*'Input Tarif'!$D$5 -> 8400000 | K6: ='Desain Program'!K8*'Desain Program'!K7*'Input Tarif'!$D$5 -> 12600000
B7: Admin & platform | C7: sesi x tarif | D7: ='Desain Program'!D8*'Input Tarif'!$D$6 -> 525000 | E7: ='Desain Program'!E8*'Input Tarif'!$D$6 -> 525000 | F7: ='Desain Program'!F8*'Input Tarif'!$D$6 -> 840000 | G7: ='Desain Program'!G8*'Input Tarif'!$D$6 -> 1260000 | H7: ='Desain Program'!H8*'Input Tarif'!$D$6 -> 525000 | I7: ='Desain Program'!I8*'Input Tarif'!$D$6 -> 525000 | J7: ='Desain Program'!J8*'Input Tarif'!$D$6 -> 840000 | K7: ='Desain Program'!K8*'Input Tarif'!$D$6 -> 1260000
B8: Subtotal A. Delivery konseling | D8: =SUM(D6:D7) -> 5775000 | E8: =SUM(E6:E7) -> 5775000 | F8: =SUM(F6:F7) -> 9240000 | G8: =SUM(G6:G7) -> 13860000 | H8: =SUM(H6:H7) -> 5775000 | I8: =SUM(I6:I7) -> 5775000 | J8: =SUM(J6:J7) -> 9240000 | K8: =SUM(K6:K7) -> 13860000
A10: B. Asesmen
B11: MHCU | C11: putaran x peserta MHCU (maks 1 per sesi) x tarif | D11: ='Desain Program'!D10*'Desain Program'!D15*'Input Tarif'!$D$7 -> 0 | E11: ='Desain Program'!E10*'Desain Program'!E15*'Input Tarif'!$D$7 -> 525000 | F11: ='Desain Program'!F10*'Desain Program'!F15*'Input Tarif'!$D$7 -> 840000 | G11: ='Desain Program'!G10*'Desain Program'!G15*'Input Tarif'!$D$7 -> 2520000 | H11: ='Desain Program'!H10*'Desain Program'!H15*'Input Tarif'!$D$7 -> 0 | I11: ='Desain Program'!I10*'Desain Program'!I15*'Input Tarif'!$D$7 -> 525000 | J11: ='Desain Program'!J10*'Desain Program'!J15*'Input Tarif'!$D$7 -> 840000 | K11: ='Desain Program'!K10*'Desain Program'!K15*'Input Tarif'!$D$7 -> 2520000
B12: Laporan agregat | C12: flag x tarif | D12: ='Desain Program'!D11*'Input Tarif'!$D$8 -> 0 | E12: ='Desain Program'!E11*'Input Tarif'!$D$8 -> 750000 | F12: ='Desain Program'!F11*'Input Tarif'!$D$8 -> 750000 | G12: ='Desain Program'!G11*'Input Tarif'!$D$8 -> 750000 | H12: ='Desain Program'!H11*'Input Tarif'!$D$8 -> 0 | I12: ='Desain Program'!I11*'Input Tarif'!$D$8 -> 750000 | J12: ='Desain Program'!J11*'Input Tarif'!$D$8 -> 750000 | K12: ='Desain Program'!K11*'Input Tarif'!$D$8 -> 750000
B13: Subtotal B. Asesmen | D13: =SUM(D11:D12) -> 0 | E13: =SUM(E11:E12) -> 1275000 | F13: =SUM(F11:F12) -> 1590000 | G13: =SUM(G11:G12) -> 3270000 | H13: =SUM(H11:H12) -> 0 | I13: =SUM(I11:I12) -> 1275000 | J13: =SUM(J11:J12) -> 1590000 | K13: =SUM(K11:K12) -> 3270000
A15: C. Psikoedukasi
B16: Webinar online | C16: sesi x tarif | D16: ='Desain Program'!D13*'Input Tarif'!$D$9 -> 1500000 | E16: ='Desain Program'!E13*'Input Tarif'!$D$9 -> 1500000 | F16: ='Desain Program'!F13*'Input Tarif'!$D$9 -> 1500000 | G16: ='Desain Program'!G13*'Input Tarif'!$D$9 -> 0 | H16: ='Desain Program'!H13*'Input Tarif'!$D$9 -> 0 | I16: ='Desain Program'!I13*'Input Tarif'!$D$9 -> 0 | J16: ='Desain Program'!J13*'Input Tarif'!$D$9 -> 0 | K16: ='Desain Program'!K13*'Input Tarif'!$D$9 -> 0
B17: Seminar offline | C17: sesi x tarif | D17: ='Desain Program'!D14*'Input Tarif'!$D$10 -> 0 | E17: ='Desain Program'!E14*'Input Tarif'!$D$10 -> 0 | F17: ='Desain Program'!F14*'Input Tarif'!$D$10 -> 0 | G17: ='Desain Program'!G14*'Input Tarif'!$D$10 -> 3000000 | H17: ='Desain Program'!H14*'Input Tarif'!$D$10 -> 0 | I17: ='Desain Program'!I14*'Input Tarif'!$D$10 -> 0 | J17: ='Desain Program'!J14*'Input Tarif'!$D$10 -> 0 | K17: ='Desain Program'!K14*'Input Tarif'!$D$10 -> 0
B18: Subtotal C. Psikoedukasi | D18: =SUM(D16:D17) -> 1500000 | E18: =SUM(E16:E17) -> 1500000 | F18: =SUM(F16:F17) -> 1500000 | G18: =SUM(G16:G17) -> 3000000 | H18: =SUM(H16:H17) -> 0 | I18: =SUM(I16:I17) -> 0 | J18: =SUM(J16:J17) -> 0 | K18: =SUM(K16:K17) -> 0
A20: D. Administrasi proyek
B21: PIC / Project Officer | C21: per program | D21: ='Input Tarif'!$D$11 -> 0 | E21: ='Input Tarif'!$D$11 -> 0 | F21: ='Input Tarif'!$D$11 -> 0 | G21: ='Input Tarif'!$D$11 -> 0 | H21: ='Input Tarif'!$D$11 -> 0 | I21: ='Input Tarif'!$D$11 -> 0 | J21: ='Input Tarif'!$D$11 -> 0 | K21: ='Input Tarif'!$D$11 -> 0
B22: Kontrak, materai, invoice | C22: per program | D22: ='Input Tarif'!$D$12 -> 150000 | E22: ='Input Tarif'!$D$12 -> 150000 | F22: ='Input Tarif'!$D$12 -> 150000 | G22: ='Input Tarif'!$D$12 -> 150000 | H22: ='Input Tarif'!$D$12 -> 150000 | I22: ='Input Tarif'!$D$12 -> 150000 | J22: ='Input Tarif'!$D$12 -> 150000 | K22: ='Input Tarif'!$D$12 -> 150000
B23: Subtotal D. Administrasi proyek | D23: =SUM(D21:D22) -> 150000 | E23: =SUM(E21:E22) -> 150000 | F23: =SUM(F21:F22) -> 150000 | G23: =SUM(G21:G22) -> 150000 | H23: =SUM(H21:H22) -> 150000 | I23: =SUM(I21:I22) -> 150000 | J23: =SUM(J21:J22) -> 150000 | K23: =SUM(K21:K22) -> 150000
A25: E. Pajak & overhead
B26: PPh 23 | C26: harga x % | D26: ='Desain Program'!D5*'Input Tarif'!$D$13 -> 240000 | E26: ='Desain Program'!E5*'Input Tarif'!$D$13 -> 220000 | F26: ='Desain Program'!F5*'Input Tarif'!$D$13 -> 400000 | G26: ='Desain Program'!G5*'Input Tarif'!$D$13 -> 630000 | H26: ='Desain Program'!H5*'Input Tarif'!$D$13 -> 230000 | I26: ='Desain Program'!I5*'Input Tarif'!$D$13 -> 210000 | J26: ='Desain Program'!J5*'Input Tarif'!$D$13 -> 350000 | K26: ='Desain Program'!K5*'Input Tarif'!$D$13 -> 570000
B27: Alokasi overhead | C27: harga x % | D27: ='Desain Program'!D5*'Input Tarif'!$D$14 -> 0 | E27: ='Desain Program'!E5*'Input Tarif'!$D$14 -> 0 | F27: ='Desain Program'!F5*'Input Tarif'!$D$14 -> 0 | G27: ='Desain Program'!G5*'Input Tarif'!$D$14 -> 0 | H27: ='Desain Program'!H5*'Input Tarif'!$D$14 -> 0 | I27: ='Desain Program'!I5*'Input Tarif'!$D$14 -> 0 | J27: ='Desain Program'!J5*'Input Tarif'!$D$14 -> 0 | K27: ='Desain Program'!K5*'Input Tarif'!$D$14 -> 0
B28: Subtotal E. Pajak & overhead | D28: =SUM(D26:D27) -> 240000 | E28: =SUM(E26:E27) -> 220000 | F28: =SUM(F26:F27) -> 400000 | G28: =SUM(G26:G27) -> 630000 | H28: =SUM(H26:H27) -> 230000 | I28: =SUM(I26:I27) -> 210000 | J28: =SUM(J26:J27) -> 350000 | K28: =SUM(K26:K27) -> 570000
B30: TOTAL BIAYA (A s/d E) | D30: =D8+D13+D18+D23+D28 -> 7665000 | E30: =E8+E13+E18+E23+E28 -> 8920000 | F30: =F8+F13+F18+F23+F28 -> 12880000 | G30: =G8+G13+G18+G23+G28 -> 20910000 | H30: =H8+H13+H18+H23+H28 -> 6155000 | I30: =I8+I13+I18+I23+I28 -> 7410000 | J30: =J8+J13+J18+J23+J28 -> 11330000 | K30: =K8+K13+K18+K23+K28 -> 17850000
