Workbook

Sheet Summary
A1: Strategi Pricing Teman Journey: Tier Psikolog dan Bagi Hasil
A2: Dibuat 13 Okt 2026. Patokan harga: sheet ACC Kia. Penyelarasan: Growth Plan 5 Okt 2026. Satuan Rupiah.
A4: Jawaban singkat
A5: 1. Harga = patokan ACC dikurangi diskon kecil (default 5%, ubah di Inputs). Pengecualian: konseling individual Tier 1 dan Tier 2 ditetapkan sama (online Rp500rb, offline Rp580rb) di kolom M sheet Pricing_Counseling. Tes harga tunggal, bagi hasil 50:50.
A6: 2. Bagi hasil psikolog : TJ = 60:40, 65:35, 65:35, 70:30 untuk Tier 1 sampai 4. Karena harga Tier 1 dan Tier 2 sama, margin TJ per sesi konseling individual Tier 2 lebih rendah dari Tier 1.
A7: 3. Masalah utama: Growth Plan memakai konseling Rp1 juta dengan psikolog 40%. Harga dan bagi hasil baru memberi profit per sesi jauh lebih kecil. Lihat bagian bawah dan sheet Alignment.
A8: 4. Risiko terbesar: harga Ibunda untuk psikolog senior tidak bisa dicek (hanya di aplikasi). Cek 3 psikolog senior sebelum harga dipublikasikan.
A10: Angka kunci (Rp per sesi) | B10: Tier 1 (0-2 th) | C10: Tier 2 (2 th 1 bln - 5 th) | D10: Tier 3 (5 th 1 bln - 10 th) | E10: Tier 4 (di atas 10 th)
A11: Harga konseling online 60 mnt | B11: =Pricing_Counseling!E5 -> 500000 | C11: =Pricing_Counseling!E6 -> 500000 | D11: =Pricing_Counseling!E7 -> 725000 | E11: =Pricing_Counseling!E8 -> 850000
A12: Fee psikolog (online) | B12: =Pricing_Counseling!G5 -> 300000 | C12: =Pricing_Counseling!G6 -> 325000 | D12: =Pricing_Counseling!G7 -> 471250 | E12: =Pricing_Counseling!G8 -> 595000
A13: Margin TJ (online) | B13: =Pricing_Counseling!H5 -> 200000 | C13: =Pricing_Counseling!H6 -> 175000 | D13: =Pricing_Counseling!H7 -> 253750 | E13: =Pricing_Counseling!H8 -> 255000
A14: Harga konseling offline 60 mnt | B14: =Pricing_Counseling!E9 -> 580000 | C14: =Pricing_Counseling!E10 -> 580000 | D14: =Pricing_Counseling!E11 -> 800000 | E14: =Pricing_Counseling!E12 -> 925000
A15: Margin TJ (offline) | B15: =Pricing_Counseling!H9 -> 232000 | C15: =Pricing_Counseling!H10 -> 203000 | D15: =Pricing_Counseling!H11 -> 280000 | E15: =Pricing_Counseling!H12 -> 277500
A17: Penyelarasan dengan Growth Plan | B17: Growth Plan | C17: Harga baru | D17: Selisih
A18: Harga rata-rata per sesi (Rp) | B18: =Alignment!B16 -> 1000000 | C18: =Alignment!C16 -> 614725 | D18: =Alignment!D16 -> -0.385275
A19: Margin TJ per sesi (Rp) | B19: =Alignment!B18 -> 600000 | C19: =Alignment!C18 -> 218651.25 | D19: =Alignment!D18 -> -0.63558125
A20: Profit per klien / biaya dapat klien: referral | B20: =Alignment!B22 -> 4.2 | C20: =Alignment!C22 -> 1.5305587 | D20: =Alignment!D22 -> -2.6694413
A21: Profit per klien / biaya dapat klien: Instagram Des 2027 | B21: =Alignment!B23 -> 1.875 | C21: =Alignment!C23 -> 0.68328516 | D21: =Alignment!D23 -> -1.1917148
A22: Sesi per bulan untuk profit Rp13 juta | B22: =Alignment!B26 -> 21.666667 | C22: =Alignment!C26 -> 59.455411 | D22: =Alignment!D26 -> 1.7440959
A23: Sesi per bulan untuk menutup biaya tetap Rp20 juta | B23: =Alignment!B28 -> 33.333333 | C23: =Alignment!C28 -> 91.469864 | D23: =Alignment!D28 -> 1.7440959
A25: Cek model: harga = fee + margin (konseling), dan campuran sesi = 100% | B25: =IF(AND(ABS(Pricing_Counseling!E34)<1,ABS(SUM(Inputs!$B$35:$B$38)-1)<0.0001),"OK","PERIKSA") -> OK

Sheet Inputs
A1: Inputs: semua angka yang bisa diubah
A2: Biru = angka input. Kuning = estimasi (ganti dengan angka asli). Hitam = rumus. Satuan Rupiah (Rp).
A4: Item | B4: Nilai | C4: Satuan | D4: Status | E4: Sumber / catatan
A5: A. Aturan harga
A6: Diskon di bawah patokan (arti 'sedikit di bawah Ibunda') | B6: 0.05 | C6: % | D6: Your plan - confirm | E6: Patokan = harga yang sudah di-ACC Kia (Google Sheet Strategi_Harga_Teman_Journey). Isi 0% untuk memakai harga ACC persis.
A7: Pembulatan harga sesi | B7: 25000 | C7: Rp | D7: Your plan - confirm | E7: Harga dibulatkan ke Rp25rb terdekat
A8: Pembulatan harga paket | B8: 100000 | C8: Rp | D8: Your plan - confirm | E8: Harga paket dibulatkan ke Rp100rb terdekat
A9: Diskon paket vs beli satuan | B9: 0.1 | C9: % | D9: Known | E9: Sheet ACC: diskon paket ~10%
A10: B. Bagi hasil (arahan Kia, sheet ACC)
A11: Bagian psikolog Tier 1 (0-2 th) | B11: 0.6 | C11: % | D11: Known | E11: Sheet ACC: Struktur Tier Psikolog
A12: Bagian psikolog Tier 2 (2 th 1 bln - 5 th) | B12: 0.65 | C12: % | D12: Known | E12: Sheet ACC: Struktur Tier Psikolog
A13: Bagian psikolog Tier 3 (5 th 1 bln - 10 th) | B13: 0.65 | C13: % | D13: Known | E13: Sheet ACC: Struktur Tier Psikolog
A14: Bagian psikolog Tier 4 (di atas 10 th) | B14: 0.7 | C14: % | D14: Known | E14: Sheet ACC: Struktur Tier Psikolog
A15: Bagian asesor untuk tes (asesmen) | B15: 0.5 | C15: % | D15: Known | E15: Sheet ACC: asesmen 50:50
A16: C. Biaya tetap
A17: Biaya tetap per bulan (di luar honor psikolog) | B17: 20000000 | C17: Rp/bulan | D17: Known | E17: Sheet ACC: Rp20 juta
A18: Running cost per bulan, Okt 2026 (Growth Plan) | B18: 32000000 | C18: Rp/bulan | D18: Known | E18: Growth Plan 5 Okt 2026, slide 2: Rp32M, naik bertahap ke Rp88M
A19: D. Biaya per sesi milik TJ
A20: Biaya platform & pembayaran per sesi konseling | B20: 50000 | C20: Rp/sesi | D20: Estimate | E20: Default CFO (Rp50rb per sesi). Ganti dengan biaya asli (Theta, payment gateway).
A21: E. Asumsi Growth Plan (5 Okt 2026)
A22: Harga konseling di Growth Plan | B22: 1000000 | C22: Rp/sesi | D22: Known | E22: Slide 11 dan 12
A23: Biaya psikolog di Growth Plan (% harga) | B23: 0.4 | C23: % | D23: Known | E23: Slide 31: pool dibayar 40% dari harga; slide 11: kelipatan 2,5x
A24: Biaya dapat 1 klien: referral | B24: 200000 | C24: Rp/klien | D24: Known | E24: Slide 18
A25: Biaya dapat 1 klien: Instagram, Jun 2027 | B25: 837000 | C25: Rp/klien | D25: Known | E25: Slide 18
A26: Biaya dapat 1 klien: Instagram, Des 2027 | B26: 448000 | C26: Rp/klien | D26: Known | E26: Slide 18
A27: Sesi per klien, Jun 2027 | B27: 1.25 | C27: sesi | D27: Known | E27: Slide 17
A28: Sesi per klien, Des 2027 | B28: 1.4 | C28: sesi | D28: Known | E28: Slide 17
A29: Sesi konseling berbayar per bulan, Des 2027 | B29: 24 | C29: sesi | D29: Known | E29: Slide 17
A30: Profit konseling yang dibutuhkan (psikolog lead + full-timer) | B30: 13000000 | C30: Rp/bulan | D30: Known | E30: Slide 17: sekitar Rp13M per bulan; Des 2027 = Rp13,4M
A31: Kapasitas 2 psikolog part-time | B31: 72 | C31: sesi/bulan | D31: Known | E31: Slide 36
A32: Biaya psikolog 1 kontrak EAP | B32: 5000000 | C32: Rp/bulan | D32: Known | E32: Slide 11
A33: Sesi EAP per kontrak per bulan | B33: 10 | C33: sesi | D33: Known | E33: Slide 36
A34: F. Campuran sesi B2C (belum ada data nyata)
A35: Porsi sesi Tier 1 | B35: 0.3 | C35: % | D35: Estimate | E35: Isi dari data booking nyata. Total harus 100%.
A36: Porsi sesi Tier 2 | B36: 0.35 | C36: % | D36: Estimate | E36: Isi dari data booking nyata. Total harus 100%.
A37: Porsi sesi Tier 3 | B37: 0.25 | C37: % | D37: Estimate | E37: Isi dari data booking nyata. Total harus 100%.
A38: Porsi sesi Tier 4 | B38: 0.1 | C38: % | D38: Estimate | E38: Isi dari data booking nyata. Total harus 100%.
A39: Porsi sesi online | B39: 0.7 | C39: % | D39: Estimate | E39: Isi dari data booking nyata
A40: G. Benchmark dan tuas
A41: Ibunda.id: harga masuk (psikolog entry-level, per jam) | B41: 179000 | C41: Rp | D41: Known | E41: Sheet ACC, sumber grome.id 2026. Harga psikolog senior Ibunda tidak publik.
...

Sheet Pricing_Counseling
A1: Harga Konseling & Terapi per Tier Psikolog
A2: Patokan = harga ACC Kia (biru). Harga usulan = patokan dikurangi diskon di Inputs, dibulatkan. Bila kolom M terisi, harga di kolom M dipakai dan menggantikan rumus. Satuan Rp per sesi atau per paket.
A4: Layanan | B4: Format | C4: Tier | D4: Patokan ACC (Rp) | E4: Harga usulan TJ (Rp) | F4: % ke psikolog | G4: Fee psikolog (Rp) | H4: Margin TJ (Rp) | I4: Margin TJ (%) | J4: Harga / fee psikolog | K4: Usulan vs patokan | L4: Catatan | M4: Harga ditetapkan (Rp, opsional)
A5: Konseling Individual | B5: Online, 60 mnt | C5: Tier 1 (0-2 th) | D5: 550000 | E5: =IF(ISNUMBER(M5),M5,MROUND(D5*(1-Inputs!$B$6),Inputs!$B$7)) -> 500000 | F5: =Inputs!$B$11 -> 0.6 | G5: =E5*F5 -> 300000 | H5: =E5-G5 -> 200000 | I5: =H5/E5 -> 0.4 | J5: =E5/G5 -> 1.6666667 | K5: =E5/D5-1 -> -0.090909091 | L5: Tier 1 dan Tier 2 ditetapkan sama, Rp500.000. Bagi hasil tetap 60% dan 65%, jadi margin TJ Tier 2 lebih rendah dari Tier 1. | M5: 500000
C6: Tier 2 (2 th 1 bln - 5 th) | D6: 650000 | E6: =IF(ISNUMBER(M6),M6,MROUND(D6*(1-Inputs!$B$6),Inputs!$B$7)) -> 500000 | F6: =Inputs!$B$12 -> 0.65 | G6: =E6*F6 -> 325000 | H6: =E6-G6 -> 175000 | I6: =H6/E6 -> 0.35 | J6: =E6/G6 -> 1.5384615 | K6: =E6/D6-1 -> -0.23076923 | M6: 500000
C7: Tier 3 (5 th 1 bln - 10 th) | D7: 750000 | E7: =IF(ISNUMBER(M7),M7,MROUND(D7*(1-Inputs!$B$6),Inputs!$B$7)) -> 725000 | F7: =Inputs!$B$13 -> 0.65 | G7: =E7*F7 -> 471250 | H7: =E7-G7 -> 253750 | I7: =H7/E7 -> 0.35 | J7: =E7/G7 -> 1.5384615 | K7: =E7/D7-1 -> -0.033333333
C8: Tier 4 (di atas 10 th) | D8: 900000 | E8: =IF(ISNUMBER(M8),M8,MROUND(D8*(1-Inputs!$B$6),Inputs!$B$7)) -> 850000 | F8: =Inputs!$B$14 -> 0.7 | G8: =E8*F8 -> 595000 | H8: =E8-G8 -> 255000 | I8: =H8/E8 -> 0.3 | J8: =E8/G8 -> 1.4285714 | K8: =E8/D8-1 -> -0.055555556
A9: Konseling Individual | B9: Offline, 60 mnt | C9: Tier 1 (0-2 th) | D9: 650000 | E9: =IF(ISNUMBER(M9),M9,MROUND(D9*(1-Inputs!$B$6),Inputs!$B$7)) -> 580000 | F9: =Inputs!$B$11 -> 0.6 | G9: =E9*F9 -> 348000 | H9: =E9-G9 -> 232000 | I9: =H9/E9 -> 0.4 | J9: =E9/G9 -> 1.6666667 | K9: =E9/D9-1 -> -0.10769231 | L9: Tier 1 dan Tier 2 ditetapkan sama, Rp580.000 (online + Rp80rb). Bagi hasil tetap 60% dan 65%. | M9: 580000
C10: Tier 2 (2 th 1 bln - 5 th) | D10: 750000 | E10: =IF(ISNUMBER(M10),M10,MROUND(D10*(1-Inputs!$B$6),Inputs!$B$7)) -> 580000 | F10: =Inputs!$B$12 -> 0.65 | G10: =E10*F10 -> 377000 | H10: =E10-G10 -> 203000 | I10: =H10/E10 -> 0.35 | J10: =E10/G10 -> 1.5384615 | K10: =E10/D10-1 -> -0.22666667 | M10: 580000
C11: Tier 3 (5 th 1 bln - 10 th) | D11: 850000 | E11: =IF(ISNUMBER(M11),M11,MROUND(D11*(1-Inputs!$B$6),Inputs!$B$7)) -> 800000 | F11: =Inputs!$B$13 -> 0.65 | G11: =E11*F11 -> 520000 | H11: =E11-G11 -> 280000 | I11: =H11/E11 -> 0.35 | J11: =E11/G11 -> 1.5384615 | K11: =E11/D11-1 -> -0.058823529
C12: Tier 4 (di atas 10 th) | D12: 975000 | E12: =IF(ISNUMBER(M12),M12,MROUND(D12*(1-Inputs!$B$6),Inputs!$B$7)) -> 925000 | F12: =Inputs!$B$14 -> 0.7 | G12: =E12*F12 -> 647500 | H12: =E12-G12 -> 277500 | I12: =H12/E12 -> 0.3 | J12: =E12/G12 -> 1.4285714 | K12: =E12/D12-1 -> -0.051282051
A13: Konseling Pasangan | B13: Offline, 90 mnt | C13: Tier 1 (0-2 th) | D13: 850000 | E13: =IF(ISNUMBER(M13),M13,MROUND(D13*(1-Inputs!$B$6),Inputs!$B$7)) -> 800000 | F13: =Inputs!$B$11 -> 0.6 | G13: =E13*F13 -> 480000 | H13: =E13-G13 -> 320000 | I13: =H13/E13 -> 0.4 | J13: =E13/G13 -> 1.6666667 | K13: =E13/D13-1 -> -0.058823529 | L13: Sekitar 1,3x konseling offline individu (ACC)
C14: Tier 2 (2 th 1 bln - 5 th) | D14: 1000000 | E14: =IF(ISNUMBER(M14),M14,MROUND(D14*(1-Inputs!$B$6),Inputs!$B$7)) -> 950000 | F14: =Inputs!$B$12 -> 0.65 | G14: =E14*F14 -> 617500 | H14: =E14-G14 -> 332500 | I14: =H14/E14 -> 0.35 | J14: =E14/G14 -> 1.5384615 | K14: =E14/D14-1 -> -0.05
C15: Tier 3 (5 th 1 bln - 10 th) | D15: 1150000 | E15: =IF(ISNUMBER(M15),M15,MROUND(D15*(1-Inputs!$B$6),Inputs!$B$7)) -> 1100000 | F15: =Inputs!$B$13 -> 0.65 | G15: =E15*F15 -> 715000 | H15: =E15-G15 -> 385000 | I15: =H15/E15 -> 0.35 | J15: =E15/G15 -> 1.5384615 | K15: =E15/D15-1 -> -0.043478261
C16: Tier 4 (di atas 10 th) | D16: 1500000 | E16: =IF(ISNUMBER(M16),M16,MROUND(D16*(1-Inputs!$B$6),Inputs!$B$7)) -> 1425000 | F16: =Inputs!$B$14 -> 0.7 | G16: =E16*F16 -> 997500 | H16: =E16-G16 -> 427500 | I16: =H16/E16 -> 0.3 | J16: =E16/G16 -> 1.4285714 | K16: =E16/D16-1 -> -0.05
A17: Pre-Marriage Check Up | B17: Paket 3 sesi @75-90 mnt | C17: Tier 1 (0-2 th) | D17: 2300000 | E17: =IF(ISNUMBER(M17),M17,MROUND(D17*(1-Inputs!$B$6),Inputs!$B$8)) -> 2200000 | F17: =Inputs!$B$11 -> 0.6 | G17: =E17*F17 -> 1320000 | H17: =E17-G17 -> 880000 | I17: =H17/E17 -> 0.4 | J17: =E17/G17 -> 1.6666667 | K17: =E17/D17-1 -> -0.043478261 | L17: 3 sesi pasangan dikurangi diskon paket 10% (ACC)
C18: Tier 2 (2 th 1 bln - 5 th) | D18: 2700000 | E18: =IF(ISNUMBER(M18),M18,MROUND(D18*(1-Inputs!$B$6),Inputs!$B$8)) -> 2600000 | F18: =Inputs!$B$12 -> 0.65 | G18: =E18*F18 -> 1690000 | H18: =E18-G18 -> 910000 | I18: =H18/E18 -> 0.35 | J18: =E18/G18 -> 1.5384615 | K18: =E18/D18-1 -> -0.037037037
C19: Tier 3 (5 th 1 bln - 10 th) | D19: 3100000 | E19: =IF(ISNUMBER(M19),M19,MROUND(D19*(1-Inputs!$B$6),Inputs!$B$8)) -> 2900000 | F19: =Inputs!$B$13 -> 0.65 | G19: =E19*F19 -> 1885000 | H19: =E19-G19 -> 1015000 | I19: =H19/E19 -> 0.35 | J19: =E19/G19 -> 1.5384615 | K19: =E19/D19-1 -> -0.064516129
C20: Tier 4 (di atas 10 th) | D20: 4000000 | E20: =IF(ISNUMBER(M20),M20,MROUND(D20*(1-Inputs!$B$6),Inputs!$B$8)) -> 3800000 | F20: =Inputs!$B$14 -> 0.7 | G20: =E20*F20 -> 2660000 | H20: =E20-G20 -> 1140000 | I20: =H20/E20 -> 0.3 | J20: =E20/G20 -> 1.4285714 | K20: =E20/D20-1 -> -0.05
A21: Marriage Check Up | B21: Paket 2 sesi @75-90 mnt | C21: Tier 1 (0-2 th) | D21: =MROUND(2*(1-Inputs!$B$9)*D13,Inputs!$B$8) -> 1500000 | E21: =IF(ISNUMBER(M21),M21,MROUND(D21*(1-Inputs!$B$6),Inputs!$B$8)) -> 1400000 | F21: =Inputs!$B$11 -> 0.6 | G21: =E21*F21 -> 840000 | H21: =E21-G21 -> 560000 | I21: =H21/E21 -> 0.4 | J21: =E21/G21 -> 1.6666667 | K21: =E21/D21-1 -> -0.066666667 | L21: ESTIMASI: 2 sesi pasangan dikurangi diskon paket. Tidak ada di sheet ACC.
C22: Tier 2 (2 th 1 bln - 5 th) | D22: =MROUND(2*(1-Inputs!$B$9)*D14,Inputs!$B$8) -> 1800000 | E22: =IF(ISNUMBER(M22),M22,MROUND(D22*(1-Inputs!$B$6),Inputs!$B$8)) -> 1700000 | F22: =Inputs!$B$12 -> 0.65 | G22: =E22*F22 -> 1105000 | H22: =E22-G22 -> 595000 | I22: =H22/E22 -> 0.35 | J22: =E22/G22 -> 1.5384615 | K22: =E22/D22-1 -> -0.055555556
C23: Tier 3 (5 th 1 bln - 10 th) | D23: =MROUND(2*(1-Inputs!$B$9)*D15,Inputs!$B$8) -> 2100000 | E23: =IF(ISNUMBER(M23),M23,MROUND(D23*(1-Inputs!$B$6),Inputs!$B$8)) -> 2000000 | F23: =Inputs!$B$13 -> 0.65 | G23: =E23*F23 -> 1300000 | H23: =E23-G23 -> 700000 | I23: =H23/E23 -> 0.35 | J23: =E23/G23 -> 1.5384615 | K23: =E23/D23-1 -> -0.047619048
C24: Tier 4 (di atas 10 th) | D24: =MROUND(2*(1-Inputs!$B$9)*D16,Inputs!$B$8) -> 2700000 | E24: =IF(ISNUMBER(M24),M24,MROUND(D24*(1-Inputs!$B$6),Inputs!$B$8)) -> 2600000 | F24: =Inputs!$B$14 -> 0.7 | G24: =E24*F24 -> 1820000 | H24: =E24-G24 -> 780000 | I24: =H24/E24 -> 0.3 | J24: =E24/G24 -> 1.4285714 | K24: =E24/D24-1 -> -0.037037037
A25: Clinical Therapy (EMDR / Hypnotherapy) | B25: Offline, 60-90 mnt | C25: Tier 1 (0-2 th) | D25: 800000 | E25: =IF(ISNUMBER(M25),M25,MROUND(D25*(1-Inputs!$B$6),Inputs!$B$7)) -> 750000 | F25: =Inputs!$B$11 -> 0.6 | G25: =E25*F25 -> 450000 | H25: =E25-G25 -> 300000 | I25: =H25/E25 -> 0.4 | J25: =E25/G25 -> 1.6666667 | K25: =E25/D25-1 -> -0.0625 | L25: Hanya untuk psikolog bersertifikat EMDR/hipnoterapi
C26: Tier 2 (2 th 1 bln - 5 th) | D26: 950000 | E26: =IF(ISNUMBER(M26),M26,MROUND(D26*(1-Inputs!$B$6),Inputs!$B$7)) -> 900000 | F26: =Inputs!$B$12 -> 0.65 | G26: =E26*F26 -> 585000 | H26: =E26-G26 -> 315000 | I26: =H26/E26 -> 0.35 | J26: =E26/G26 -> 1.5384615 | K26: =E26/D26-1 -> -0.052631579
C27: Tier 3 (5 th 1 bln - 10 th) | D27: 1050000 | E27: =IF(ISNUMBER(M27),M27,MROUND(D27*(1-Inputs!$B$6),Inputs!$B$7)) -> 1000000 | F27: =Inputs!$B$13 -> 0.65 | G27: =E27*F27 -> 650000 | H27: =E27-G27 -> 350000 | I27: =H27/E27 -> 0.35 | J27: =E27/G27 -> 1.5384615 | K27: =E27/D27-1 -> -0.047619048
C28: Tier 4 (di atas 10 th) | D28: 1400000 | E28: =IF(ISNUMBER(M28),M28,MROUND(D28*(1-Inputs!$B$6),Inputs!$B$7)) -> 1325000 | F28: =Inputs!$B$14 -> 0.7 | G28: =E28*F28 -> 927500 | H28: =E28-G28 -> 397500 | I28: =H28/E28 -> 0.3 | J28: =E28/G28 -> 1.4285714 | K28: =E28/D28-1 -> -0.053571429
A29: Clinical Therapy (EMDR / Hypnotherapy) | B29: Online, 60-90 mnt | C29: Tier 1 (0-2 th) | D29: 700000 | E29: =IF(ISNUMBER(M29),M29,MROUND(D29*(1-Inputs!$B$6),Inputs!$B$7)) -> 675000 | F29: =Inputs!$B$11 -> 0.6 | G29: =E29*F29 -> 405000 | H29: =E29-G29 -> 270000 | I29: =H29/E29 -> 0.4 | J29: =E29/G29 -> 1.6666667 | K29: =E29/D29-1 -> -0.035714286 | L29: Sekitar 10% di bawah offline (ACC)
C30: Tier 2 (2 th 1 bln - 5 th) | D30: 850000 | E30: =IF(ISNUMBER(M30),M30,MROUND(D30*(1-Inputs!$B$6),Inputs!$B$7)) -> 800000 | F30: =Inputs!$B$12 -> 0.65 | G30: =E30*F30 -> 520000 | H30: =E30-G30 -> 280000 | I30: =H30/E30 -> 0.35 | J30: =E30/G30 -> 1.5384615 | K30: =E30/D30-1 -> -0.058823529
C31: Tier 3 (5 th 1 bln - 10 th) | D31: 950000 | E31: =IF(ISNUMBER(M31),M31,MROUND(D31*(1-Inputs!$B$6),Inputs!$B$7)) -> 900000 | F31: =Inputs!$B$13 -> 0.65 | G31: =E31*F31 -> 585000 | H31: =E31-G31 -> 315000 | I31: =H31/E31 -> 0.35 | J31: =E31/G31 -> 1.5384615 | K31: =E31/D31-1 -> -0.052631579
C32: Tier 4 (di atas 10 th) | D32: 1250000 | E32: =IF(ISNUMBER(M32),M32,MROUND(D32*(1-Inputs!$B$6),Inputs!$B$7)) -> 1200000 | F32: =Inputs!$B$14 -> 0.7 | G32: =E32*F32 -> 840000 | H32: =E32-G32 -> 360000 | I32: =H32/E32 -> 0.3 | J32: =E32/G32 -> 1.4285714 | K32: =E32/D32-1 -> -0.04
A34: Cek: harga = fee psikolog + margin TJ (harus 0) | E34: =SUM(E5:E32)-SUM(G5:G32)-SUM(H5:H32) -> 0
A35: Catatan: bagi hasil di sini dihitung dari harga sebelum biaya platform. Margin TJ belum dikurangi biaya platform dan biaya akuisisi (lihat Profit_Share).

Sheet Pricing_Assessment
A1: Harga Tes (Asesmen): harga tunggal, bagi hasil 50:50
A2: Mengikuti sheet ACC: tes tidak berjenjang per tier karena bagi hasilnya sama untuk semua asesor. Harga sudah termasuk laporan tertulis.
A4: Layanan | B4: Usia | C4: Patokan ACC (Rp) | D4: Harga usulan TJ (Rp) | E4: % ke asesor | F4: Fee asesor (Rp) | G4: Biaya alat tes (Rp) | H4: Margin TJ (Rp) | I4: Margin TJ (%) | J4: Catatan
A5: Skrining Tumbuh Kembang | B5: 0-5 th | C5: 650000 | D5: =MROUND(C5*(1-Inputs!$B$6),Inputs!$B$7) -> 625000 | E5: =Inputs!$B$15 -> 0.5 | F5: =D5*E5 -> 312500 | G5: 0 | H5: =D5-F5-G5 -> 312500 | I5: =H5/D5 -> 0.5 | J5: ACC
A6: Tes IQ | B6: Anak sampai dewasa | C6: 750000 | D6: =MROUND(C6*(1-Inputs!$B$6),Inputs!$B$7) -> 725000 | E6: =Inputs!$B$15 -> 0.5 | F6: =D6*E6 -> 362500 | G6: 0 | H6: =D6-F6-G6 -> 362500 | I6: =H6/D6 -> 0.5 | J6: ESTIMASI: tidak ada di sheet ACC. Disamakan dengan Tes Minat Bakat (baterai kognitif + laporan). Cek harga WISC/IQ Rumah Dandelion.
A7: Tes Kesiapan Sekolah | B7: 4-6 th | C7: 850000 | D7: =MROUND(C7*(1-Inputs!$B$6),Inputs!$B$7) -> 800000 | E7: =Inputs!$B$15 -> 0.5 | F7: =D7*E7 -> 400000 | G7: 0 | H7: =D7-F7-G7 -> 400000 | I7: =H7/D7 -> 0.5 | J7: ACC
A8: Tes Minat Bakat | B8: Minimal 14 th | C8: 1700000 | D8: =MROUND(C8*(1-Inputs!$B$6),Inputs!$B$7) -> 1625000 | E8: =Inputs!$B$15 -> 0.5 | F8: =D8*E8 -> 812500 | G8: 0 | H8: =D8-F8-G8 -> 812500 | I8: =H8/D8 -> 0.5 | J8: ACC
A9: Tes Profiling | B9: 6-13 th | C9: 1300000 | D9: =MROUND(C9*(1-Inputs!$B$6),Inputs!$B$7) -> 1225000 | E9: =Inputs!$B$15 -> 0.5 | F9: =D9*E9 -> 612500 | G9: 0 | H9: =D9-F9-G9 -> 612500 | I9: =H9/D9 -> 0.5 | J9: ACC
A10: Tes Kesehatan Mental Dewasa (MHCU) | B10: Dewasa | C10: 400000 | D10: =MROUND(C10*(1-Inputs!$B$6),Inputs!$B$7) -> 375000 | E10: =Inputs!$B$15 -> 0.5 | F10: =D10*E10 -> 187500 | G10: =Inputs!$B$42 -> 70000 | H10: =D10-F10-G10 -> 117500 | I10: =H10/D10 -> 0.31333333 | J10: ACC (komponen asesmen MHCU)
A12: Catatan: biaya alat tes selain MHCU diisi Rp0 sebagai tempat sementara (kuning). Margin tes akan lebih rendah bila ada lisensi atau alat bayar-per-pakai.

Sheet Catalog
A1: Katalog Harga Teman Journey (harga usulan)
A2: Semua angka mengambil dari sheet Pricing. Ubah di Inputs atau Pricing, katalog ikut berubah.
A4: A. Layanan berjenjang per tier psikolog (Rp)
A5: Layanan | B5: Format | C5: Tier 1 (0-2 th) | D5: Tier 2 (2 th 1 bln - 5 th) | E5: Tier 3 (5 th 1 bln - 10 th) | F5: Tier 4 (di atas 10 th)
A6: Konseling Individual | B6: Online, 60 mnt | C6: =Pricing_Counseling!E5 -> 500000 | D6: =Pricing_Counseling!E6 -> 500000 | E6: =Pricing_Counseling!E7 -> 725000 | F6: =Pricing_Counseling!E8 -> 850000
A7: Konseling Individual | B7: Offline, 60 mnt | C7: =Pricing_Counseling!E9 -> 580000 | D7: =Pricing_Counseling!E10 -> 580000 | E7: =Pricing_Counseling!E11 -> 800000 | F7: =Pricing_Counseling!E12 -> 925000
A8: Konseling Pasangan | B8: Offline, 90 mnt | C8: =Pricing_Counseling!E13 -> 800000 | D8: =Pricing_Counseling!E14 -> 950000 | E8: =Pricing_Counseling!E15 -> 1100000 | F8: =Pricing_Counseling!E16 -> 1425000
A9: Pre-Marriage Check Up | B9: Paket 3 sesi @75-90 mnt | C9: =Pricing_Counseling!E17 -> 2200000 | D9: =Pricing_Counseling!E18 -> 2600000 | E9: =Pricing_Counseling!E19 -> 2900000 | F9: =Pricing_Counseling!E20 -> 3800000
A10: Marriage Check Up | B10: Paket 2 sesi @75-90 mnt | C10: =Pricing_Counseling!E21 -> 1400000 | D10: =Pricing_Counseling!E22 -> 1700000 | E10: =Pricing_Counseling!E23 -> 2000000 | F10: =Pricing_Counseling!E24 -> 2600000
A11: Clinical Therapy (EMDR / Hypnotherapy) | B11: Offline, 60-90 mnt | C11: =Pricing_Counseling!E25 -> 750000 | D11: =Pricing_Counseling!E26 -> 900000 | E11: =Pricing_Counseling!E27 -> 1000000 | F11: =Pricing_Counseling!E28 -> 1325000
A12: Clinical Therapy (EMDR / Hypnotherapy) | B12: Online, 60-90 mnt | C12: =Pricing_Counseling!E29 -> 675000 | D12: =Pricing_Counseling!E30 -> 800000 | E12: =Pricing_Counseling!E31 -> 900000 | F12: =Pricing_Counseling!E32 -> 1200000
A14: B. Tes (harga tunggal, semua asesor) (Rp)
A15: Layanan | B15: Usia | C15: Harga
A16: Skrining Tumbuh Kembang | B16: 0-5 th | C16: =Pricing_Assessment!D5 -> 625000
A17: Tes IQ | B17: Anak sampai dewasa | C17: =Pricing_Assessment!D6 -> 725000
A18: Tes Kesiapan Sekolah | B18: 4-6 th | C18: =Pricing_Assessment!D7 -> 800000
A19: Tes Minat Bakat | B19: Minimal 14 th | C19: =Pricing_Assessment!D8 -> 1625000
A20: Tes Profiling | B20: 6-13 th | C20: =Pricing_Assessment!D9 -> 1225000
A21: Tes Kesehatan Mental Dewasa (MHCU) | B21: Dewasa | C21: =Pricing_Assessment!D10 -> 375000

Sheet Profit_Share
A1: Bagi Hasil Psikolog dan Teman Journey
A2: Persentase mengikuti arahan Kia (sheet ACC). Batas tier diperbarui sesuai permintaan: 0-2, 2 th 1 bln-5, 5 th 1 bln-10, di atas 10 tahun.
A3: A. Struktur tier
A4: Tier | B4: Pengalaman psikolog | C4: % psikolog | D4: % TJ | E4: Layak untuk | F4: Catatan
A5: Tier 1 | B5: 0-2 tahun | C5: =Inputs!$B$11 -> 0.6 | D5: =1-C5 -> 0.4 | E5: Konseling individual, tes. Terapi klinis hanya jika bersertifikat. | F5: Diawasi psikolog senior. Tahap awal (belum ada klien sendiri).
A6: Tier 2 | B6: 2 tahun 1 bulan - 5 tahun | C6: =Inputs!$B$12 -> 0.65 | D6: =1-C6 -> 0.35 | E6: Semua layanan konseling, pasangan, tes. | F6: Naik dari Tier 1 bila ada rating klien dan jam terbang.
A7: Tier 3 | B7: 5 tahun 1 bulan - 10 tahun | C7: =Inputs!$B$13 -> 0.65 | D7: =1-C7 -> 0.35 | E7: Semua layanan, termasuk pranikah, nikah, terapi. | F7: Sheet ACC punya celah 8-10 tahun. Batas baru menutup celah itu.
A8: Tier 4 | B8: Di atas 10 tahun | C8: =Inputs!$B$14 -> 0.7 | D8: =1-C8 -> 0.3 | E8: Semua layanan, kasus kompleks, supervisi. | F8: ACC: atau Dosen PTN. Konfirmasi apakah dosen PTN langsung Tier 4.
A10: B. Dari harga sampai ke kantong TJ: Konseling Individual Online 60 mnt (per sesi, Rp)
A11: Baris | B11: Tier 1 (0-2 th) | C11: Tier 2 (2 th 1 bln - 5 th) | D11: Tier 3 (5 th 1 bln - 10 th) | E11: Tier 4 (di atas 10 th)
A12: Harga usulan | B12: =Pricing_Counseling!E5 -> 500000 | C12: =Pricing_Counseling!E6 -> 500000 | D12: =Pricing_Counseling!E7 -> 725000 | E12: =Pricing_Counseling!E8 -> 850000
A13: Fee psikolog | B13: =Pricing_Counseling!G5 -> 300000 | C13: =Pricing_Counseling!G6 -> 325000 | D13: =Pricing_Counseling!G7 -> 471250 | E13: =Pricing_Counseling!G8 -> 595000
A14: Margin kotor TJ | B14: =Pricing_Counseling!H5 -> 200000 | C14: =Pricing_Counseling!H6 -> 175000 | D14: =Pricing_Counseling!H7 -> 253750 | E14: =Pricing_Counseling!H8 -> 255000
A15: Dikurangi biaya platform dan pembayaran | B15: =-Inputs!$B$20 -> -50000 | C15: =-Inputs!$B$20 -> -50000 | D15: =-Inputs!$B$20 -> -50000 | E15: =-Inputs!$B$20 -> -50000
A16: Kontribusi TJ per sesi: klien organik (word of mouth) | B16: =B14+B15 -> 150000 | C16: =C14+C15 -> 125000 | D16: =D14+D15 -> 203750 | E16: =E14+E15 -> 205000
A17: Dikurangi biaya akuisisi per sesi: klien Instagram (biaya dapat klien / sesi per klien, Des 2027) | B17: =-Inputs!$B$26/Inputs!$B$28 -> -320000 | C17: =-Inputs!$B$26/Inputs!$B$28 -> -320000 | D17: =-Inputs!$B$26/Inputs!$B$28 -> -320000 | E17: =-Inputs!$B$26/Inputs!$B$28 -> -320000
A18: Kontribusi TJ per sesi: klien Instagram | B18: =B16+B17 -> -170000 | C18: =C16+C17 -> -195000 | D18: =D16+D17 -> -116250 | E18: =E16+E17 -> -115000
A19: Dikurangi biaya akuisisi per sesi: klien referral (Des 2027) | B19: =-Inputs!$B$24/Inputs!$B$28 -> -142857.14 | C19: =-Inputs!$B$24/Inputs!$B$28 -> -142857.14 | D19: =-Inputs!$B$24/Inputs!$B$28 -> -142857.14 | E19: =-Inputs!$B$24/Inputs!$B$28 -> -142857.14
A20: Kontribusi TJ per sesi: klien referral | B20: =B16+B19 -> 7142.8571 | C20: =C16+C19 -> -17857.143 | D20: =D16+D19 -> 60892.857 | E20: =E16+E19 -> 62142.857
A21: Kontribusi TJ per klien (1,4 sesi): Instagram | B21: =B18*Inputs!$B$28 -> -238000 | C21: =C18*Inputs!$B$28 -> -273000 | D21: =D18*Inputs!$B$28 -> -162750 | E21: =E18*Inputs!$B$28 -> -161000
A22: Kontribusi TJ per klien (1,4 sesi): referral | B22: =B20*Inputs!$B$28 -> 10000 | C22: =C20*Inputs!$B$28 -> -25000 | D22: =D20*Inputs!$B$28 -> 85250 | E22: =E20*Inputs!$B$28 -> 87000
A24: C. Penghasilan psikolog per bulan: konseling online 60 mnt (Rp)
A25: Sesi per bulan | B25: Tier 1 (0-2 th) | C25: Tier 2 (2 th 1 bln - 5 th) | D25: Tier 3 (5 th 1 bln - 10 th) | E25: Tier 4 (di atas 10 th)
A26: 8 | B26: =$A26*B13 -> 2400000 | C26: =$A26*C13 -> 2600000 | D26: =$A26*D13 -> 3770000 | E26: =$A26*E13 -> 4760000
A27: 16 | B27: =$A27*B13 -> 4800000 | C27: =$A27*C13 -> 5200000 | D27: =$A27*D13 -> 7540000 | E27: =$A27*E13 -> 9520000
A28: 24 | B28: =$A28*B13 -> 7200000 | C28: =$A28*C13 -> 7800000 | D28: =$A28*D13 -> 11310000 | E28: =$A28*E13 -> 14280000
A29: 36 | B29: =$A29*B13 -> 10800000 | C29: =$A29*C13 -> 11700000 | D29: =$A29*D13 -> 16965000 | E29: =$A29*E13 -> 21420000
A30: 36 sesi per bulan = kapasitas 1 psikolog part-time di Growth Plan (3 shift per minggu, 3 sesi per shift).
A32: D. Aturan bagi hasil (usulan, untuk dimasukkan ke kontrak psikolog)
A33: 1. Bagi hasil dihitung dari harga yang benar-benar dibayar klien, setelah diskon paket. Credit referral Rp100rb ditanggung porsi TJ, bukan psikolog.
A34: 2. Dibayar per sesi yang terlaksana, tanpa gaji tetap. Ini sejalan dengan Growth Plan: part-timer dibayar per sesi supaya bulan sepi tidak membakar kas.
A35: 3. Klien batal kurang dari 24 jam: psikolog menerima 50% dari fee sesi (usulan, perlu persetujuan Kia).
A36: 4. Review tier tiap 6 bulan: naik tier bila masa pengalaman cukup dan rating klien 4,5 dari 5 atau lebih (sesuai Growth Plan slide 35).
A37: 5. EAP dan B2B: fee flat per sesi sesuai tier (lihat Alignment, blok EAP), bukan persentase.
A38: 6. Tes: 50:50 dari harga tes setelah biaya alat tes. Tidak berjenjang per tier.
A39: 7. Terapi klinis (EMDR/hipnoterapi): hanya psikolog bersertifikat. Harga mengikuti tier pengalaman.
A40: 8. Opsional (tuas): untuk klien yang datang dari iklan TJ, sebagian poin bagi hasil dapat pindah ke TJ sebagai biaya akuisisi. Default 0 poin (sesuai ACC). Angka di Inputs.

Sheet Alignment
A1: Penyelarasan dengan Growth Plan (5 Okt 2026)
A2: Growth Plan mengasumsikan konseling Rp1 juta per sesi dan psikolog 40%. Sheet ini menunjukkan apa yang berubah dengan harga dan bagi hasil baru.
A4: A. Ekonomi campuran (memakai campuran tier dan porsi online dari Inputs, estimasi)
A5: Harga rata-rata online (Rp/sesi) | B5: =SUMPRODUCT(Inputs!$B$35:$B$38,Pricing_Counseling!E5:E8) -> 591250
A6: Harga rata-rata offline (Rp/sesi) | B6: =SUMPRODUCT(Inputs!$B$35:$B$38,Pricing_Counseling!E9:E12) -> 669500
A7: Margin TJ rata-rata online (Rp/sesi) | B7: =SUMPRODUCT(Inputs!$B$35:$B$38,Pricing_Counseling!H5:H8) -> 210187.5
A8: Margin TJ rata-rata offline (Rp/sesi) | B8: =SUMPRODUCT(Inputs!$B$35:$B$38,Pricing_Counseling!H9:H12) -> 238400
A9: Harga rata-rata semua sesi (Rp/sesi) | B9: =Inputs!$B$39*B5+(1-Inputs!$B$39)*B6 -> 614725
A10: Margin TJ rata-rata semua sesi (Rp/sesi) | B10: =Inputs!$B$39*B7+(1-Inputs!$B$39)*B8 -> 218651.25
A11: % rata-rata ke psikolog | B11: =1-B10/B9 -> 0.64431046
A12: Margin TJ setelah biaya platform (Rp/sesi) | B12: =B10-Inputs!$B$20 -> 168651.25
A14: B. Growth Plan vs harga baru
A15: Ukuran | B15: Growth Plan | C15: Harga baru | D15: Selisih | E15: Arti
A16: Harga rata-rata per sesi (Rp) | B16: =Inputs!$B$22 -> 1000000 | C16: =B9 -> 614725 | D16: =C16/B16-1 -> -0.385275 | E16: Harga baru jauh di bawah asumsi plan.
A17: % ke psikolog | B17: =Inputs!$B$23 -> 0.4 | C17: =B11 -> 0.64431046 | D17: =C17-B17 -> 0.24431046 | E17: Bagi hasil ACC lebih tinggi dari 40% di plan.
A18: Margin TJ per sesi (Rp, kotor) | B18: =Inputs!$B$22*(1-Inputs!$B$23) -> 600000 | C18: =B10 -> 218651.25 | D18: =C18/B18-1 -> -0.63558125 | E18: Profit per sesi turun tajam.
A19: Margin TJ per sesi setelah biaya platform (Rp) | B19: =B18 -> 600000 | C19: =B12 -> 168651.25 | D19: =C19/B19-1 -> -0.71891458 | E19: Plan tidak memotong biaya platform.
A20: Harga / biaya psikolog (kelipatan) | B20: =1/Inputs!$B$23 -> 2.5 | C20: =B9/(B9-B10) -> 1.5520468 | D20: =C20-B20 -> -0.94795319 | E20: Aturan plan: konseling 2,5x (pengecualian dari 3x).
A21: Profit per klien: margin kotor x sesi per klien Des 2027 (Rp) | B21: =B18*Inputs!$B$28 -> 840000 | C21: =C18*Inputs!$B$28 -> 306111.75 | D21: =C21/B21-1 -> -0.63558125 | E21: Plan: Rp840rb per klien.
A22: Profit per klien / biaya dapat klien: referral | B22: =B21/Inputs!$B$24 -> 4.2 | C22: =C21/Inputs!$B$24 -> 1.5305587 | D22: =C22-B22 -> -2.6694413 | E22: Plan: 4,2x.
A23: Profit per klien / biaya dapat klien: Instagram Des 2027 | B23: =B21/Inputs!$B$26 -> 1.875 | C23: =C21/Inputs!$B$26 -> 0.68328516 | D23: =C23-B23 -> -1.1917148 | E23: Plan: 1,9x. Di bawah 1x = iklan tidak balik modal dari konseling saja.
A24: Profit per klien / biaya dapat klien: Instagram Jun 2027 | B24: =B18*Inputs!$B$27/Inputs!$B$25 -> 0.89605735 | C24: =C18*Inputs!$B$27/Inputs!$B$25 -> 0.3265401 | D24: =C24-B24 -> -0.56951725 | E24: Plan: 0,9x.
A25: Profit konseling di volume plan Des 2027 (Rp/bulan) | B25: =Inputs!$B$29*B18 -> 14400000 | C25: =Inputs!$B$29*C18 -> 5247630 | D25: =C25/B25-1 -> -0.63558125 | E25: 24 sesi per bulan.
A26: Sesi per bulan untuk profit Rp13 juta | B26: =Inputs!$B$30/B18 -> 21.666667 | C26: =Inputs!$B$30/C18 -> 59.455411 | D26: =C26/B26-1 -> 1.7440959 | E26: Target plan untuk membayar psikolog lead + full-timer.
A27: Beban 2 psikolog part-time (kapasitas 72 sesi) | B27: =B26/Inputs!$B$31 -> 0.30092593 | C27: =C26/Inputs!$B$31 -> 0.8257696 | D27: =C27-B27 -> 0.52484368 | E27: Sehat 60-80% (slide 36). Di atas 100% = butuh psikolog tambahan.
A28: Sesi per bulan untuk menutup biaya tetap Rp20 juta | B28: =Inputs!$B$17/B18 -> 33.333333 | C28: =Inputs!$B$17/C18 -> 91.469864 | D28: =C28/B28-1 -> 1.7440959 | E28: Konseling saja belum cukup. B2B tetap mesin utama.
A29: Sesi per bulan untuk menutup running cost Rp32 juta | B29: =Inputs!$B$18/B18 -> 53.333333 | C29: =Inputs!$B$18/C18 -> 146.35178 | D29: =C29/B29-1 -> 1.7440959 | E29: Running cost Growth Plan Okt 2026.
A30: Biaya tetap Rp20 juta tertutup di 24 sesi per bulan | B30: =B25/Inputs!$B$17 -> 0.72 | C30: =C25/Inputs!$B$17 -> 0.2623815 | D30: =C30-B30 -> -0.4576185
A32: C. Profit per klien / biaya dapat klien, jika klien membeli lebih banyak sesi (harga baru, margin setelah biaya platform)
A33: Sesi per klien | B33: Referral | C33: Instagram Des 2027 | D33: Instagram Jun 2027
A34: Biaya dapat klien (Rp) | B34: =Inputs!$B$24 -> 200000 | C34: =Inputs!$B$26 -> 448000 | D34: =Inputs!$B$25 -> 837000
A35: 1.4 | B35: =$A35*$B$12/B$34 -> 1.1805588 | C35: =$A35*$B$12/C$34 -> 0.52703516 | D35: =$A35*$B$12/D$34 -> 0.28209289
A36: 2 | B36: =$A36*$B$12/B$34 -> 1.6865125 | C36: =$A36*$B$12/C$34 -> 0.75290737 | D36: =$A36*$B$12/D$34 -> 0.40298984
A37: 3 | B37: =$A37*$B$12/B$34 -> 2.5297688 | C37: =$A37*$B$12/C$34 -> 1.129361 | D37: =$A37*$B$12/D$34 -> 0.60448477
A38: 4 | B38: =$A38*$B$12/B$34 -> 3.373025 | C38: =$A38*$B$12/C$34 -> 1.5058147 | D38: =$A38*$B$12/D$34 -> 0.80597969
A39: Aturan Growth Plan untuk iklan: harus menghasilkan 3x biayanya (ROAS 3x). Tabel ini menunjukkan berapa sesi per klien yang dibutuhkan.
A41: D. Tuas untuk menutup selisih (diurutkan dari paling mudah dilakukan)
A42: Tuas | B42: Efek | C42: Satuan | D42: Cara
A43: 1. Paket 4 sesi (sheet Pricing: paket diskon 10%) menaikkan sesi per klien | B43: =Inputs!$B$45*$B$12/Inputs!$B$26 -> 1.129361 | C43: profit / biaya dapat klien, Instagram Des 2027 | D43: Tawarkan paket setelah sesi pertama. Mengubah klien sekali datang jadi klien berulang.
A44: Sama, untuk klien referral | B44: =Inputs!$B$45*$B$12/Inputs!$B$24 -> 2.5297688 | C44: profit / biaya dapat klien, referral
...

Sheet To_Fill
A1: To_Fill: angka yang masih estimasi
A2: Setiap baris mengubah angka di model. Isi kolom kuning dengan angka asli, lalu masukkan ke sheet Inputs.
A4: Item | B4: Nilai yang dipakai | C4: Kenapa penting | D4: Di mana | E4: Angka asli Anda
A5: Harga Ibunda untuk psikolog senior (cek 3 psikolog di aplikasi) | B5: Tidak tersedia. Hanya harga masuk Rp179rb. | C5: Ini patokan 'sedikit di bawah Ibunda'. Bila Ibunda senior di bawah Tier 3-4 TJ, harga TJ terlalu tinggi. | D5: Inputs, bagian A dan G
A6: Diskon di bawah patokan | B6: =Inputs!B6 -> 0.05 | C6: 0% = harga ACC persis. 5% = sedikit di bawah. | D6: Inputs
A7: Campuran tier dan porsi online | B7: 30/35/25/10 dan 70% | C7: Menentukan margin rata-rata per sesi dan semua hasil di sheet Alignment. | D7: Inputs, bagian F
A8: Biaya platform per sesi | B8: =Inputs!B20 -> 50000 | C8: Rp50rb per sesi memotong margin sekitar 20-25%. | D8: Inputs
A9: Harga Tes IQ | B9: Rp750rb (estimasi) | C9: Tidak ada di sheet ACC. Samakan dengan harga Rumah Dandelion bila ada. | D9: Pricing_Assessment
A10: Harga Tes Kesehatan Mental Anak | B10: Rp600rb (estimasi) | C10: Tidak ada di sheet ACC. | D10: Pricing_Assessment
A11: Harga Marriage Check Up | B11: Turunan dari konseling pasangan (estimasi) | C11: Tidak ada di sheet ACC. Tentukan jumlah sesi dan isi. | D11: Pricing_Counseling
A12: Biaya alat tes selain MHCU | B12: Rp0 | C12: Margin tes terlalu tinggi bila alat tes berbayar. | D12: Pricing_Assessment
A13: Biaya tetap untuk titik impas | B13: Rp20 juta (ACC) vs Rp32 juta (Growth Plan) | C13: Dua dokumen memakai angka berbeda. Pilih satu. | D13: Inputs, bagian C
A14: Aturan Tier 4: apakah dosen PTN langsung Tier 4 | B14: Belum ditentukan | C14: Sheet ACC menyebut 'atau Dosen PTN'. Permintaan baru hanya menyebut 10 tahun. | D14: Profit_Share
A15: Terapi klinis: siapa yang bersertifikat EMDR/hipnoterapi | B15: Belum ada data | C15: Menentukan tier mana yang boleh menjual layanan ini. | D15: Pricing_Counseling

Sheet Perbandingan_Kompetitor
A1: Perbandingan Harga dengan Kompetitor (Amanasa dan Ibunda.id)
A2: Selisih = harga TJ dibagi harga kompetitor, dikurangi 1. Positif: TJ lebih mahal. Dalam kurung: TJ lebih murah. Harga TJ diambil dari sheet Pricing_Counseling dan Pricing_Assessment.
A3: Biru: harga kompetitor. Kuning: estimasi. Sumber Amanasa: pricelist story Instagram @amanasa.id (kebanyakan diunggah sekitar 5 minggu sebelum 12 Okt 2026, daftar MHCU sekitar 24 minggu). Sumber Ibunda.id: halaman harga situs ibunda.id (tab Offline).
A5: Temuan utama (dihitung dari tabel di bawah)
A6: Konseling online: TJ vs Amanasa (rata-rata 4 tier) | C6: =AVERAGE(F15:F18) -> 0.2946761 | H6: =IF(C6>0,"TJ lebih mahal","TJ lebih murah") -> TJ lebih mahal
A7: Konseling offline: TJ vs Amanasa (rata-rata 4 tier) | C7: =AVERAGE(F21:F24) -> -0.095159583 | H7: =IF(C7>0,"TJ lebih mahal","TJ lebih murah") -> TJ lebih murah
A8: Konseling offline: TJ vs Ibunda (Tier 1 sampai 4) | C8: =AVERAGE(G21:G24) -> 0.20847883 | H8: =IF(C8>0,"TJ lebih mahal","TJ lebih murah") -> TJ lebih mahal
A9: Konseling pasangan per 60 mnt: TJ vs Amanasa on-site (rata-rata) | C9: =AVERAGE(F27:F30) -> -0.1994382 | H9: =IF(C9>0,"TJ lebih mahal","TJ lebih murah") -> TJ lebih murah
A10: Pre-Marriage dan Marriage Check Up: TJ vs Couple Fit Check (rata-rata) | C10: =AVERAGE(F33:F36,F39:F42) -> -0.63212121 | H10: =IF(C10>0,"TJ lebih mahal","TJ lebih murah") -> TJ lebih murah
A11: Clinical Therapy offline: TJ vs Amanasa Hipnoterapi (rata-rata) | C11: =AVERAGE(F45:F48) -> 0.44021739 | H11: =IF(C11>0,"TJ lebih mahal","TJ lebih murah") -> TJ lebih mahal
A13: A. Konseling individual online (Rp per sesi, 60 menit)
A14: Layanan | B14: Tingkat atau format | C14: Harga TJ (Rp) | D14: Amanasa (Rp) | E14: Ibunda.id (Rp) | F14: TJ vs Amanasa | G14: TJ vs Ibunda | H14: Pembanding dan catatan
A15: Konseling individual online, 60 mnt | B15: Tier 1 (0-2 th) | C15: =Pricing_Counseling!E5 -> 500000 | D15: 395000 | E15: Belum ada data | F15: =IF(ISNUMBER(D15),C15/D15-1,"") -> 0.26582278 | G15: =IF(ISNUMBER(E15),C15/E15-1,"") | H15: Amanasa: psikolog Associate, Google Meet. Tab Online Ibunda belum dicek.
B16: Tier 2 (2 th 1 bln - 5 th) | C16: =Pricing_Counseling!E6 -> 500000 | D16: 395000 | E16: Belum ada data | F16: =IF(ISNUMBER(D16),C16/D16-1,"") -> 0.26582278 | G16: =IF(ISNUMBER(E16),C16/E16-1,"") | H16: Amanasa: psikolog Associate.
B17: Tier 3 (5 th 1 bln - 10 th) | C17: =Pricing_Counseling!E7 -> 725000 | D17: 595000 | E17: Belum ada data | F17: =IF(ISNUMBER(D17),C17/D17-1,"") -> 0.2184874 | G17: =IF(ISNUMBER(E17),C17/E17-1,"") | H17: Amanasa: Co-Founder, Rp395.000 ditambah Rp200.000.
B18: Tier 4 (di atas 10 th) | C18: =Pricing_Counseling!E8 -> 850000 | D18: 595000 | E18: Belum ada data | F18: =IF(ISNUMBER(D18),C18/D18-1,"") -> 0.42857143 | G18: =IF(ISNUMBER(E18),C18/E18-1,"") | H18: Amanasa: Co-Founder.
A19: B. Konseling individual offline (Rp per sesi, 60 menit)
A20: Layanan | B20: Tingkat atau format | C20: Harga TJ (Rp) | D20: Amanasa (Rp) | E20: Ibunda.id (Rp) | F20: TJ vs Amanasa | G20: TJ vs Ibunda | H20: Pembanding dan catatan
A21: Konseling individual offline, 60 mnt | B21: Tier 1 (0-2 th) | C21: =Pricing_Counseling!E9 -> 580000 | D21: 690000 | E21: 469000 | F21: =IF(ISNUMBER(D21),C21/D21-1,"") -> -0.15942029 | G21: =IF(ISNUMBER(E21),C21/E21-1,"") -> 0.23667377 | H21: Amanasa: Associate, on-site Klinik Eksekutif Jakarta atau Rumah Asa. Ibunda Essential (setara Tier 1 dan Tier 2): pengalaman 2-4 tahun.
B22: Tier 2 (2 th 1 bln - 5 th) | C22: =Pricing_Counseling!E10 -> 580000 | D22: 690000 | E22: 469000 | F22: =IF(ISNUMBER(D22),C22/D22-1,"") -> -0.15942029 | G22: =IF(ISNUMBER(E22),C22/E22-1,"") -> 0.23667377 | H22: Ibunda Essential (setara Tier 1 dan Tier 2).
B23: Tier 3 (5 th 1 bln - 10 th) | C23: =Pricing_Counseling!E11 -> 800000 | D23: 890000 | E23: 569000 | F23: =IF(ISNUMBER(D23),C23/D23-1,"") -> -0.1011236 | G23: =IF(ISNUMBER(E23),C23/E23-1,"") -> 0.4059754 | H23: Ibunda Profesional: pengalaman 4-10 tahun. Amanasa Co-Founder: Rp690.000 ditambah Rp200.000 (asumsi, tambahan Rp200.000 tercantum di harga online).
B24: Tier 4 (di atas 10 th) | C24: =Pricing_Counseling!E12 -> 925000 | D24: 890000 | E24: 969000 | F24: =IF(ISNUMBER(D24),C24/D24-1,"") -> 0.039325843 | G24: =IF(ISNUMBER(E24),C24/E24-1,"") -> -0.045407637 | H24: Ibunda Premium: pengalaman di atas 10 tahun. Amanasa Co-Founder (asumsi yang sama).
A25: C. Konseling pasangan (Rp per 60 menit)
A26: Layanan | B26: Tingkat atau format | C26: Harga TJ (Rp) | D26: Amanasa (Rp) | E26: Ibunda.id (Rp) | F26: TJ vs Amanasa | G26: TJ vs Ibunda | H26: Pembanding dan catatan
A27: Konseling pasangan offline, harga TJ per 60 mnt | B27: Tier 1 (0-2 th) | C27: =Pricing_Counseling!E13/(90/60) -> 533333.33 | D27: 890000 | E27: Belum ada data | F27: =IF(ISNUMBER(D27),C27/D27-1,"") -> -0.40074906 | G27: =IF(ISNUMBER(E27),C27/E27-1,"") | H27: TJ: sesi 90 mnt dibagi 1,5 agar sebanding. Amanasa on-site 60 mnt Rp890.000 (online Rp595.000), psikolog berpengalaman tanpa pembedaan tingkat.
B28: Tier 2 (2 th 1 bln - 5 th) | C28: =Pricing_Counseling!E14/(90/60) -> 633333.33 | D28: 890000 | E28: Belum ada data | F28: =IF(ISNUMBER(D28),C28/D28-1,"") -> -0.28838951 | G28: =IF(ISNUMBER(E28),C28/E28-1,"")
B29: Tier 3 (5 th 1 bln - 10 th) | C29: =Pricing_Counseling!E15/(90/60) -> 733333.33 | D29: 890000 | E29: Belum ada data | F29: =IF(ISNUMBER(D29),C29/D29-1,"") -> -0.17602996 | G29: =IF(ISNUMBER(E29),C29/E29-1,"")
B30: Tier 4 (di atas 10 th) | C30: =Pricing_Counseling!E16/(90/60) -> 950000 | D30: 890000 | E30: Belum ada data | F30: =IF(ISNUMBER(D30),C30/D30-1,"") -> 0.06741573 | G30: =IF(ISNUMBER(E30),C30/E30-1,"")
A31: D. Pre-Marriage Check Up (Rp per paket)
A32: Layanan | B32: Tingkat atau format | C32: Harga TJ (Rp) | D32: Amanasa (Rp) | E32: Ibunda.id (Rp) | F32: TJ vs Amanasa | G32: TJ vs Ibunda | H32: Pembanding dan catatan
A33: Pre-Marriage Check Up, paket 3 sesi | B33: Tier 1 (0-2 th) | C33: =Pricing_Counseling!E17 -> 2200000 | D33: 5500000 | E33: Belum ada data | F33: =IF(ISNUMBER(D33),C33/D33-1,"") -> -0.6 | G33: =IF(ISNUMBER(E33),C33/E33-1,"") | H33: Amanasa Couple Fit Check: konseling awal 60 mnt, asesmen PREPARE/ENRICH dan Personality Check, konseling hasil 120 mnt, follow-up 60 mnt, semuanya online. Associate Rp5.500.000, Founder Rp7.500.000. Paket TJ belum memuat asesmen.
B34: Tier 2 (2 th 1 bln - 5 th) | C34: =Pricing_Counseling!E18 -> 2600000 | D34: 5500000 | E34: Belum ada data | F34: =IF(ISNUMBER(D34),C34/D34-1,"") -> -0.52727273 | G34: =IF(ISNUMBER(E34),C34/E34-1,"") | H34: Dibandingkan dengan Couple Fit Check Associate.
B35: Tier 3 (5 th 1 bln - 10 th) | C35: =Pricing_Counseling!E19 -> 2900000 | D35: 7500000 | E35: Belum ada data | F35: =IF(ISNUMBER(D35),C35/D35-1,"") -> -0.61333333 | G35: =IF(ISNUMBER(E35),C35/E35-1,"") | H35: Dibandingkan dengan Couple Fit Check Founder.
B36: Tier 4 (di atas 10 th) | C36: =Pricing_Counseling!E20 -> 3800000 | D36: 7500000 | E36: Belum ada data | F36: =IF(ISNUMBER(D36),C36/D36-1,"") -> -0.49333333 | G36: =IF(ISNUMBER(E36),C36/E36-1,"")
A37: E. Marriage Check Up (Rp per paket)
A38: Layanan | B38: Tingkat atau format | C38: Harga TJ (Rp) | D38: Amanasa (Rp) | E38: Ibunda.id (Rp) | F38: TJ vs Amanasa | G38: TJ vs Ibunda | H38: Pembanding dan catatan
A39: Marriage Check Up, paket 2 sesi | B39: Tier 1 (0-2 th) | C39: =Pricing_Counseling!E21 -> 1400000 | D39: 5500000 | E39: Belum ada data | F39: =IF(ISNUMBER(D39),C39/D39-1,"") -> -0.74545455 | G39: =IF(ISNUMBER(E39),C39/E39-1,"") | H39: Couple Fit Check Amanasa untuk pasangan yang sudah menikah dan yang mempersiapkan pernikahan (harga sama). Sheet ACC tidak memuat Marriage Check Up, harga TJ adalah estimasi.
B40: Tier 2 (2 th 1 bln - 5 th) | C40: =Pricing_Counseling!E22 -> 1700000 | D40: 5500000 | E40: Belum ada data | F40: =IF(ISNUMBER(D40),C40/D40-1,"") -> -0.69090909 | G40: =IF(ISNUMBER(E40),C40/E40-1,"")
B41: Tier 3 (5 th 1 bln - 10 th) | C41: =Pricing_Counseling!E23 -> 2000000 | D41: 7500000 | E41: Belum ada data | F41: =IF(ISNUMBER(D41),C41/D41-1,"") -> -0.73333333 | G41: =IF(ISNUMBER(E41),C41/E41-1,"")
B42: Tier 4 (di atas 10 th) | C42: =Pricing_Counseling!E24 -> 2600000 | D42: 7500000 | E42: Belum ada data | F42: =IF(ISNUMBER(D42),C42/D42-1,"") -> -0.65333333 | G42: =IF(ISNUMBER(E42),C42/E42-1,"")
...
