Workbook

Sheet Summary
A1: Teman Journey - 2027 plan: profitable with both founders paid
A2: Goal for 2027: a business that is profitable on its own and pays both founders. Investors come later, after scale. All money in Rp million.
A3: Active scenario: | B3: =CHOOSE(Inputs!$C$6,"1. Base plan","2. No new B2B deal Jan-Jun 2027","3. BI cuts volume","4. Worst case (2 + 3)") -> 1. Base plan
A4: Active price plan: | B4: =CHOOSE(Inputs!$C$85,"1. Current prices","2. New rate card") -> 2. New rate card
A5: Question | B5: Answer | C5: Unit | D5: What it means
A6: A. Is 2027 profitable?
A7: Revenue FY 2027 | B7: =PnL!$D$12 -> 2039.9735 | C7: Rp m | D7: Total sales booked in 2027.
A8: Gross profit FY 2027 | B8: =PnL!$D$23 -> 1377.3341 | C8: Rp m | D8: Revenue minus delivery cost.
A9: Total fixed cost FY 2027 | B9: =PnL!$D$31 -> 834.92567 | C9: Rp m | D9: Base + founders + sales + delivery steps.
A10: of which founder salaries | B10: =PnL!$D$28 -> 270 | C10: Rp m | D10: Both founders, from the start month in Inputs.
A11: Net profit FY 2027 | B11: =PnL!$D$35 -> 532.20857 | C11: Rp m | D11: After founder salaries and tax.
A12: Net margin FY 2027 | B12: =PnL!$D$36 -> 0.26088994 | C12: % | D12: Net profit / revenue.
A13: Meets your target margin? | B13: =IF(PnL!$D$36>=Inputs!$C$82,"Yes","No") -> Yes | D13: Target is set in Inputs.
A14: Break-even: BI work needed per month (in KPW-event equivalents) | B14: =IF(Unit_Economics!$G$5<=0,0,(PnL!$D$31/12-(PnL!$D$23-PnL!$D$6-PnL!$D$7+PnL!$D$15+PnL!$D$16)/12)/Unit_Economics!$G$5) -> 0.58375142 | C14: events | D14: With banks, EAP and B2C at plan, this many KPW-size BI events a month (or the same profit from Flagships) covers all 2027 fixed costs.
A15: B. Is cash safe? (Pillar 3)
A16: Lowest month-end cash (Oct 26 - Dec 27) | B16: =MIN(CashFlow!$E$21:$S$21) -> 82.489448 | C16: Rp m | D16: Must stay above zero.
A17: Month of lowest cash | B17: =INDEX(Volume!$E$4:$S$4,MATCH(MIN(CashFlow!$E$21:$S$21),CashFlow!$E$21:$S$21,0)) -> Feb-27 | D17: Where the squeeze is.
A18: Months below the cash floor | B18: =COUNTIF(CashFlow!$E$25:$S$25,0) -> 1 | C18: months | D18: Floor = 1 month fixed cost + delivery cost.
A19: Cash at end of 2027 | B19: =CashFlow!$D$21 -> 523.85587 | C19: Rp m
A20: Peak money owed by clients | B20: =CashFlow!$D$26 -> 219.8 | C20: Rp m | D20: Cash tied up in unpaid invoices.
A21: Runway at end of Dec 2026 if B2B stops | B21: =CashFlow!$G$21/(Capacity_OPEX!$H$32-((PnL!$D$10+PnL!$D$11-PnL!$D$19-PnL!$D$20)/12)) -> 4.5089578 | C21: months | D21: Months you survive on B2C alone with 2027 cost base.
A22: C. Can we deliver it? (Pillar 2)
A23: Peak facilitators needed in one month | B23: =Capacity_OPEX!$D$8 -> 8 | C23: people | D23: Compare with your plan of 11.
A24: Facilitators to certify by end 2027 | B24: =Capacity_OPEX!$D$9-Inputs!$C$35 -> 6 | C24: people
A25: Month the Project Manager is hired | B25: =IFERROR(INDEX(Volume!$E$4:$S$4,MATCH(1,Capacity_OPEX!$E$15:$S$15,0)),"Not needed") -> Dec-27 | D25: Triggered by the 3-month average of B2B events.
A26: D. What will investors ask? (risk)
A27: BI share of 2027 revenue | B27: =PnL!$D$41 -> 0.44697884 | C27: % | D27: Concentration risk. Lower is safer.
A28: B2B share of 2027 revenue | B28: =IF(PnL!$D$12=0,0,PnL!$D$42/PnL!$D$12) -> 0.87942318 | C28: %
A29: Q4 share of 2027 revenue | B29: =IF(PnL!$D$12=0,0,SUM(PnL!Q12:S12)/PnL!$D$12) -> 0.44837037 | C29: % | D29: Seasonality risk.
A30: Cost to win one new B2B client (CAC) | B30: =Unit_Economics!$B$13 -> 6 | C30: Rp m | D30: Sales spend / new clients.
A31: Memo: Coreitera revenue from TJ in 2027 | B31: =PnL!$D$43 -> 89.25 | C31: Rp m | D31: The 'tech' revenue line for the investor story.
A32: Memo: Theta revenue from TJ in 2027 | B32: =PnL!$D$44 -> 22.798676 | C32: Rp m
A34: Scenario comparison (v15 values from Excel; refresh with analysis/excel_runner.py, then rebuild)
A35: Measure | B35: Old timing, v13 costs | C35: Real timing, v13 costs | D35: Our plan (v15) | E35: Our plan, no bank deal | F35: Our plan, BI buys 30% less
A36: Revenue FY 2027 | B36: 1501.5 | C36: 1461.5 | D36: 2039.9735 | E36: 1879.4735 | F36: 1766.426
A37: Net profit FY 2027 | B37: 378.3835 | C37: 402.0835 | D37: 532.20857 | E37: 426.01107 | F37: 373.56576
A38: Net margin FY 2027 | B38: 0.25200366 | C38: 0.275117 | D38: 0.26088994 | E38: 0.22666511 | F38: 0.21148113
A39: Lowest month-end cash (Oct 26 - Dec 27) | B39: 203.52008 | C39: 92.338083 | D39: 82.489448 | E39: 82.489448 | F39: 67.012075
A40: Month of lowest cash | B40: Oct-26 | C40: Apr-27 | D40: Feb-27 | E40: Feb-27 | F40: Apr-27
A41: Months below the cash floor | B41: 0 | C41: 0 | D41: 1 | E41: 1 | F41: 4
...

Sheet Outlook
A1: Outlook: sales, costs and cash each month (Rp million)
A2: Read the bars against the line: when the grey cost bar is taller than the blue sales bar, cash goes down. Cash is paid later than sales, because clients pay 0 to 60 days after the event.
A4: Month | B4: =Volume!E4 -> Oct-26 | C4: =Volume!F4 -> Nov-26 | D4: =Volume!G4 -> Dec-26 | E4: =Volume!H4 -> Jan-27 | F4: =Volume!I4 -> Feb-27 | G4: =Volume!J4 -> Mar-27 | H4: =Volume!K4 -> Apr-27 | I4: =Volume!L4 -> May-27 | ... P4: =Volume!S4 -> Dec-27
A5: Sales (revenue) | B5: =PnL!E12 -> 17.089743 | C5: =PnL!F12 -> 17.189401 | D5: =PnL!G12 -> 17.293813 | E5: =PnL!H12 -> 18.453031 | F5: =PnL!I12 -> 53.719665 | G5: =PnL!J12 -> 162.50689 | H5: =PnL!K12 -> 93.8367 | I5: =PnL!L12 -> 169.38018 | ... P5: =PnL!S12 -> 284.57599
A6: Delivery cost | B6: =PnL!E21 -> 5.835897 | C6: =PnL!F21 -> 5.8757606 | D6: =PnL!G21 -> 5.9175252 | E6: =PnL!H21 -> 6.3812124 | F6: =PnL!I21 -> 19.487866 | G6: =PnL!J21 -> 49.852755 | H6: =PnL!K21 -> 29.13468 | I6: =PnL!L21 -> 52.602072 | ... P6: =PnL!S21 -> 98.680394
A7: Fixed cost | B7: =PnL!E31 -> 31.685442 | C7: =PnL!F31 -> 31.687136 | D7: =PnL!G31 -> 31.688911 | E7: =PnL!H31 -> 41.953176 | F7: =PnL!I31 -> 40.393148 | G7: =PnL!J31 -> 59.401521 | H7: =PnL!K31 -> 57.593458 | I7: =PnL!L31 -> 65.653056 | ... P7: =PnL!S31 -> 93.132888
A8: Tax | B8: =PnL!E34 -> 0.085448713 | C8: =PnL!F34 -> 0.085947007 | D8: =PnL!G34 -> 0.086469065 | E8: =PnL!H34 -> 0.092265155 | F8: =PnL!I34 -> 0.26859832 | G8: =PnL!J34 -> 0.81253444 | H8: =PnL!K34 -> 0.4691835 | I8: =PnL!L34 -> 0.8469009 | ... P8: =PnL!S34 -> 1.4228799
A9: Total cost | B9: =B6+B7+B8 -> 37.606788 | C9: =C6+C7+C8 -> 37.648844 | D9: =D6+D7+D8 -> 37.692906 | E9: =E6+E7+E8 -> 48.426653 | F9: =F6+F7+F8 -> 60.149613 | G9: =G6+G7+G8 -> 110.06681 | H9: =H6+H7+H8 -> 87.197321 | I9: =I6+I7+I8 -> 119.10203 | ... P9: =P6+P7+P8 -> 193.23616
A10: Net profit | B10: =PnL!E35 -> -20.517045 | C10: =PnL!F35 -> -20.459443 | D10: =PnL!G35 -> -20.399093 | E10: =PnL!H35 -> -29.973622 | F10: =PnL!I35 -> -6.4299477 | G10: =PnL!J35 -> 52.440077 | H10: =PnL!K35 -> 6.6393782 | I10: =PnL!L35 -> 50.278151 | ... P10: =PnL!S35 -> 91.339824
A11: Cash in | B11: =CashFlow!E11 -> 2.0897425 | C11: =CashFlow!F11 -> 17.189401 | D11: =CashFlow!G11 -> 17.293813 | E11: =CashFlow!H11 -> 18.453031 | F11: =CashFlow!I11 -> 38.719665 | G11: =CashFlow!J11 -> 116.80689 | H11: =CashFlow!K11 -> 86.7367 | I11: =CashFlow!L11 -> 160.43018 | ... P11: =CashFlow!S11 -> 345.97599
A12: Cash out | B12: =CashFlow!E17 -> 37.521339 | C12: =CashFlow!F17 -> 37.648346 | D12: =CashFlow!G17 -> 37.692384 | E12: =CashFlow!H17 -> 48.420857 | F12: =CashFlow!I17 -> 59.973279 | G12: =CashFlow!J17 -> 109.52287 | H12: =CashFlow!K17 -> 87.540672 | I12: =CashFlow!L17 -> 118.72431 | ... P12: =CashFlow!S17 -> 193.71258
A13: Cash at end of month | B13: =CashFlow!E21 -> 174.5684 | C13: =CashFlow!F21 -> 154.10946 | D13: =CashFlow!G21 -> 133.71089 | E13: =CashFlow!H21 -> 103.74306 | F13: =CashFlow!I21 -> 82.489448 | G13: =CashFlow!J21 -> 89.773461 | H13: =CashFlow!K21 -> 88.969488 | I13: =CashFlow!L21 -> 130.67536 | ... P13: =CashFlow!S21 -> 523.85587
A14: Cash floor (1 month of costs) | B14: =CashFlow!E24 -> 37.521339 | C14: =CashFlow!F24 -> 37.562897 | D14: =CashFlow!G24 -> 37.606437 | E14: =CashFlow!H24 -> 48.334388 | F14: =CashFlow!I24 -> 59.881014 | G14: =CashFlow!J24 -> 109.25428 | H14: =CashFlow!K24 -> 86.728138 | I14: =CashFlow!L24 -> 118.25513 | ... P14: =CashFlow!S24 -> 191.81328
A15: Above the floor? (1 = yes) | B15: =CashFlow!E25 -> 1 | C15: =CashFlow!F25 -> 1 | D15: =CashFlow!G25 -> 1 | E15: =CashFlow!H25 -> 1 | F15: =CashFlow!I25 -> 1 | G15: =CashFlow!J25 -> 0 | H15: =CashFlow!K25 -> 1 | I15: =CashFlow!L25 -> 1 | ... P15: =CashFlow!S25 -> 1

Sheet Roadmap
A1: Roadmap: when we must start selling and preparing, worked backward from each start date
A2: Rule: start from the date the work begins and go back through three clocks: sales (lead to signed), delivery (people ready) and cash (work done to cash in). Regulators and banks also need us inside their budget, which they plan in the second half of the year before.
A4: Today (blue: change it when you review) | C4: 46300
A6: A. Lead times by client type, in days (Estimate until we log 3 real deals of each type in section E)
A7: Client type | B7: Contract and paperwork (legal, vendor registration, work order) | C7: Pitch, scoping, proposal | D7: Finding qualified leads
A8: Private company | B8: 14 | C8: 45 | D8: 30
A9: Regulator (BI, OJK, LPS) | B9: 42 | C9: 75 | D9: 30
A10: State-owned bank | B10: 42 | C10: 75 | D10: 30
A11: B2C public | B11: 0 | C11: 30 | D11: 30
A13: B. Sales clock: the latest date to start each deal
A14: Milestone | B14: Client type | C14: New client? (1 = yes) | D14: Work starts | E14: Client budget window closes | F14: Sign by | G14: Start pitching | H14: Start finding leads | I14: Latest start | J14: Owner | K14: Status today
A15: BI 2027: Flagship and regional programs (first in March) | B15: Regulator (BI, OJK, LPS) | C15: 0 | D15: 46447 | E15: 46387 | F15: =D15-VLOOKUP(B15,$A$8:$D$11,2,0) -> 46405 | G15: =F15-VLOOKUP(B15,$A$8:$D$11,3,0) -> 46330 | H15: =G15-C15*VLOOKUP(B15,$A$8:$D$11,4,0) -> 46330 | I15: =IF(E15="",H15,MIN(H15,E15-VLOOKUP(B15,$A$8:$D$11,3,0))) -> 46312 | J15: Kia | K15: =IF(G15<$C$4,"Late",IF(I15<$C$4,"At risk",IF(I15-$C$4<=31,"Start now","On track"))) -> Start now
A16: BI 2027: regional events Jul-Sep (moved from the Q4 peak) | B16: Regulator (BI, OJK, LPS) | C16: 0 | D16: 46569 | E16: 46387 | F16: =D16-VLOOKUP(B16,$A$8:$D$11,2,0) -> 46527 | G16: =F16-VLOOKUP(B16,$A$8:$D$11,3,0) -> 46452 | H16: =G16-C16*VLOOKUP(B16,$A$8:$D$11,4,0) -> 46452 | I16: =IF(E16="",H16,MIN(H16,E16-VLOOKUP(B16,$A$8:$D$11,3,0))) -> 46312 | J16: Kia | K16: =IF(G16<$C$4,"Late",IF(I16<$C$4,"At risk",IF(I16-$C$4<=31,"Start now","On track"))) -> Start now
A17: BI 2027: regional peak Oct-Dec | B17: Regulator (BI, OJK, LPS) | C17: 0 | D17: 46661 | E17: 46387 | F17: =D17-VLOOKUP(B17,$A$8:$D$11,2,0) -> 46619 | G17: =F17-VLOOKUP(B17,$A$8:$D$11,3,0) -> 46544 | H17: =G17-C17*VLOOKUP(B17,$A$8:$D$11,4,0) -> 46544 | I17: =IF(E17="",H17,MIN(H17,E17-VLOOKUP(B17,$A$8:$D$11,3,0))) -> 46312 | J17: Kia | K17: =IF(G17<$C$4,"Late",IF(I17<$C$4,"At risk",IF(I17-$C$4<=31,"Start now","On track"))) -> Start now
A18: EAP contract 2: the warm lead (chase now) | B18: Private company | C18: 0 | D18: 46419 | F18: =D18-VLOOKUP(B18,$A$8:$D$11,2,0) -> 46405 | G18: =F18-VLOOKUP(B18,$A$8:$D$11,3,0) -> 46360 | H18: =G18-C18*VLOOKUP(B18,$A$8:$D$11,4,0) -> 46360 | I18: =IF(E18="",H18,MIN(H18,E18-VLOOKUP(B18,$A$8:$D$11,3,0))) -> 46360 | J18: Galih | K18: =IF(G18<$C$4,"Late",IF(I18<$C$4,"At risk",IF(I18-$C$4<=31,"Start now","On track"))) -> On track
A19: EAP contract 2 if the client is a bank | B19: State-owned bank | C19: 1 | D19: 46419 | E19: 46387 | F19: =D19-VLOOKUP(B19,$A$8:$D$11,2,0) -> 46377 | G19: =F19-VLOOKUP(B19,$A$8:$D$11,3,0) -> 46302 | H19: =G19-C19*VLOOKUP(B19,$A$8:$D$11,4,0) -> 46272 | I19: =IF(E19="",H19,MIN(H19,E19-VLOOKUP(B19,$A$8:$D$11,3,0))) -> 46272 | J19: Galih | K19: =IF(G19<$C$4,"Late",IF(I19<$C$4,"At risk",IF(I19-$C$4<=31,"Start now","On track"))) -> At risk
A20: EAP contract 3 with a bank | B20: State-owned bank | C20: 1 | D20: 46569 | E20: 46387 | F20: =D20-VLOOKUP(B20,$A$8:$D$11,2,0) -> 46527 | G20: =F20-VLOOKUP(B20,$A$8:$D$11,3,0) -> 46452 | H20: =G20-C20*VLOOKUP(B20,$A$8:$D$11,4,0) -> 46422 | I20: =IF(E20="",H20,MIN(H20,E20-VLOOKUP(B20,$A$8:$D$11,3,0))) -> 46312 | J20: Kia | K20: =IF(G20<$C$4,"Late",IF(I20<$C$4,"At risk",IF(I20-$C$4<=31,"Start now","On track"))) -> Start now
A21: Bank agreement: training days | B21: State-owned bank | C21: 1 | D21: 46661 | E21: 46387 | F21: =D21-VLOOKUP(B21,$A$8:$D$11,2,0) -> 46619 | G21: =F21-VLOOKUP(B21,$A$8:$D$11,3,0) -> 46544 | H21: =G21-C21*VLOOKUP(B21,$A$8:$D$11,4,0) -> 46514 | I21: =IF(E21="",H21,MIN(H21,E21-VLOOKUP(B21,$A$8:$D$11,3,0))) -> 46312 | J21: Kia, then BD co-founder | K21: =IF(G21<$C$4,"Late",IF(I21<$C$4,"At risk",IF(I21-$C$4<=31,"Start now","On track"))) -> Start now
A22: B2C events (Instagram campaign, then tickets) | B22: B2C public | C22: 1 | D22: 46661 | F22: =D22-VLOOKUP(B22,$A$8:$D$11,2,0) -> 46661 | G22: =F22-VLOOKUP(B22,$A$8:$D$11,3,0) -> 46631 | H22: =G22-C22*VLOOKUP(B22,$A$8:$D$11,4,0) -> 46601 | I22: =IF(E22="",H22,MIN(H22,E22-VLOOKUP(B22,$A$8:$D$11,3,0))) -> 46601 | J22: Galih (lead marketing) | K22: =IF(G22<$C$4,"Late",IF(I22<$C$4,"At risk",IF(I22-$C$4<=31,"Start now","On track"))) -> On track
A23: OJK and LPS programs for 2028 | B23: Regulator (BI, OJK, LPS) | C23: 1 | D23: 46813 | E23: 46660 | F23: =D23-VLOOKUP(B23,$A$8:$D$11,2,0) -> 46771 | G23: =F23-VLOOKUP(B23,$A$8:$D$11,3,0) -> 46696 | H23: =G23-C23*VLOOKUP(B23,$A$8:$D$11,4,0) -> 46666 | I23: =IF(E23="",H23,MIN(H23,E23-VLOOKUP(B23,$A$8:$D$11,3,0))) -> 46585 | J23: Kia, then BD co-founder | K23: =IF(G23<$C$4,"Late",IF(I23<$C$4,"At risk",IF(I23-$C$4<=31,"Start now","On track"))) -> On track
A24: BI 2028 programs | B24: Regulator (BI, OJK, LPS) | C24: 0 | D24: 46813 | E24: 46752 | F24: =D24-VLOOKUP(B24,$A$8:$D$11,2,0) -> 46771 | G24: =F24-VLOOKUP(B24,$A$8:$D$11,3,0) -> 46696 | H24: =G24-C24*VLOOKUP(B24,$A$8:$D$11,4,0) -> 46696 | I24: =IF(E24="",H24,MIN(H24,E24-VLOOKUP(B24,$A$8:$D$11,3,0))) -> 46677 | J24: Kia | K24: =IF(G24<$C$4,"Late",IF(I24<$C$4,"At risk",IF(I24-$C$4<=31,"Start now","On track"))) -> On track
A25: Latest start = the earlier of: start finding leads, or the budget window close minus the pitch time.
A27: C. Delivery clock: people ready before the work
A28: Item | B28: Why | D28: Needed by | E28: Lead time (months) | I28: Latest start | J28: Owner | K28: Status today
A29: 3 certified trainers | B29: First programs in March need 3 trainers | D29: 46447 | E29: 3 | I29: =EDATE(D29,-E29) -> 46357 | J29: Galih | K29: =IF(I29<$C$4,"Late",IF(I29-$C$4<=31,"Start now","On track")) -> On track
A30: Part-time psychologist pool for EAP 2 | B30: EAP 2 starts in February | D30: 46419 | E30: 1 | I30: =EDATE(D30,-E30) -> 46388 | J30: Galih | K30: =IF(I30<$C$4,"Late",IF(I30-$C$4<=31,"Start now","On track")) -> On track
A31: Second paid part-time psychologist | B31: B2C evenings and EAP days from January | D31: 46388 | E31: 2 | I31: =EDATE(D31,-E31) -> 46327 | J31: Galih | K31: =IF(I31<$C$4,"Late",IF(I31-$C$4<=31,"Start now","On track")) -> Start now
A32: Standby project manager (paid per project) | B32: From July, more than 2 projects in a month | D32: 46569 | E32: 2 | I32: =EDATE(D32,-E32) -> 46508 | J32: Kia | K32: =IF(I32<$C$4,"Late",IF(I32-$C$4<=31,"Start now","On track")) -> On track
A33: Sales co-founder | B33: Joins in July; searching takes longer than a normal hire | D33: 46569 | E33: 6 | I33: =EDATE(D33,-E33) -> 46388 | J33: Kia and Galih | K33: =IF(I33<$C$4,"Late",IF(I33-$C$4<=31,"Start now","On track")) -> On track
A34: 8 certified trainers | B34: Busiest months: Oct to Dec 2027 | D34: 46661 | E34: 3 | I34: =EDATE(D34,-E34) -> 46569 | J34: Galih | K34: =IF(I34<$C$4,"Late",IF(I34-$C$4<=31,"Start now","On track")) -> On track
A35: Lead Partnership (non-psychologist) | B35: Manages EAP clients from October; brings clients | D35: 46661 | E35: 3 | I35: =EDATE(D35,-E35) -> 46569 | J35: Kia | K35: =IF(I35<$C$4,"Late",IF(I35-$C$4<=31,"Start now","On track")) -> On track
A36: Intern for invoices | B36: Invoices grow to about 11 a month in Q4 | D36: 46631 | E36: 1 | I36: =EDATE(D36,-E36) -> 46600 | J36: Galih | K36: =IF(I36<$C$4,"Late",IF(I36-$C$4<=31,"Start now","On track")) -> On track
A38: D. Cash clock: work done, cash not yet in
A39: Lowest cash in the plan (Rp m) | D39: =MIN(Outlook!B13:P13) -> 82.489448
A40: Month of the lowest cash | D40: =INDEX(Outlook!B4:P4,MATCH(MIN(Outlook!B13:P13),Outlook!B13:P13,0)) -> Feb-27
A41: Months below the safety floor | D41: =COUNTIF(Outlook!B15:P15,0) -> 1
A42: Down payment on Flagship programs (Inputs) | D42: =Inputs!$C$117 -> 0
A43: Costs leave in the event month; BI central pays 60/30/10% over 60 days, regional offices per payday, banks 20/50/30%, EAP the next month. Fix a gap before signing: a down payment, staged invoices, or a later start.
A45: E. Sales speed log: fill in after every won or lost deal, then replace the estimates in section A
A46: Client | B46: Client type | C46: First contact | D46: Proposal sent | E46: Signed | F46: Work started | G46: Cash in | H46: Days to sign | I46: Days to cash | J46: Won or lost | K46: Note
...

Sheet B2C
A1: B2C funnel: Instagram followers to paid counseling sessions, and B2C vs B2B revenue (Rp million)
A2: Growth is set per quarter (blue). Followers on 5 Oct 2026: @temanjourney_id. Today about 2 paid sessions a month, so the booking rate starts at about 0.6 new paying clients a month per 1,000 followers. Feeds Volume row 28.
A4: Quarterly inputs (blue = change freely)
C5: Q4 2026 | D5: Q1 2027 | E5: Q2 2027 | F5: Q3 2027 | G5: Q4 2027
A6: Follower growth in the quarter | C6: 0.15 | D6: 0.25 | E6: 0.28 | F6: 0.28 | G6: 0.24
A7: Booking rate: new paying clients a month per 1,000 followers | C7: 0.58 | D7: 0.7 | E7: 0.85 | F7: 1 | G7: 1
A8: Sessions per client | C8: 1 | D8: 1.1 | E8: 1.25 | F8: 1.4 | G8: 1.4
A9: Referral share of new clients (target 20% by Q4 2027) | C9: 0 | D9: 0.05 | E9: 0.1 | F9: 0.15 | G9: 0.2
A10: Instagram followers on 5 Oct 2026 | C10: 3439
A11: Theta voucher sessions a month per EAP contract | C11: 2
A12: Theta vouchers start | C12: Apr-27
A13: Sessions one paid part-time psychologist covers a month (3 shifts a week x 3) | C13: 36
A14: Paid part-time psychologists from Jan-27 | C14: 2
A15: Pool capacity: 20 part-timers x 8 hours a month | C15: 160
A16: Full-time psychologist pay, if hired (gross) | C16: 9
A17: Referral reward per referred client (Rp100k credit to each side) | C17: 0.2 | E17: Base Instagram ads already in the software budget (Rp m a month) | K17: 1
A18: Line | B18: Unit | C18: Q4 2026 | D18: FY 2027 | E18: =Volume!E4 -> Oct-26 | F18: =Volume!F4 -> Nov-26 | G18: =Volume!G4 -> Dec-26 | H18: =Volume!H4 -> Jan-27 | I18: =Volume!I4 -> Feb-27 | J18: =Volume!J4 -> Mar-27 | K18: =Volume!K4 -> Apr-27 | L18: =Volume!L4 -> May-27 | ... S18: =Volume!S4 -> Dec-27
A19: Quarter (1 = Q4 2026 ... 5 = Q4 2027) | B19: # | E19: =INT((Volume!E6-1)/3)+1 -> 1 | F19: =INT((Volume!F6-1)/3)+1 -> 1 | G19: =INT((Volume!G6-1)/3)+1 -> 1 | H19: =INT((Volume!H6-1)/3)+1 -> 2 | I19: =INT((Volume!I6-1)/3)+1 -> 2 | J19: =INT((Volume!J6-1)/3)+1 -> 2 | K19: =INT((Volume!K6-1)/3)+1 -> 3 | L19: =INT((Volume!L6-1)/3)+1 -> 3 | ... S19: =INT((Volume!S6-1)/3)+1 -> 5
A20: Instagram followers (end of month) | B20: people | C20: =MAX(E20:G20) -> 3954.85 | D20: =MAX(H20:S20) -> 10043.421 | E20: =$C$10*(1+INDEX($C$6:$G$6,E19))^(1/3) -> 3603.0044 | F20: =E20*(1+INDEX($C$6:$G$6,F19))^(1/3) -> 3774.83 | G20: =F20*(1+INDEX($C$6:$G$6,G19))^(1/3) -> 3954.85 | H20: =G20*(1+INDEX($C$6:$G$6,H19))^(1/3) -> 4260.233 | I20: =H20*(1+INDEX($C$6:$G$6,I19))^(1/3) -> 4589.1969 | J20: =I20*(1+INDEX($C$6:$G$6,J19))^(1/3) -> 4943.5625 | K20: =J20*(1+INDEX($C$6:$G$6,K19))^(1/3) -> 5367.5573 | L20: =K20*(1+INDEX($C$6:$G$6,L19))^(1/3) -> 5827.9168 | M20: =L20*(1+INDEX($C$6:$G$6,M19))^(1/3) -> 6327.76 | ... S20: =R20*(1+INDEX($C$6:$G$6,S19))^(1/3) -> 10043.421
A21: Booking rate | B21: per 1,000 | C21: =MAX(E21:G21) -> 0.58 | D21: =MAX(H21:S21) -> 1 | E21: =INDEX($C$7:$G$7,E19) -> 0.58 | F21: =INDEX($C$7:$G$7,F19) -> 0.58 | G21: =INDEX($C$7:$G$7,G19) -> 0.58 | H21: =INDEX($C$7:$G$7,H19) -> 0.7 | I21: =INDEX($C$7:$G$7,I19) -> 0.7 | J21: =INDEX($C$7:$G$7,J19) -> 0.7 | K21: =INDEX($C$7:$G$7,K19) -> 0.85 | L21: =INDEX($C$7:$G$7,L19) -> 0.85 | ... S21: =INDEX($C$7:$G$7,S19) -> 1
A22: Sessions per client | B22: x | C22: =MAX(E22:G22) -> 1 | D22: =MAX(H22:S22) -> 1.4 | E22: =INDEX($C$8:$G$8,E19) -> 1 | F22: =INDEX($C$8:$G$8,F19) -> 1 | G22: =INDEX($C$8:$G$8,G19) -> 1 | H22: =INDEX($C$8:$G$8,H19) -> 1.1 | I22: =INDEX($C$8:$G$8,I19) -> 1.1 | J22: =INDEX($C$8:$G$8,J19) -> 1.1 | K22: =INDEX($C$8:$G$8,K19) -> 1.25 | L22: =INDEX($C$8:$G$8,L19) -> 1.25 | ... S22: =INDEX($C$8:$G$8,S19) -> 1.4
A23: New paying clients from Instagram | B23: clients | C23: =SUM(E23:G23) -> 6.572957 | D23: =SUM(H23:S23) -> 75.073114 | E23: =E20/1000*E21 -> 2.0897425 | F23: =F20/1000*F21 -> 2.1894014 | G23: =G20/1000*G21 -> 2.293813 | H23: =H20/1000*H21 -> 2.9821631 | I23: =I20/1000*I21 -> 3.2124378 | J23: =J20/1000*J21 -> 3.4604938 | K23: =K20/1000*K21 -> 4.5624237 | L23: =L20/1000*L21 -> 4.9537293 | ... S23: =S20/1000*S21 -> 10.043421
A24: Sessions from Instagram | B24: sessions | C24: =SUM(E24:G24) -> 6.572957 | D24: =SUM(H24:S24) -> 99.971619 | E24: =E23*E22 -> 2.0897425 | F24: =F23*F22 -> 2.1894014 | G24: =G23*G22 -> 2.293813 | H24: =H23*H22 -> 3.2803794 | I24: =I23*I22 -> 3.5336816 | J24: =J23*J22 -> 3.8065431 | K24: =K23*K22 -> 5.7030296 | L24: =L23*L22 -> 6.1921616 | ... S24: =S23*S22 -> 14.060789
A25: Sessions from Theta vouchers (EAP staff) | B25: sessions | C25: =SUM(E25:G25) -> 0 | D25: =SUM(H25:S25) -> 48 | E25: =IF(Volume!E6>=IFERROR(MATCH($C$12,Volume!$E$4:$S$4,0),99),$C$11*Volume!E26,0) -> 0 | F25: =IF(Volume!F6>=IFERROR(MATCH($C$12,Volume!$E$4:$S$4,0),99),$C$11*Volume!F26,0) -> 0 | G25: =IF(Volume!G6>=IFERROR(MATCH($C$12,Volume!$E$4:$S$4,0),99),$C$11*Volume!G26,0) -> 0 | H25: =IF(Volume!H6>=IFERROR(MATCH($C$12,Volume!$E$4:$S$4,0),99),$C$11*Volume!H26,0) -> 0 | I25: =IF(Volume!I6>=IFERROR(MATCH($C$12,Volume!$E$4:$S$4,0),99),$C$11*Volume!I26,0) -> 0 | J25: =IF(Volume!J6>=IFERROR(MATCH($C$12,Volume!$E$4:$S$4,0),99),$C$11*Volume!J26,0) -> 0 | K25: =IF(Volume!K6>=IFERROR(MATCH($C$12,Volume!$E$4:$S$4,0),99),$C$11*Volume!K26,0) -> 4 | L25: =IF(Volume!L6>=IFERROR(MATCH($C$12,Volume!$E$4:$S$4,0),99),$C$11*Volume!L26,0) -> 4 | ... S25: =IF(Volume!S6>=IFERROR(MATCH($C$12,Volume!$E$4:$S$4,0),99),$C$11*Volume!S26,0) -> 6
A26: Paid B2C counseling sessions (Instagram + vouchers + referral) | B26: sessions | C26: =SUM(E26:G26) -> 6.572957 | D26: =SUM(H26:S26) -> 165.97351 | E26: =E24+E25+E52 -> 2.0897425 | F26: =F24+F25+F52 -> 2.1894014 | G26: =G24+G25+G52 -> 2.293813 | H26: =H24+H25+H52 -> 3.453031 | I26: =I24+I25+I52 -> 3.7196649 | J26: =J24+J25+J52 -> 4.0068875 | K26: =K24+K25+K52 -> 10.3367 | L26: =L24+L25+L52 -> 10.88018 | ... S26: =S24+S25+S52 -> 23.575986
A27: Revenue
A28: Counseling revenue | B28: Rp m | C28: =SUM(E28:G28) -> 6.572957 | D28: =SUM(H28:S28) -> 165.97351 | E28: =PnL!E11 -> 2.0897425 | F28: =PnL!F11 -> 2.1894014 | G28: =PnL!G11 -> 2.293813 | H28: =PnL!H11 -> 3.453031 | I28: =PnL!I11 -> 3.7196649 | J28: =PnL!J11 -> 4.0068875 | K28: =PnL!K11 -> 10.3367 | L28: =PnL!L11 -> 10.88018 | ... S28: =PnL!S11 -> 23.575986
A29: Public events | B29: events | C29: =SUM(E29:G29) -> 0 | D29: =SUM(H29:S29) -> 4 | E29: =Volume!E27 -> 0 | F29: =Volume!F27 -> 0 | G29: =Volume!G27 -> 0 | H29: =Volume!H27 -> 0 | I29: =Volume!I27 -> 1 | J29: =Volume!J27 -> 0 | K29: =Volume!K27 -> 0 | L29: =Volume!L27 -> 0 | ... S29: =Volume!S27 -> 1
A30: Public event revenue | B30: Rp m | C30: =SUM(E30:G30) -> 0 | D30: =SUM(H30:S30) -> 80 | E30: =PnL!E10 -> 0 | F30: =PnL!F10 -> 0 | G30: =PnL!G10 -> 0 | H30: =PnL!H10 -> 0 | I30: =PnL!I10 -> 20 | J30: =PnL!J10 -> 0 | K30: =PnL!K10 -> 0 | L30: =PnL!L10 -> 0 | ... S30: =PnL!S10 -> 20
A31: B2C revenue | B31: Rp m | C31: =SUM(E31:G31) -> 6.572957 | D31: =SUM(H31:S31) -> 245.97351 | E31: =E28+E30 -> 2.0897425 | F31: =F28+F30 -> 2.1894014 | G31: =G28+G30 -> 2.293813 | H31: =H28+H30 -> 3.453031 | I31: =I28+I30 -> 23.719665 | J31: =J28+J30 -> 4.0068875 | K31: =K28+K30 -> 10.3367 | L31: =L28+L30 -> 10.88018 | ... S31: =S28+S30 -> 43.575986
A32: B2B revenue (regulators, banks, EAP) | B32: Rp m | C32: =SUM(E32:G32) -> 45 | D32: =SUM(H32:S32) -> 1794 | E32: =PnL!E12-E31 -> 15 | F32: =PnL!F12-F31 -> 15 | G32: =PnL!G12-G31 -> 15 | H32: =PnL!H12-H31 -> 15 | I32: =PnL!I12-I31 -> 30 | J32: =PnL!J12-J31 -> 158.5 | K32: =PnL!K12-K31 -> 83.5 | L32: =PnL!L12-L31 -> 158.5 | ... S32: =PnL!S12-S31 -> 241
A33: B2C share of all revenue | B33: % | C33: =IF(SUM(PnL!E12:G12)=0,0,C31/SUM(PnL!E12:G12)) -> 0.12744968 | D33: =IF(SUM(PnL!H12:S12)=0,0,D31/SUM(PnL!H12:S12)) -> 0.12057682 | E33: =IF(PnL!E12=0,0,E31/PnL!E12) -> 0.12228052 | F33: =IF(PnL!F12=0,0,F31/PnL!F12) -> 0.12736926 | G33: =IF(PnL!G12=0,0,G31/PnL!G12) -> 0.13263778 | H33: =IF(PnL!H12=0,0,H31/PnL!H12) -> 0.18712541 | I33: =IF(PnL!I12=0,0,I31/PnL!I12) -> 0.44154529 | J33: =IF(PnL!J12=0,0,J31/PnL!J12) -> 0.024656724 | K33: =IF(PnL!K12=0,0,K31/PnL!K12) -> 0.11015626 | L33: =IF(PnL!L12=0,0,L31/PnL!L12) -> 0.064235258 | ... S33: =IF(PnL!S12=0,0,S31/PnL!S12) -> 0.15312601
A34: Can B2C pay for our psychologists?
A35: B2C gross profit (after psychologist session fees and event costs) | B35: Rp m | C35: =SUM(E35:G35) -> 3.9437742 | D35: =SUM(H35:S35) -> 147.58411 | E35: =PnL!E10+PnL!E11-PnL!E19-PnL!E20 -> 1.2538455 | F35: =PnL!F10+PnL!F11-PnL!F19-PnL!F20 -> 1.3136409 | G35: =PnL!G10+PnL!G11-PnL!G19-PnL!G20 -> 1.3762878 | H35: =PnL!H10+PnL!H11-PnL!H19-PnL!H20 -> 2.0718186 | I35: =PnL!I10+PnL!I11-PnL!I19-PnL!I20 -> 14.231799 | J35: =PnL!J10+PnL!J11-PnL!J19-PnL!J20 -> 2.4041325 | K35: =PnL!K10+PnL!K11-PnL!K19-PnL!K20 -> 6.2020197 | L35: =PnL!L10+PnL!L11-PnL!L19-PnL!L20 -> 6.5281077 | ... S35: =PnL!S10+PnL!S11-PnL!S19-PnL!S20 -> 26.145592
A36: Paid psychologists' pay incl. BPJS and THR | B36: Rp m | C36: =SUM(E36:G36) -> 6.9 | D36: =SUM(H36:S36) -> 65.136 | E36: =Pay_Plan!E9*(1+Inputs!$C$106*Pay_Plan!E14) -> 2.3 | F36: =Pay_Plan!F9*(1+Inputs!$C$106*Pay_Plan!F14) -> 2.3 | G36: =Pay_Plan!G9*(1+Inputs!$C$106*Pay_Plan!G14) -> 2.3 | H36: =Pay_Plan!H9*(1+Inputs!$C$106*Pay_Plan!H14) -> 5.428 | I36: =Pay_Plan!I9*(1+Inputs!$C$106*Pay_Plan!I14) -> 5.428 | J36: =Pay_Plan!J9*(1+Inputs!$C$106*Pay_Plan!J14) -> 5.428 | K36: =Pay_Plan!K9*(1+Inputs!$C$106*Pay_Plan!K14) -> 5.428 | L36: =Pay_Plan!L9*(1+Inputs!$C$106*Pay_Plan!L14) -> 5.428 | ... S36: =Pay_Plan!S9*(1+Inputs!$C$106*Pay_Plan!S14) -> 5.428
A37: Extra Instagram ads | B37: Rp m | C37: =SUM(E37:G37) -> 0 | D37: =SUM(H37:S37) -> 42 | E37: =Pay_Plan!E12 -> 0 | F37: =Pay_Plan!F12 -> 0 | G37: =Pay_Plan!G12 -> 0 | H37: =Pay_Plan!H12 -> 3.5 | I37: =Pay_Plan!I12 -> 3.5 | J37: =Pay_Plan!J12 -> 3.5 | K37: =Pay_Plan!K12 -> 3.5 | L37: =Pay_Plan!L12 -> 3.5 | ... S37: =Pay_Plan!S12 -> 3.5
A38: Psychologists' pay covered by B2C gross profit | B38: x | C38: =IF(C36=0,0,C35/C36) -> 0.57156147 | D38: =IF(D36=0,0,D35/D36) -> 2.265784 | E38: =IF(E36=0,0,E35/E36) -> 0.54515023 | F38: =IF(F36=0,0,F35/F36) -> 0.5711482 | G38: =IF(G36=0,0,G35/G36) -> 0.598386 | H38: =IF(H36=0,0,H35/H36) -> 0.38169097 | I38: =IF(I36=0,0,I35/I36) -> 2.6219232 | J38: =IF(J36=0,0,J35/J36) -> 0.44291314 | ... S38: =IF(S36=0,0,S35/S36) -> 4.8168002
A39: B2C profit after psychologists, ads and referral rewards | B39: Rp m | C39: =SUM(E39:G39) -> -2.9562258 | D39: =SUM(H39:S39) -> 37.819167 | E39: =E35-E36-E37-E53 -> -1.0461545 | F39: =F35-F36-F37-F53 -> -0.98635915 | G39: =G35-G36-G37-G53 -> -0.9237122 | H39: =H35-H36-H37-H53 -> -6.8875726 | I39: =I35-I36-I37-I53 -> 5.2699838 | J39: =J35-J36-J37-J53 -> -6.5602937 | K39: =K35-K36-K37-K53 -> -2.8273675 | L39: =L35-L36-L37-L53 -> -2.5099751 | ... S39: =S35-S36-S37-S53 -> 16.715421
A40: Capacity (COO)
A41: COO: sessions to deliver (B2C + EAP) | B41: sessions | C41: =SUM(E41:G41) -> 36.572957 | D41: =SUM(H41:S41) -> 455.97351 | E41: =E26+Volume!E26*Inputs!$C$68 -> 12.089743 | F41: =F26+Volume!F26*Inputs!$C$68 -> 12.189401 | G41: =G26+Volume!G26*Inputs!$C$68 -> 12.293813 | H41: =H26+Volume!H26*Inputs!$C$68 -> 13.453031 | I41: =I26+Volume!I26*Inputs!$C$68 -> 23.719665 | J41: =J26+Volume!J26*Inputs!$C$68 -> 24.006888 | K41: =K26+Volume!K26*Inputs!$C$68 -> 30.3367 | L41: =L26+Volume!L26*Inputs!$C$68 -> 30.88018 | ... S41: =S26+Volume!S26*Inputs!$C$68 -> 53.575986
...

Sheet Inputs
A1: Inputs and assumptions (all money in Rp million)
A2: Blue numbers are inputs you can change. Status: Known = you told us or it is in your v10 file; Your plan = your own budget; Estimate = industry estimate used until you give the real number (yellow-shaded, listed in the To_Fill sheet).
A4: Key | B4: Item | C4: Value | D4: Unit | E4: Status | F4: Source / logic
A5: 0. Scenario selector
A6: scen | B6: Active scenario (1-4) | C6: 1 | D6: number | E6: Known | F6: 1 = Base plan (v10 volumes). 2 = No new B2B event closes Jan-Jun 2027. 3 = BI cuts its volume by the % below. 4 = Both 2 and 3 (worst case).
A7: bi_cut | B7: BI volume cut used in scenarios 3 and 4 | C7: 0.3 | D7: % | E7: Known | F7: Stress test size. Change freely.
A8: 1. Prices (per event, or per month for EAP)
A9: p_flag | B9: Flagship regulator ToT (CBP Rupiah) | C9: 85 | D9: Rp m / event | E9: Known | F9: Your v10 file.
A10: p_kpw | B10: Regulator regional ToT (BI KPW and LPS) | C10: 20 | D10: Rp m / event | E10: Known | F10: Your v10 file.
A11: p_kcp | B11: Bank branch event (KCP) | C11: 35 | D11: Rp m / event | E11: Known | F11: Your v10 file.
A12: p_eap | B12: Bank EAP subscription | C12: 15 | D12: Rp m / month | E12: Known | F12: Your v10 file.
A13: p_b2ce | B13: B2C mass event | C13: 20 | D13: Rp m / event | E13: Known | F13: Your v10 file.
A14: p_b2cc | B14: B2C counseling client | C14: 1 | D14: Rp m / client | E14: Known | F14: Your v10 file (Rp 1,000,000 per session).
A15: 2. Delivery cost (cost of goods sold)
A16: c_flag | B16: Flagship delivery cost | C16: 25 | D16: Rp m / event | E16: Known | F16: Your v10 file: travel, hotel, materials, premium facilitator fees.
A17: c_kpw | B17: KPW / LPS delivery cost | C17: 8 | D17: Rp m / event | E17: Known | F17: Your v10 file. Covers about 2 handler fees only, so travel is assumed paid by the client (see below).
A18: c_kcp | B18: Bank KCP event delivery cost | C18: 12 | D18: Rp m / event | E18: Known | F18: Your v10 file.
A19: c_eap | B19: EAP delivery cost | C19: 5 | D19: Rp m / month | E19: Known | F19: Your v10 file: on-call tele-counseling retainer.
A20: c_b2ce | B20: B2C event delivery cost | C20: 8 | D20: Rp m / event | E20: Known | F20: Your v10 file: venue, ads, materials, fees.
A21: c_b2cc | B21: B2C counseling cost (psychologist fee) | C21: 0.4 | D21: % of price | E21: Known | F21: Your v10 file: Rp 400k of Rp 1m.
A22: travel_client | B22: Client pays travel for regional events? (1 = yes, 0 = no) | C22: 1 | D22: switch | E22: Estimate | F22: The Rp 8m KPW cost only covers 2 handler fees, so we assume BI pays travel.
A23: travel_pp | B23: Travel cost per handler per regional trip | C23: 3.5 | D23: Rp m / person | E23: Estimate | F23: Industry estimate: return flight ~Rp 2m + 2 hotel nights ~Rp 1m + per diem ~Rp 0.5m.
A24: regional_share | B24: Share of KPW / LPS events outside Jakarta | C24: 0.8 | D24: % | E24: Estimate | F24: Estimate: most KPW offices are outside Jakarta.
A25: 3. Delivery staffing (from your v10 file)
A26: h_flag | B26: Handlers per Flagship event | C26: 4 | D26: people | E26: Known | F26: 1 PM, 1 Lead Psychologist, 2 Facilitators.
A27: h_kpw | B27: Handlers per KPW / LPS event | C27: 2 | D27: people | E27: Known | F27: 1 Lead, 1 Facilitator.
A28: h_kcp | B28: Handlers per KCP event | C28: 2 | D28: people | E28: Known | F28: 1 Lead, 1 Facilitator.
A29: h_b2ce | B29: Handlers per B2C event | C29: 2 | D29: people | E29: Known | F29: 1 Lead, 1 Facilitator / Assistant.
A30: d_flag | B30: Days per Flagship event | C30: 3 | D30: days | E30: Estimate | F30: You said 2-3 day program; we use 3.
A31: d_kpw | B31: Days per KPW / LPS event | C31: 1 | D31: days | E31: Estimate | F31: Estimate.
A32: d_kcp | B32: Days per KCP event | C32: 1 | D32: days | E32: Estimate | F32: Estimate.
A33: d_b2ce | B33: Days per B2C event | C33: 1 | D33: days | E33: Estimate | F33: Estimate (weekend event).
A34: fac_cap | B34: Max events per facilitator per month | C34: 2 | D34: events | E34: Known | F34: Your v10 quality rule.
A35: fac_now | B35: Certified facilitators today | C35: 2 | D35: people | E35: Known | F35: You told us: 2 active core facilitators.
A36: fac_plan | B36: Your plan: facilitators certified by Nov 2026 | C36: 11 | D36: people | E36: Known | F36: Your earlier plan.
A37: cert_cost | B37: Cost to certify one new facilitator | C37: 2.5 | D37: Rp m / person | E37: Estimate | F37: Industry estimate: 2-day internal ToT, materials, observed practice event.
A38: 4. Fixed cost: base (your 2027 'bensin' budget, monthly)
A39: o_lead_mkt | B39: Lead Marketing | C39: 2.5 | D39: Rp m / month | E39: Known | F39: Your 2027 budget.
A40: o_socmed | B40: Social Media Specialist | C40: 1.5 | D40: Rp m / month | E40: Known | F40: Your 2027 budget.
A41: o_intern_mkt | B41: Marketing intern | C41: 1 | D41: Rp m / month | E41: Known | F41: Your 2027 budget.
...

Sheet Pay_Plan
A1: Pay plan: gross pay a month for every role (Rp million). Blue cells are your decisions; change them freely.
A2: Decided 5 Oct 2026: BPJS + THR from Jan-27; social media up in steps; admin to the minimum wage from Jul-27; lead marketing capped at Rp4m in 2027 (KPI: 10k IG followers) with Rp3.5m of her budget moved to ads; admin paid per client (Rp1.8m base + Rp17k a client + Rp620k bonus); pay rises for admin, social media and lead marketing unlock when sales targets are met (rows 27-30), not by date; psychologist stays part-time (no full-time hire for now); a non-psychologist Lead Partnership from Oct-27; IG ads today Rp1m (software budget) + Rp3.5m moved from lead marketing; founders: only one is paid today (Rp10m); Rp25m from Mar-27 keeps room for the second founder, whose start is still to decide.
A4: Line | B4: Unit | C4: Q4 2026 | D4: FY 2027 | E4: =Volume!E4 -> Oct-26 | F4: =Volume!F4 -> Nov-26 | G4: =Volume!G4 -> Dec-26 | H4: =Volume!H4 -> Jan-27 | I4: =Volume!I4 -> Feb-27 | J4: =Volume!J4 -> Mar-27 | K4: =Volume!K4 -> Apr-27 | L4: =Volume!L4 -> May-27 | ... S4: =Volume!S4 -> Dec-27
A5: Gross pay a month (blue = your input)
A6: Admin (formula: base + fee per client + weekly bonus; minimum wage once step 2 is unlocked) | B6: Rp m | C6: =SUM(E6:G6) -> 6.0217403 | D6: =SUM(H6:S6) -> 48.390108 | E6: =IF(E30>=2,MAX(Inputs!$C$122,Inputs!$C$118+Inputs!$C$119*(Volume!E28+Volume!E26*Inputs!$C$68)+IF((Volume!E28+Volume!E26*Inputs!$C$68)>=Inputs!$C$121,Inputs!$C$120,0)),Inputs!$C$118+Inputs!$C$119*(Volume!E28+Volume!E26*Inputs!$C$68)+IF((Volume!E28+Volume!E26*Inputs!$C$68)>=Inputs!$C$121,Inputs!$C$120,0)) -> 2.0055256 | F6: =IF(F30>=2,MAX(Inputs!$C$122,Inputs!$C$118+Inputs!$C$119*(Volume!F28+Volume!F26*Inputs!$C$68)+IF((Volume!F28+Volume!F26*Inputs!$C$68)>=Inputs!$C$121,Inputs!$C$120,0)),Inputs!$C$118+Inputs!$C$119*(Volume!F28+Volume!F26*Inputs!$C$68)+IF((Volume!F28+Volume!F26*Inputs!$C$68)>=Inputs!$C$121,Inputs!$C$120,0)) -> 2.0072198 | G6: =IF(G30>=2,MAX(Inputs!$C$122,Inputs!$C$118+Inputs!$C$119*(Volume!G28+Volume!G26*Inputs!$C$68)+IF((Volume!G28+Volume!G26*Inputs!$C$68)>=Inputs!$C$121,Inputs!$C$120,0)),Inputs!$C$118+Inputs!$C$119*(Volume!G28+Volume!G26*Inputs!$C$68)+IF((Volume!G28+Volume!G26*Inputs!$C$68)>=Inputs!$C$121,Inputs!$C$120,0)) -> 2.0089948 | H6: =IF(H30>=2,MAX(Inputs!$C$122,Inputs!$C$118+Inputs!$C$119*(Volume!H28+Volume!H26*Inputs!$C$68)+IF((Volume!H28+Volume!H26*Inputs!$C$68)>=Inputs!$C$121,Inputs!$C$120,0)),Inputs!$C$118+Inputs!$C$119*(Volume!H28+Volume!H26*Inputs!$C$68)+IF((Volume!H28+Volume!H26*Inputs!$C$68)>=Inputs!$C$121,Inputs!$C$120,0)) -> 2.0287015 | I6: =IF(I30>=2,MAX(Inputs!$C$122,Inputs!$C$118+Inputs!$C$119*(Volume!I28+Volume!I26*Inputs!$C$68)+IF((Volume!I28+Volume!I26*Inputs!$C$68)>=Inputs!$C$121,Inputs!$C$120,0)),Inputs!$C$118+Inputs!$C$119*(Volume!I28+Volume!I26*Inputs!$C$68)+IF((Volume!I28+Volume!I26*Inputs!$C$68)>=Inputs!$C$121,Inputs!$C$120,0)) -> 2.8232343 | J6: =IF(J30>=2,MAX(Inputs!$C$122,Inputs!$C$118+Inputs!$C$119*(Volume!J28+Volume!J26*Inputs!$C$68)+IF((Volume!J28+Volume!J26*Inputs!$C$68)>=Inputs!$C$121,Inputs!$C$120,0)),Inputs!$C$118+Inputs!$C$119*(Volume!J28+Volume!J26*Inputs!$C$68)+IF((Volume!J28+Volume!J26*Inputs!$C$68)>=Inputs!$C$121,Inputs!$C$120,0)) -> 2.8281171 | K6: =IF(K30>=2,MAX(Inputs!$C$122,Inputs!$C$118+Inputs!$C$119*(Volume!K28+Volume!K26*Inputs!$C$68)+IF((Volume!K28+Volume!K26*Inputs!$C$68)>=Inputs!$C$121,Inputs!$C$120,0)),Inputs!$C$118+Inputs!$C$119*(Volume!K28+Volume!K26*Inputs!$C$68)+IF((Volume!K28+Volume!K26*Inputs!$C$68)>=Inputs!$C$121,Inputs!$C$120,0)) -> 2.9357239 | L6: =IF(L30>=2,MAX(Inputs!$C$122,Inputs!$C$118+Inputs!$C$119*(Volume!L28+Volume!L26*Inputs!$C$68)+IF((Volume!L28+Volume!L26*Inputs!$C$68)>=Inputs!$C$121,Inputs!$C$120,0)),Inputs!$C$118+Inputs!$C$119*(Volume!L28+Volume!L26*Inputs!$C$68)+IF((Volume!L28+Volume!L26*Inputs!$C$68)>=Inputs!$C$121,Inputs!$C$120,0)) -> 2.9449631 | ... S6: =IF(S30>=2,MAX(Inputs!$C$122,Inputs!$C$118+Inputs!$C$119*(Volume!S28+Volume!S26*Inputs!$C$68)+IF((Volume!S28+Volume!S26*Inputs!$C$68)>=Inputs!$C$121,Inputs!$C$120,0)),Inputs!$C$118+Inputs!$C$119*(Volume!S28+Volume!S26*Inputs!$C$68)+IF((Volume!S28+Volume!S26*Inputs!$C$68)>=Inputs!$C$121,Inputs!$C$120,0)) -> 5.73
A7: Social media specialist (formula: 1.5, then 3.0 / 4.5 / minimum wage at pay steps 1 / 2 / 3) | B7: Rp m | C7: =SUM(E7:G7) -> 4.5 | D7: =SUM(H7:S7) -> 38.73 | E7: =CHOOSE(E30+1,1.5,3,4.5,Inputs!$C$122) -> 1.5 | F7: =CHOOSE(F30+1,1.5,3,4.5,Inputs!$C$122) -> 1.5 | G7: =CHOOSE(G30+1,1.5,3,4.5,Inputs!$C$122) -> 1.5 | H7: =CHOOSE(H30+1,1.5,3,4.5,Inputs!$C$122) -> 1.5 | I7: =CHOOSE(I30+1,1.5,3,4.5,Inputs!$C$122) -> 1.5 | J7: =CHOOSE(J30+1,1.5,3,4.5,Inputs!$C$122) -> 1.5 | K7: =CHOOSE(K30+1,1.5,3,4.5,Inputs!$C$122) -> 1.5 | L7: =CHOOSE(L30+1,1.5,3,4.5,Inputs!$C$122) -> 3 | ... S7: =CHOOSE(S30+1,1.5,3,4.5,Inputs!$C$122) -> 5.73
A8: Lead marketing (formula: 2.5, then 4.0 cap at pay step 1; KPI 10k IG followers; has shares) | B8: Rp m | C8: =SUM(E8:G8) -> 7.5 | D8: =SUM(H8:S8) -> 42 | E8: =IF(E30>=1,4,2.5) -> 2.5 | F8: =IF(F30>=1,4,2.5) -> 2.5 | G8: =IF(G30>=1,4,2.5) -> 2.5 | H8: =IF(H30>=1,4,2.5) -> 2.5 | I8: =IF(I30>=1,4,2.5) -> 2.5 | J8: =IF(J30>=1,4,2.5) -> 2.5 | K8: =IF(K30>=1,4,2.5) -> 2.5 | L8: =IF(L30>=1,4,2.5) -> 4 | ... S8: =IF(S30>=1,4,2.5) -> 4
A9: Psychologists, paid part-time: PIC now + 1 more from Jan-27 (no full-time hire in 2027) | B9: Rp m | C9: =SUM(E9:G9) -> 6.9 | D9: =SUM(H9:S9) -> 55.2 | E9: 2.3 | F9: 2.3 | G9: 2.3 | H9: 4.6 | I9: 4.6 | J9: 4.6 | K9: 4.6 | L9: 4.6 | M9: 4.6 | N9: 4.6 | O9: 4.6 | P9: 4.6 | Q9: 4.6 | R9: 4.6 | S9: 4.6
A10: Interns, not Magang (2 people) | B10: Rp m | C10: =SUM(E10:G10) -> 6 | D10: =SUM(H10:S10) -> 24 | E10: 2 | F10: 2 | G10: 2 | H10: 2 | I10: 2 | J10: 2 | K10: 2 | L10: 2 | M10: 2 | N10: 2 | O10: 2 | P10: 2 | Q10: 2 | R10: 2 | S10: 2
A11: Founders: Rp10m now (one founder paid); Rp25m from Mar-27 = room for both (second founder's start: to decide) | B11: Rp m | C11: =SUM(E11:G11) -> 30 | D11: =SUM(H11:S11) -> 270 | E11: 10 | F11: 10 | G11: 10 | H11: 10 | I11: 10 | J11: 25 | K11: 25 | L11: 25 | M11: 25 | N11: 25 | O11: 25 | P11: 25 | Q11: 25 | R11: 25 | S11: 25
A12: Extra IG ads (Rp3.5m moved from lead marketing; Rp1m is already in the software budget) | B12: Rp m | C12: =SUM(E12:G12) -> 0 | D12: =SUM(H12:S12) -> 42 | E12: 0 | F12: 0 | G12: 0 | H12: 3.5 | I12: 3.5 | J12: 3.5 | K12: 3.5 | L12: 3.5 | M12: 3.5 | N12: 3.5 | O12: 3.5 | P12: 3.5 | Q12: 3.5 | R12: 3.5 | S12: 3.5
A13: Lead Partnership, non-psychologist (formula: from Inputs) | B13: Rp m | C13: =SUM(E13:G13) -> 0 | D13: =SUM(H13:S13) -> 18 | E13: =IF(Volume!E6>=IFERROR(MATCH(Inputs!$C$125,Volume!$E$4:$S$4,0),99),Inputs!$C$124,0) -> 0 | F13: =IF(Volume!F6>=IFERROR(MATCH(Inputs!$C$125,Volume!$E$4:$S$4,0),99),Inputs!$C$124,0) -> 0 | G13: =IF(Volume!G6>=IFERROR(MATCH(Inputs!$C$125,Volume!$E$4:$S$4,0),99),Inputs!$C$124,0) -> 0 | H13: =IF(Volume!H6>=IFERROR(MATCH(Inputs!$C$125,Volume!$E$4:$S$4,0),99),Inputs!$C$124,0) -> 0 | I13: =IF(Volume!I6>=IFERROR(MATCH(Inputs!$C$125,Volume!$E$4:$S$4,0),99),Inputs!$C$124,0) -> 0 | J13: =IF(Volume!J6>=IFERROR(MATCH(Inputs!$C$125,Volume!$E$4:$S$4,0),99),Inputs!$C$124,0) -> 0 | K13: =IF(Volume!K6>=IFERROR(MATCH(Inputs!$C$125,Volume!$E$4:$S$4,0),99),Inputs!$C$124,0) -> 0 | L13: =IF(Volume!L6>=IFERROR(MATCH(Inputs!$C$125,Volume!$E$4:$S$4,0),99),Inputs!$C$124,0) -> 0 | ... S13: =IF(Volume!S6>=IFERROR(MATCH(Inputs!$C$125,Volume!$E$4:$S$4,0),99),Inputs!$C$124,0) -> 6
A14: BPJS + THR paid on staff pay? (1 = yes) | B14: flag | C14: =MAX(E14:G14) -> 0 | D14: =MAX(H14:S14) -> 1 | E14: 0 | F14: 0 | G14: 0 | H14: 1 | I14: 1 | J14: 1 | K14: 1 | L14: 1 | M14: 1 | N14: 1 | O14: 1 | P14: 1 | Q14: 1 | R14: 1 | S14: 1
A15: Team cost incl. BPJS and THR (staff + psychologist + interns) | B15: Rp m | C15: =SUM(E15:G15) -> 30.92174 | D15: =SUM(H15:S15) -> 262.73773 | E15: =(E6+E7+E8+E9+E13)*(1+Inputs!$C$106*E14)+E10 -> 10.305526 | F15: =(F6+F7+F8+F9+F13)*(1+Inputs!$C$106*F14)+F10 -> 10.30722 | G15: =(G6+G7+G8+G9+G13)*(1+Inputs!$C$106*G14)+G10 -> 10.308995 | H15: =(H6+H7+H8+H9+H13)*(1+Inputs!$C$106*H14)+H10 -> 14.541868 | I15: =(I6+I7+I8+I9+I13)*(1+Inputs!$C$106*I14)+I10 -> 15.479416 | J15: =(J6+J7+J8+J9+J13)*(1+Inputs!$C$106*J14)+J10 -> 15.485178 | K15: =(K6+K7+K8+K9+K13)*(1+Inputs!$C$106*K14)+K10 -> 15.612154 | L15: =(L6+L7+L8+L9+L13)*(1+Inputs!$C$106*L14)+L10 -> 19.163056 | ... S15: =(S6+S7+S8+S9+S13)*(1+Inputs!$C$106*S14)+S10 -> 32.7508
A16: Total pay plan (team + founders + extra ads) | B16: Rp m | C16: =SUM(E16:G16) -> 60.92174 | D16: =SUM(H16:S16) -> 574.73773 | E16: =E15+E11+E12 -> 20.305526 | F16: =F15+F11+F12 -> 20.30722 | G16: =G15+G11+G12 -> 20.308995 | H16: =H15+H11+H12 -> 28.041868 | I16: =I15+I11+I12 -> 28.979416 | J16: =J15+J11+J12 -> 43.985178 | K16: =K15+K11+K12 -> 44.112154 | L16: =L15+L11+L12 -> 47.663056 | ... S16: =S15+S11+S12 -> 61.2508
A18: Running cost by group: all fixed costs a month (Rp million)
A19: Founders | B19: Rp m | C19: =SUM(E19:G19) -> 30 | D19: =SUM(H19:S19) -> 270 | E19: =Capacity_OPEX!E26 -> 10 | F19: =Capacity_OPEX!F26 -> 10 | G19: =Capacity_OPEX!G26 -> 10 | H19: =Capacity_OPEX!H26 -> 10 | I19: =Capacity_OPEX!I26 -> 10 | J19: =Capacity_OPEX!J26 -> 25 | K19: =Capacity_OPEX!K26 -> 25 | L19: =Capacity_OPEX!L26 -> 25 | ... S19: =Capacity_OPEX!S26 -> 25
A20: Team: staff, psychologist, interns, BPJS, THR | B20: Rp m | C20: =SUM(E20:G20) -> 30.92174 | D20: =SUM(H20:S20) -> 262.73773 | E20: =Capacity_OPEX!E22+Capacity_OPEX!E37 -> 10.305526 | F20: =Capacity_OPEX!F22+Capacity_OPEX!F37 -> 10.30722 | G20: =Capacity_OPEX!G22+Capacity_OPEX!G37 -> 10.308995 | H20: =Capacity_OPEX!H22+Capacity_OPEX!H37 -> 14.541868 | I20: =Capacity_OPEX!I22+Capacity_OPEX!I37 -> 15.479416 | J20: =Capacity_OPEX!J22+Capacity_OPEX!J37 -> 15.485178 | K20: =Capacity_OPEX!K22+Capacity_OPEX!K37 -> 15.612154 | L20: =Capacity_OPEX!L22+Capacity_OPEX!L37 -> 19.163056 | ... S20: =Capacity_OPEX!S22+Capacity_OPEX!S37 -> 32.7508
A21: Marketing: software and IG ads | B21: Rp m | C21: =SUM(E21:G21) -> 6.23975 | D21: =SUM(H21:S21) -> 69.587941 | E21: =Capacity_OPEX!E23+Capacity_OPEX!E38 -> 2.0799167 | F21: =Capacity_OPEX!F23+Capacity_OPEX!F38 -> 2.0799167 | G21: =Capacity_OPEX!G23+Capacity_OPEX!G38 -> 2.0799167 | H21: =Capacity_OPEX!H23+Capacity_OPEX!H38 -> 5.6113079 | I21: =Capacity_OPEX!I23+Capacity_OPEX!I38 -> 5.6137318 | J21: =Capacity_OPEX!J23+Capacity_OPEX!J38 -> 5.6163429 | K21: =Capacity_OPEX!K23+Capacity_OPEX!K38 -> 5.6813039 | L21: =Capacity_OPEX!L23+Capacity_OPEX!L38 -> 5.6899995 | ... S21: =Capacity_OPEX!S23+Capacity_OPEX!S38 -> 6.0820877
A22: Office and accountant | B22: Rp m | C22: =SUM(E22:G22) -> 21.9 | D22: =SUM(H22:S22) -> 87.6 | E22: =Capacity_OPEX!E24+Capacity_OPEX!E25 -> 7.3 | F22: =Capacity_OPEX!F24+Capacity_OPEX!F25 -> 7.3 | G22: =Capacity_OPEX!G24+Capacity_OPEX!G25 -> 7.3 | H22: =Capacity_OPEX!H24+Capacity_OPEX!H25 -> 7.3 | I22: =Capacity_OPEX!I24+Capacity_OPEX!I25 -> 7.3 | J22: =Capacity_OPEX!J24+Capacity_OPEX!J25 -> 7.3 | K22: =Capacity_OPEX!K24+Capacity_OPEX!K25 -> 7.3 | L22: =Capacity_OPEX!L24+Capacity_OPEX!L25 -> 7.3 | ... S22: =Capacity_OPEX!S24+Capacity_OPEX!S25 -> 7.3
A23: Sales and delivery support: co-founder, travel, project manager, 2nd admin, trainer training | B23: Rp m | C23: =SUM(E23:G23) -> 6 | D23: =SUM(H23:S23) -> 145 | E23: =Capacity_OPEX!E27+Capacity_OPEX!E28+Capacity_OPEX!E29+Capacity_OPEX!E30+Capacity_OPEX!E31+Capacity_OPEX!E39 -> 2 | F23: =Capacity_OPEX!F27+Capacity_OPEX!F28+Capacity_OPEX!F29+Capacity_OPEX!F30+Capacity_OPEX!F31+Capacity_OPEX!F39 -> 2 | G23: =Capacity_OPEX!G27+Capacity_OPEX!G28+Capacity_OPEX!G29+Capacity_OPEX!G30+Capacity_OPEX!G31+Capacity_OPEX!G39 -> 2 | H23: =Capacity_OPEX!H27+Capacity_OPEX!H28+Capacity_OPEX!H29+Capacity_OPEX!H30+Capacity_OPEX!H31+Capacity_OPEX!H39 -> 4.5 | I23: =Capacity_OPEX!I27+Capacity_OPEX!I28+Capacity_OPEX!I29+Capacity_OPEX!I30+Capacity_OPEX!I31+Capacity_OPEX!I39 -> 2 | J23: =Capacity_OPEX!J27+Capacity_OPEX!J28+Capacity_OPEX!J29+Capacity_OPEX!J30+Capacity_OPEX!J31+Capacity_OPEX!J39 -> 6 | K23: =Capacity_OPEX!K27+Capacity_OPEX!K28+Capacity_OPEX!K29+Capacity_OPEX!K30+Capacity_OPEX!K31+Capacity_OPEX!K39 -> 4 | L23: =Capacity_OPEX!L27+Capacity_OPEX!L28+Capacity_OPEX!L29+Capacity_OPEX!L30+Capacity_OPEX!L31+Capacity_OPEX!L39 -> 8.5 | ... S23: =Capacity_OPEX!S27+Capacity_OPEX!S28+Capacity_OPEX!S29+Capacity_OPEX!S30+Capacity_OPEX!S31+Capacity_OPEX!S39 -> 22
A24: Total running cost (equals Capacity_OPEX total) | B24: Rp m | C24: =SUM(E24:G24) -> 95.06149 | D24: =SUM(H24:S24) -> 834.92567 | E24: =SUM(E19:E23) -> 31.685442 | F24: =SUM(F19:F23) -> 31.687136 | G24: =SUM(G19:G23) -> 31.688911 | H24: =SUM(H19:H23) -> 41.953176 | I24: =SUM(I19:I23) -> 40.393148 | J24: =SUM(J19:J23) -> 59.401521 | K24: =SUM(K19:K23) -> 57.593458 | L24: =SUM(L19:L23) -> 65.653056 | ... S24: =SUM(S19:S23) -> 93.132888
A25: Check: difference to Capacity_OPEX total (must be 0) | B25: Rp m | C25: =SUM(E25:G25) -> 0 | D25: =SUM(H25:S25) -> 0 | E25: =ROUND(E24-Capacity_OPEX!E32,6) -> 0 | F25: =ROUND(F24-Capacity_OPEX!F32,6) -> 0 | G25: =ROUND(G24-Capacity_OPEX!G32,6) -> 0 | H25: =ROUND(H24-Capacity_OPEX!H32,6) -> 0 | I25: =ROUND(I24-Capacity_OPEX!I32,6) -> 0 | J25: =ROUND(J24-Capacity_OPEX!J32,6) -> 0 | K25: =ROUND(K24-Capacity_OPEX!K32,6) -> 0 | L25: =ROUND(L24-Capacity_OPEX!L32,6) -> 0 | ... S25: =ROUND(S24-Capacity_OPEX!S32,6) -> 0
A27: Pay steps: unlocked by sales, not by date (founders, 5 Oct 2026)
A28: Average sales of the previous 3 months (Rp m) | E28: =0 -> 0 | F28: =AVERAGE(PnL!E12) -> 17.089743 | G28: =AVERAGE(PnL!F12,PnL!E12) -> 17.139572 | H28: =AVERAGE(PnL!G12,PnL!F12,PnL!E12) -> 17.190986 | I28: =AVERAGE(PnL!H12,PnL!G12,PnL!F12) -> 17.645415 | J28: =AVERAGE(PnL!I12,PnL!H12,PnL!G12) -> 29.82217 | K28: =AVERAGE(PnL!J12,PnL!I12,PnL!H12) -> 78.226528 | L28: =AVERAGE(PnL!K12,PnL!J12,PnL!I12) -> 103.35442 | M28: =AVERAGE(PnL!L12,PnL!K12,PnL!J12) -> 141.90792 | N28: =AVERAGE(PnL!M12,PnL!L12,PnL!K12) -> 111.06238 | O28: =AVERAGE(PnL!N12,PnL!M12,PnL!L12) -> 161.22218 | ... S28: =AVERAGE(PnL!R12,PnL!Q12,PnL!P12) -> 283.80937
A29: Highest so far (a pay step never goes back down) | E29: =E28 -> 0 | F29: =MAX(E29,F28) -> 17.089743 | G29: =MAX(F29,G28) -> 17.139572 | H29: =MAX(G29,H28) -> 17.190986 | I29: =MAX(H29,I28) -> 17.645415 | J29: =MAX(I29,J28) -> 29.82217 | K29: =MAX(J29,K28) -> 78.226528 | L29: =MAX(K29,L28) -> 103.35442 | M29: =MAX(L29,M28) -> 141.90792 | ... S29: =MAX(R29,S28) -> 283.80937
A30: Pay step unlocked this month (0 to 3) | E30: =(E29>=Inputs!$C$123)+(E29>=Inputs!$C$126)+(E29>=Inputs!$C$127) -> 0 | F30: =(F29>=Inputs!$C$123)+(F29>=Inputs!$C$126)+(F29>=Inputs!$C$127) -> 0 | G30: =(G29>=Inputs!$C$123)+(G29>=Inputs!$C$126)+(G29>=Inputs!$C$127) -> 0 | H30: =(H29>=Inputs!$C$123)+(H29>=Inputs!$C$126)+(H29>=Inputs!$C$127) -> 0 | I30: =(I29>=Inputs!$C$123)+(I29>=Inputs!$C$126)+(I29>=Inputs!$C$127) -> 0 | J30: =(J29>=Inputs!$C$123)+(J29>=Inputs!$C$126)+(J29>=Inputs!$C$127) -> 0 | K30: =(K29>=Inputs!$C$123)+(K29>=Inputs!$C$126)+(K29>=Inputs!$C$127) -> 0 | L30: =(L29>=Inputs!$C$123)+(L29>=Inputs!$C$126)+(L29>=Inputs!$C$127) -> 1 | ... S30: =(S29>=Inputs!$C$123)+(S29>=Inputs!$C$126)+(S29>=Inputs!$C$127) -> 3

Sheet Volume
A1: Event volume plan (from your v10 file, moved to Oct 2026 - Dec 2027)
A2: Rp million unless stated. Q4 2026 and FY 2027 columns are totals (or averages / peaks where stated).
A4: Line | B4: Unit | C4: Q4 2026 | D4: FY 2027 | E4: Oct-26 | F4: Nov-26 | G4: Dec-26 | H4: Jan-27 | I4: Feb-27 | J4: Mar-27 | K4: Apr-27 | L4: May-27 | M4: Jun-27 | N4: Jul-27 | O4: Aug-27 | P4: Sep-27 | Q4: Oct-27 | R4: Nov-27 | S4: Dec-27
A5: Timeline helpers
A6: Month number | B6: # | E6: 1 | F6: 2 | G6: 3 | H6: 4 | I6: 5 | J6: 6 | K6: 7 | L6: 8 | M6: 9 | N6: 10 | O6: 11 | P6: 12 | Q6: 13 | R6: 14 | S6: 15
A7: Is 2027? (1 = yes) | B7: flag | E7: 0 | F7: 0 | G7: 0 | H7: 1 | I7: 1 | J7: 1 | K7: 1 | L7: 1 | M7: 1 | N7: 1 | O7: 1 | P7: 1 | Q7: 1 | R7: 1 | S7: 1
A8: Is Jan-Jun 2027? (1 = yes) | B8: flag | E8: 0 | F8: 0 | G8: 0 | H8: 1 | I8: 1 | J8: 1 | K8: 1 | L8: 1 | M8: 1 | N8: 0 | O8: 0 | P8: 0 | Q8: 0 | R8: 0 | S8: 0
A9: Scenario switch: new B2B events allowed (1 = yes) | B9: flag | E9: =IF(AND(OR(Inputs!$C$6=2,Inputs!$C$6=4),E8=1),0,1) -> 1 | F9: =IF(AND(OR(Inputs!$C$6=2,Inputs!$C$6=4),F8=1),0,1) -> 1 | G9: =IF(AND(OR(Inputs!$C$6=2,Inputs!$C$6=4),G8=1),0,1) -> 1 | H9: =IF(AND(OR(Inputs!$C$6=2,Inputs!$C$6=4),H8=1),0,1) -> 1 | I9: =IF(AND(OR(Inputs!$C$6=2,Inputs!$C$6=4),I8=1),0,1) -> 1 | J9: =IF(AND(OR(Inputs!$C$6=2,Inputs!$C$6=4),J8=1),0,1) -> 1 | K9: =IF(AND(OR(Inputs!$C$6=2,Inputs!$C$6=4),K8=1),0,1) -> 1 | L9: =IF(AND(OR(Inputs!$C$6=2,Inputs!$C$6=4),L8=1),0,1) -> 1 | ... S9: =IF(AND(OR(Inputs!$C$6=2,Inputs!$C$6=4),S8=1),0,1) -> 1
A10: Scenario factor: BI volume | B10: x | E10: =IF(OR(Inputs!$C$6=3,Inputs!$C$6=4),1-Inputs!$C$7,1) -> 1 | F10: =IF(OR(Inputs!$C$6=3,Inputs!$C$6=4),1-Inputs!$C$7,1) -> 1 | G10: =IF(OR(Inputs!$C$6=3,Inputs!$C$6=4),1-Inputs!$C$7,1) -> 1 | H10: =IF(OR(Inputs!$C$6=3,Inputs!$C$6=4),1-Inputs!$C$7,1) -> 1 | I10: =IF(OR(Inputs!$C$6=3,Inputs!$C$6=4),1-Inputs!$C$7,1) -> 1 | J10: =IF(OR(Inputs!$C$6=3,Inputs!$C$6=4),1-Inputs!$C$7,1) -> 1 | K10: =IF(OR(Inputs!$C$6=3,Inputs!$C$6=4),1-Inputs!$C$7,1) -> 1 | L10: =IF(OR(Inputs!$C$6=3,Inputs!$C$6=4),1-Inputs!$C$7,1) -> 1 | ... S10: =IF(OR(Inputs!$C$6=3,Inputs!$C$6=4),1-Inputs!$C$7,1) -> 1
A11: New prices active this month? (1 = yes) | B11: flag | E11: =IF(AND(Inputs!$C$85=2,E6>=IFERROR(MATCH(Inputs!$C$86,$E$4:$S$4,0),99)),1,0) -> 0 | F11: =IF(AND(Inputs!$C$85=2,F6>=IFERROR(MATCH(Inputs!$C$86,$E$4:$S$4,0),99)),1,0) -> 0 | G11: =IF(AND(Inputs!$C$85=2,G6>=IFERROR(MATCH(Inputs!$C$86,$E$4:$S$4,0),99)),1,0) -> 0 | H11: =IF(AND(Inputs!$C$85=2,H6>=IFERROR(MATCH(Inputs!$C$86,$E$4:$S$4,0),99)),1,0) -> 1 | I11: =IF(AND(Inputs!$C$85=2,I6>=IFERROR(MATCH(Inputs!$C$86,$E$4:$S$4,0),99)),1,0) -> 1 | J11: =IF(AND(Inputs!$C$85=2,J6>=IFERROR(MATCH(Inputs!$C$86,$E$4:$S$4,0),99)),1,0) -> 1 | K11: =IF(AND(Inputs!$C$85=2,K6>=IFERROR(MATCH(Inputs!$C$86,$E$4:$S$4,0),99)),1,0) -> 1 | L11: =IF(AND(Inputs!$C$85=2,L6>=IFERROR(MATCH(Inputs!$C$86,$E$4:$S$4,0),99)),1,0) -> 1 | ... S11: =IF(AND(Inputs!$C$85=2,S6>=IFERROR(MATCH(Inputs!$C$86,$E$4:$S$4,0),99)),1,0) -> 1
A12: Price plan factor: B2B volume kept | B12: x | E12: =IF(E11=1,Inputs!$C$98,1) -> 1 | F12: =IF(F11=1,Inputs!$C$98,1) -> 1 | G12: =IF(G11=1,Inputs!$C$98,1) -> 1 | H12: =IF(H11=1,Inputs!$C$98,1) -> 1 | I12: =IF(I11=1,Inputs!$C$98,1) -> 1 | J12: =IF(J11=1,Inputs!$C$98,1) -> 1 | K12: =IF(K11=1,Inputs!$C$98,1) -> 1 | L12: =IF(L11=1,Inputs!$C$98,1) -> 1 | ... S12: =IF(S11=1,Inputs!$C$98,1) -> 1
A14: Base plan volumes (blue = your v10 plan; edit here)
A15: Flagship regulator ToT | B15: events | C15: =SUM(E15:G15) -> 1 | D15: =SUM(H15:S15) -> 5 | E15: 0 | F15: 1 | G15: 0 | H15: 0 | I15: 0 | J15: 1 | K15: 0 | L15: 1 | M15: 0 | N15: 1 | O15: 0 | P15: 1 | Q15: 0 | R15: 1 | S15: 0
A16: KPW / LPS regional ToT | B16: events | C16: =SUM(E16:G16) -> 10 | D16: =SUM(H16:S16) -> 17 | E16: 2 | F16: 3 | G16: 5 | H16: 0 | I16: 0 | J16: 1 | K16: 0 | L16: 1 | M16: 1 | N16: 1 | O16: 1 | P16: 2 | Q16: 2 | R16: 3 | S16: 5
A17: Bank KCP events | B17: events | C17: =SUM(E17:G17) -> 2 | D17: =SUM(H17:S17) -> 4 | E17: 1 | F17: 1 | G17: 0 | H17: 0 | I17: 0 | J17: 0 | K17: 1 | L17: 0 | M17: 0 | N17: 1 | O17: 0 | P17: 0 | Q17: 1 | R17: 1 | S17: 0
A18: Bank EAP contracts active | B18: contracts | C18: =MAX(E18:G18) -> 1 | D18: =MAX(H18:S18) -> 1 | E18: 1 | F18: 1 | G18: 1 | H18: 1 | I18: 1 | J18: 1 | K18: 1 | L18: 1 | M18: 1 | N18: 1 | O18: 1 | P18: 1 | Q18: 1 | R18: 1 | S18: 1
A19: B2C mass events | B19: events | C19: =SUM(E19:G19) -> 3 | D19: =SUM(H19:S19) -> 5 | E19: 1 | F19: 1 | G19: 1 | H19: 1 | I19: 1 | J19: 0 | K19: 0 | L19: 0 | M19: 0 | N19: 0 | O19: 0 | P19: 0 | Q19: 1 | R19: 1 | S19: 1
A20: B2C counseling clients | B20: clients | C20: =SUM(E20:G20) -> 6 | D20: =SUM(H20:S20) -> 23 | E20: 2 | F20: 2 | G20: 2 | H20: 3 | I20: 2 | J20: 1 | K20: 1 | L20: 0 | M20: 2 | N20: 1 | O20: 3 | P20: 4 | Q20: 2 | R20: 2 | S20: 2
A22: Volumes used in the model (after scenario)
A23: Flagship regulator ToT | B23: events | C23: =SUM(E23:G23) -> 0 | D23: =SUM(H23:S23) -> 5 | E23: =E15*E9*E12*E10*(1-E34) -> 0 | F23: =F15*F9*F12*F10*(1-F34) -> 0 | G23: =G15*G9*G12*G10*(1-G34) -> 0 | H23: =H15*H9*H12*H10*(1-H34) -> 0 | I23: =I15*I9*I12*I10*(1-I34) -> 0 | J23: =J15*J9*J12*J10*(1-J34) -> 1 | K23: =K15*K9*K12*K10*(1-K34) -> 0 | L23: =L15*L9*L12*L10*(1-L34) -> 1 | ... S23: =S15*S9*S12*S10*(1-S34) -> 0
A24: KPW / LPS regional ToT | B24: events | C24: =SUM(E24:G24) -> 0 | D24: =SUM(H24:S24) -> 17 | E24: =E16*E9*E12*(1-Inputs!$C$83*(1-E10))*(1-E34) -> 0 | F24: =F16*F9*F12*(1-Inputs!$C$83*(1-F10))*(1-F34) -> 0 | G24: =G16*G9*G12*(1-Inputs!$C$83*(1-G10))*(1-G34) -> 0 | H24: =H16*H9*H12*(1-Inputs!$C$83*(1-H10))*(1-H34) -> 0 | I24: =I16*I9*I12*(1-Inputs!$C$83*(1-I10))*(1-I34) -> 0 | J24: =J16*J9*J12*(1-Inputs!$C$83*(1-J10))*(1-J34) -> 1 | K24: =K16*K9*K12*(1-Inputs!$C$83*(1-K10))*(1-K34) -> 0 | L24: =L16*L9*L12*(1-Inputs!$C$83*(1-L10))*(1-L34) -> 1 | ... S24: =S16*S9*S12*(1-Inputs!$C$83*(1-S10))*(1-S34) -> 5
A25: Bank KCP events (incl. growth-plan bank days) | B25: events | C25: =SUM(E25:G25) -> 0 | D25: =SUM(H25:S25) -> 7 | E25: =E17*E9*E12*(1-E34)+E36 -> 0 | F25: =F17*F9*F12*(1-F34)+F36 -> 0 | G25: =G17*G9*G12*(1-G34)+G36 -> 0 | H25: =H17*H9*H12*(1-H34)+H36 -> 0 | I25: =I17*I9*I12*(1-I34)+I36 -> 0 | J25: =J17*J9*J12*(1-J34)+J36 -> 0 | K25: =K17*K9*K12*(1-K34)+K36 -> 1 | L25: =L17*L9*L12*(1-L34)+L36 -> 0 | ... S25: =S17*S9*S12*(1-S34)+S36 -> 1
A26: Bank EAP contracts active (existing + growth plan) | B26: contracts | C26: =MAX(E26:G26) -> 1 | D26: =MAX(H26:S26) -> 3 | E26: =E18+E35 -> 1 | F26: =F18+F35 -> 1 | G26: =G18+G35 -> 1 | H26: =H18+H35 -> 1 | I26: =I18+I35 -> 2 | J26: =J18+J35 -> 2 | K26: =K18+K35 -> 2 | L26: =L18+L35 -> 2 | ... S26: =S18+S35 -> 3
A27: B2C mass events | B27: events | C27: =SUM(E27:G27) -> 0 | D27: =SUM(H27:S27) -> 4 | E27: =E19*(1-E34*Inputs!$C$103)+Inputs!$C$105*IF(Volume!E6=IFERROR(MATCH(Inputs!$C$128,$E$4:$S$4,0),99),1,0) -> 0 | F27: =F19*(1-F34*Inputs!$C$103)+Inputs!$C$105*IF(Volume!F6=IFERROR(MATCH(Inputs!$C$128,$E$4:$S$4,0),99),1,0) -> 0 | G27: =G19*(1-G34*Inputs!$C$103)+Inputs!$C$105*IF(Volume!G6=IFERROR(MATCH(Inputs!$C$128,$E$4:$S$4,0),99),1,0) -> 0 | H27: =H19*(1-H34*Inputs!$C$103)+Inputs!$C$105*IF(Volume!H6=IFERROR(MATCH(Inputs!$C$128,$E$4:$S$4,0),99),1,0) -> 0 | I27: =I19*(1-I34*Inputs!$C$103)+Inputs!$C$105*IF(Volume!I6=IFERROR(MATCH(Inputs!$C$128,$E$4:$S$4,0),99),1,0) -> 1 | J27: =J19*(1-J34*Inputs!$C$103)+Inputs!$C$105*IF(Volume!J6=IFERROR(MATCH(Inputs!$C$128,$E$4:$S$4,0),99),1,0) -> 0 | K27: =K19*(1-K34*Inputs!$C$103)+Inputs!$C$105*IF(Volume!K6=IFERROR(MATCH(Inputs!$C$128,$E$4:$S$4,0),99),1,0) -> 0 | L27: =L19*(1-L34*Inputs!$C$103)+Inputs!$C$105*IF(Volume!L6=IFERROR(MATCH(Inputs!$C$128,$E$4:$S$4,0),99),1,0) -> 0 | ... S27: =S19*(1-S34*Inputs!$C$103)+Inputs!$C$105*IF(Volume!S6=IFERROR(MATCH(Inputs!$C$128,$E$4:$S$4,0),99),1,0) -> 1
A28: B2C counseling sessions (B2C funnel sheet when the growth plan is on) | B28: clients | C28: =SUM(E28:G28) -> 6.572957 | D28: =SUM(H28:S28) -> 165.97351 | E28: =IF(Inputs!$C$105=1,B2C!E26,E20) -> 2.0897425 | F28: =IF(Inputs!$C$105=1,B2C!F26,F20) -> 2.1894014 | G28: =IF(Inputs!$C$105=1,B2C!G26,G20) -> 2.293813 | H28: =IF(Inputs!$C$105=1,B2C!H26,H20) -> 3.453031 | I28: =IF(Inputs!$C$105=1,B2C!I26,I20) -> 3.7196649 | J28: =IF(Inputs!$C$105=1,B2C!J26,J20) -> 4.0068875 | K28: =IF(Inputs!$C$105=1,B2C!K26,K20) -> 10.3367 | L28: =IF(Inputs!$C$105=1,B2C!L26,L20) -> 10.88018 | ... S28: =IF(Inputs!$C$105=1,B2C!S26,S20) -> 23.575986
A29: Total B2B events (Flagship + KPW/LPS + KCP) | B29: events | C29: =SUM(E29:G29) -> 0 | D29: =SUM(H29:S29) -> 29 | E29: =E23+E24+E25 -> 0 | F29: =F23+F24+F25 -> 0 | G29: =G23+G24+G25 -> 0 | H29: =H23+H24+H25 -> 0 | I29: =I23+I24+I25 -> 0 | J29: =J23+J24+J25 -> 2 | K29: =K23+K24+K25 -> 1 | L29: =L23+L24+L25 -> 2 | ... S29: =S23+S24+S25 -> 6
A31: Notes: v15 adds the timing switch (no new sales before the first delivery month) and the growth plan (new EAP contracts and bank days). Change them in Inputs sections 11 and 12.
A33: Timing and growth plan (v15)
A34: Pipeline gap: no new sales yet (1 = yes) | B34: flag | C34: =MAX(E34:G34) -> 1 | D34: =MAX(H34:S34) -> 1 | E34: =IF(AND(Inputs!$C$101=1,E6<IFERROR(MATCH(Inputs!$C$102,$E$4:$S$4,0),1)),1,0) -> 1 | F34: =IF(AND(Inputs!$C$101=1,F6<IFERROR(MATCH(Inputs!$C$102,$E$4:$S$4,0),1)),1,0) -> 1 | G34: =IF(AND(Inputs!$C$101=1,G6<IFERROR(MATCH(Inputs!$C$102,$E$4:$S$4,0),1)),1,0) -> 1 | H34: =IF(AND(Inputs!$C$101=1,H6<IFERROR(MATCH(Inputs!$C$102,$E$4:$S$4,0),1)),1,0) -> 1 | I34: =IF(AND(Inputs!$C$101=1,I6<IFERROR(MATCH(Inputs!$C$102,$E$4:$S$4,0),1)),1,0) -> 1 | J34: =IF(AND(Inputs!$C$101=1,J6<IFERROR(MATCH(Inputs!$C$102,$E$4:$S$4,0),1)),1,0) -> 0 | K34: =IF(AND(Inputs!$C$101=1,K6<IFERROR(MATCH(Inputs!$C$102,$E$4:$S$4,0),1)),1,0) -> 0 | L34: =IF(AND(Inputs!$C$101=1,L6<IFERROR(MATCH(Inputs!$C$102,$E$4:$S$4,0),1)),1,0) -> 0 | ... S34: =IF(AND(Inputs!$C$101=1,S6<IFERROR(MATCH(Inputs!$C$102,$E$4:$S$4,0),1)),1,0) -> 0
A35: New EAP contracts active (growth plan) | B35: contracts | C35: =MAX(E35:G35) -> 0 | D35: =MAX(H35:S35) -> 2 | E35: =Inputs!$C$105*(IF(E6>=IFERROR(MATCH(Inputs!$C$107,$E$4:$S$4,0),99),1,0)+IF(E6>=IFERROR(MATCH(Inputs!$C$108,$E$4:$S$4,0),99),1,0)) -> 0 | F35: =Inputs!$C$105*(IF(F6>=IFERROR(MATCH(Inputs!$C$107,$E$4:$S$4,0),99),1,0)+IF(F6>=IFERROR(MATCH(Inputs!$C$108,$E$4:$S$4,0),99),1,0)) -> 0 | G35: =Inputs!$C$105*(IF(G6>=IFERROR(MATCH(Inputs!$C$107,$E$4:$S$4,0),99),1,0)+IF(G6>=IFERROR(MATCH(Inputs!$C$108,$E$4:$S$4,0),99),1,0)) -> 0 | H35: =Inputs!$C$105*(IF(H6>=IFERROR(MATCH(Inputs!$C$107,$E$4:$S$4,0),99),1,0)+IF(H6>=IFERROR(MATCH(Inputs!$C$108,$E$4:$S$4,0),99),1,0)) -> 0 | I35: =Inputs!$C$105*(IF(I6>=IFERROR(MATCH(Inputs!$C$107,$E$4:$S$4,0),99),1,0)+IF(I6>=IFERROR(MATCH(Inputs!$C$108,$E$4:$S$4,0),99),1,0)) -> 1 | J35: =Inputs!$C$105*(IF(J6>=IFERROR(MATCH(Inputs!$C$107,$E$4:$S$4,0),99),1,0)+IF(J6>=IFERROR(MATCH(Inputs!$C$108,$E$4:$S$4,0),99),1,0)) -> 1 | K35: =Inputs!$C$105*(IF(K6>=IFERROR(MATCH(Inputs!$C$107,$E$4:$S$4,0),99),1,0)+IF(K6>=IFERROR(MATCH(Inputs!$C$108,$E$4:$S$4,0),99),1,0)) -> 1 | L35: =Inputs!$C$105*(IF(L6>=IFERROR(MATCH(Inputs!$C$107,$E$4:$S$4,0),99),1,0)+IF(L6>=IFERROR(MATCH(Inputs!$C$108,$E$4:$S$4,0),99),1,0)) -> 1 | ... S35: =Inputs!$C$105*(IF(S6>=IFERROR(MATCH(Inputs!$C$107,$E$4:$S$4,0),99),1,0)+IF(S6>=IFERROR(MATCH(Inputs!$C$108,$E$4:$S$4,0),99),1,0)) -> 2
