Workbook

Sheet Summary
A1: Teman Journey - 2027 plan (v16): EAP as the channel, BI kept as a premium client, new school channel
A2: Goal for 2027: a business that is profitable on its own and pays both founders. Investors come later, after scale. All money in Rp million.
A3: Active scenario: | B3: =CHOOSE(Inputs!$C$6,"1. Base plan","2. No new B2B deal Jan-Jun 2027","3. BI cuts volume","4. Worst case (2 + 3)") -> 1. Base plan
A4: Active price plan: | B4: =CHOOSE(Inputs!$C$85,"1. Current prices","2. New rate card") -> 2. New rate card
A5: Question | B5: Answer | C5: Unit | D5: What it means
A6: A. Is 2027 profitable?
A7: Revenue FY 2027 | B7: =PnL!$D$12 -> 2432.5546 | C7: Rp m | D7: Total sales booked in 2027.
A8: Gross profit FY 2027 | B8: =PnL!$D$23 -> 1451.7137 | C8: Rp m | D8: Revenue minus delivery cost.
A9: Total fixed cost FY 2027 | B9: =PnL!$D$31 -> 882.92578 | C9: Rp m | D9: Base + founders + sales + delivery steps.
A10: of which founder salaries | B10: =PnL!$D$28 -> 270 | C10: Rp m | D10: Both founders, from the start month in Inputs.
A11: Net profit FY 2027 | B11: =PnL!$D$35 -> 556.6252 | C11: Rp m | D11: After founder salaries and tax.
A12: Net margin FY 2027 | B12: =PnL!$D$36 -> 0.22882331 | C12: % | D12: Net profit / revenue.
A13: Meets your target margin? | B13: =IF(PnL!$D$36>=Inputs!$C$82,"Yes","No") -> Yes | D13: Target is set in Inputs.
A14: Break-even: BI work needed per month (in KPW-event equivalents) | B14: =IF(Unit_Economics!$G$5<=0,0,(PnL!$D$31/12-(PnL!$D$23-PnL!$D$6-PnL!$D$7+PnL!$D$15+PnL!$D$16)/12)/Unit_Economics!$G$5) -> 0.46329694 | C14: events | D14: With banks, EAP and B2C at plan, this many KPW-size BI events a month (or the same profit from Flagships) covers all 2027 fixed costs.
A15: B. Is cash safe? (Pillar 3)
A16: Lowest month-end cash (Oct 26 - Dec 27) | B16: =MIN(CashFlow!$E$21:$S$21) -> 69.760296 | C16: Rp m | D16: Must stay above zero.
A17: Month of lowest cash | B17: =INDEX(Volume!$E$4:$S$4,MATCH(MIN(CashFlow!$E$21:$S$21),CashFlow!$E$21:$S$21,0)) -> Feb-27 | D17: Where the squeeze is.
A18: Months below the cash floor | B18: =COUNTIF(CashFlow!$E$25:$S$25,0) -> 5 | C18: months | D18: Floor = 1 month fixed cost + delivery cost.
A19: Cash at end of 2027 | B19: =CashFlow!$D$21 -> 541.81498 | C19: Rp m
A20: Peak money owed by clients | B20: =CashFlow!$D$26 -> 237.69875 | C20: Rp m | D20: Cash tied up in unpaid invoices.
A21: Runway at end of Dec 2026 if B2B stops | B21: =CashFlow!$G$21/(Capacity_OPEX!$H$32-((PnL!$D$10+PnL!$D$11-PnL!$D$19-PnL!$D$20)/12)) -> 3.3346773 | C21: months | D21: Months you survive on B2C alone with 2027 cost base.
A22: C. Can we deliver it? (Pillar 2)
A23: Peak facilitators needed in one month | B23: =Capacity_OPEX!$D$8 -> 9 | C23: people | D23: Compare with your plan of 11.
A24: Facilitators to certify by end 2027 | B24: =Capacity_OPEX!$D$9-Inputs!$C$35 -> 7 | C24: people
A25: Month the Project Manager is hired | B25: =IFERROR(INDEX(Volume!$E$4:$S$4,MATCH(1,Capacity_OPEX!$E$15:$S$15,0)),"Not needed") -> Dec-27 | D25: Triggered by the 3-month average of B2B events.
A26: D. What will investors ask? (risk)
A27: BI share of 2027 revenue | B27: =PnL!$D$41 -> 0.55690549 | C27: % | D27: Concentration risk. Lower is safer.
A28: B2B share of 2027 revenue | B28: =IF(PnL!$D$12=0,0,PnL!$D$42/PnL!$D$12) -> 0.93451881 | C28: %
A29: Q4 share of 2027 revenue | B29: =IF(PnL!$D$12=0,0,SUM(PnL!Q12:S12)/PnL!$D$12) -> 0.42631613 | C29: % | D29: Seasonality risk.
A30: Cost to win one new B2B client (CAC) | B30: =Unit_Economics!$B$13 -> 6 | C30: Rp m | D30: Sales spend / new clients.
A31: Memo: Coreitera revenue from TJ in 2027 | B31: =PnL!$D$43 -> 89.25 | C31: Rp m | D31: The 'tech' revenue line for the investor story.
A32: Memo: Theta revenue from TJ in 2027 | B32: =PnL!$D$44 -> 44.772326 | C32: Rp m
A34: Scenario comparison (v16 values; refresh with analysis/lo_runner.py, then rebuild)
A35: Measure | B35: v15 plan (check) | C35: v16 plan | D35: v16 recommended (new prices + cash guard) | E35: v16 conservative | F35: v16 aggressive
A36: Revenue FY 2027 | B36: 2039.9735 | C36: 2432.5546 | D36: 2451.4196 | E36: 1738.751 | F36: 3300.0779
A37: Net profit FY 2027 | B37: 532.20857 | C37: 556.6252 | D37: 612.39587 | E37: 235.93773 | F37: 982.83707
A38: Net margin FY 2027 | B38: 0.26088994 | C38: 0.22882331 | D38: 0.24981275 | E38: 0.1356938 | F38: 0.29782239
A39: Lowest month-end cash (Oct 26 - Dec 27) | B39: 82.489448 | C39: 69.760296 | D39: 106.75957 | E39: 55.370504 | F39: 69.209735
A40: Month of lowest cash | B40: Feb-27 | C40: Feb-27 | D40: Jan-27 | E40: Apr-27 | F40: Feb-27
A41: Months below the cash floor | B41: 1 | C41: 5 | D41: 1 | E41: 7 | F41: 5
...

Sheet Outlook
A1: Outlook: sales, costs and cash each month (Rp million)
A2: Read the bars against the line: when the grey cost bar is taller than the blue sales bar, cash goes down. Cash is paid later than sales, because clients pay 0 to 60 days after the event.
A4: Month | B4: =Volume!E4 -> Oct-26 | C4: =Volume!F4 -> Nov-26 | D4: =Volume!G4 -> Dec-26 | E4: =Volume!H4 -> Jan-27 | F4: =Volume!I4 -> Feb-27 | G4: =Volume!J4 -> Mar-27 | H4: =Volume!K4 -> Apr-27 | I4: =Volume!L4 -> May-27 | ... P4: =Volume!S4 -> Dec-27
A5: Sales (revenue) | B5: =PnL!E12 -> 20.428617 | C5: =PnL!F12 -> 22.032105 | D5: =PnL!G12 -> 22.096289 | E5: =PnL!H12 -> 22.808889 | F5: =PnL!I12 -> 71.830236 | G5: =PnL!J12 -> 175.59012 | H5: =PnL!K12 -> 110.16744 | I5: =PnL!L12 -> 199.75153 | ... P5: =PnL!S12 -> 303.27404
A6: Delivery cost | B6: =PnL!E21 -> 8.6621793 | C6: =PnL!F21 -> 10.498458 | D6: =PnL!G21 -> 10.465034 | E6: =PnL!H21 -> 10.98213 | F6: =PnL!I21 -> 38.071621 | G6: =PnL!J21 -> 61.577273 | H6: =PnL!K21 -> 45.592659 | I6: =PnL!L21 -> 74.210092 | ... P6: =PnL!S21 -> 121.59837
A7: Fixed cost | B7: =PnL!E31 -> 31.685442 | C7: =PnL!F31 -> 32.474586 | D7: =PnL!G31 -> 32.476361 | E7: =PnL!H31 -> 42.882367 | F7: =PnL!I31 -> 42.785582 | G7: =PnL!J31 -> 62.411306 | H7: =PnL!K31 -> 58.300834 | I7: =PnL!L31 -> 67.360432 | ... P7: =PnL!S31 -> 97.312888
A8: Tax | B8: =PnL!E34 -> 0.10214308 | C8: =PnL!F34 -> 0.11016052 | D8: =PnL!G34 -> 0.11048145 | E8: =PnL!H34 -> 0.11404445 | F8: =PnL!I34 -> 0.35915118 | G8: =PnL!J34 -> 0.87795062 | H8: =PnL!K34 -> 0.55083722 | I8: =PnL!L34 -> 0.99875767 | ... P8: =PnL!S34 -> 1.5163702
A9: Total cost | B9: =B6+B7+B8 -> 40.449765 | C9: =C6+C7+C8 -> 43.083205 | D9: =D6+D7+D8 -> 43.051876 | E9: =E6+E7+E8 -> 53.978541 | F9: =F6+F7+F8 -> 81.216355 | G9: =G6+G7+G8 -> 124.86653 | H9: =H6+H7+H8 -> 104.44433 | I9: =I6+I7+I8 -> 142.56928 | ... P9: =P6+P7+P8 -> 220.42763
A10: Net profit | B10: =PnL!E35 -> -20.021148 | C10: =PnL!F35 -> -21.0511 | D10: =PnL!G35 -> -20.955587 | E10: =PnL!H35 -> -31.169652 | F10: =PnL!I35 -> -9.3861181 | G10: =PnL!J35 -> 50.723595 | H10: =PnL!K35 -> 5.7231127 | I10: =PnL!L35 -> 57.182253 | ... P10: =PnL!S35 -> 82.846414
A11: Cash in | B11: =CashFlow!E11 -> 5.428617 | C11: =CashFlow!F11 -> 24.567855 | D11: =CashFlow!G11 -> 17.024789 | E11: =CashFlow!H11 -> 25.344639 | F11: =CashFlow!I11 -> 48.814986 | G11: =CashFlow!J11 -> 136.45637 | H11: =CashFlow!K11 -> 104.51644 | I11: =CashFlow!L11 -> 189.40053 | ... P11: =CashFlow!S11 -> 376.67404
A12: Cash out | B12: =CashFlow!E17 -> 40.347622 | C12: =CashFlow!F17 -> 43.075188 | D12: =CashFlow!G17 -> 43.051556 | E12: =CashFlow!H17 -> 53.974978 | F12: =CashFlow!I17 -> 80.971248 | G12: =CashFlow!J17 -> 124.34773 | H12: =CashFlow!K17 -> 104.77144 | I12: =CashFlow!L17 -> 142.12136 | ... P12: =CashFlow!S17 -> 221.05085
A13: Cash at end of month | B13: =CashFlow!E21 -> 175.081 | C13: =CashFlow!F21 -> 156.57366 | D13: =CashFlow!G21 -> 130.5469 | E13: =CashFlow!H21 -> 101.91656 | F13: =CashFlow!I21 -> 69.760296 | G13: =CashFlow!J21 -> 81.868941 | H13: =CashFlow!K21 -> 81.61394 | I13: =CashFlow!L21 -> 128.89311 | ... P13: =CashFlow!S21 -> 541.81498
A14: Cash floor (1 month of costs) | B14: =CashFlow!E24 -> 40.347622 | C14: =CashFlow!F24 -> 42.973045 | D14: =CashFlow!G24 -> 42.941395 | E14: =CashFlow!H24 -> 53.864497 | F14: =CashFlow!I24 -> 80.857203 | G14: =CashFlow!J24 -> 123.98858 | H14: =CashFlow!K24 -> 103.89349 | I14: =CashFlow!L24 -> 141.57052 | ... P14: =CashFlow!S24 -> 218.91126
A15: Above the floor? (1 = yes) | B15: =CashFlow!E25 -> 1 | C15: =CashFlow!F25 -> 1 | D15: =CashFlow!G25 -> 1 | E15: =CashFlow!H25 -> 1 | F15: =CashFlow!I25 -> 0 | G15: =CashFlow!J25 -> 0 | H15: =CashFlow!K25 -> 0 | I15: =CashFlow!L25 -> 0 | ... P15: =CashFlow!S25 -> 1

Sheet Roadmap
A1: Roadmap: when we must start selling and preparing, worked backward from each start date
A2: Rule: start from the date the work begins and go back through three clocks: sales (lead to signed), delivery (people ready) and cash (work done to cash in). Regulators and banks also need us inside their budget, which they plan in the second half of the year before.
A4: Today (blue: change it when you review) | C4: 46300
A6: A. Lead times by client type, in days (Estimate until we log 3 real deals of each type in section E)
A7: Client type | B7: Contract and paperwork (legal, vendor registration, work order) | C7: Pitch, scoping, proposal | D7: Finding qualified leads
A8: Private company | B8: 14 | C8: 45 | D8: 30
A9: Regulator (BI, OJK, LPS) | B9: 42 | C9: 75 | D9: 30
A10: State-owned bank | B10: 42 | C10: 75 | D10: 30
A11: B2C public | B11: 0 | C11: 30 | D11: 30
A13: B. Sales clock: the latest date to start each deal
A14: Milestone | B14: Client type | C14: New client? (1 = yes) | D14: Work starts | E14: Client budget window closes | F14: Sign by | G14: Start pitching | H14: Start finding leads | I14: Latest start | J14: Owner | K14: Status today
A15: BI 2027: Flagship and regional programs (first in March) | B15: Regulator (BI, OJK, LPS) | C15: 0 | D15: 46447 | E15: 46387 | F15: =D15-VLOOKUP(B15,$A$8:$D$11,2,0) -> 46405 | G15: =F15-VLOOKUP(B15,$A$8:$D$11,3,0) -> 46330 | H15: =G15-C15*VLOOKUP(B15,$A$8:$D$11,4,0) -> 46330 | I15: =IF(E15="",H15,MIN(H15,E15-VLOOKUP(B15,$A$8:$D$11,3,0))) -> 46312 | J15: Kia | K15: =IF(G15<$C$4,"Late",IF(I15<$C$4,"At risk",IF(I15-$C$4<=31,"Start now","On track"))) -> Start now
A16: BI 2027: regional events Jul-Sep (moved from the Q4 peak) | B16: Regulator (BI, OJK, LPS) | C16: 0 | D16: 46569 | E16: 46387 | F16: =D16-VLOOKUP(B16,$A$8:$D$11,2,0) -> 46527 | G16: =F16-VLOOKUP(B16,$A$8:$D$11,3,0) -> 46452 | H16: =G16-C16*VLOOKUP(B16,$A$8:$D$11,4,0) -> 46452 | I16: =IF(E16="",H16,MIN(H16,E16-VLOOKUP(B16,$A$8:$D$11,3,0))) -> 46312 | J16: Kia | K16: =IF(G16<$C$4,"Late",IF(I16<$C$4,"At risk",IF(I16-$C$4<=31,"Start now","On track"))) -> Start now
A17: BI 2027: regional peak Oct-Dec | B17: Regulator (BI, OJK, LPS) | C17: 0 | D17: 46661 | E17: 46387 | F17: =D17-VLOOKUP(B17,$A$8:$D$11,2,0) -> 46619 | G17: =F17-VLOOKUP(B17,$A$8:$D$11,3,0) -> 46544 | H17: =G17-C17*VLOOKUP(B17,$A$8:$D$11,4,0) -> 46544 | I17: =IF(E17="",H17,MIN(H17,E17-VLOOKUP(B17,$A$8:$D$11,3,0))) -> 46312 | J17: Kia | K17: =IF(G17<$C$4,"Late",IF(I17<$C$4,"At risk",IF(I17-$C$4<=31,"Start now","On track"))) -> Start now
A18: EAP contract 2: the warm lead (chase now) | B18: Private company | C18: 0 | D18: 46419 | F18: =D18-VLOOKUP(B18,$A$8:$D$11,2,0) -> 46405 | G18: =F18-VLOOKUP(B18,$A$8:$D$11,3,0) -> 46360 | H18: =G18-C18*VLOOKUP(B18,$A$8:$D$11,4,0) -> 46360 | I18: =IF(E18="",H18,MIN(H18,E18-VLOOKUP(B18,$A$8:$D$11,3,0))) -> 46360 | J18: Galih | K18: =IF(G18<$C$4,"Late",IF(I18<$C$4,"At risk",IF(I18-$C$4<=31,"Start now","On track"))) -> On track
A19: EAP contract 2 if the client is a bank | B19: State-owned bank | C19: 1 | D19: 46419 | E19: 46387 | F19: =D19-VLOOKUP(B19,$A$8:$D$11,2,0) -> 46377 | G19: =F19-VLOOKUP(B19,$A$8:$D$11,3,0) -> 46302 | H19: =G19-C19*VLOOKUP(B19,$A$8:$D$11,4,0) -> 46272 | I19: =IF(E19="",H19,MIN(H19,E19-VLOOKUP(B19,$A$8:$D$11,3,0))) -> 46272 | J19: Galih | K19: =IF(G19<$C$4,"Late",IF(I19<$C$4,"At risk",IF(I19-$C$4<=31,"Start now","On track"))) -> At risk
A20: EAP contract 3 with a bank | B20: State-owned bank | C20: 1 | D20: 46569 | E20: 46387 | F20: =D20-VLOOKUP(B20,$A$8:$D$11,2,0) -> 46527 | G20: =F20-VLOOKUP(B20,$A$8:$D$11,3,0) -> 46452 | H20: =G20-C20*VLOOKUP(B20,$A$8:$D$11,4,0) -> 46422 | I20: =IF(E20="",H20,MIN(H20,E20-VLOOKUP(B20,$A$8:$D$11,3,0))) -> 46312 | J20: Kia | K20: =IF(G20<$C$4,"Late",IF(I20<$C$4,"At risk",IF(I20-$C$4<=31,"Start now","On track"))) -> Start now
A21: Bank agreement: training days | B21: State-owned bank | C21: 1 | D21: 46661 | E21: 46387 | F21: =D21-VLOOKUP(B21,$A$8:$D$11,2,0) -> 46619 | G21: =F21-VLOOKUP(B21,$A$8:$D$11,3,0) -> 46544 | H21: =G21-C21*VLOOKUP(B21,$A$8:$D$11,4,0) -> 46514 | I21: =IF(E21="",H21,MIN(H21,E21-VLOOKUP(B21,$A$8:$D$11,3,0))) -> 46312 | J21: Kia, then BD co-founder | K21: =IF(G21<$C$4,"Late",IF(I21<$C$4,"At risk",IF(I21-$C$4<=31,"Start now","On track"))) -> Start now
A22: B2C events (Instagram campaign, then tickets) | B22: B2C public | C22: 1 | D22: 46661 | F22: =D22-VLOOKUP(B22,$A$8:$D$11,2,0) -> 46661 | G22: =F22-VLOOKUP(B22,$A$8:$D$11,3,0) -> 46631 | H22: =G22-C22*VLOOKUP(B22,$A$8:$D$11,4,0) -> 46601 | I22: =IF(E22="",H22,MIN(H22,E22-VLOOKUP(B22,$A$8:$D$11,3,0))) -> 46601 | J22: Galih (lead marketing) | K22: =IF(G22<$C$4,"Late",IF(I22<$C$4,"At risk",IF(I22-$C$4<=31,"Start now","On track"))) -> On track
A23: OJK and LPS programs for 2028 | B23: Regulator (BI, OJK, LPS) | C23: 1 | D23: 46813 | E23: 46660 | F23: =D23-VLOOKUP(B23,$A$8:$D$11,2,0) -> 46771 | G23: =F23-VLOOKUP(B23,$A$8:$D$11,3,0) -> 46696 | H23: =G23-C23*VLOOKUP(B23,$A$8:$D$11,4,0) -> 46666 | I23: =IF(E23="",H23,MIN(H23,E23-VLOOKUP(B23,$A$8:$D$11,3,0))) -> 46585 | J23: Kia, then BD co-founder | K23: =IF(G23<$C$4,"Late",IF(I23<$C$4,"At risk",IF(I23-$C$4<=31,"Start now","On track"))) -> On track
A24: BI 2028 programs | B24: Regulator (BI, OJK, LPS) | C24: 0 | D24: 46813 | E24: 46752 | F24: =D24-VLOOKUP(B24,$A$8:$D$11,2,0) -> 46771 | G24: =F24-VLOOKUP(B24,$A$8:$D$11,3,0) -> 46696 | H24: =G24-C24*VLOOKUP(B24,$A$8:$D$11,4,0) -> 46696 | I24: =IF(E24="",H24,MIN(H24,E24-VLOOKUP(B24,$A$8:$D$11,3,0))) -> 46677 | J24: Kia | K24: =IF(G24<$C$4,"Late",IF(I24<$C$4,"At risk",IF(I24-$C$4<=31,"Start now","On track"))) -> On track
A25: Latest start = the earlier of: start finding leads, or the budget window close minus the pitch time.
A27: C. Delivery clock: people ready before the work
A28: Item | B28: Why | D28: Needed by | E28: Lead time (months) | I28: Latest start | J28: Owner | K28: Status today
A29: 3 certified trainers | B29: First programs in March need 3 trainers | D29: 46447 | E29: 3 | I29: =EDATE(D29,-E29) -> 46357 | J29: Galih | K29: =IF(I29<$C$4,"Late",IF(I29-$C$4<=31,"Start now","On track")) -> On track
A30: Part-time psychologist pool for EAP 2 | B30: EAP 2 starts in February | D30: 46419 | E30: 1 | I30: =EDATE(D30,-E30) -> 46388 | J30: Galih | K30: =IF(I30<$C$4,"Late",IF(I30-$C$4<=31,"Start now","On track")) -> On track
A31: Second paid part-time psychologist | B31: B2C evenings and EAP days from January | D31: 46388 | E31: 2 | I31: =EDATE(D31,-E31) -> 46327 | J31: Galih | K31: =IF(I31<$C$4,"Late",IF(I31-$C$4<=31,"Start now","On track")) -> Start now
A32: Standby project manager (paid per project) | B32: From July, more than 2 projects in a month | D32: 46569 | E32: 2 | I32: =EDATE(D32,-E32) -> 46508 | J32: Kia | K32: =IF(I32<$C$4,"Late",IF(I32-$C$4<=31,"Start now","On track")) -> On track
A33: Sales co-founder | B33: Joins in July; searching takes longer than a normal hire | D33: 46569 | E33: 6 | I33: =EDATE(D33,-E33) -> 46388 | J33: Kia and Galih | K33: =IF(I33<$C$4,"Late",IF(I33-$C$4<=31,"Start now","On track")) -> On track
A34: 8 certified trainers | B34: Busiest months: Oct to Dec 2027 | D34: 46661 | E34: 3 | I34: =EDATE(D34,-E34) -> 46569 | J34: Galih | K34: =IF(I34<$C$4,"Late",IF(I34-$C$4<=31,"Start now","On track")) -> On track
A35: Lead Partnership (non-psychologist) | B35: Manages EAP clients from October; brings clients | D35: 46661 | E35: 3 | I35: =EDATE(D35,-E35) -> 46569 | J35: Kia | K35: =IF(I35<$C$4,"Late",IF(I35-$C$4<=31,"Start now","On track")) -> On track
A36: Intern for invoices | B36: Invoices grow to about 11 a month in Q4 | D36: 46631 | E36: 1 | I36: =EDATE(D36,-E36) -> 46600 | J36: Galih | K36: =IF(I36<$C$4,"Late",IF(I36-$C$4<=31,"Start now","On track")) -> On track
A38: D. Cash clock: work done, cash not yet in
A39: Lowest cash in the plan (Rp m) | D39: =MIN(Outlook!B13:P13) -> 69.760296
A40: Month of the lowest cash | D40: =INDEX(Outlook!B4:P4,MATCH(MIN(Outlook!B13:P13),Outlook!B13:P13,0)) -> Feb-27
A41: Months below the safety floor | D41: =COUNTIF(Outlook!B15:P15,0) -> 5
A42: Down payment on Flagship programs (Inputs) | D42: =Inputs!$C$117 -> 0
A43: Costs leave in the event month; BI central pays 60/30/10% over 60 days, regional offices per payday, banks 20/50/30%, EAP the next month. Fix a gap before signing: a down payment, staged invoices, or a later start.
A45: E. Sales speed log: fill in after every won or lost deal, then replace the estimates in section A
A46: Client | B46: Client type | C46: First contact | D46: Proposal sent | E46: Signed | F46: Work started | G46: Cash in | H46: Days to sign | I46: Days to cash | J46: Won or lost | K46: Note
...

Sheet Segments
A1: Targets by priority: where 2027 revenue comes from (Rp million)
A2: Priority (founders, 16 Oct 2026): 1. EAP as the channel to counseling and training. BI stays at today's volume as a premium client (BAU). 2. LPS and OJK. 3. Banks (private banks last). New: schools. Rows add up to PnL row 12.
A4: Line | B4: Unit | C4: Q4 2026 | D4: FY 2027 | E4: =Volume!E4 -> Oct-26 | F4: =Volume!F4 -> Nov-26 | G4: =Volume!G4 -> Dec-26 | H4: =Volume!H4 -> Jan-27 | I4: =Volume!I4 -> Feb-27 | J4: =Volume!J4 -> Mar-27 | K4: =Volume!K4 -> Apr-27 | L4: =Volume!L4 -> May-27 | ... S4: =Volume!S4 -> Dec-27
A5: 1. EAP channel (primary): KPw packages, new EAP contracts, their trainings, channel counseling | B5: Rp m | C5: =SUM(E5:G5) -> 11.37245 | D5: =SUM(H5:S5) -> 572.8105 | E5: =PnL!E47+PnL!E48+IF(Volume!E26=0,0,PnL!E9*(Volume!E35+Volume!E18*(1-Inputs!$C$152*Inputs!$C$131))/Volume!E26)+Volume!E49*Inputs!$C$14 -> 0 | F5: =PnL!F47+PnL!F48+IF(Volume!F26=0,0,PnL!F9*(Volume!F35+Volume!F18*(1-Inputs!$C$152*Inputs!$C$131))/Volume!F26)+Volume!F49*Inputs!$C$14 -> 5.686225 | G5: =PnL!G47+PnL!G48+IF(Volume!G26=0,0,PnL!G9*(Volume!G35+Volume!G18*(1-Inputs!$C$152*Inputs!$C$131))/Volume!G26)+Volume!G49*Inputs!$C$14 -> 5.686225 | H5: =PnL!H47+PnL!H48+IF(Volume!H26=0,0,PnL!H9*(Volume!H35+Volume!H18*(1-Inputs!$C$152*Inputs!$C$131))/Volume!H26)+Volume!H49*Inputs!$C$14 -> 5.686225 | I5: =PnL!I47+PnL!I48+IF(Volume!I26=0,0,PnL!I9*(Volume!I35+Volume!I18*(1-Inputs!$C$152*Inputs!$C$131))/Volume!I26)+Volume!I49*Inputs!$C$14 -> 26.399666 | J5: =PnL!J47+PnL!J48+IF(Volume!J26=0,0,PnL!J9*(Volume!J35+Volume!J18*(1-Inputs!$C$152*Inputs!$C$131))/Volume!J26)+Volume!J49*Inputs!$C$14 -> 29.626991 | K5: =PnL!K47+PnL!K48+IF(Volume!K26=0,0,PnL!K9*(Volume!K35+Volume!K18*(1-Inputs!$C$152*Inputs!$C$131))/Volume!K26)+Volume!K49*Inputs!$C$14 -> 35.313215 | L5: =PnL!L47+PnL!L48+IF(Volume!L26=0,0,PnL!L9*(Volume!L35+Volume!L18*(1-Inputs!$C$152*Inputs!$C$131))/Volume!L26)+Volume!L49*Inputs!$C$14 -> 49.563215 | ... S5: =PnL!S47+PnL!S48+IF(Volume!S26=0,0,PnL!S9*(Volume!S35+Volume!S18*(1-Inputs!$C$152*Inputs!$C$131))/Volume!S26)+Volume!S49*Inputs!$C$14 -> 63.947297
A6: BI BAU premium: Flagship, BI regional ToT, existing EAP (kept at today's volume) | B6: Rp m | C6: =SUM(E6:G6) -> 45 | D6: =SUM(H6:S6) -> 1091.825 | E6: =PnL!E6+PnL!E7*Inputs!$C$83+IF(Volume!E26=0,0,PnL!E9*Volume!E18*Inputs!$C$152*Inputs!$C$131/Volume!E26) -> 15 | F6: =PnL!F6+PnL!F7*Inputs!$C$83+IF(Volume!F26=0,0,PnL!F9*Volume!F18*Inputs!$C$152*Inputs!$C$131/Volume!F26) -> 15 | G6: =PnL!G6+PnL!G7*Inputs!$C$83+IF(Volume!G26=0,0,PnL!G9*Volume!G18*Inputs!$C$152*Inputs!$C$131/Volume!G26) -> 15 | H6: =PnL!H6+PnL!H7*Inputs!$C$83+IF(Volume!H26=0,0,PnL!H9*Volume!H18*Inputs!$C$152*Inputs!$C$131/Volume!H26) -> 15 | I6: =PnL!I6+PnL!I7*Inputs!$C$83+IF(Volume!I26=0,0,PnL!I9*Volume!I18*Inputs!$C$152*Inputs!$C$131/Volume!I26) -> 15 | J6: =PnL!J6+PnL!J7*Inputs!$C$83+IF(Volume!J26=0,0,PnL!J9*Volume!J18*Inputs!$C$152*Inputs!$C$131/Volume!J26) -> 139.225 | K6: =PnL!K6+PnL!K7*Inputs!$C$83+IF(Volume!K26=0,0,PnL!K9*Volume!K18*Inputs!$C$152*Inputs!$C$131/Volume!K26) -> 15 | L6: =PnL!L6+PnL!L7*Inputs!$C$83+IF(Volume!L26=0,0,PnL!L9*Volume!L18*Inputs!$C$152*Inputs!$C$131/Volume!L26) -> 139.225 | ... S6: =PnL!S6+PnL!S7*Inputs!$C$83+IF(Volume!S26=0,0,PnL!S9*Volume!S18*Inputs!$C$152*Inputs!$C$131/Volume!S26) -> 136.125
A7: 2. LPS / OJK (secondary) | B7: Rp m | C7: =SUM(E7:G7) -> 0 | D7: =SUM(H7:S7) -> 130.815 | E7: =PnL!E7*(1-Inputs!$C$83)+PnL!E49 -> 0 | F7: =PnL!F7*(1-Inputs!$C$83)+PnL!F49 -> 0 | G7: =PnL!G7*(1-Inputs!$C$83)+PnL!G49 -> 0 | H7: =PnL!H7*(1-Inputs!$C$83)+PnL!H49 -> 0 | I7: =PnL!I7*(1-Inputs!$C$83)+PnL!I49 -> 0 | J7: =PnL!J7*(1-Inputs!$C$83)+PnL!J49 -> 4.275 | K7: =PnL!K7*(1-Inputs!$C$83)+PnL!K49 -> 0 | L7: =PnL!L7*(1-Inputs!$C$83)+PnL!L49 -> 4.275 | ... S7: =PnL!S7*(1-Inputs!$C$83)+PnL!S49 -> 31.065
A8: 3. Banks: state and private (tertiary) | B8: Rp m | C8: =SUM(E8:G8) -> 0 | D8: =SUM(H8:S8) -> 374.5 | E8: =PnL!E8 -> 0 | F8: =PnL!F8 -> 0 | G8: =PnL!G8 -> 0 | H8: =PnL!H8 -> 0 | I8: =PnL!I8 -> 0 | J8: =PnL!J8 -> 0 | K8: =PnL!K8 -> 53.5 | L8: =PnL!L8 -> 0 | ... S8: =PnL!S8 -> 53.5
A9: New: schools | B9: Rp m | C9: =SUM(E9:G9) -> 0 | D9: =SUM(H9:S9) -> 144 | E9: =PnL!E50 -> 0 | F9: =PnL!F50 -> 0 | G9: =PnL!G50 -> 0 | H9: =PnL!H50 -> 0 | I9: =PnL!I50 -> 24 | J9: =PnL!J50 -> 0 | K9: =PnL!K50 -> 0 | L9: =PnL!L50 -> 0 | ... S9: =PnL!S50 -> 0
A10: B2C direct: Instagram, referral, vouchers, public events | B10: Rp m | C10: =SUM(E10:G10) -> 8.184561 | D10: =SUM(H10:S10) -> 118.60407 | E10: =PnL!E10+PnL!E11-Volume!E49*Inputs!$C$14 -> 5.428617 | F10: =PnL!F10+PnL!F11-Volume!F49*Inputs!$C$14 -> 1.3458798 | G10: =PnL!G10+PnL!G11-Volume!G49*Inputs!$C$14 -> 1.4100642 | H10: =PnL!H10+PnL!H11-Volume!H49*Inputs!$C$14 -> 2.1226645 | I10: =PnL!I10+PnL!I11-Volume!I49*Inputs!$C$14 -> 6.430571 | J10: =PnL!J10+PnL!J11-Volume!J49*Inputs!$C$14 -> 2.4631339 | K10: =PnL!K10+PnL!K11-Volume!K49*Inputs!$C$14 -> 6.3542276 | L10: =PnL!L10+PnL!L11-Volume!L49*Inputs!$C$14 -> 6.6883184 | ... S10: =PnL!S10+PnL!S11-Volume!S49*Inputs!$C$14 -> 18.636748
A11: Total | B11: Rp m | C11: =SUM(E11:G11) -> 64.557011 | D11: =SUM(H11:S11) -> 2432.5546 | E11: =SUM(E5:E10) -> 20.428617 | F11: =SUM(F5:F10) -> 22.032105 | G11: =SUM(G5:G10) -> 22.096289 | H11: =SUM(H5:H10) -> 22.808889 | I11: =SUM(I5:I10) -> 71.830236 | J11: =SUM(J5:J10) -> 175.59012 | K11: =SUM(K5:K10) -> 110.16744 | L11: =SUM(L5:L10) -> 199.75153 | ... S11: =SUM(S5:S10) -> 303.27404
A12: Check: difference to PnL total revenue (must be 0) | B12: Rp m | C12: =SUM(E12:G12) -> 0 | D12: =SUM(H12:S12) -> 0 | E12: =ROUND(E11-PnL!E12,6) -> 0 | F12: =ROUND(F11-PnL!F12,6) -> 0 | G12: =ROUND(G11-PnL!G12,6) -> 0 | H12: =ROUND(H11-PnL!H12,6) -> 0 | I12: =ROUND(I11-PnL!I12,6) -> 0 | J12: =ROUND(J11-PnL!J12,6) -> 0 | K12: =ROUND(K11-PnL!K12,6) -> 0 | L12: =ROUND(L11-PnL!L12,6) -> 0 | ... S12: =ROUND(S11-PnL!S12,6) -> 0
A13: Mix
A14: Share: EAP channel | B14: % | C14: =IF(C11=0,0,C5/C11) -> 0.17616135 | D14: =IF(D11=0,0,D5/D11) -> 0.23547694 | E14: =IF(E11=0,0,E5/E11) -> 0 | F14: =IF(F11=0,0,F5/F11) -> 0.25808814 | G14: =IF(G11=0,0,G5/G11) -> 0.25733846 | H14: =IF(H11=0,0,H5/H11) -> 0.24929863 | I14: =IF(I11=0,0,I5/I11) -> 0.36752859 | J14: =IF(J11=0,0,J5/J11) -> 0.16872811 | ... S14: =IF(S11=0,0,S5/S11) -> 0.21085648
A15: Share: BI BAU | B15: % | C15: =IF(C11=0,0,C6/C11) -> 0.6970583 | D15: =IF(D11=0,0,D6/D11) -> 0.44883885 | E15: =IF(E11=0,0,E6/E11) -> 0.7342641 | F15: =IF(F11=0,0,F6/F11) -> 0.68082465 | G15: =IF(G11=0,0,G6/G11) -> 0.67884702 | H15: =IF(H11=0,0,H6/H11) -> 0.65763833 | I15: =IF(I11=0,0,I6/I11) -> 0.20882571 | J15: =IF(J11=0,0,J6/J11) -> 0.79289767 | ... S15: =IF(S11=0,0,S6/S11) -> 0.44885147
A16: Share: LPS / OJK | B16: % | C16: =IF(C11=0,0,C7/C11) -> 0 | D16: =IF(D11=0,0,D7/D11) -> 0.0537768 | E16: =IF(E11=0,0,E7/E11) -> 0 | F16: =IF(F11=0,0,F7/F11) -> 0 | G16: =IF(G11=0,0,G7/G11) -> 0 | H16: =IF(H11=0,0,H7/H11) -> 0 | I16: =IF(I11=0,0,I7/I11) -> 0 | J16: =IF(J11=0,0,J7/J11) -> 0.024346472 | ... S16: =IF(S11=0,0,S7/S11) -> 0.10243211
A17: Share: banks | B17: % | C17: =IF(C11=0,0,C8/C11) -> 0 | D17: =IF(D11=0,0,D8/D11) -> 0.15395338 | E17: =IF(E11=0,0,E8/E11) -> 0 | F17: =IF(F11=0,0,F8/F11) -> 0 | G17: =IF(G11=0,0,G8/G11) -> 0 | H17: =IF(H11=0,0,H8/H11) -> 0 | I17: =IF(I11=0,0,I8/I11) -> 0 | J17: =IF(J11=0,0,J8/J11) -> 0 | ... S17: =IF(S11=0,0,S8/S11) -> 0.17640811
A18: Share: schools | B18: % | C18: =IF(C11=0,0,C9/C11) -> 0 | D18: =IF(D11=0,0,D9/D11) -> 0.059197028 | E18: =IF(E11=0,0,E9/E11) -> 0 | F18: =IF(F11=0,0,F9/F11) -> 0 | G18: =IF(G11=0,0,G9/G11) -> 0 | H18: =IF(H11=0,0,H9/H11) -> 0 | I18: =IF(I11=0,0,I9/I11) -> 0.33412113 | J18: =IF(J11=0,0,J9/J11) -> 0 | ... S18: =IF(S11=0,0,S9/S11) -> 0
A19: Share: B2C direct | B19: % | C19: =IF(C11=0,0,C10/C11) -> 0.12678036 | D19: =IF(D11=0,0,D10/D11) -> 0.048757002 | E19: =IF(E11=0,0,E10/E11) -> 0.2657359 | F19: =IF(F11=0,0,F10/F11) -> 0.061087209 | G19: =IF(G11=0,0,G10/G11) -> 0.063814525 | H19: =IF(H11=0,0,H10/H11) -> 0.093063034 | I19: =IF(I11=0,0,I10/I11) -> 0.089524569 | J19: =IF(J11=0,0,J10/J11) -> 0.014027747 | ... S19: =IF(S11=0,0,S10/S11) -> 0.06145184
A20: All money from BI (BI BAU + KPw packages + their trainings): concentration risk | B20: Rp m | C20: =SUM(E20:G20) -> 55.143 | D20: =SUM(H20:S20) -> 1354.703 | E20: =PnL!E40 -> 15 | F20: =PnL!F40 -> 20.0715 | G20: =PnL!G40 -> 20.0715 | H20: =PnL!H40 -> 20.0715 | I20: =PnL!I40 -> 22.9695 | J20: =PnL!J40 -> 152.266 | K20: =PnL!K40 -> 33.1125 | L20: =PnL!L40 -> 164.4625 | ... S20: =PnL!S40 -> 167.1585
A21: Share of revenue from BI | B21: % | C21: =IF(C11=0,0,C20/C11) -> 0.85417523 | D21: =IF(D11=0,0,D20/D11) -> 0.55690549 | E21: =IF(E11=0,0,E20/E11) -> 0.7342641 | F21: =IF(F11=0,0,F20/F11) -> 0.91101146 | G21: =IF(G11=0,0,G20/G11) -> 0.90836519 | H21: =IF(H11=0,0,H20/H11) -> 0.87998585 | I21: =IF(I11=0,0,I20/I11) -> 0.31977481 | J21: =IF(J11=0,0,J20/J11) -> 0.86716722 | ... S21: =IF(S11=0,0,S20/S11) -> 0.55117971
A23: 2027 targets: the numbers to track every month
A24: Priority | B24: Target for 2027 | C24: Unit | D24: Plan (FY 2027) | E24: Owner
A25: 1. EAP channel | B25: New BI KPw packages signed | C25: packages | D25: =Volume!D39 -> 10 | E25: Kia
A26: 1. EAP channel | B26: Commit-2 second terms + renewals | C26: packages | D26: =Volume!D40+Volume!D41 -> 4.64 | E26: Kia
A27: 1. EAP channel | B27: Enterprise EAP contracts running in Dec 2027 (incl. existing) | C27: contracts | D27: =Volume!S26 -> 3 | E27: Galih
A28: 1. EAP channel | B28: Trainings sold to EAP clients | C28: events | D28: =Volume!D44+Volume!D45 -> 2.25 | E28: Kia
A29: 1. EAP channel | B29: Paid counseling sessions through channels | C29: sessions | D29: =Volume!D49 -> 66.18 | E29: Galih
A30: BI BAU | B30: Flagship + BI regional ToT (same as v15) | C30: events | D30: =Volume!D23+Volume!D24*Inputs!$C$83 -> 19.45 | E30: Kia
A31: 2. LPS / OJK | B31: LPS / OJK programs (incl. non-BI regional ToT) | C31: events | D31: =Volume!D46+Volume!D24*(1-Inputs!$C$83) -> 4.59 | E31: Kia, then BD co-founder
A32: 3. Banks | B32: Bank training days and events | C32: events | D32: =Volume!D25 -> 7 | E32: Kia, then BD co-founder
A33: New: schools | B33: Schools tested / students | C33: schools | D33: =Volume!D47 -> 6 | E33: Galih's wife (schools lead)
A34: New: schools | B34: Students tested | C34: students | D34: =Volume!D48 -> 480 | E34: Galih's wife (schools lead)
A35: B2C direct | B35: Paid B2C sessions (all sources) | C35: sessions | D35: =B2C!D26 -> 232.15351 | E35: Galih (lead marketing)
A36: Result | B36: BI share of revenue (all BI money) | C36: % | D36: =D21 -> 0.55690549 | E36: Kia
A37: Result | B37: Net margin FY 2027 | C37: % | D37: =PnL!D36 -> 0.22882331 | E37: Both founders

Sheet B2C
A1: B2C funnel: Instagram followers to paid counseling sessions, and B2C vs B2B revenue (Rp million)
A2: Growth is set per quarter (blue). Followers on 5 Oct 2026: @temanjourney_id. Today about 2 paid sessions a month, so the booking rate starts at about 0.6 new paying clients a month per 1,000 followers. Feeds Volume row 28.
A4: Quarterly inputs (blue = change freely)
C5: Q4 2026 | D5: Q1 2027 | E5: Q2 2027 | F5: Q3 2027 | G5: Q4 2027
A6: Follower growth in the quarter | C6: 0.15 | D6: 0.25 | E6: 0.28 | F6: 0.28 | G6: 0.24
A7: Booking rate: new paying clients a month per 1,000 followers | C7: 0.58 | D7: 0.7 | E7: 0.85 | F7: 1 | G7: 1
A8: Sessions per client | C8: 1 | D8: 1.1 | E8: 1.25 | F8: 1.4 | G8: 1.4
A9: Referral share of new clients (target 20% by Q4 2027) | C9: 0 | D9: 0.05 | E9: 0.1 | F9: 0.15 | G9: 0.2
A10: Instagram followers on 5 Oct 2026 | C10: 3439
A11: Theta voucher sessions a month per EAP contract | C11: 2
A12: Theta vouchers start | C12: Apr-27
A13: Sessions one paid part-time psychologist covers a month (3 shifts a week x 3) | C13: 36
A14: Paid part-time psychologists from Jan-27 | C14: 2
A15: Pool capacity: 20 part-timers x 8 hours a month | C15: 160
A16: Full-time psychologist pay, if hired (gross) | C16: 9
A17: Referral reward per referred client (Rp100k credit to each side) | C17: 0.2 | E17: Base Instagram ads already in the software budget (Rp m a month) | K17: 1
A18: Line | B18: Unit | C18: Q4 2026 | D18: FY 2027 | E18: =Volume!E4 -> Oct-26 | F18: =Volume!F4 -> Nov-26 | G18: =Volume!G4 -> Dec-26 | H18: =Volume!H4 -> Jan-27 | I18: =Volume!I4 -> Feb-27 | J18: =Volume!J4 -> Mar-27 | K18: =Volume!K4 -> Apr-27 | L18: =Volume!L4 -> May-27 | ... S18: =Volume!S4 -> Dec-27
A19: Quarter (1 = Q4 2026 ... 5 = Q4 2027) | B19: # | E19: =INT((Volume!E6-1)/3)+1 -> 1 | F19: =INT((Volume!F6-1)/3)+1 -> 1 | G19: =INT((Volume!G6-1)/3)+1 -> 1 | H19: =INT((Volume!H6-1)/3)+1 -> 2 | I19: =INT((Volume!I6-1)/3)+1 -> 2 | J19: =INT((Volume!J6-1)/3)+1 -> 2 | K19: =INT((Volume!K6-1)/3)+1 -> 3 | L19: =INT((Volume!L6-1)/3)+1 -> 3 | ... S19: =INT((Volume!S6-1)/3)+1 -> 5
A20: Instagram followers (end of month) | B20: people | C20: =MAX(E20:G20) -> 3954.85 | D20: =MAX(H20:S20) -> 10043.421 | E20: =$C$10*(1+INDEX($C$6:$G$6,E19))^(1/3) -> 3603.0044 | F20: =E20*(1+INDEX($C$6:$G$6,F19))^(1/3) -> 3774.83 | G20: =F20*(1+INDEX($C$6:$G$6,G19))^(1/3) -> 3954.85 | H20: =G20*(1+INDEX($C$6:$G$6,H19))^(1/3) -> 4260.233 | I20: =H20*(1+INDEX($C$6:$G$6,I19))^(1/3) -> 4589.1969 | J20: =I20*(1+INDEX($C$6:$G$6,J19))^(1/3) -> 4943.5625 | K20: =J20*(1+INDEX($C$6:$G$6,K19))^(1/3) -> 5367.5573 | L20: =K20*(1+INDEX($C$6:$G$6,L19))^(1/3) -> 5827.9168 | M20: =L20*(1+INDEX($C$6:$G$6,M19))^(1/3) -> 6327.76 | ... S20: =R20*(1+INDEX($C$6:$G$6,S19))^(1/3) -> 10043.421
A21: Booking rate | B21: per 1,000 | C21: =MAX(E21:G21) -> 0.58 | D21: =MAX(H21:S21) -> 1 | E21: =INDEX($C$7:$G$7,E19) -> 0.58 | F21: =INDEX($C$7:$G$7,F19) -> 0.58 | G21: =INDEX($C$7:$G$7,G19) -> 0.58 | H21: =INDEX($C$7:$G$7,H19) -> 0.7 | I21: =INDEX($C$7:$G$7,I19) -> 0.7 | J21: =INDEX($C$7:$G$7,J19) -> 0.7 | K21: =INDEX($C$7:$G$7,K19) -> 0.85 | L21: =INDEX($C$7:$G$7,L19) -> 0.85 | ... S21: =INDEX($C$7:$G$7,S19) -> 1
A22: Sessions per client | B22: x | C22: =MAX(E22:G22) -> 1 | D22: =MAX(H22:S22) -> 1.4 | E22: =INDEX($C$8:$G$8,E19) -> 1 | F22: =INDEX($C$8:$G$8,F19) -> 1 | G22: =INDEX($C$8:$G$8,G19) -> 1 | H22: =INDEX($C$8:$G$8,H19) -> 1.1 | I22: =INDEX($C$8:$G$8,I19) -> 1.1 | J22: =INDEX($C$8:$G$8,J19) -> 1.1 | K22: =INDEX($C$8:$G$8,K19) -> 1.25 | L22: =INDEX($C$8:$G$8,L19) -> 1.25 | ... S22: =INDEX($C$8:$G$8,S19) -> 1.4
A23: New paying clients from Instagram | B23: clients | C23: =SUM(E23:G23) -> 6.572957 | D23: =SUM(H23:S23) -> 75.073114 | E23: =E20/1000*E21 -> 2.0897425 | F23: =F20/1000*F21 -> 2.1894014 | G23: =G20/1000*G21 -> 2.293813 | H23: =H20/1000*H21 -> 2.9821631 | I23: =I20/1000*I21 -> 3.2124378 | J23: =J20/1000*J21 -> 3.4604937 | K23: =K20/1000*K21 -> 4.5624237 | L23: =L20/1000*L21 -> 4.9537293 | ... S23: =S20/1000*S21 -> 10.043421
A24: Sessions from Instagram | B24: sessions | C24: =SUM(E24:G24) -> 6.572957 | D24: =SUM(H24:S24) -> 99.971619 | E24: =E23*E22 -> 2.0897425 | F24: =F23*F22 -> 2.1894014 | G24: =G23*G22 -> 2.293813 | H24: =H23*H22 -> 3.2803794 | I24: =I23*I22 -> 3.5336816 | J24: =J23*J22 -> 3.8065431 | K24: =K23*K22 -> 5.7030296 | L24: =L23*L22 -> 6.1921616 | ... S24: =S23*S22 -> 14.060789
A25: Sessions from Theta vouchers (EAP staff) | B25: sessions | C25: =SUM(E25:G25) -> 0 | D25: =SUM(H25:S25) -> 48 | E25: =IF(Volume!E6>=IFERROR(MATCH($C$12,Volume!$E$4:$S$4,0),99),$C$11*Volume!E26,0) -> 0 | F25: =IF(Volume!F6>=IFERROR(MATCH($C$12,Volume!$E$4:$S$4,0),99),$C$11*Volume!F26,0) -> 0 | G25: =IF(Volume!G6>=IFERROR(MATCH($C$12,Volume!$E$4:$S$4,0),99),$C$11*Volume!G26,0) -> 0 | H25: =IF(Volume!H6>=IFERROR(MATCH($C$12,Volume!$E$4:$S$4,0),99),$C$11*Volume!H26,0) -> 0 | I25: =IF(Volume!I6>=IFERROR(MATCH($C$12,Volume!$E$4:$S$4,0),99),$C$11*Volume!I26,0) -> 0 | J25: =IF(Volume!J6>=IFERROR(MATCH($C$12,Volume!$E$4:$S$4,0),99),$C$11*Volume!J26,0) -> 0 | K25: =IF(Volume!K6>=IFERROR(MATCH($C$12,Volume!$E$4:$S$4,0),99),$C$11*Volume!K26,0) -> 4 | L25: =IF(Volume!L6>=IFERROR(MATCH($C$12,Volume!$E$4:$S$4,0),99),$C$11*Volume!L26,0) -> 4 | ... S25: =IF(Volume!S6>=IFERROR(MATCH($C$12,Volume!$E$4:$S$4,0),99),$C$11*Volume!S26,0) -> 6
A26: Paid B2C counseling sessions (Instagram + vouchers + referral + channels) | B26: sessions | C26: =SUM(E26:G26) -> 8.572957 | D26: =SUM(H26:S26) -> 232.15351 | E26: =E24+E25+E52+Volume!E49 -> 2.0897425 | F26: =F24+F25+F52+Volume!F49 -> 3.1894014 | G26: =G24+G25+G52+Volume!G49 -> 3.293813 | H26: =H24+H25+H52+Volume!H49 -> 4.453031 | I26: =I24+I25+I52+Volume!I49 -> 9.2996649 | J26: =J24+J25+J52+Volume!J49 -> 6.5868875 | K26: =K24+K25+K52+Volume!K49 -> 13.9167 | L26: =L24+L25+L52+Volume!L49 -> 14.46018 | ... S26: =S24+S25+S52+Volume!S49 -> 28.315986
A27: Revenue
A28: Counseling revenue | B28: Rp m | C28: =SUM(E28:G28) -> 5.270011 | D28: =SUM(H28:S28) -> 142.71057 | E28: =PnL!E11 -> 1.284617 | F28: =PnL!F11 -> 1.9606048 | G28: =PnL!G11 -> 2.0247892 | H28: =PnL!H11 -> 2.7373895 | I28: =PnL!I11 -> 5.7167365 | J28: =PnL!J11 -> 4.0491244 | K28: =PnL!K11 -> 8.5549431 | L28: =PnL!L11 -> 8.8890339 | ... S28: =PnL!S11 -> 17.406545
A29: Public events | B29: events | C29: =SUM(E29:G29) -> 1 | D29: =SUM(H29:S29) -> 4 | E29: =Volume!E27 -> 1 | F29: =Volume!F27 -> 0 | G29: =Volume!G27 -> 0 | H29: =Volume!H27 -> 0 | I29: =Volume!I27 -> 1 | J29: =Volume!J27 -> 0 | K29: =Volume!K27 -> 0 | L29: =Volume!L27 -> 0 | ... S29: =Volume!S27 -> 1
A30: Public event revenue | B30: Rp m | C30: =SUM(E30:G30) -> 4.144 | D30: =SUM(H30:S30) -> 16.576 | E30: =PnL!E10 -> 4.144 | F30: =PnL!F10 -> 0 | G30: =PnL!G10 -> 0 | H30: =PnL!H10 -> 0 | I30: =PnL!I10 -> 4.144 | J30: =PnL!J10 -> 0 | K30: =PnL!K10 -> 0 | L30: =PnL!L10 -> 0 | ... S30: =PnL!S10 -> 4.144
A31: B2C revenue | B31: Rp m | C31: =SUM(E31:G31) -> 9.414011 | D31: =SUM(H31:S31) -> 159.28657 | E31: =E28+E30 -> 5.428617 | F31: =F28+F30 -> 1.9606048 | G31: =G28+G30 -> 2.0247892 | H31: =H28+H30 -> 2.7373895 | I31: =I28+I30 -> 9.8607365 | J31: =J28+J30 -> 4.0491244 | K31: =K28+K30 -> 8.5549431 | L31: =L28+L30 -> 8.8890339 | ... S31: =S28+S30 -> 21.550545
A32: B2B revenue (regulators, banks, EAP) | B32: Rp m | C32: =SUM(E32:G32) -> 55.143 | D32: =SUM(H32:S32) -> 2273.268 | E32: =PnL!E12-E31 -> 15 | F32: =PnL!F12-F31 -> 20.0715 | G32: =PnL!G12-G31 -> 20.0715 | H32: =PnL!H12-H31 -> 20.0715 | I32: =PnL!I12-I31 -> 61.9695 | J32: =PnL!J12-J31 -> 171.541 | K32: =PnL!K12-K31 -> 101.6125 | L32: =PnL!L12-L31 -> 190.8625 | ... S32: =PnL!S12-S31 -> 281.7235
A33: B2C share of all revenue | B33: % | C33: =IF(SUM(PnL!E12:G12)=0,0,C31/SUM(PnL!E12:G12)) -> 0.14582477 | D33: =IF(SUM(PnL!H12:S12)=0,0,D31/SUM(PnL!H12:S12)) -> 0.06548119 | E33: =IF(PnL!E12=0,0,E31/PnL!E12) -> 0.2657359 | F33: =IF(PnL!F12=0,0,F31/PnL!F12) -> 0.088988538 | G33: =IF(PnL!G12=0,0,G31/PnL!G12) -> 0.091634807 | H33: =IF(PnL!H12=0,0,H31/PnL!H12) -> 0.12001415 | I33: =IF(PnL!I12=0,0,I31/PnL!I12) -> 0.13727835 | J33: =IF(PnL!J12=0,0,J31/PnL!J12) -> 0.023060092 | K33: =IF(PnL!K12=0,0,K31/PnL!K12) -> 0.077654004 | L33: =IF(PnL!L12=0,0,L31/PnL!L12) -> 0.044500454 | ... S33: =IF(PnL!S12=0,0,S31/PnL!S12) -> 0.071059641
A34: Can B2C pay for our psychologists?
A35: B2C gross profit (after psychologist session fees and event costs) | B35: Rp m | C35: =SUM(E35:G35) -> 2.8598399 | D35: =SUM(H35:S35) -> 44.80898 | E35: =PnL!E10+PnL!E11-PnL!E19-PnL!E20 -> 1.7664377 | F35: =PnL!F10+PnL!F11-PnL!F19-PnL!F20 -> 0.53789654 | G35: =PnL!G10+PnL!G11-PnL!G19-PnL!G20 -> 0.55550568 | H35: =PnL!H10+PnL!H11-PnL!H19-PnL!H20 -> 0.75100924 | I35: =PnL!I10+PnL!I11-PnL!I19-PnL!I20 -> 2.9824001 | J35: =PnL!J10+PnL!J11-PnL!J19-PnL!J20 -> 1.1108868 | K35: =PnL!K10+PnL!K11-PnL!K19-PnL!K20 -> 2.3470688 | L35: =PnL!L10+PnL!L11-PnL!L19-PnL!L20 -> 2.4387274 | ... S35: =PnL!S10+PnL!S11-PnL!S19-PnL!S20 -> 6.1895265
A36: Paid psychologists' pay incl. BPJS and THR | B36: Rp m | C36: =SUM(E36:G36) -> 6.9 | D36: =SUM(H36:S36) -> 65.136 | E36: =Pay_Plan!E9*(1+Inputs!$C$106*Pay_Plan!E14) -> 2.3 | F36: =Pay_Plan!F9*(1+Inputs!$C$106*Pay_Plan!F14) -> 2.3 | G36: =Pay_Plan!G9*(1+Inputs!$C$106*Pay_Plan!G14) -> 2.3 | H36: =Pay_Plan!H9*(1+Inputs!$C$106*Pay_Plan!H14) -> 5.428 | I36: =Pay_Plan!I9*(1+Inputs!$C$106*Pay_Plan!I14) -> 5.428 | J36: =Pay_Plan!J9*(1+Inputs!$C$106*Pay_Plan!J14) -> 5.428 | K36: =Pay_Plan!K9*(1+Inputs!$C$106*Pay_Plan!K14) -> 5.428 | L36: =Pay_Plan!L9*(1+Inputs!$C$106*Pay_Plan!L14) -> 5.428 | ... S36: =Pay_Plan!S9*(1+Inputs!$C$106*Pay_Plan!S14) -> 5.428
A37: Extra Instagram ads | B37: Rp m | C37: =SUM(E37:G37) -> 0 | D37: =SUM(H37:S37) -> 42 | E37: =Pay_Plan!E12 -> 0 | F37: =Pay_Plan!F12 -> 0 | G37: =Pay_Plan!G12 -> 0 | H37: =Pay_Plan!H12 -> 3.5 | I37: =Pay_Plan!I12 -> 3.5 | J37: =Pay_Plan!J12 -> 3.5 | K37: =Pay_Plan!K12 -> 3.5 | L37: =Pay_Plan!L12 -> 3.5 | ... S37: =Pay_Plan!S12 -> 3.5
A38: Psychologists' pay covered by B2C gross profit | B38: x | C38: =IF(C36=0,0,C35/C36) -> 0.41446955 | D38: =IF(D36=0,0,D35/D36) -> 0.68792957 | E38: =IF(E36=0,0,E35/E36) -> 0.76801639 | F38: =IF(F36=0,0,F35/F36) -> 0.23386806 | G38: =IF(G36=0,0,G35/G36) -> 0.24152421 | H38: =IF(H36=0,0,H35/H36) -> 0.13835837 | I38: =IF(I36=0,0,I35/I36) -> 0.54944733 | J38: =IF(J36=0,0,J35/J36) -> 0.20465859 | ... S38: =IF(S36=0,0,S35/S36) -> 1.140296
A39: B2C profit after psychologists, ads and referral rewards | B39: Rp m | C39: =SUM(E39:G39) -> -4.0401601 | D39: =SUM(H39:S39) -> -64.955961 | E39: =E35-E36-E37-E53 -> -0.53356231 | F39: =F35-F36-F37-F53 -> -1.7621035 | G39: =G35-G36-G37-G53 -> -1.7444943 | H39: =H35-H36-H37-H53 -> -8.208382 | I39: =I35-I36-I37-I53 -> -5.979415 | J39: =J35-J36-J37-J53 -> -7.8535394 | K39: =K35-K36-K37-K53 -> -6.6823184 | L39: =L35-L36-L37-L53 -> -6.5993555 | ... S39: =S35-S36-S37-S53 -> -3.2406446
A40: Capacity (COO)
A41: COO: sessions to deliver (B2C + EAP + BI KPw packages) | B41: sessions | C41: =SUM(E41:G41) -> 56.272957 | D41: =SUM(H41:S41) -> 895.44651 | E41: =E26+Volume!E26*Inputs!$C$68+Volume!E43 -> 12.089743 | F41: =F26+Volume!F26*Inputs!$C$68+Volume!F43 -> 22.039401 | G41: =G26+Volume!G26*Inputs!$C$68+Volume!G43 -> 22.143813 | H41: =H26+Volume!H26*Inputs!$C$68+Volume!H43 -> 23.303031 | I41: =I26+Volume!I26*Inputs!$C$68+Volume!I43 -> 43.282665 | J41: =J26+Volume!J26*Inputs!$C$68+Volume!J43 -> 49.419888 | K41: =K26+Volume!K26*Inputs!$C$68+Volume!K43 -> 65.5997 | L41: =L26+Volume!L26*Inputs!$C$68+Volume!L43 -> 66.14318 | ... S41: =S26+Volume!S26*Inputs!$C$68+Volume!S43 -> 100.26499
...

Sheet B2C_Pricing
A1: B2C prices: psychologist tiers and profit share (latest price list, 13 Oct 2026)
A2: Source: B2C Pricing/TJ_Pricing_Tier_Psikolog_Profit_Sharing.xlsx (Pricing_Counseling, Inputs). Blue = copy of that file; change both together. Rp million per session. Feeds Inputs b2c_p_new and b2c_f_new.
A4: Tier (psychologist experience) | B4: Online 60 min price | C4: Offline 60 min price | D4: Share to psychologist | E4: Share of sessions (mix) | F4: Fee online | G4: Fee offline | H4: TJ margin online | I4: TJ margin offline
A5: Tier 1 (0-2 years) | B5: 0.5 | C5: 0.58 | D5: 0.6 | E5: 0.3 | F5: =B5*D5 -> 0.3 | G5: =C5*D5 -> 0.348 | H5: =B5-F5 -> 0.2 | I5: =C5-G5 -> 0.232
A6: Tier 2 (2-5 years) | B6: 0.5 | C6: 0.58 | D6: 0.65 | E6: 0.35 | F6: =B6*D6 -> 0.325 | G6: =C6*D6 -> 0.377 | H6: =B6-F6 -> 0.175 | I6: =C6-G6 -> 0.203
A7: Tier 3 (5-10 years) | B7: 0.725 | C7: 0.8 | D7: 0.65 | E7: 0.25 | F7: =B7*D7 -> 0.47125 | G7: =C7*D7 -> 0.52 | H7: =B7-F7 -> 0.25375 | I7: =C7-G7 -> 0.28
A8: Tier 4 (over 10 years) | B8: 0.85 | C8: 0.925 | D8: 0.7 | E8: 0.1 | F8: =B8*D8 -> 0.595 | G8: =C8*D8 -> 0.6475 | H8: =B8-F8 -> 0.255 | I8: =C8-G8 -> 0.2775
A9: Check: mix adds to 100% | E9: =IF(ABS(SUM(E5:E8)-1)<0.0001,"OK","CHECK") -> OK
A11: Share of sessions online (rest offline) | B11: 0.7 | C11: Estimate: fill from real bookings
A12: Platform and payment cost per session (paid by TJ) | B12: 0.05 | C12: Estimate: pricing file default (Rp50k)
A13: 4-session package discount | B13: 0.1 | C13: Known: ACC sheet, ~10%
A14: Share of clients on the 4-session package | B14: =Inputs!$C$136 -> 0 | C14: Inputs b2c_pack (0 = price list as is)
A15: Blended result (feeds the model)
A16: Average list price per session | B16: =SUMPRODUCT(E5:E8,B5:B8)*B11+SUMPRODUCT(E5:E8,C5:C8)*(1-B11) -> 0.614725
A17: Average psychologist fee per session | B17: =SUMPRODUCT(E5:E8,F5:F8)*B11+SUMPRODUCT(E5:E8,G5:G8)*(1-B11) -> 0.39607375
A18: Average price actually paid (after package discount) | B18: =B16*(1-B14*B13) -> 0.614725
A19: Psychologist fee on the price paid (profit share is on the price paid) | B19: =B17*(1-B14*B13) -> 0.39607375
A20: TJ margin per session after platform cost | B20: =B18-B19-B12 -> 0.16865125
A21: Cost share used by the model: (fee + platform) / price | B21: =(B19+B12)/B18 -> 0.72564765
A22: v15 for comparison: price, and TJ margin per session | B22: =Inputs!$C$134 -> 1
A23: v15 TJ margin per session (Rp1m x 60%) | B23: =Inputs!$C$134*(1-Inputs!$C$135) -> 0.6
A24: New margin vs v15 margin | B24: =B20/B23-1 -> -0.71891458
A26: Reference: assessments (one price for all assessors, 50:50 share after the test-tool cost)
A27: Tes Minat Bakat (interest and aptitude) | B27: 1.625 | C27: 14+
A28: Tes IQ | B28: 0.725 | C28: child to adult
A29: Tes Profiling | B29: 1.225 | C29: 6-13
A30: MHCU (adult mental health check) | B30: 0.375 | C30: adult
A32: Read: the latest price list earns about Rp170k per session after the psychologist and platform, against Rp600k in v15. Counseling alone cannot pay for Instagram ads (see B2C rows 56-59); it pays when clients come through EAP, schools and referral.

Sheet Channels
A1: Channels (v16): EAP packages for BI regional offices, and schools
A2: Package prices and costs: SPKnProposalAnalysis/BI Sibolga/Internal_-_BI_Sibolga_Costing_format_TJ_v4.xlsx (costs with every session paid at the Rp350k honor; before the 2% PPh 23 withholding). Rp million.
A4: BI KPw package (3 months) | B4: Price | C4: Cost (all sessions paid) | D4: Counseling sessions | E4: Mix (blue) | F4: Margin | G4: Price / cost | H4: Price for a 30% margin | I4: Gap to that price
A5: Sapa (intro: 15 sessions) | B5: 7.5 | C5: 5.925 | D5: 15 | E5: 0.25 | F5: =1-C5/B5 -> 0.21 | G5: =B5/C5 -> 1.2658228 | H5: =C5/(1-0.3) -> 8.4642857 | I5: =MAX(0,H5-B5) -> 0.96428571
A6: Tumbuh (24 sessions + MHCU + report) | B6: 14 | C6: 10.7 | D6: 24 | E6: 0.35 | F6: =1-C6/B6 -> 0.23571429 | G6: =B6/C6 -> 1.3084112 | H6: =C6/(1-0.3) -> 15.285714 | I6: =MAX(0,H6-B6) -> 1.2857143
A7: Seperjalanan (36 sessions + 2 MHCU + webinar + 2 penyuluhan) | B7: 23 | C7: 16.64 | D7: 36 | E7: 0.25 | F7: =1-C7/B7 -> 0.27652174 | G7: =B7/C7 -> 1.3822115 | H7: =C7/(1-0.3) -> 23.771429 | I7: =MAX(0,H7-B7) -> 0.77142857
A8: Berbagi (Seperjalanan, webinar free) | B8: 20 | C8: 18.74 | D8: 36 | E8: 0.05 | F8: =1-C8/B8 -> 0.063 | G8: =B8/C8 -> 1.0672359 | H8: =C8/(1-0.3) -> 26.771429 | I8: =MAX(0,H8-B8) -> 6.7714286
A9: Penyuluhan (Seperjalanan, no webinar) | B9: 20 | C9: 16.64 | D9: 36 | E9: 0.1 | F9: =1-C9/B9 -> 0.168 | G9: =B9/C9 -> 1.2019231 | H9: =C9/(1-0.3) -> 23.771429 | I9: =MAX(0,H9-B9) -> 3.7714286
A10: Average package (mix-weighted) | B10: =SUMPRODUCT($E$5:$E$9,B5:B9) -> 15.525 | C10: =SUMPRODUCT($E$5:$E$9,C5:C9) -> 11.98725 | D10: =SUMPRODUCT($E$5:$E$9,D5:D9) -> 26.55 | E10: =SUM(E5:E9) -> 1 | F10: =1-C10/B10 -> 0.2278744 | G10: =B10/C10 -> 1.2951261
A11: Read: with every session paid at Rp350k the packages earn 7-27%, far below the 3x rule for training. They make money only when the paid part-timers deliver the sessions inside their fixed pay. Next offices: price Tumbuh and Seperjalanan at or above column H, and keep Sapa as the small intro.
A13: Monthly plan (blue = change freely)
A14: Line | B14: Unit | C14: Q4 2026 | D14: FY 2027 | E14: =Volume!E4 -> Oct-26 | F14: =Volume!F4 -> Nov-26 | G14: =Volume!G4 -> Dec-26 | H14: =Volume!H4 -> Jan-27 | I14: =Volume!I4 -> Feb-27 | J14: =Volume!J4 -> Mar-27 | K14: =Volume!K4 -> Apr-27 | L14: =Volume!L4 -> May-27 | ... S14: =Volume!S4 -> Dec-27
A15: New BI KPw packages signed (new offices; Nov-26 = Sibolga) | B15: packages | C15: =SUM(E15:G15) -> 1 | D15: =SUM(H15:S15) -> 10 | E15: 0 | F15: 1 | G15: 0 | H15: 0 | I15: 1 | J15: 1 | K15: 1 | L15: 1 | M15: 0 | N15: 1 | O15: 1 | P15: 1 | Q15: 2 | R15: 1 | S15: 0
A16: Schools tested (group interest and aptitude test; Feb pilot, Jul grade 10, Aug-Nov grade 12) | B16: schools | C16: =SUM(E16:G16) -> 0 | D16: =SUM(H16:S16) -> 6 | E16: 0 | F16: 0 | G16: 0 | H16: 0 | I16: 1 | J16: 0 | K16: 0 | L16: 0 | M16: 0 | N16: 1 | O16: 1 | P16: 1 | Q16: 1 | R16: 1 | S16: 0
A18: Why these dates: BI KPw offices spend their own yearly budget, most of it in the second half; schools test grade 10 before the major choice (Jun-Jul) and grade 12 before college applications (Aug-Nov).

Sheet Inputs
A1: Inputs and assumptions (all money in Rp million)
A2: Blue numbers are inputs you can change. Status: Known = you told us or it is in your v10 file; Your plan = your own budget; Estimate = industry estimate used until you give the real number (yellow-shaded, listed in the To_Fill sheet).
A4: Key | B4: Item | C4: Value | D4: Unit | E4: Status | F4: Source / logic
A5: 0. Scenario selector
A6: scen | B6: Active scenario (1-4) | C6: 1 | D6: number | E6: Known | F6: 1 = Base plan (v10 volumes). 2 = No new B2B event closes Jan-Jun 2027. 3 = BI cuts its volume by the % below. 4 = Both 2 and 3 (worst case).
A7: bi_cut | B7: BI volume cut used in scenarios 3 and 4 | C7: 0.3 | D7: % | E7: Known | F7: Stress test size. Change freely.
A8: 1. Prices (per event, or per month for EAP)
A9: p_flag | B9: Flagship regulator ToT (CBP Rupiah) | C9: 85 | D9: Rp m / event | E9: Known | F9: Your v10 file.
A10: p_kpw | B10: Regulator regional ToT (BI KPW and LPS) | C10: 20 | D10: Rp m / event | E10: Known | F10: Your v10 file.
A11: p_kcp | B11: Bank branch event (KCP) | C11: 35 | D11: Rp m / event | E11: Known | F11: Your v10 file.
A12: p_eap | B12: Bank EAP subscription | C12: 15 | D12: Rp m / month | E12: Known | F12: Your v10 file.
A13: p_b2ce | B13: B2C mass event | C13: =IF(Inputs!$C$131=1,Inputs!$C$137,Inputs!$C$139) -> 4.144 | D13: Rp m / event | E13: Known | F13: v16: Lyfe at 30s format (Inputs section 14). v15: your v10 file.
A14: p_b2cc | B14: B2C counseling client | C14: =IF(Inputs!$C$131=1,Inputs!$C$132,Inputs!$C$134) -> 0.614725 | D14: Rp m / client | E14: Known | F14: v16: latest price list (B2C_Pricing sheet). v15: Rp1,000,000 per session.
A15: 2. Delivery cost (cost of goods sold)
A16: c_flag | B16: Flagship delivery cost | C16: 25 | D16: Rp m / event | E16: Known | F16: Your v10 file: travel, hotel, materials, premium facilitator fees.
A17: c_kpw | B17: KPW / LPS delivery cost | C17: 8 | D17: Rp m / event | E17: Known | F17: Your v10 file. Covers about 2 handler fees only, so travel is assumed paid by the client (see below).
A18: c_kcp | B18: Bank KCP event delivery cost | C18: 12 | D18: Rp m / event | E18: Known | F18: Your v10 file.
A19: c_eap | B19: EAP delivery cost | C19: 5 | D19: Rp m / month | E19: Known | F19: Your v10 file: on-call tele-counseling retainer.
A20: c_b2ce | B20: B2C event delivery cost | C20: =IF(Inputs!$C$131=1,Inputs!$C$138,Inputs!$C$140) -> 2.73 | D20: Rp m / event | E20: Known | F20: v16: Lyfe RAB at 16 people. v15: venue, ads, materials, fees.
A21: c_b2cc | B21: B2C counseling cost (psychologist fee) | C21: =IF(Inputs!$C$131=1,Inputs!$C$133,Inputs!$C$135) -> 0.72564765 | D21: % of price | E21: Known | F21: v16: psychologist share by tier + platform cost (B2C_Pricing). v15: Rp400k of Rp1m.
A22: travel_client | B22: Client pays travel for regional events? (1 = yes, 0 = no) | C22: 1 | D22: switch | E22: Estimate | F22: The Rp 8m KPW cost only covers 2 handler fees, so we assume BI pays travel.
A23: travel_pp | B23: Travel cost per handler per regional trip | C23: 3.5 | D23: Rp m / person | E23: Estimate | F23: Industry estimate: return flight ~Rp 2m + 2 hotel nights ~Rp 1m + per diem ~Rp 0.5m.
A24: regional_share | B24: Share of KPW / LPS events outside Jakarta | C24: 0.8 | D24: % | E24: Estimate | F24: Estimate: most KPW offices are outside Jakarta.
A25: 3. Delivery staffing (from your v10 file)
A26: h_flag | B26: Handlers per Flagship event | C26: 4 | D26: people | E26: Known | F26: 1 PM, 1 Lead Psychologist, 2 Facilitators.
A27: h_kpw | B27: Handlers per KPW / LPS event | C27: 2 | D27: people | E27: Known | F27: 1 Lead, 1 Facilitator.
A28: h_kcp | B28: Handlers per KCP event | C28: 2 | D28: people | E28: Known | F28: 1 Lead, 1 Facilitator.
A29: h_b2ce | B29: Handlers per B2C event | C29: 2 | D29: people | E29: Known | F29: 1 Lead, 1 Facilitator / Assistant.
A30: d_flag | B30: Days per Flagship event | C30: 3 | D30: days | E30: Estimate | F30: You said 2-3 day program; we use 3.
A31: d_kpw | B31: Days per KPW / LPS event | C31: 1 | D31: days | E31: Estimate | F31: Estimate.
A32: d_kcp | B32: Days per KCP event | C32: 1 | D32: days | E32: Estimate | F32: Estimate.
A33: d_b2ce | B33: Days per B2C event | C33: 1 | D33: days | E33: Estimate | F33: Estimate (weekend event).
A34: fac_cap | B34: Max events per facilitator per month | C34: 2 | D34: events | E34: Known | F34: Your v10 quality rule.
A35: fac_now | B35: Certified facilitators today | C35: 2 | D35: people | E35: Known | F35: You told us: 2 active core facilitators.
A36: fac_plan | B36: Your plan: facilitators certified by Nov 2026 | C36: 11 | D36: people | E36: Known | F36: Your earlier plan.
A37: cert_cost | B37: Cost to certify one new facilitator | C37: 2.5 | D37: Rp m / person | E37: Estimate | F37: Industry estimate: 2-day internal ToT, materials, observed practice event.
A38: 4. Fixed cost: base (your 2027 'bensin' budget, monthly)
A39: o_lead_mkt | B39: Lead Marketing | C39: 2.5 | D39: Rp m / month | E39: Known | F39: Your 2027 budget.
A40: o_socmed | B40: Social Media Specialist | C40: 1.5 | D40: Rp m / month | E40: Known | F40: Your 2027 budget.
A41: o_intern_mkt | B41: Marketing intern | C41: 1 | D41: Rp m / month | E41: Known | F41: Your 2027 budget.
...

Sheet Pay_Plan
A1: Pay plan: gross pay a month for every role (Rp million). Blue cells are your decisions; change them freely.
A2: Decided 5 Oct 2026: BPJS + THR from Jan-27; social media up in steps; admin to the minimum wage from Jul-27; lead marketing capped at Rp4m in 2027 (KPI: 10k IG followers) with Rp3.5m of her budget moved to ads; admin paid per client (Rp1.8m base + Rp17k a client + Rp620k bonus); pay rises for admin, social media and lead marketing unlock when sales targets are met (rows 27-30), not by date; psychologist stays part-time (no full-time hire for now); a non-psychologist Lead Partnership from Oct-27; IG ads today Rp1m (software budget) + Rp3.5m moved from lead marketing; founders: only one is paid today (Rp10m); Rp25m from Mar-27 keeps room for the second founder, whose start is still to decide.
A4: Line | B4: Unit | C4: Q4 2026 | D4: FY 2027 | E4: =Volume!E4 -> Oct-26 | F4: =Volume!F4 -> Nov-26 | G4: =Volume!G4 -> Dec-26 | H4: =Volume!H4 -> Jan-27 | I4: =Volume!I4 -> Feb-27 | J4: =Volume!J4 -> Mar-27 | K4: =Volume!K4 -> Apr-27 | L4: =Volume!L4 -> May-27 | ... S4: =Volume!S4 -> Dec-27
A5: Gross pay a month (blue = your input)
A6: Admin (formula: base + fee per client + weekly bonus; minimum wage once step 2 is unlocked) | B6: Rp m | C6: =SUM(E6:G6) -> 7.5966403 | D6: =SUM(H6:S6) -> 56.421724 | E6: =IF(E30>=2,MAX(Inputs!$C$122,Inputs!$C$118+Inputs!$C$119*(Volume!E28+Volume!E26*Inputs!$C$68+Volume!E43)+IF((Volume!E28+Volume!E26*Inputs!$C$68+Volume!E43)>=Inputs!$C$121,Inputs!$C$120,0)),Inputs!$C$118+Inputs!$C$119*(Volume!E28+Volume!E26*Inputs!$C$68+Volume!E43)+IF((Volume!E28+Volume!E26*Inputs!$C$68+Volume!E43)>=Inputs!$C$121,Inputs!$C$120,0)) -> 2.0055256 | F6: =IF(F30>=2,MAX(Inputs!$C$122,Inputs!$C$118+Inputs!$C$119*(Volume!F28+Volume!F26*Inputs!$C$68+Volume!F43)+IF((Volume!F28+Volume!F26*Inputs!$C$68+Volume!F43)>=Inputs!$C$121,Inputs!$C$120,0)),Inputs!$C$118+Inputs!$C$119*(Volume!F28+Volume!F26*Inputs!$C$68+Volume!F43)+IF((Volume!F28+Volume!F26*Inputs!$C$68+Volume!F43)>=Inputs!$C$121,Inputs!$C$120,0)) -> 2.7946698 | G6: =IF(G30>=2,MAX(Inputs!$C$122,Inputs!$C$118+Inputs!$C$119*(Volume!G28+Volume!G26*Inputs!$C$68+Volume!G43)+IF((Volume!G28+Volume!G26*Inputs!$C$68+Volume!G43)>=Inputs!$C$121,Inputs!$C$120,0)),Inputs!$C$118+Inputs!$C$119*(Volume!G28+Volume!G26*Inputs!$C$68+Volume!G43)+IF((Volume!G28+Volume!G26*Inputs!$C$68+Volume!G43)>=Inputs!$C$121,Inputs!$C$120,0)) -> 2.7964448 | H6: =IF(H30>=2,MAX(Inputs!$C$122,Inputs!$C$118+Inputs!$C$119*(Volume!H28+Volume!H26*Inputs!$C$68+Volume!H43)+IF((Volume!H28+Volume!H26*Inputs!$C$68+Volume!H43)>=Inputs!$C$121,Inputs!$C$120,0)),Inputs!$C$118+Inputs!$C$119*(Volume!H28+Volume!H26*Inputs!$C$68+Volume!H43)+IF((Volume!H28+Volume!H26*Inputs!$C$68+Volume!H43)>=Inputs!$C$121,Inputs!$C$120,0)) -> 2.8161515 | I6: =IF(I30>=2,MAX(Inputs!$C$122,Inputs!$C$118+Inputs!$C$119*(Volume!I28+Volume!I26*Inputs!$C$68+Volume!I43)+IF((Volume!I28+Volume!I26*Inputs!$C$68+Volume!I43)>=Inputs!$C$121,Inputs!$C$120,0)),Inputs!$C$118+Inputs!$C$119*(Volume!I28+Volume!I26*Inputs!$C$68+Volume!I43)+IF((Volume!I28+Volume!I26*Inputs!$C$68+Volume!I43)>=Inputs!$C$121,Inputs!$C$120,0)) -> 3.1558053 | J6: =IF(J30>=2,MAX(Inputs!$C$122,Inputs!$C$118+Inputs!$C$119*(Volume!J28+Volume!J26*Inputs!$C$68+Volume!J43)+IF((Volume!J28+Volume!J26*Inputs!$C$68+Volume!J43)>=Inputs!$C$121,Inputs!$C$120,0)),Inputs!$C$118+Inputs!$C$119*(Volume!J28+Volume!J26*Inputs!$C$68+Volume!J43)+IF((Volume!J28+Volume!J26*Inputs!$C$68+Volume!J43)>=Inputs!$C$121,Inputs!$C$120,0)) -> 3.2601381 | K6: =IF(K30>=2,MAX(Inputs!$C$122,Inputs!$C$118+Inputs!$C$119*(Volume!K28+Volume!K26*Inputs!$C$68+Volume!K43)+IF((Volume!K28+Volume!K26*Inputs!$C$68+Volume!K43)>=Inputs!$C$121,Inputs!$C$120,0)),Inputs!$C$118+Inputs!$C$119*(Volume!K28+Volume!K26*Inputs!$C$68+Volume!K43)+IF((Volume!K28+Volume!K26*Inputs!$C$68+Volume!K43)>=Inputs!$C$121,Inputs!$C$120,0)) -> 3.5351949 | L6: =IF(L30>=2,MAX(Inputs!$C$122,Inputs!$C$118+Inputs!$C$119*(Volume!L28+Volume!L26*Inputs!$C$68+Volume!L43)+IF((Volume!L28+Volume!L26*Inputs!$C$68+Volume!L43)>=Inputs!$C$121,Inputs!$C$120,0)),Inputs!$C$118+Inputs!$C$119*(Volume!L28+Volume!L26*Inputs!$C$68+Volume!L43)+IF((Volume!L28+Volume!L26*Inputs!$C$68+Volume!L43)>=Inputs!$C$121,Inputs!$C$120,0)) -> 3.5444341 | ... S6: =IF(S30>=2,MAX(Inputs!$C$122,Inputs!$C$118+Inputs!$C$119*(Volume!S28+Volume!S26*Inputs!$C$68+Volume!S43)+IF((Volume!S28+Volume!S26*Inputs!$C$68+Volume!S43)>=Inputs!$C$121,Inputs!$C$120,0)),Inputs!$C$118+Inputs!$C$119*(Volume!S28+Volume!S26*Inputs!$C$68+Volume!S43)+IF((Volume!S28+Volume!S26*Inputs!$C$68+Volume!S43)>=Inputs!$C$121,Inputs!$C$120,0)) -> 5.73
A7: Social media specialist (formula: 1.5, then 3.0 / 4.5 / minimum wage at pay steps 1 / 2 / 3) | B7: Rp m | C7: =SUM(E7:G7) -> 4.5 | D7: =SUM(H7:S7) -> 44.19 | E7: =CHOOSE(E30+1,1.5,3,4.5,Inputs!$C$122) -> 1.5 | F7: =CHOOSE(F30+1,1.5,3,4.5,Inputs!$C$122) -> 1.5 | G7: =CHOOSE(G30+1,1.5,3,4.5,Inputs!$C$122) -> 1.5 | H7: =CHOOSE(H30+1,1.5,3,4.5,Inputs!$C$122) -> 1.5 | I7: =CHOOSE(I30+1,1.5,3,4.5,Inputs!$C$122) -> 1.5 | J7: =CHOOSE(J30+1,1.5,3,4.5,Inputs!$C$122) -> 1.5 | K7: =CHOOSE(K30+1,1.5,3,4.5,Inputs!$C$122) -> 1.5 | L7: =CHOOSE(L30+1,1.5,3,4.5,Inputs!$C$122) -> 3 | ... S7: =CHOOSE(S30+1,1.5,3,4.5,Inputs!$C$122) -> 5.73
A8: Lead marketing (formula: 2.5, then 4.0 cap at pay step 1; KPI 10k IG followers; has shares) | B8: Rp m | C8: =SUM(E8:G8) -> 7.5 | D8: =SUM(H8:S8) -> 42 | E8: =IF(E30>=1,4,2.5) -> 2.5 | F8: =IF(F30>=1,4,2.5) -> 2.5 | G8: =IF(G30>=1,4,2.5) -> 2.5 | H8: =IF(H30>=1,4,2.5) -> 2.5 | I8: =IF(I30>=1,4,2.5) -> 2.5 | J8: =IF(J30>=1,4,2.5) -> 2.5 | K8: =IF(K30>=1,4,2.5) -> 2.5 | L8: =IF(L30>=1,4,2.5) -> 4 | ... S8: =IF(S30>=1,4,2.5) -> 4
A9: Psychologists, paid part-time: PIC now + 1 more from Jan-27 (no full-time hire in 2027) | B9: Rp m | C9: =SUM(E9:G9) -> 6.9 | D9: =SUM(H9:S9) -> 55.2 | E9: 2.3 | F9: 2.3 | G9: 2.3 | H9: 4.6 | I9: 4.6 | J9: 4.6 | K9: 4.6 | L9: 4.6 | M9: 4.6 | N9: 4.6 | O9: 4.6 | P9: 4.6 | Q9: 4.6 | R9: 4.6 | S9: 4.6
A10: Interns, not Magang (2 people) | B10: Rp m | C10: =SUM(E10:G10) -> 6 | D10: =SUM(H10:S10) -> 24 | E10: 2 | F10: 2 | G10: 2 | H10: 2 | I10: 2 | J10: 2 | K10: 2 | L10: 2 | M10: 2 | N10: 2 | O10: 2 | P10: 2 | Q10: 2 | R10: 2 | S10: 2
A11: Founders: Rp10m now (one founder paid); Rp25m from Mar-27 = room for both (second founder's start: to decide) | B11: Rp m | C11: =SUM(E11:G11) -> 30 | D11: =SUM(H11:S11) -> 270 | E11: 10 | F11: 10 | G11: 10 | H11: 10 | I11: 10 | J11: 25 | K11: 25 | L11: 25 | M11: 25 | N11: 25 | O11: 25 | P11: 25 | Q11: 25 | R11: 25 | S11: 25
A12: Extra IG ads (Rp3.5m moved from lead marketing; Rp1m is already in the software budget) | B12: Rp m | C12: =SUM(E12:G12) -> 0 | D12: =SUM(H12:S12) -> 42 | E12: 0 | F12: 0 | G12: 0 | H12: 3.5 | I12: 3.5 | J12: 3.5 | K12: 3.5 | L12: 3.5 | M12: 3.5 | N12: 3.5 | O12: 3.5 | P12: 3.5 | Q12: 3.5 | R12: 3.5 | S12: 3.5
A13: Lead Partnership, non-psychologist (formula: from Inputs) | B13: Rp m | C13: =SUM(E13:G13) -> 0 | D13: =SUM(H13:S13) -> 18 | E13: =IF(Volume!E6>=IFERROR(MATCH(Inputs!$C$125,Volume!$E$4:$S$4,0),99),Inputs!$C$124,0) -> 0 | F13: =IF(Volume!F6>=IFERROR(MATCH(Inputs!$C$125,Volume!$E$4:$S$4,0),99),Inputs!$C$124,0) -> 0 | G13: =IF(Volume!G6>=IFERROR(MATCH(Inputs!$C$125,Volume!$E$4:$S$4,0),99),Inputs!$C$124,0) -> 0 | H13: =IF(Volume!H6>=IFERROR(MATCH(Inputs!$C$125,Volume!$E$4:$S$4,0),99),Inputs!$C$124,0) -> 0 | I13: =IF(Volume!I6>=IFERROR(MATCH(Inputs!$C$125,Volume!$E$4:$S$4,0),99),Inputs!$C$124,0) -> 0 | J13: =IF(Volume!J6>=IFERROR(MATCH(Inputs!$C$125,Volume!$E$4:$S$4,0),99),Inputs!$C$124,0) -> 0 | K13: =IF(Volume!K6>=IFERROR(MATCH(Inputs!$C$125,Volume!$E$4:$S$4,0),99),Inputs!$C$124,0) -> 0 | L13: =IF(Volume!L6>=IFERROR(MATCH(Inputs!$C$125,Volume!$E$4:$S$4,0),99),Inputs!$C$124,0) -> 0 | ... S13: =IF(Volume!S6>=IFERROR(MATCH(Inputs!$C$125,Volume!$E$4:$S$4,0),99),Inputs!$C$124,0) -> 6
A14: BPJS + THR paid on staff pay? (1 = yes) | B14: flag | C14: =MAX(E14:G14) -> 0 | D14: =MAX(H14:S14) -> 1 | E14: 0 | F14: 0 | G14: 0 | H14: 1 | I14: 1 | J14: 1 | K14: 1 | L14: 1 | M14: 1 | N14: 1 | O14: 1 | P14: 1 | Q14: 1 | R14: 1 | S14: 1
A15: Team cost incl. BPJS and THR (staff + psychologist + interns) | B15: Rp m | C15: =SUM(E15:G15) -> 32.49664 | D15: =SUM(H15:S15) -> 278.65783 | E15: =(E6+E7+E8+E9+E13)*(1+Inputs!$C$106*E14)+E10 -> 10.305526 | F15: =(F6+F7+F8+F9+F13)*(1+Inputs!$C$106*F14)+F10 -> 11.09467 | G15: =(G6+G7+G8+G9+G13)*(1+Inputs!$C$106*G14)+G10 -> 11.096445 | H15: =(H6+H7+H8+H9+H13)*(1+Inputs!$C$106*H14)+H10 -> 15.471059 | I15: =(I6+I7+I8+I9+I13)*(1+Inputs!$C$106*I14)+I10 -> 15.87185 | J15: =(J6+J7+J8+J9+J13)*(1+Inputs!$C$106*J14)+J10 -> 15.994963 | K15: =(K6+K7+K8+K9+K13)*(1+Inputs!$C$106*K14)+K10 -> 16.31953 | L15: =(L6+L7+L8+L9+L13)*(1+Inputs!$C$106*L14)+L10 -> 19.870432 | ... S15: =(S6+S7+S8+S9+S13)*(1+Inputs!$C$106*S14)+S10 -> 32.7508
