Workbook

Sheet Ringkasan
A1: RINGKASAN - BI Fit and Proper Test (INTERNAL, bukan untuk klien)
A3: Jumlah peserta | B3: =Asumsi!$B$3 -> 6
A4: Harga disepakati BI | B4: =Asumsi!$B$4 -> 15000000
A5: Harga per peserta | B5: =Asumsi!$B$4/Asumsi!$B$3 -> 2500000
A6: Status pajak | B6: =Asumsi!$B$5 -> Non-PKP
A7: Diterima setelah pajak (PPN jika PKP, PPh 23) | B7: =RAB!$B$29 -> 14700000
A8: Jumlah biaya | B8: =RAB!$J$20 -> 8770000
A9: Biaya per peserta | B9: =RAB!$J$20/Asumsi!$B$3 -> 1461666.7
A10: Markup harga terhadap biaya | B10: =RAB!$B$35 -> 0.71037628
A11: PROFIT NETT (setelah pajak dan komisi) | B11: =RAB!$B$33 -> 5337000
A12: Margin nett terhadap harga | B12: =RAB!$B$34 -> 0.3558
A13: AFTER COST jika semua sesi oleh psikolog in-house | B13: =RAB!$B$37 -> 13170000
A14: Cek harga per layanan di proposal | B14: ='Harga Proposal'!F12 -> OK
A16: Catatan:
A17: 1. Semua honor psikolog dihitung per jam: Rp110.000/jam untuk kerja dokumen (rubrik, skoring, laporan), Rp350.000/jam untuk tatap muka (LGD, wawancara) sesuai biaya dasar konseling.
A18: 2. Rubrik disusun 2 psikolog, masing-masing minimal 2 jam, sesuai arahan Galih.
A19: 3. TJ Non-PKP (dikonfirmasi 28 Okt 2026), jadi tidak ada PPN. Penawaran 28 Okt yang menulis 'sudah termasuk PPN' perlu dikoreksi jika dikirim ulang.
A20: 4. Transport mengasumsikan tatap muka di Jakarta. Jika lokasi lain atau online, ubah di Asumsi.
A21: 5. Tab 'Harga Proposal' adalah satu-satunya angka yang boleh keluar ke BI. Tab lain internal.

Sheet Asumsi
A1: ASUMSI - BI Fit and Proper Test (INTERNAL, bukan untuk klien). Sel biru = input.
A2: Asumsi | B2: Nilai | C2: Satuan | D2: Sumber / catatan
A3: Jumlah peserta | B3: 6 | C3: orang | D3: Penawaran 28 Okt 2026, disetujui BI
A4: Harga final disepakati BI (total) | B4: 15000000 | C4: Rp | D4: BI: "pakai Rp15.000.000 saja". Naik dari penawaran Rp14.520.000
A5: Status pajak Teman Journey (PKP / Non-PKP) | B5: Non-PKP | C5: - | D5: Dikonfirmasi Galih 28 Okt 2026: Non-PKP. Ganti ke PKP hanya jika sudah dikukuhkan PKP
A6: Tarif PPN efektif (hanya jika PKP) | B6: 0.11 | C6: % | D6: 12% x DPP nilai lain 11/12 = 11% efektif
A7: PPh 23 dipotong BI | B7: 0.02 | C7: % | D7: Sama dengan model BI Sibolga. Bisa dikreditkan di SPT badan, di sini dihitung sebagai biaya (konservatif)
A8: Honor psikolog: penyusunan dokumen per jam | B8: 110000 | C8: Rp/jam | D8: Diberikan Galih (28 Okt 2026): Rp110.000 per jam untuk pembuatan dokumen
A9: Jam minimal per psikolog per rubrik | B9: 2 | C9: jam | D9: Diberikan Galih: tiap psikolog minimal 2 jam
A10: Psikolog yang menyusun tiap rubrik | B10: 2 | C10: orang | D10: Juri utama + psikolog fasilitator LGD menyusun bersama
A11: Honor psikolog: tatap muka asesmen per jam (biaya dasar konseling) | B11: 350000 | C11: Rp/jam | D11: Biaya dasar konseling TJ: honor psikolog Rp350.000 per sesi 60 menit (BI Sibolga, dari Kia)
A12: Jam koordinasi kebutuhan BI per psikolog | B12: 1 | C12: jam | D12: Kick-off: kompetensi target, jadwal, format laporan
A13: Jam penyusunan studi kasus dan instruksi LGD | B13: 2 | C13: jam | D13: Disusun psikolog fasilitator LGD
A14: Durasi LGD termasuk briefing | B14: 2 | C14: jam | D14: Briefing 15 menit, diskusi 60-75 menit, penutupan
A15: Psikolog di sesi LGD | B15: 2 | C15: orang | D15: 1 fasilitator + 1 asesor, masing-masing mengamati 3 peserta
A16: Jam skoring LGD per psikolog | B16: 1 | C16: jam | D16: Mengisi rubrik dan catatan perilaku
A17: Durasi wawancara per peserta | B17: 1 | C17: jam | D17: Wawancara terstruktur berbasis perilaku
A18: Jam skoring dan catatan wawancara per peserta | B18: 0.5 | C18: jam
A19: Jam penulisan laporan per peserta | B19: 2 | C19: jam | D19: Integrasi tes, LGD, wawancara
A20: Jam review mutu laporan oleh juri utama per peserta | B20: 0.5 | C20: jam
A21: Jam rapat integrasi hasil per psikolog | B21: 1 | C21: jam | D21: Menyepakati rekomendasi akhir tiap peserta
A22: Tes BFI + DISC per peserta | B22: 120000 | C22: Rp/peserta | D22: RAB lama
A23: Admin dan koordinasi jadwal per peserta | B23: 35000 | C23: Rp/peserta | D23: Rujukan admin per sesi BI Sibolga
A24: Transport psikolog per orang per hari | B24: 150000 | C24: Rp | D24: ASUMSI: pelaksanaan tatap muka di Jakarta. Isi 0 jika online
A25: Total kehadiran psikolog (orang x hari) | B25: 3 | C25: orang-hari | D25: ASUMSI: juri utama 2 hari (LGD + wawancara), fasilitator 1 hari
A26: Kontrak dan materai | B26: 150000 | C26: Rp | D26: Rujukan BI Sibolga
A27: Komisi (% dari profit kotor) | B27: 0.1 | C27: % | D27: RAB lama
A28: Biaya operasional bulanan TJ | B28: 20000000 | C28: Rp | D28: Rujukan BI Sibolga
A29: Target profit nett | B29: 1000000 | C29: Rp | D29: RAB lama

Sheet RAB
A1: RAB INTERNAL - Asesmen Fit and Proper Test, Bank Indonesia (6 peserta)
A2: Biaya psikolog = orang x jam x kali x tarif per jam. Kolom Komponen menghubungkan tiap biaya ke layanan di proposal.
A4: No | B4: Kategori | C4: Item biaya | D4: Orang | E4: Jam / orang | F4: Kali | G4: Qty | H4: Satuan | I4: Tarif | J4: Total | K4: Komponen proposal | L4: Jenis
A5: 1 | B5: Persiapan | C5: Koordinasi kebutuhan dan kompetensi target dengan BI | D5: =Asumsi!$B$10 -> 2 | E5: =Asumsi!$B$12 -> 1 | F5: 1 | G5: =D5*E5*F5 -> 2 | H5: jam | I5: =Asumsi!$B$8 -> 110000 | J5: =G5*I5 -> 220000 | K5: 1 | L5: Honor
A6: 2 | B6: Persiapan | C6: Rubrik penilaian wawancara | D6: =Asumsi!$B$10 -> 2 | E6: =Asumsi!$B$9 -> 2 | F6: 1 | G6: =D6*E6*F6 -> 4 | H6: jam | I6: =Asumsi!$B$8 -> 110000 | J6: =G6*I6 -> 440000 | K6: 1 | L6: Honor
A7: 3 | B7: Persiapan | C7: Rubrik penilaian LGD | D7: =Asumsi!$B$10 -> 2 | E7: =Asumsi!$B$9 -> 2 | F7: 1 | G7: =D7*E7*F7 -> 4 | H7: jam | I7: =Asumsi!$B$8 -> 110000 | J7: =G7*I7 -> 440000 | K7: 1 | L7: Honor
A8: 4 | B8: Persiapan | C8: Studi kasus dan instruksi LGD | D8: 1 | E8: =Asumsi!$B$13 -> 2 | F8: 1 | G8: =D8*E8*F8 -> 2 | H8: jam | I8: =Asumsi!$B$8 -> 110000 | J8: =G8*I8 -> 220000 | K8: 1 | L8: Honor
A9: 5 | B9: Tes | C9: Tes BFI + DISC (platform dan skoring) | D9: 1 | E9: 1 | F9: =Asumsi!$B$3 -> 6 | G9: =D9*E9*F9 -> 6 | H9: peserta | I9: =Asumsi!$B$22 -> 120000 | J9: =G9*I9 -> 720000 | K9: 2 | L9: Langsung
A10: 6 | B10: LGD | C10: Pelaksanaan LGD (fasilitator + asesor) | D10: =Asumsi!$B$15 -> 2 | E10: =Asumsi!$B$14 -> 2 | F10: 1 | G10: =D10*E10*F10 -> 4 | H10: jam | I10: =Asumsi!$B$11 -> 350000 | J10: =G10*I10 -> 1400000 | K10: 3 | L10: Honor
A11: 7 | B11: LGD | C11: Skoring dan catatan perilaku LGD | D11: =Asumsi!$B$15 -> 2 | E11: =Asumsi!$B$16 -> 1 | F11: 1 | G11: =D11*E11*F11 -> 2 | H11: jam | I11: =Asumsi!$B$8 -> 110000 | J11: =G11*I11 -> 220000 | K11: 3 | L11: Honor
A12: 8 | B12: Wawancara | C12: Wawancara oleh psikolog juri utama | D12: 1 | E12: =Asumsi!$B$17 -> 1 | F12: =Asumsi!$B$3 -> 6 | G12: =D12*E12*F12 -> 6 | H12: jam | I12: =Asumsi!$B$11 -> 350000 | J12: =G12*I12 -> 2100000 | K12: 4 | L12: Honor
A13: 9 | B13: Wawancara | C13: Skoring dan catatan wawancara | D13: 1 | E13: =Asumsi!$B$18 -> 0.5 | F13: =Asumsi!$B$3 -> 6 | G13: =D13*E13*F13 -> 3 | H13: jam | I13: =Asumsi!$B$8 -> 110000 | J13: =G13*I13 -> 330000 | K13: 4 | L13: Honor
A14: 10 | B14: Laporan | C14: Penulisan laporan asesmen komprehensif | D14: 1 | E14: =Asumsi!$B$19 -> 2 | F14: =Asumsi!$B$3 -> 6 | G14: =D14*E14*F14 -> 12 | H14: jam | I14: =Asumsi!$B$8 -> 110000 | J14: =G14*I14 -> 1320000 | K14: 5 | L14: Honor
A15: 11 | B15: Laporan | C15: Review mutu laporan oleh juri utama | D15: 1 | E15: =Asumsi!$B$20 -> 0.5 | F15: =Asumsi!$B$3 -> 6 | G15: =D15*E15*F15 -> 3 | H15: jam | I15: =Asumsi!$B$8 -> 110000 | J15: =G15*I15 -> 330000 | K15: 5 | L15: Honor
A16: 12 | B16: Laporan | C16: Rapat integrasi hasil dan rekomendasi | D16: =Asumsi!$B$10 -> 2 | E16: =Asumsi!$B$21 -> 1 | F16: 1 | G16: =D16*E16*F16 -> 2 | H16: jam | I16: =Asumsi!$B$8 -> 110000 | J16: =G16*I16 -> 220000 | K16: 5 | L16: Honor
A17: 13 | B17: Operasional | C17: Admin dan koordinasi jadwal peserta | D17: 1 | E17: 1 | F17: =Asumsi!$B$3 -> 6 | G17: =D17*E17*F17 -> 6 | H17: peserta | I17: =Asumsi!$B$23 -> 35000 | J17: =G17*I17 -> 210000 | K17: Overhead | L17: Langsung
A18: 14 | B18: Operasional | C18: Transport psikolog | D18: 1 | E18: 1 | F18: =Asumsi!$B$25 -> 3 | G18: =D18*E18*F18 -> 3 | H18: orang-hari | I18: =Asumsi!$B$24 -> 150000 | J18: =G18*I18 -> 450000 | K18: Overhead | L18: Langsung
A19: 15 | B19: Operasional | C19: Kontrak dan materai | D19: 1 | E19: 1 | F19: 1 | G19: =D19*E19*F19 -> 1 | H19: deal | I19: =Asumsi!$B$26 -> 150000 | J19: =G19*I19 -> 150000 | K19: Overhead | L19: Langsung
I20: Jumlah Biaya | J20: =SUM(J5:J19) -> 8770000
I21: Biaya per peserta | J21: =J20/Asumsi!$B$3 -> 1461666.7
I22: Total honor psikolog | J22: =SUMIF(L5:L19,"Honor",J5:J19) -> 7240000
B24: PENDAPATAN DAN PROFIT
A25: NILAI AKHIR (harga disepakati BI) | B25: =Asumsi!$B$4 -> 15000000
A26: PPN terutang (0 jika Non-PKP) | B26: =IF(Asumsi!$B$5="PKP",B25-B25/(1+Asumsi!$B$6),0) -> 0
A27: Pendapatan bersih PPN (DPP) | B27: =B25-B26 -> 15000000
A28: PPh 23 dipotong BI | B28: =B27*Asumsi!$B$7 -> 300000
A29: AFTER PAJAK | B29: =B27-B28 -> 14700000
A30: Jumlah Biaya | B30: =RAB!$J$20 -> 8770000
A31: AFTER COST (profit kotor) | B31: =B29-B30 -> 5930000
A32: Komisi | B32: =MAX(0,B31*Asumsi!$B$27) -> 593000
A33: PROFIT NETT | B33: =B31-B32 -> 5337000
A34: Margin nett terhadap harga | B34: =B33/B25 -> 0.3558
A35: Markup harga (DPP) terhadap biaya | B35: =B27/RAB!$J$20-1 -> 0.71037628
A36: Capai target profit nett? | B36: =IF(B33>=Asumsi!$B$29,"Ya","Belum") -> Ya
A37: AFTER COST jika semua sesi oleh psikolog in-house (honor Rp0) | B37: =B31+RAB!$J$22 -> 13170000
A38: % biaya operasional 1 bulan tertutup (profit nett) | B38: =B33/Asumsi!$B$28 -> 0.26685
A40: SKENARIO MARKUP (cek: harga Rp15jt ada di markup berapa)
A41: Markup | B41: Harga jual total | C41: Harga / peserta | D41: Profit nett (setelah pajak, komisi)
A42: 0.3 | B42: =RAB!$J$20*(1+A42) -> 11401000 | C42: =B42/Asumsi!$B$3 -> 1900166.7 | D42: =(B42*(1-Asumsi!$B$7)-RAB!$J$20)*(1-Asumsi!$B$27) -> 2162682
A43: 0.4 | B43: =RAB!$J$20*(1+A43) -> 12278000 | C43: =B43/Asumsi!$B$3 -> 2046333.3 | D43: =(B43*(1-Asumsi!$B$7)-RAB!$J$20)*(1-Asumsi!$B$27) -> 2936196
...

Sheet Harga Proposal
A1: HARGA PER LAYANAN UNTUK PROPOSAL (harga jual, bukan biaya). Sel biru = harga yang ditulis di proposal.
A2: Total harus sama dengan harga disepakati BI. Overhead dibagi ke tiap layanan sesuai porsi biaya langsungnya.
A4: No | B4: Layanan (bahasa proposal) | C4: Volume | D4: Satuan | E4: Harga satuan | F4: Jumlah | G4: Biaya langsung | H4: Biaya + porsi overhead | I4: Markup
A5: 1 | B5: Penyesuaian kebutuhan dan penyusunan rubrik penilaian | C5: 1 | D5: paket | E5: 2800000 | F5: =C5*E5 -> 2800000 | G5: =SUMIF(RAB!$K$5:$K$19,A5,RAB!$J$5:$J$19) -> 1320000 | H5: =G5+G5/SUM($G$5:$G$9)*SUMIF(RAB!$K$5:$K$19,"Overhead",RAB!$J$5:$J$19) -> 1454321.6 | I5: =F5/H5-1 -> 0.92529629
A6: 2 | B6: Tes psikologi BFI dan DISC | C6: =Asumsi!$B$3 -> 6 | D6: peserta | E6: 200000 | F6: =C6*E6 -> 1200000 | G6: =SUMIF(RAB!$K$5:$K$19,A6,RAB!$J$5:$J$19) -> 720000 | H6: =G6+G6/SUM($G$5:$G$9)*SUMIF(RAB!$K$5:$K$19,"Overhead",RAB!$J$5:$J$19) -> 793266.33 | I6: =F6/H6-1 -> 0.5127328
A7: 3 | B7: Leaderless Group Discussion (LGD) | C7: 1 | D7: sesi | E7: 2750000 | F7: =C7*E7 -> 2750000 | G7: =SUMIF(RAB!$K$5:$K$19,A7,RAB!$J$5:$J$19) -> 1620000 | H7: =G7+G7/SUM($G$5:$G$9)*SUMIF(RAB!$K$5:$K$19,"Overhead",RAB!$J$5:$J$19) -> 1784849.2 | I7: =F7/H7-1 -> 0.54074637
A8: 4 | B8: Wawancara oleh psikolog juri utama | C8: =Asumsi!$B$3 -> 6 | D8: peserta | E8: 675000 | F8: =C8*E8 -> 4050000 | G8: =SUMIF(RAB!$K$5:$K$19,A8,RAB!$J$5:$J$19) -> 2430000 | H8: =G8+G8/SUM($G$5:$G$9)*SUMIF(RAB!$K$5:$K$19,"Overhead",RAB!$J$5:$J$19) -> 2677273.9 | I8: =F8/H8-1 -> 0.5127328
A9: 5 | B9: Laporan asesmen komprehensif dan rekomendasi | C9: =Asumsi!$B$3 -> 6 | D9: peserta | E9: 700000 | F9: =C9*E9 -> 4200000 | G9: =SUMIF(RAB!$K$5:$K$19,A9,RAB!$J$5:$J$19) -> 1870000 | H9: =G9+G9/SUM($G$5:$G$9)*SUMIF(RAB!$K$5:$K$19,"Overhead",RAB!$J$5:$J$19) -> 2060288.9 | I9: =F9/H9-1 -> 1.038549
B10: TOTAL | F10: =SUM(F5:F9) -> 15000000 | G10: =SUM(G5:G9) -> 7960000 | H10: =SUM(H5:H9) -> 8770000 | I10: =F10/H10-1 -> 0.71037628
B11: Harga per peserta | F11: =F10/Asumsi!$B$3 -> 2500000
B12: Cek: total = harga disepakati BI | F12: =IF(F10=Asumsi!$B$4,"OK","TIDAK SAMA") -> OK

Sheet RAB Lama vs Baru
A1: Kenapa RAB lama tidak bisa dipakai: total biayanya Rp15.020.000, lebih besar dari harga Rp15.000.000
A3: Item RAB lama | B3: RAB lama | C3: Baris RAB baru | D3: RAB baru | E3: Selisih | F3: Kenapa berubah
A4: Psikolog juri utama (Rp750.000 x 6 kandidat) | B4: 4500000 | C4: 8-9 | D4: =RAB!$J$12+RAB!$J$13 -> 2430000 | E4: =D4-B4 -> -2070000 | F4: Lama: tarif borongan per kandidat tanpa dasar jam. Baru: 1 jam wawancara (Rp350rb/jam) + 0,5 jam skoring (Rp110rb/jam) per peserta
A5: Psikolog LGD (Rp2.000.000 per sesi) | B5: 2000000 | C5: 6-7 | D5: =RAB!$J$10+RAB!$J$11 -> 1620000 | E5: =D5-B5 -> -380000 | F5: Baru: 2 psikolog x 2 jam tatap muka + 1 jam skoring masing-masing
A6: BFI - DISC (Rp120.000 x 6) | B6: 720000 | C6: 5 | D6: =RAB!$J$9 -> 720000 | E6: =D6-B6 -> 0 | F6: Tidak berubah
A7: Rubrik asesmen LGD (Rp2.500.000) | B7: 2500000 | C7: 3-4 | D7: =RAB!$J$7+RAB!$J$8 -> 660000 | E7: =D7-B7 -> -1840000 | F7: Baru: 2 psikolog x 2 jam x Rp110rb/jam, ditambah studi kasus LGD 2 jam
A8: Rubrik asesmen wawancara (Rp2.750.000) | B8: 2750000 | C8: 1-2 | D8: =RAB!$J$5+RAB!$J$6 -> 660000 | E8: =D8-B8 -> -2090000 | F8: Baru: 2 psikolog x 2 jam x Rp110rb/jam, ditambah 1 jam koordinasi kebutuhan BI per psikolog
A9: Laporan asesmen komprehensif (Rp425.000 x 6) | B9: 2550000 | C9: 10-12 | D9: =RAB!$J$14+RAB!$J$15+RAB!$J$16 -> 1870000 | E9: =D9-B9 -> -680000 | F9: Baru: 2 jam tulis + 0,5 jam review per laporan, ditambah 1 jam rapat integrasi per psikolog
A10: (tidak ada) | B10: 0 | C10: 13-15 | D10: =RAB!$J$17+RAB!$J$18+RAB!$J$19 -> 810000 | E10: =D10-B10 -> 810000 | F10: Baru: admin, transport, kontrak dan materai yang dulu belum dihitung
A11: TOTAL BIAYA | B11: =SUM(B4:B10) -> 15020000 | D11: =SUM(D4:D10) -> 8770000 | E11: =SUM(E4:E10) -> -6250000
A12: Profit kotor pada harga Rp15jt (sebelum pajak dan komisi) | B12: =Asumsi!$B$4-B11 -> -20000 | D12: =Asumsi!$B$4-D11 -> 6230000
